Workbook
Name RiskMatrixRef: '[2]set up'!$C$14
Name RiskMatrixRef: 'set up'!$C$14

Sheet Data Rights Notice

Sheet 0700 Mooring
O2: Risk Ranking | AA2: Updated Risk Ranking | AM2: 2nd Updated Risk Ranking
B4: 0700 Mooring FMECA Table | P4: Severity Class | T4: Risk Class | AB4: Severity Class | AF4: Risk Class | AN4: Severity Class | AR4: Risk Class
B5: Risk ID | C5: Item Description | D5: Function | E5: Tech. Class | F5: Novel Aspects | G5: Failure Mode | H5: Failure Effects (Local, WEC, System) | I5: Failure Cause(s) | J5: Initial Mode of Operation | K5: Risk Reduction Design | L5: Preventative Detection | M5: Post Failure Detection | N5: Post Failure Repair Strategy (automated, manual) | O5: Occurrence | P5: Human Safety | Q5: Environment | R5: Operation | S5: Assets | T5: Human Safety | U5: Environment | V5: Operation | W5: Assets | X5: Recommended Actions | Y5: Responsible Party | Z5: Actions Taken | AA5: Occurrence | AB5: Human Safety | AC5: Environment | AD5: Operation | AE5: Assets | AF5: Human Safety | AG5: Environment | AH5: Operation | AI5: Assets | AJ5: 2nd Recommended Actions | AK5: Responsible Party (2nd) | AL5: Actions Taken (2nd) | AM5: Occurrence | AN5: Human Safety | AO5: Environment | AP5: Operation | AQ5: Assets | AR5: Human Safety | AS5: Environment | AT5: Operation | AU5: Assets | AV5: Status (open or closed) | AW5: Notes
B6: 0700 | C6: Mooring system (this line is a placeholder for notes) | T6: =IF(AND(ISNUMBER(P6),ISNUMBER($O6)),OFFSET(RiskMatrixRef,-$O6+1,P6-1),"") | U6: =IF(AND(ISNUMBER(Q6),ISNUMBER($O6)),OFFSET(RiskMatrixRef,-$O6+1,Q6-1),"") | V6: =IF(AND(ISNUMBER(R6),ISNUMBER($O6)),OFFSET(RiskMatrixRef,-$O6+1,R6-1),"") | W6: =IF(AND(ISNUMBER(S6),ISNUMBER($O6)),OFFSET(RiskMatrixRef,-$O6+1,S6-1),"") | AW6: 1) mooring system for the prototype deployment is an adaptation to an existing 'universal' mooring system… mooring for future systems not expected to be similar, aside from perhaps the bridle
B7: 0710-1 | C7: Single point (Hawser lines, Shackles and Pendants) | D7: Primary station keeping | E7: 2 | F7: Loading | G7: Double hawser failure (including hardware failure) | H7: 1) Loss of station keeping 2) Loss of umbilical (see 0800) 4) BOB - buoy on beach or BOTS - buoy out to sea 5) Loss of primary fiber communications | I7: Extreme load induced damage (Overload) | J7: Normal | K7: none | L7: none | M7: 1) GPS watch circle alarm 2) Yaw direction detection 3) Mooring load cells 4) Visual detection 5) Loss of umbilical connectivity | N7: Mooring: Repair/replace on site Umbilical: Repair/replace on site… but long lead time (~12mo) WEC Hull: recover WEC, dry dock repair | O7: 3 | P7: 4 | Q7: 7 | R7: 9 | S7: 9 | T7: =IF(AND(ISNUMBER(P7),ISNUMBER($O7)),OFFSET(RiskMatrixRef,-$O7+1,P7-1),"") -> Low | U7: =IF(AND(ISNUMBER(Q7),ISNUMBER($O7)),OFFSET(RiskMatrixRef,-$O7+1,Q7-1),"") -> Low | V7: =IF(AND(ISNUMBER(R7),ISNUMBER($O7)),OFFSET(RiskMatrixRef,-$O7+1,R7-1),"") -> Med | W7: =IF(AND(ISNUMBER(S7),ISNUMBER($O7)),OFFSET(RiskMatrixRef,-$O7+1,S7-1),"") -> Med | X7: 1) design of umibilical to incorporate repairable weak link to allow for shorter repair time and reduced cost of failure 2) A salvage/emergency response plan to be defined prior to first deployment, stating the mitigating actions for the failure and the expected time window for the operation(s) to be carried out. It needs to be demonstrated that the expected time window is achievable for the sudden occurrence of the event | Y7: 1) Marine contractor feasibility study 2) Marine contractor | AW7: Assumes that buoy on beach results in significant damage to the structure
B8: 0710-2 | C8: Single point (Hawser lines, Shackles and Pendants) | D8: Primary station keeping | E8: 2 | F8: Loading | G8: Double hawser failure (including hardware failure) | H8: 1) Loss of station keeping 2) Loss of umbilical (see 0800) 4) BOB - buoy on beach or BOTS - buoy out to sea 5) Loss of primary fiber communications | I8: Snap loads | J8: Normal | K8: none | L8: none | M8: 1) GPS watch circle alarm 2) Yaw direction detection 3) Mooring load cells 4) Visual detection 5) Loss of umbilical connectivity | N8: Mooring: Repair/replace on site Umbilical: Repair/replace on site… but long lead time (~12mo) WEC Hull: recover WEC, dry dock repair | O8: 3 | P8: 4 | Q8: 7 | R8: 9 | S8: 9 | T8: =IF(AND(ISNUMBER(P8),ISNUMBER($O8)),OFFSET(RiskMatrixRef,-$O8+1,P8-1),"") -> Low | U8: =IF(AND(ISNUMBER(Q8),ISNUMBER($O8)),OFFSET(RiskMatrixRef,-$O8+1,Q8-1),"") -> Low | V8: =IF(AND(ISNUMBER(R8),ISNUMBER($O8)),OFFSET(RiskMatrixRef,-$O8+1,R8-1),"") -> Med | W8: =IF(AND(ISNUMBER(S8),ISNUMBER($O8)),OFFSET(RiskMatrixRef,-$O8+1,S8-1),"") -> Med | X8: 1) design of umibilical to incorporate repairable weak link to allow for shorter repair time and reduced cost of failure 2) A salvage/emergency response plan to be defined prior to first deployment, stating the mitigating actions for the failure and the expected time window for the operation(s) to be carried out. It needs to be demonstrated that the expected time window is achievable for the sudden occurrence of the event 3) load cases to include investigation of snap loading | AW8: Assumes that buoy on beach results in significant damage to the structure
B9: 0710-3 | C9: Single point (Hawser lines, Shackles and Pendants) | D9: Primary station keeping | E9: 2 | F9: Loading | G9: Double hawser failure (including hardware failure) | H9: 1) Loss of station keeping 2) Loss of umbilical (see 0800) 4) BOB - buoy on beach or BOTS - buoy out to sea 5) Loss of primary fiber communications | I9: fatigue induced damage | J9: Normal | K9: 1) Material selection and component sizing | L9: Regularly scheduled visual inspection, with repair/ replacement as needed | M9: 1) GPS watch circle alarm 2) Yaw direction detection 3) Mooring load cells 4) Visual detection 5) Loss of umbilical connectivity | N9: Mooring: Repair/replace on site Umbilical: Repair/replace on site… but long lead time (~12mo) WEC Hull: recover WEC, dry dock repair | O9: 3 | P9: 4 | Q9: 7 | R9: 9 | S9: 9 | T9: =IF(AND(ISNUMBER(P9),ISNUMBER($O9)),OFFSET(RiskMatrixRef,-$O9+1,P9-1),"") -> Low | U9: =IF(AND(ISNUMBER(Q9),ISNUMBER($O9)),OFFSET(RiskMatrixRef,-$O9+1,Q9-1),"") -> Low | V9: =IF(AND(ISNUMBER(R9),ISNUMBER($O9)),OFFSET(RiskMatrixRef,-$O9+1,R9-1),"") -> Med | W9: =IF(AND(ISNUMBER(S9),ISNUMBER($O9)),OFFSET(RiskMatrixRef,-$O9+1,S9-1),"") -> Med | X9: 1) design of umibilical to incorporate repairable weak link to allow for shorter repair time and reduced cost of failure 2) A salvage/emergency response plan to be defined prior to first deployment, stating the mitigating actions for the failure and the expected time window for the operation(s) to be carried out. It needs to be demonstrated that the expected time window is achievable for the sudden occurrence of the event | Y9: 1) Marine contractor feasibility study 2) Marine contractor | AW9: Assumes that buoy on beach results in significant damage to the structure
B10: 0710-4 | C10: Single point (Hawser lines, Shackles and Pendants) | D10: Primary station keeping | E10: 2 | F10: Loading | G10: Double hawser failure (including hardware failure) | H10: 1) Loss of station keeping 2) Loss of umbilical (see 0800) 4) BOB - buoy on beach or BOTS - buoy out to sea 5) Loss of primary fiber communications | I10: Non-service ship strike | J10: Normal | K10: 1) Lights, radar reflectors (e.g. visibility) 2) Hawsers and hardware below ship draft (~4m) | L10: none | M10: 1) GPS watch circle alarm 2) Yaw direction detection 3) Mooring load cells 4) Visual detection 5) Loss of umbilical connectivity | N10: Mooring: Repair/replace on site Umbilical: Repair/replace on site… but long lead time (~12mo) WEC Hull: recover WEC, dry dock repair | O10: 2 | P10: 4 | Q10: 7 | R10: 9 | S10: 9 | T10: =IF(AND(ISNUMBER(P10),ISNUMBER($O10)),OFFSET(RiskMatrixRef,-$O10+1,P10-1),"") -> Low | U10: =IF(AND(ISNUMBER(Q10),ISNUMBER($O10)),OFFSET(RiskMatrixRef,-$O10+1,Q10-1),"") -> Low | V10: =IF(AND(ISNUMBER(R10),ISNUMBER($O10)),OFFSET(RiskMatrixRef,-$O10+1,R10-1),"") -> Low | W10: =IF(AND(ISNUMBER(S10),ISNUMBER($O10)),OFFSET(RiskMatrixRef,-$O10+1,S10-1),"") -> Low | X10: 1) design of umibilical to incorporate repairable weak link to allow for shorter repair time and reduced cost of failure 2) A salvage/emergency response plan to be defined prior to first deployment, stating the mitigating actions for the failure and the expected time window for the operation(s) to be carried out. It needs to be demonstrated that the expected time window is achievable for the sudden occurrence of the event 3) establish exclusion zone at deployed area | Y10: 1) Marine contractor | AW10: Assumes that buoy on beach results in significant damage to the structure
B11: 0710-5 | C11: Single point (Hawser lines, Shackles and Pendants) | D11: Primary station keeping | E11: 2 | F11: Loading | G11: Double hawser failure (including hardware failure) | H11: 1) Loss of station keeping 2) Loss of umbilical (see 0800) 4) BOB - buoy on beach or BOTS - buoy out to sea 5) Loss of primary fiber communications | I11: Vandalism/ negligence | J11: Normal | K11: 1) Surveillance system 2) Hawsers and hardware below easy access (~4m) | L11: none | M11: 1) GPS watch circle alarm 2) Yaw direction detection 3) Mooring load cells 4) Visual detection 5) Loss of umbilical connectivity | N11: Mooring: Repair/replace on site Umbilical: Repair/replace on site… but long lead time (~12mo) WEC Hull: recover WEC, dry dock repair | O11: 4 | P11: 4 | Q11: 7 | R11: 9 | S11: 9 | T11: =IF(AND(ISNUMBER(P11),ISNUMBER($O11)),OFFSET(RiskMatrixRef,-$O11+1,P11-1),"") -> Low | U11: =IF(AND(ISNUMBER(Q11),ISNUMBER($O11)),OFFSET(RiskMatrixRef,-$O11+1,Q11-1),"") -> Low | V11: =IF(AND(ISNUMBER(R11),ISNUMBER($O11)),OFFSET(RiskMatrixRef,-$O11+1,R11-1),"") -> Med | W11: =IF(AND(ISNUMBER(S11),ISNUMBER($O11)),OFFSET(RiskMatrixRef,-$O11+1,S11-1),"") -> Med | X11: 1) design of umibilical to incorporate repairable weak link to allow for shorter repair time and reduced cost of failure 2) A salvage/emergency response plan to be defined prior to first deployment, stating the mitigating actions for the failure and the expected time window for the operation(s) to be carried out. It needs to be demonstrated that the expected time window is achievable for the sudden occurrence of the event | Y11: 1) Marine contractor feasibility study | AW11: Assumes that buoy on beach results in significant damage to the structure
B12: 0712-1 | C12: Single point chain (vertical) | D12: Keep foam buoy in position Connecting sinker to buoy | E12: 2 | F12: Loading | G12: Line break | H12: 1) Change to WEC orientation 2) Sub-optimal WEC response 3) Possible entaglement between single point sinker and umbilical | I12: Extreme load induced damage | J12: Normal | K12: none | L12: none | M12: 1) Visual detection | N12: Replace on site | O12: 5 | P12: 1 | Q12: 1 | R12: 4 | S12: 4 | T12: =IF(AND(ISNUMBER(P12),ISNUMBER($O12)),OFFSET(RiskMatrixRef,-$O12+1,P12-1),"") -> Low | U12: =IF(AND(ISNUMBER(Q12),ISNUMBER($O12)),OFFSET(RiskMatrixRef,-$O12+1,Q12-1),"") -> Low | V12: =IF(AND(ISNUMBER(R12),ISNUMBER($O12)),OFFSET(RiskMatrixRef,-$O12+1,R12-1),"") -> Low | W12: =IF(AND(ISNUMBER(S12),ISNUMBER($O12)),OFFSET(RiskMatrixRef,-$O12+1,S12-1),"") -> Low | X12: none | AW12: 4.5 ton sinker (0715) will be supported by WEC reserve buoyancy in event of single point chain failure rather than by buoy (0714). WEC performance will be negatively effected, but no stability issues expected
B13: 0712-2 | C13: Single point chain (vertical) | D13: Keep foam buoy in position Connecting sinker to buoy | E13: 2 | F13: Loading | G13: Line break | H13: 1) Change to WEC orientation 2) Sub-optimal WEC response 3) Possible entaglement between single point sinker and umbilical | I13: Snap loads | J13: Normal | K13: none | L13: none | M13: 1) Visual detection | N13: Replace on site | O13: 4 | P13: 1 | Q13: 1 | R13: 4 | S13: 4 | T13: =IF(AND(ISNUMBER(P13),ISNUMBER($O13)),OFFSET(RiskMatrixRef,-$O13+1,P13-1),"") -> Low | U13: =IF(AND(ISNUMBER(Q13),ISNUMBER($O13)),OFFSET(RiskMatrixRef,-$O13+1,Q13-1),"") -> Low | V13: =IF(AND(ISNUMBER(R13),ISNUMBER($O13)),OFFSET(RiskMatrixRef,-$O13+1,R13-1),"") -> Low | W13: =IF(AND(ISNUMBER(S13),ISNUMBER($O13)),OFFSET(RiskMatrixRef,-$O13+1,S13-1),"") -> Low | X13: 1) load cases to include investigation of snap loading
B14: 0712-3 | C14: Single point chain (vertical) | D14: Keep foam buoy in position Connecting sinker to buoy | E14: 2 | F14: Loading | G14: Line break | H14: 1) Change to WEC orientation 2) Sub-optimal WEC response 3) Possible entaglement between single point sinker and umbilical | I14: fatigue induced damage | J14: Normal | K14: none | L14: Regularly scheduled visual inspection, with repair/ replacement as needed | M14: 1) Visual detection | N14: Replace on site | O14: 7 | P14: 1 | Q14: 1 | R14: 4 | S14: 4 | T14: =IF(AND(ISNUMBER(P14),ISNUMBER($O14)),OFFSET(RiskMatrixRef,-$O14+1,P14-1),"") -> Low | U14: =IF(AND(ISNUMBER(Q14),ISNUMBER($O14)),OFFSET(RiskMatrixRef,-$O14+1,Q14-1),"") -> Low | V14: =IF(AND(ISNUMBER(R14),ISNUMBER($O14)),OFFSET(RiskMatrixRef,-$O14+1,R14-1),"") -> Low | W14: =IF(AND(ISNUMBER(S14),ISNUMBER($O14)),OFFSET(RiskMatrixRef,-$O14+1,S14-1),"") -> Low | X14: none
B15: 0712-4 | C15: Single point chain (vertical) | D15: Keep foam buoy in position Connecting sinker to buoy | E15: 2 | F15: Loading | G15: Line break | H15: 1) Change to WEC orientation 2) Sub-optimal WEC response 3) Possible entaglement between single point sinker and umbilical | I15: Non-service ship strike | J15: Normal | K15: 1) Lights, radar reflectors (e.g. visibility) | L15: none | M15: 1) Visual detection | N15: Replace on site | O15: 3 | P15: 4 | Q15: 1 | R15: 4 | S15: 4 | T15: =IF(AND(ISNUMBER(P15),ISNUMBER($O15)),OFFSET(RiskMatrixRef,-$O15+1,P15-1),"") -> Low | U15: =IF(AND(ISNUMBER(Q15),ISNUMBER($O15)),OFFSET(RiskMatrixRef,-$O15+1,Q15-1),"") -> Low | V15: =IF(AND(ISNUMBER(R15),ISNUMBER($O15)),OFFSET(RiskMatrixRef,-$O15+1,R15-1),"") -> Low | W15: =IF(AND(ISNUMBER(S15),ISNUMBER($O15)),OFFSET(RiskMatrixRef,-$O15+1,S15-1),"") -> Low | X15: 1) establish exclusion zone at deployed area
B16: 0712-5 | C16: Single point chain (vertical) | D16: Keep foam buoy in position Connecting sinker to buoy | E16: 2 | F16: Loading | G16: Line break | H16: 1) Change to WEC orientation 2) Sub-optimal WEC response 3) Possible entaglement between single point sinker and umbilical | I16: Corrosion | J16: Normal | K16: none | L16: Regularly scheduled visual inspection, with repair/ replacement as needed | M16: 1) Visual detection | N16: Replace on site | O16: 7 | P16: 1 | Q16: 1 | R16: 4 | S16: 4 | T16: =IF(AND(ISNUMBER(P16),ISNUMBER($O16)),OFFSET(RiskMatrixRef,-$O16+1,P16-1),"") -> Low | U16: =IF(AND(ISNUMBER(Q16),ISNUMBER($O16)),OFFSET(RiskMatrixRef,-$O16+1,Q16-1),"") -> Low | V16: =IF(AND(ISNUMBER(R16),ISNUMBER($O16)),OFFSET(RiskMatrixRef,-$O16+1,R16-1),"") -> Low | W16: =IF(AND(ISNUMBER(S16),ISNUMBER($O16)),OFFSET(RiskMatrixRef,-$O16+1,S16-1),"") -> Low | X16: none
B17: 0713-1 | C17: Single point hawser lines | D17: Load transfer from Bridle to WETS moorings Provide restoring forces for position keeping | E17: 2 | F17: Loading Material integrity subjected to marine environment: Exposure to UV, marine growth control | G17: Single hawser failure | H17: 1) Change in mooring system response and loads 2) Significantly greater watch circle 3) Loss of aft mooring line 4) Loss of umbilical connectivity (see 0800) | I17: Extreme load induced damage (Overload) | J17: Normal | K17: 1) Redundant system (WEC remains moored) | L17: none | M17: 1) GPS watch circle alarm 2) Visual detection 3) Loss of umbilical connectivity | N17: Mooring: Repair/replace on site Umbilical: Repair/replace on site… but long lead time (~12mo) | O17: 5 | P17: 1 | Q17: 1 | R17: 9 | S17: 7 | T17: =IF(AND(ISNUMBER(P17),ISNUMBER($O17)),OFFSET(RiskMatrixRef,-$O17+1,P17-1),"") -> Low | U17: =IF(AND(ISNUMBER(Q17),ISNUMBER($O17)),OFFSET(RiskMatrixRef,-$O17+1,Q17-1),"") -> Low | V17: =IF(AND(ISNUMBER(R17),ISNUMBER($O17)),OFFSET(RiskMatrixRef,-$O17+1,R17-1),"") -> Med | W17: =IF(AND(ISNUMBER(S17),ISNUMBER($O17)),OFFSET(RiskMatrixRef,-$O17+1,S17-1),"") -> Med | X17: 1) design of umibilical to incorporate repairable weak link to allow for shorter repair time and reduced cost of failure 2) Load derivation methodology to take into account the uncertainties in the loading due to site characterisation measurements and hydrodynamic modelling. 3) CPwr to demonstrate the derivation of loading is conservative for the site, including providing evidence from site assessment and validation of the overall loading upon deployment. | AF17: =IF(AND(ISNUMBER(AB17),ISNUMBER($AA17)),OFFSET(RiskMatrixRef,-$AA17+1,AB17-1),"") | AG17: =IF(AND(ISNUMBER(AC17),ISNUMBER($AA17)),OFFSET(RiskMatrixRef,-$AA17+1,AC17-1),"") | AH17: =IF(AND(ISNUMBER(AD17),ISNUMBER($AA17)),OFFSET(RiskMatrixRef,-$AA17+1,AD17-1),"") | AI17: =IF(AND(ISNUMBER(AE17),ISNUMBER($AA17)),OFFSET(RiskMatrixRef,-$AA17+1,AE17-1),"") | AR17: =IF(AND(ISNUMBER(AN17),ISNUMBER($AM17)),OFFSET(RiskMatrixRef,-$AM17+1,AN17-1),"") | AS17: =IF(AND(ISNUMBER(AO17),ISNUMBER($AM17)),OFFSET(RiskMatrixRef,-$AM17+1,AO17-1),"") | AT17: =IF(AND(ISNUMBER(AP17),ISNUMBER($AM17)),OFFSET(RiskMatrixRef,-$AM17+1,AP17-1),"") | AU17: =IF(AND(ISNUMBER(AQ17),ISNUMBER($AM17)),OFFSET(RiskMatrixRef,-$AM17+1,AQ17-1),"")
B18: 0713-2 | C18: Single point hawser lines | D18: Load transfer from Bridle to WETS moorings Provide restoring forces for position keeping | E18: 2 | F18: Loading Material integrity subjected to marine environment: Exposure to UV, marine growth control | G18: Single hawser failure | H18: 1) Change in mooring system response and loads 2) Significantly greater watch circle 3) Loss of aft mooring line 4) Loss of umbilical connectivity (see 0800) | I18: Snap loads | J18: Normal | K18: 1) Redundant system (WEC remains moored) | L18: none | M18: 1) GPS watch circle alarm 2) Visual detection 3) Loss of umbilical connectivity | N18: Mooring: Repair/replace on site Umbilical: Repair/replace on site… but long lead time (~12mo) | O18: 4 | P18: 1 | Q18: 1 | R18: 9 | S18: 7 | T18: =IF(AND(ISNUMBER(P18),ISNUMBER($O18)),OFFSET(RiskMatrixRef,-$O18+1,P18-1),"") -> Low | U18: =IF(AND(ISNUMBER(Q18),ISNUMBER($O18)),OFFSET(RiskMatrixRef,-$O18+1,Q18-1),"") -> Low | V18: =IF(AND(ISNUMBER(R18),ISNUMBER($O18)),OFFSET(RiskMatrixRef,-$O18+1,R18-1),"") -> Med | W18: =IF(AND(ISNUMBER(S18),ISNUMBER($O18)),OFFSET(RiskMatrixRef,-$O18+1,S18-1),"") -> Low | X18: 1) design of umibilical to incorporate repairable weak link to allow for shorter repair time and reduced cost of failure 2) load cases to include investigation of snap loading
B19: 0713-3 | C19: Single point hawser lines | D19: Load transfer from Bridle to WETS moorings Provide restoring forces for position keeping | E19: 2 | F19: Loading Material integrity subjected to marine environment: Exposure to UV, marine growth control | G19: Single hawser failure | H19: 1) Change in mooring system response and loads 2) Significantly greater watch circle 3) Loss of aft mooring line 4) Loss of umbilical connectivity (see 0800) | I19: Fatigue induced damage | J19: Normal | K19: 1) Redundant system (WEC remains moored) | L19: Regularly scheduled visual inspection, with repair/ replacement as needed | M19: 1) GPS watch circle alarm 2) Visual detection 3) Loss of umbilical connectivity | N19: Mooring: Repair/replace on site Umbilical: Repair/replace on site… but long lead time (~12mo) | O19: 7 | P19: 1 | Q19: 1 | R19: 9 | S19: 7 | T19: =IF(AND(ISNUMBER(P19),ISNUMBER($O19)),OFFSET(RiskMatrixRef,-$O19+1,P19-1),"") -> Low | U19: =IF(AND(ISNUMBER(Q19),ISNUMBER($O19)),OFFSET(RiskMatrixRef,-$O19+1,Q19-1),"") -> Low | V19: =IF(AND(ISNUMBER(R19),ISNUMBER($O19)),OFFSET(RiskMatrixRef,-$O19+1,R19-1),"") -> High | W19: =IF(AND(ISNUMBER(S19),ISNUMBER($O19)),OFFSET(RiskMatrixRef,-$O19+1,S19-1),"") -> Med | X19: 1) design of umibilical to incorporate repairable weak link to allow for shorter repair time and reduced cost of failure 2) Load derivation methodology to take into account the uncertainties in the loading due to site characterisation measurements and hydrodynamic modelling. 3) CPwr to demonstrate the derivation of loading is conservative for the site, including providing evidence from site assessment and validation of the overall loading upon deployment.
B20: 0713-4 | C20: Single point hawser lines | D20: Load transfer from Bridle to WETS moorings Provide restoring forces for position keeping | E20: 2 | F20: Loading Material integrity subjected to marine environment: Exposure to UV, marine growth control | G20: Single hawser failure | H20: 1) Change in mooring system response and loads 2) Significantly greater watch circle 3) Loss of aft mooring line 4) Loss of umbilical connectivity (see 0800) | I20: Non-service ship strike | J20: Normal | K20: 1) Redundant system (WEC remains moored) 2) Lights, radar reflectors (e.g. visibility) 3) Hawsers and hardware below ship draft (~4m) | L20: none | M20: 1) GPS watch circle alarm 2) Visual detection 3) Loss of umbilical connectivity | N20: Mooring: Repair/replace on site Umbilical: Repair/replace on site… but long lead time (~12mo) | O20: 3 | P20: 1 | Q20: 1 | R20: 9 | S20: 7 | T20: =IF(AND(ISNUMBER(P20),ISNUMBER($O20)),OFFSET(RiskMatrixRef,-$O20+1,P20-1),"") -> Low | U20: =IF(AND(ISNUMBER(Q20),ISNUMBER($O20)),OFFSET(RiskMatrixRef,-$O20+1,Q20-1),"") -> Low | V20: =IF(AND(ISNUMBER(R20),ISNUMBER($O20)),OFFSET(RiskMatrixRef,-$O20+1,R20-1),"") -> Med | W20: =IF(AND(ISNUMBER(S20),ISNUMBER($O20)),OFFSET(RiskMatrixRef,-$O20+1,S20-1),"") -> Low | X20: 1) design of umibilical to incorporate repairable weak link to allow for shorter repair time and reduced cost of failure 2) establish exclusion zone at deployed area | AW20: probability of occurrence to be reviewed; if there are likely to be ships in the area with draft more than 3-4 m, then the occurrence will be higher than 3
B21: 0713-5 | C21: Single point hawser lines | D21: Load transfer from Bridle to WETS moorings Provide restoring forces for position keeping | E21: 2 | F21: Loading Material integrity subjected to marine environment: Exposure to UV, marine growth control | G21: Single hawser failure | H21: 1) Change in mooring system response and loads 2) Significantly greater watch circle 3) Loss of aft mooring line 4) Loss of umbilical connectivity (see 0800) | I21: Fish bite | J21: Normal | K21: 1) Redundant system (WEC remains moored) | L21: Regularly scheduled visual inspection, with repair/ replacement as needed | M21: 1) GPS watch circle alarm 2) Visual detection | N21: Mooring: Repair/replace on site Umbilical: Repair/replace on site… but long lead time (~12mo) | O21: 8 | P21: 1 | Q21: 1 | R21: 9 | S21: 7 | T21: =IF(AND(ISNUMBER(P21),ISNUMBER($O21)),OFFSET(RiskMatrixRef,-$O21+1,P21-1),"") -> Low | U21: =IF(AND(ISNUMBER(Q21),ISNUMBER($O21)),OFFSET(RiskMatrixRef,-$O21+1,Q21-1),"") -> Low | V21: =IF(AND(ISNUMBER(R21),ISNUMBER($O21)),OFFSET(RiskMatrixRef,-$O21+1,R21-1),"") -> High | W21: =IF(AND(ISNUMBER(S21),ISNUMBER($O21)),OFFSET(RiskMatrixRef,-$O21+1,S21-1),"") -> Med | X21: 1) design of umibilical to incorporate repairable weak link to allow for shorter repair time and reduced cost of failure 2) analysis: expected fish bite failures and detectability with regular inspections 3) protective sheath on the lines at risk for fish bite, if warranted | Y21: 1) Marine contractor 2) Marine contractor feasibility study
B22: 0713-6 | C22: Single point hawser lines | D22: Load transfer from Bridle to WETS moorings Provide restoring forces for position keeping | E22: 2 | F22: Loading Material integrity subjected to marine environment: Exposure to UV, marine growth control | G22: Single hawser failure | H22: 1) Change in mooring system response and loads 2) Significantly greater watch circle 3) Loss of aft mooring line 4) Loss of umbilical connectivity (see 0800) | I22: Vandalism/ negligence | J22: Normal | K22: 1) Redundant system (WEC remains moored) 2) Surveillance system 3) Hawsers and hardware below easy access (~4m) | L22: none | M22: 1) GPS watch circle alarm 2) Visual detection 3) Loss of umbilical connectivity | N22: Mooring: Repair/replace on site Umbilical: Repair/replace on site… but long lead time (~12mo) | O22: 4 | P22: 1 | Q22: 1 | R22: 9 | S22: 7 | T22: =IF(AND(ISNUMBER(P22),ISNUMBER($O22)),OFFSET(RiskMatrixRef,-$O22+1,P22-1),"") -> Low | U22: =IF(AND(ISNUMBER(Q22),ISNUMBER($O22)),OFFSET(RiskMatrixRef,-$O22+1,Q22-1),"") -> Low | V22: =IF(AND(ISNUMBER(R22),ISNUMBER($O22)),OFFSET(RiskMatrixRef,-$O22+1,R22-1),"") -> Med | W22: =IF(AND(ISNUMBER(S22),ISNUMBER($O22)),OFFSET(RiskMatrixRef,-$O22+1,S22-1),"") -> Low | X22: 1) design of umibilical to incorporate repairable weak link to allow for shorter repair time and reduced cost of failure | Y22: 1) Marine contractor 2) Marine contractor feasibility study
B23: 0713-7 | C23: Single point hawser lines | D23: Load transfer from Bridle to WETS moorings Provide restoring forces for position keeping | E23: 2 | F23: Loading Material integrity subjected to marine environment: Exposure to UV, marine growth control | G23: Single hawser failure | H23: 1) Change in mooring system response and loads 2) Significantly greater watch circle 3) Loss of aft mooring line 4) Loss of umbilical connectivity (see 0800) | I23: Material degradation due to exposure to UV | J23: Normal | K23: 1) Redundant system (WEC remains moored) | L23: Regularly scheduled visual inspection, with repair/ replacement as needed | M23: 1) GPS watch circle alarm 2) Visual detection 3) Loss of umbilical connectivity | N23: Mooring: Repair/replace on site Umbilical: Repair/replace on site… but long lead time (~12mo) | O23: 7 | P23: 1 | Q23: 1 | R23: 9 | S23: 7 | T23: =IF(AND(ISNUMBER(P23),ISNUMBER($O23)),OFFSET(RiskMatrixRef,-$O23+1,P23-1),"") -> Low | U23: =IF(AND(ISNUMBER(Q23),ISNUMBER($O23)),OFFSET(RiskMatrixRef,-$O23+1,Q23-1),"") -> Low | V23: =IF(AND(ISNUMBER(R23),ISNUMBER($O23)),OFFSET(RiskMatrixRef,-$O23+1,R23-1),"") -> High | W23: =IF(AND(ISNUMBER(S23),ISNUMBER($O23)),OFFSET(RiskMatrixRef,-$O23+1,S23-1),"") -> Med | X23: 1) design of umibilical to incorporate repairable weak link to allow for shorter repair time and reduced cost of failure | AW23: CPwr to provide recommended actions to reduce risk of failure due to UV exposure, if warranted
B24: 0713-8 | C24: Single point hawser lines | D24: Load transfer from Bridle to WETS moorings Provide restoring forces for position keeping | E24: 2 | F24: Loading Material integrity subjected to marine environment: Exposure to UV, marine growth control | G24: Single hawser failure | H24: 1) Change in mooring system response and loads 2) Significantly greater watch circle 3) Loss of aft mooring line 4) Loss of umbilical connectivity (see 0800) | I24: Degradation due to marine growth | J24: Normal | K24: 1) Redundant system (WEC remains moored) | L24: Regularly scheduled visual inspection, with repair/ replacement as needed | M24: 1) GPS watch circle alarm 2) Visual detection 3) Loss of umbilical connectivity | N24: Mooring: Repair/replace on site Umbilical: Repair/replace on site… but long lead time (~12mo) | O24: 7 | P24: 1 | Q24: 1 | R24: 9 | S24: 7 | T24: =IF(AND(ISNUMBER(P24),ISNUMBER($O24)),OFFSET(RiskMatrixRef,-$O24+1,P24-1),"") -> Low | U24: =IF(AND(ISNUMBER(Q24),ISNUMBER($O24)),OFFSET(RiskMatrixRef,-$O24+1,Q24-1),"") -> Low | V24: =IF(AND(ISNUMBER(R24),ISNUMBER($O24)),OFFSET(RiskMatrixRef,-$O24+1,R24-1),"") -> High | W24: =IF(AND(ISNUMBER(S24),ISNUMBER($O24)),OFFSET(RiskMatrixRef,-$O24+1,S24-1),"") -> Med | X24: 1) design of umibilical to incorporate repairable weak link to allow for shorter repair time and reduced cost of failure | AW24: CPwr to provide recommended actions to reduce risk of failure due to marine growth, if warranted
B25: 0714-1 | C25: Single point MB-225 foam buoy | D25: Provide buoyancy to the mooring system, maintain tension in the mooring lines and geometric configuration of the mooring system | E25: 2 | F25: Loading Long term buoyancy loss | G25: Collapse/loss of buoyancy | H25: 1) Change to WEC orientation 2) Sub-optimal WEC response 3) Possible entaglement between single point sinker and umbilical | I25: Non-service ship strike | J25: Normal | K25: 1) Lights, radar reflectors (e.g. visibility) | L25: none | M25: 1) Visual detection | N25: Replace on site | O25: 3 | P25: 1 | Q25: 1 | R25: 4 | S25: 4 | T25: =IF(AND(ISNUMBER(P25),ISNUMBER($O25)),OFFSET(RiskMatrixRef,-$O25+1,P25-1),"") -> Low | U25: =IF(AND(ISNUMBER(Q25),ISNUMBER($O25)),OFFSET(RiskMatrixRef,-$O25+1,Q25-1),"") -> Low | V25: =IF(AND(ISNUMBER(R25),ISNUMBER($O25)),OFFSET(RiskMatrixRef,-$O25+1,R25-1),"") -> Low | W25: =IF(AND(ISNUMBER(S25),ISNUMBER($O25)),OFFSET(RiskMatrixRef,-$O25+1,S25-1),"") -> Low | X25: 1) establish exclusion zone at deployed area
B26: 0714-2 | C26: Single point MB-225 foam buoy | D26: Provide buoyancy to the mooring system, maintain tension in the mooring lines and geometric configuration of the mooring system | E26: 2 | F26: Loading Long term buoyancy loss | G26: Loss of buoyancy | H26: 1) Change to WEC orientation 2) Sub-optimal WEC response 3) Possible entaglement between single point sinker and umbilical | I26: Material degradation leading to loss of buoyancy | J26: Normal | K26: none | L26: Regularly scheduled visual inspection, with repair/ replacement as needed | M26: 1) Visual detection | N26: Replace on site | O26: 7 | P26: 1 | Q26: 1 | R26: 4 | S26: 4 | T26: =IF(AND(ISNUMBER(P26),ISNUMBER($O26)),OFFSET(RiskMatrixRef,-$O26+1,P26-1),"") -> Low | U26: =IF(AND(ISNUMBER(Q26),ISNUMBER($O26)),OFFSET(RiskMatrixRef,-$O26+1,Q26-1),"") -> Low | V26: =IF(AND(ISNUMBER(R26),ISNUMBER($O26)),OFFSET(RiskMatrixRef,-$O26+1,R26-1),"") -> Low | W26: =IF(AND(ISNUMBER(S26),ISNUMBER($O26)),OFFSET(RiskMatrixRef,-$O26+1,S26-1),"") -> Low | X26: 1) Inspection of buoy to detect loss of buoyancy or damage to be implemented
B27: 0715-1 | C27: Single point sinker | D27: Provide weight to foam buoy. Connection point between Brindle and single point mooring | E27: 2 | F27: Loading Local bending of chain link | G27: Crack/Loss of mass | H27: 1) Loss of WEC orientation and equilibrium position 2) Possible loss of umbilical connectivity (see 0800) 3) Possible loss of buoy, BOB - buoy on beach or BOTS - buoy out to sea 4) Possible damage to WEC | I27: Extreme loading (overload) | J27: Normal | K27: none | L27: none | M27: 1) GPS watch circle alarm 2) Yaw direction detection 3) Mooring load cells 4) Visual detection 5) Loss of umbilical connectivity | N27: Mooring: Repair/replace on site Umbilical: Repair/replace on site… but long lead time (~12mo) WEC Hull: recover WEC, dry dock repair | O27: 5 | P27: 4 | Q27: 7 | R27: 9 | S27: 9 | T27: =IF(AND(ISNUMBER(P27),ISNUMBER($O27)),OFFSET(RiskMatrixRef,-$O27+1,P27-1),"") -> Low | U27: =IF(AND(ISNUMBER(Q27),ISNUMBER($O27)),OFFSET(RiskMatrixRef,-$O27+1,Q27-1),"") -> Med | V27: =IF(AND(ISNUMBER(R27),ISNUMBER($O27)),OFFSET(RiskMatrixRef,-$O27+1,R27-1),"") -> Med | W27: =IF(AND(ISNUMBER(S27),ISNUMBER($O27)),OFFSET(RiskMatrixRef,-$O27+1,S27-1),"") -> Med | X27: 1) design of umibilical to incorporate repairable weak link to allow for shorter repair time and reduced cost of failure 2) Load derivation methodology to take into account the uncertainties in the loading due to site characterisation measurements and hydrodynamic modelling. 3) CPwr to demonstrate the derivation of loading is conservative for the site, including providing evidence from site assessment and validation of the overall loading upon deployment. | AW27: 1) Assumes that if the sinker fails, the WEC bridle will no longer be connected to the existing mooring 2) Assumes that buoy on beach results in significant damage to the structure
B28: 0715-2 | C28: Single point sinker | D28: Provide weight to foam buoy. Connection point between Brindle and single point mooring | E28: 2 | F28: Loading Local bending of chain link | G28: Crack/Loss of mass | H28: 1) Loss of WEC orientation and equilibrium position 2) Possible loss of umbilical connectivity (see 0800) 3) Possible loss of buoy, BOB - buoy on beach or BOTS - buoy out to sea 4) Possible damage to WEC | I28: Snap loads | J28: Normal | K28: none | L28: none | M28: 1) GPS watch circle alarm 2) Yaw direction detection 3) Mooring load cells 4) Visual detection 5) Loss of umbilical connectivity | N28: Mooring: Repair/replace on site Umbilical: Repair/replace on site… but long lead time (~12mo) WEC Hull: recover WEC, dry dock repair | O28: 4 | P28: 4 | Q28: 7 | R28: 9 | S28: 9 | T28: =IF(AND(ISNUMBER(P28),ISNUMBER($O28)),OFFSET(RiskMatrixRef,-$O28+1,P28-1),"") -> Low | U28: =IF(AND(ISNUMBER(Q28),ISNUMBER($O28)),OFFSET(RiskMatrixRef,-$O28+1,Q28-1),"") -> Low | V28: =IF(AND(ISNUMBER(R28),ISNUMBER($O28)),OFFSET(RiskMatrixRef,-$O28+1,R28-1),"") -> Med | W28: =IF(AND(ISNUMBER(S28),ISNUMBER($O28)),OFFSET(RiskMatrixRef,-$O28+1,S28-1),"") -> Med | X28: 1) design of umibilical to incorporate repairable weak link to allow for shorter repair time and reduced cost of failure 2) load cases to include investigation of snap loading | AW28: 1) Assumes that if the sinker fails, the WEC bridle will no longer be connected to the existing mooring 2) Assumes that buoy on beach results in significant damage to the structure
B29: 0715-3 | C29: Single point sinker | D29: Provide weight to foam buoy. Connection point between Brindle and single point mooring | E29: 2 | F29: Loading Local bending of chain link | G29: Crack/Loss of mass | H29: 1) Loss of WEC orientation and equilibrium position 2) Possible loss of umbilical connectivity (see 0800) 3) Possible loss of buoy, BOB - buoy on beach or BOTS - buoy out to sea 4) Possible damage to WEC | I29: Fatigue induced damage | J29: Normal | K29: none | L29: Regularly scheduled visual inspection, with repair/ replacement as needed | M29: 1) GPS watch circle alarm 2) Yaw direction detection 3) Mooring load cells 4) Visual detection 5) Loss of umbilical connectivity | N29: Mooring: Repair/replace on site Umbilical: Repair/replace on site… but long lead time (~12mo) WEC Hull: recover WEC, dry dock repair | O29: 7 | P29: 4 | Q29: 7 | R29: 9 | S29: 9 | T29: =IF(AND(ISNUMBER(P29),ISNUMBER($O29)),OFFSET(RiskMatrixRef,-$O29+1,P29-1),"") -> Low | U29: =IF(AND(ISNUMBER(Q29),ISNUMBER($O29)),OFFSET(RiskMatrixRef,-$O29+1,Q29-1),"") -> Med | V29: =IF(AND(ISNUMBER(R29),ISNUMBER($O29)),OFFSET(RiskMatrixRef,-$O29+1,R29-1),"") -> High | W29: =IF(AND(ISNUMBER(S29),ISNUMBER($O29)),OFFSET(RiskMatrixRef,-$O29+1,S29-1),"") -> High | X29: 1) design of umibilical to incorporate repairable weak link to allow for shorter repair time and reduced cost of failure 2) Load derivation methodology to take into account the uncertainties in the loading due to site characterisation measurements and hydrodynamic modelling. 3) CPwr to demonstrate the derivation of loading is conservative for the site, including providing evidence from site assessment and validation of the overall loading upon deployment. | AW29: 1) Assumes that if the sinker fails, the WEC bridle will no longer be connected to the existing mooring 2) Assumes that buoy on beach results in significant damage to the structure
B30: 0715-4 | C30: Single point sinker | D30: Provide weight to foam buoy. Connection point between Brindle and single point mooring | E30: 2 | F30: Loading Local bending of chain link | G30: Crack/Loss of mass | H30: 1) Loss of WEC orientation and equilibrium position 2) Possible loss of umbilical connectivity (see 0800) 3) Possible loss of buoy, BOB - buoy on beach or BOTS - buoy out to sea 4) Possible damage to WEC | I30: Non-service ship strike | J30: Normal | K30: none | L30: none | M30: 1) GPS watch circle alarm 2) Yaw direction detection 3) Mooring load cells 4) Visual detection 5) Loss of umbilical connectivity | N30: Mooring: Repair/replace on site Umbilical: Repair/replace on site… but long lead time (~12mo) WEC Hull: recover WEC, dry dock repair | O30: 3 | P30: 4 | Q30: 7 | R30: 9 | S30: 9 | T30: =IF(AND(ISNUMBER(P30),ISNUMBER($O30)),OFFSET(RiskMatrixRef,-$O30+1,P30-1),"") -> Low | U30: =IF(AND(ISNUMBER(Q30),ISNUMBER($O30)),OFFSET(RiskMatrixRef,-$O30+1,Q30-1),"") -> Low | V30: =IF(AND(ISNUMBER(R30),ISNUMBER($O30)),OFFSET(RiskMatrixRef,-$O30+1,R30-1),"") -> Med | W30: =IF(AND(ISNUMBER(S30),ISNUMBER($O30)),OFFSET(RiskMatrixRef,-$O30+1,S30-1),"") -> Med | X30: 1) design of umibilical to incorporate repairable weak link to allow for shorter repair time and reduced cost of failure 2) establish exclusion zone at deployed area | AW30: 1) Assumes that if the sinker fails, the WEC bridle will no longer be connected to the existing mooring 2) Assumes that buoy on beach results in significant damage to the structure
B31: 0716-1 | C31: Single point shackles, pendants | D31: Connection points for Hawser lines to chain, pendant and buoy Load transfer | E31: 2 | F31: Loading | G31: Yield/crack | H31: 1) Change in mooring system response and loads 2) Significantly greater watch circle 3) Loss of aft mooring line 4) Loss of umbilical connectivity (see 0800) | I31: Extreme load induced damage (Overload) | J31: Normal | K31: 1) Redundant system (WEC remains moored) 2) Conservative design (partial safety factors) | L31: none | M31: 1) GPS watch circle alarm 2) Visual detection 3) Loss of umbilical connectivity | N31: Mooring: Repair/replace on site Umbilical: Repair/replace on site… but long lead time (~12mo) | O31: 5 | P31: 1 | Q31: 1 | R31: 9 | S31: 7 | T31: =IF(AND(ISNUMBER(P31),ISNUMBER($O31)),OFFSET(RiskMatrixRef,-$O31+1,P31-1),"") -> Low | U31: =IF(AND(ISNUMBER(Q31),ISNUMBER($O31)),OFFSET(RiskMatrixRef,-$O31+1,Q31-1),"") -> Low | V31: =IF(AND(ISNUMBER(R31),ISNUMBER($O31)),OFFSET(RiskMatrixRef,-$O31+1,R31-1),"") -> Med | W31: =IF(AND(ISNUMBER(S31),ISNUMBER($O31)),OFFSET(RiskMatrixRef,-$O31+1,S31-1),"") -> Med | X31: 1) design of umibilical to incorporate repairable weak link to allow for shorter repair time and reduced cost of failure 2) Load derivation methodology to take into account the uncertainties in the loading due to site characterisation measurements and hydrodynamic modelling. 3) CPwr to demonstrate the derivation of loading is conservative for the site, including providing evidence from site assessment and validation of the overall loading upon deployment. | Y31: 1) Marine contractor 2) Marine contractor feasibility study | AF31: =IF(AND(ISNUMBER(AB31),ISNUMBER($AA31)),OFFSET(RiskMatrixRef,-$AA31+1,AB31-1),"") | AG31: =IF(AND(ISNUMBER(AC31),ISNUMBER($AA31)),OFFSET(RiskMatrixRef,-$AA31+1,AC31-1),"") | AH31: =IF(AND(ISNUMBER(AD31),ISNUMBER($AA31)),OFFSET(RiskMatrixRef,-$AA31+1,AD31-1),"") | AI31: =IF(AND(ISNUMBER(AE31),ISNUMBER($AA31)),OFFSET(RiskMatrixRef,-$AA31+1,AE31-1),"") | AR31: =IF(AND(ISNUMBER(AN31),ISNUMBER($AM31)),OFFSET(RiskMatrixRef,-$AM31+1,AN31-1),"") | AS31: =IF(AND(ISNUMBER(AO31),ISNUMBER($AM31)),OFFSET(RiskMatrixRef,-$AM31+1,AO31-1),"") | AT31: =IF(AND(ISNUMBER(AP31),ISNUMBER($AM31)),OFFSET(RiskMatrixRef,-$AM31+1,AP31-1),"") | AU31: =IF(AND(ISNUMBER(AQ31),ISNUMBER($AM31)),OFFSET(RiskMatrixRef,-$AM31+1,AQ31-1),"")
B32: 0716-2 | C32: Single point shackles, pendants | D32: Connection points for Hawser lines to chain, pendant and buoy Load transfer | E32: 2 | F32: Loading | G32: Yield/crack | H32: 1) Change in mooring system response and loads 2) Significantly greater watch circle 3) Loss of aft mooring line 4) Loss of umbilical connectivity (see 0800) | I32: Snap loads | J32: Normal | K32: 1) Redundant system (WEC remains moored) | L32: none | M32: 1) GPS watch circle alarm 2) Visual detection 3) Loss of umbilical connectivity | N32: Mooring: Repair/replace on site Umbilical: Repair/replace on site… but long lead time (~12mo) | O32: 4 | P32: 1 | Q32: 1 | R32: 9 | S32: 7 | T32: =IF(AND(ISNUMBER(P32),ISNUMBER($O32)),OFFSET(RiskMatrixRef,-$O32+1,P32-1),"") -> Low | U32: =IF(AND(ISNUMBER(Q32),ISNUMBER($O32)),OFFSET(RiskMatrixRef,-$O32+1,Q32-1),"") -> Low | V32: =IF(AND(ISNUMBER(R32),ISNUMBER($O32)),OFFSET(RiskMatrixRef,-$O32+1,R32-1),"") -> Med | W32: =IF(AND(ISNUMBER(S32),ISNUMBER($O32)),OFFSET(RiskMatrixRef,-$O32+1,S32-1),"") -> Low | X32: 1) design of umibilical to incorporate repairable weak link to allow for shorter repair time and reduced cost of failure 2) load cases to include investigation of snap loading
B33: 0716-3 | C33: Single point shackles, pendants | D33: Connection points for Hawser lines to chain, pendant and buoy Load transfer | E33: 2 | F33: Loading | G33: Yield/crack | H33: 1) Change in mooring system response and loads 2) Significantly greater watch circle 3) Loss of aft mooring line 4) Loss of umbilical connectivity (see 0800) | I33: Fatigue induced damage | J33: Normal | K33: 1) Redundant system (WEC remains moored) 2) Material selection and component sizing 3) Conservative design (partial safety factors) | L33: Regularly scheduled visual inspection, with repair/ replacement as needed | M33: 1) GPS watch circle alarm 2) Visual detection 3) Loss of umbilical connectivity | N33: Mooring: Repair/replace on site Umbilical: Repair/replace on site… but long lead time (~12mo) | O33: 7 | P33: 1 | Q33: 1 | R33: 9 | S33: 7 | T33: =IF(AND(ISNUMBER(P33),ISNUMBER($O33)),OFFSET(RiskMatrixRef,-$O33+1,P33-1),"") -> Low | U33: =IF(AND(ISNUMBER(Q33),ISNUMBER($O33)),OFFSET(RiskMatrixRef,-$O33+1,Q33-1),"") -> Low | V33: =IF(AND(ISNUMBER(R33),ISNUMBER($O33)),OFFSET(RiskMatrixRef,-$O33+1,R33-1),"") -> High | W33: =IF(AND(ISNUMBER(S33),ISNUMBER($O33)),OFFSET(RiskMatrixRef,-$O33+1,S33-1),"") -> Med | X33: 1) design of umibilical to incorporate repairable weak link to allow for shorter repair time and reduced cost of failure 2) Load derivation methodology to take into account the uncertainties in the loading due to site characterisation measurements and hydrodynamic modelling. 3) CPwr to demonstrate the derivation of loading is conservative for the site, including providing evidence from site assessment and validation of the overall loading upon deployment.
B34: 0716-4 | C34: Single point shackles, pendants | D34: Connection points for Hawser lines to chain, pendant and buoy Load transfer | E34: 2 | F34: Loading | G34: Yield/crack | H34: 1) Change in mooring system response and loads 2) Significantly greater watch circle 3) Loss of aft mooring line 4) Loss of umbilical connectivity (see 0800) | I34: Non-service ship strike | J34: Normal | K34: 1) Redundant system (WEC remains moored) 2) Lights, radar reflectors (e.g. visibility) 3) Hawsers and hardware below ship draft (~4m) | L34: none | M34: 1) GPS watch circle alarm 2) Visual detection 3) Loss of umbilical connectivity | N34: Mooring: Repair/replace on site Umbilical: Repair/replace on site… but long lead time (~12mo) | O34: 3 | P34: 1 | Q34: 1 | R34: 9 | S34: 7 | T34: =IF(AND(ISNUMBER(P34),ISNUMBER($O34)),OFFSET(RiskMatrixRef,-$O34+1,P34-1),"") -> Low | U34: =IF(AND(ISNUMBER(Q34),ISNUMBER($O34)),OFFSET(RiskMatrixRef,-$O34+1,Q34-1),"") -> Low | V34: =IF(AND(ISNUMBER(R34),ISNUMBER($O34)),OFFSET(RiskMatrixRef,-$O34+1,R34-1),"") -> Med | W34: =IF(AND(ISNUMBER(S34),ISNUMBER($O34)),OFFSET(RiskMatrixRef,-$O34+1,S34-1),"") -> Low | X34: 1) design of umibilical to incorporate repairable weak link to allow for shorter repair time and reduced cost of failure 2) establish exclusion zone at deployed area | Y34: 1) Marine contractor 2) Marine contractor feasibility study | AW34: Assume pendant is made of steel, hence failure cause related to polyester material is not considered.
B35: 0716-5 | C35: Single point shackles, pendants | D35: Connection points for Hawser lines to chain, pendant and buoy Load transfer | E35: 2 | F35: Loading | G35: Yield/crack | H35: 1) Change in mooring system response and loads 2) Significantly greater watch circle 3) Loss of aft mooring line 4) Loss of umbilical connectivity (see 0800) | I35: Vandalism/ negligence | J35: Normal | K35: 1) Redundant system (WEC remains moored) 2) Surveillance system 3) Hawsers and hardware below easy access (~4m) | L35: none | M35: 1) GPS watch circle alarm 2) Visual detection 3) Loss of umbilical connectivity | N35: Mooring: Repair/replace on site Umbilical: Repair/replace on site… but long lead time (~12mo) | O35: 4 | P35: 1 | Q35: 1 | R35: 9 | S35: 7 | T35: =IF(AND(ISNUMBER(P35),ISNUMBER($O35)),OFFSET(RiskMatrixRef,-$O35+1,P35-1),"") -> Low | U35: =IF(AND(ISNUMBER(Q35),ISNUMBER($O35)),OFFSET(RiskMatrixRef,-$O35+1,Q35-1),"") -> Low | V35: =IF(AND(ISNUMBER(R35),ISNUMBER($O35)),OFFSET(RiskMatrixRef,-$O35+1,R35-1),"") -> Med | W35: =IF(AND(ISNUMBER(S35),ISNUMBER($O35)),OFFSET(RiskMatrixRef,-$O35+1,S35-1),"") -> Low | X35: 1) design of umibilical to incorporate repairable weak link to allow for shorter repair time and reduced cost of failure
B36: 0716-6 | C36: Single point shackles, pendants | D36: Connection points for Hawser lines to chain, pendant and buoy Load transfer | E36: 2 | F36: Loading | G36: Yield/crack | H36: 1) Change in mooring system response and loads 2) Significantly greater watch circle 3) Loss of aft mooring line 4) Loss of umbilical connectivity (see 0800) | I36: Corrosion | J36: Normal | K36: 1) Redundant system (WEC remains moored) | L36: Regularly scheduled visual inspection, with repair/ replacement as needed | M36: 1) GPS watch circle alarm 2) Visual detection 3) Loss of umbilical connectivity | N36: Mooring: Repair/replace on site Umbilical: Repair/replace on site… but long lead time (~12mo) | O36: 7 | P36: 1 | Q36: 1 | R36: 9 | S36: 7 | T36: =IF(AND(ISNUMBER(P36),ISNUMBER($O36)),OFFSET(RiskMatrixRef,-$O36+1,P36-1),"") -> Low | U36: =IF(AND(ISNUMBER(Q36),ISNUMBER($O36)),OFFSET(RiskMatrixRef,-$O36+1,Q36-1),"") -> Low | V36: =IF(AND(ISNUMBER(R36),ISNUMBER($O36)),OFFSET(RiskMatrixRef,-$O36+1,R36-1),"") -> High | W36: =IF(AND(ISNUMBER(S36),ISNUMBER($O36)),OFFSET(RiskMatrixRef,-$O36+1,S36-1),"") -> Med | X36: 1) design of umibilical to incorporate repairable weak link to allow for shorter repair time and reduced cost of failure 2) CPwr to confirm that corrosion allowance has been considered in the structural design; if not, corrosion allowance to be defined as per DNV-OS-E301 with annual inspection
B37: 0720-1 | C37: Bridle (hawswer lines and hardware) | D37: Constrain WEC to weathervane about the single point Yaw stability | E37: 2 | F37: Loading | G37: Double bridle line failure (including hardware failure) | H37: 1) Loss of station keeping 2) Loss of umbilical connectivity (see 0800) 3) BOB - buoy on beach or BOTS - buoy out to sea 4) Entanglement of WEC in mooring system 5) Damage to mooring connection point at the hull area | I37: Extreme load induced damage | J37: Normal | K37: none | L37: none | M37: 1) GPS watch circle alarm 2) Yaw direction detection 3) Mooring load cells 4) Visual detection 5) Loss of umbilical connectivity | N37: Mooring: Repair/replace on site Umbilical: Repair/replace on site… but long lead time (~12mo) WEC Hull: recover WEC, dry dock repair | O37: 4 | P37: 4 | Q37: 7 | R37: 9 | S37: 9 | T37: =IF(AND(ISNUMBER(P37),ISNUMBER($O37)),OFFSET(RiskMatrixRef,-$O37+1,P37-1),"") -> Low | U37: =IF(AND(ISNUMBER(Q37),ISNUMBER($O37)),OFFSET(RiskMatrixRef,-$O37+1,Q37-1),"") -> Low | V37: =IF(AND(ISNUMBER(R37),ISNUMBER($O37)),OFFSET(RiskMatrixRef,-$O37+1,R37-1),"") -> Med | W37: =IF(AND(ISNUMBER(S37),ISNUMBER($O37)),OFFSET(RiskMatrixRef,-$O37+1,S37-1),"") -> Med | X37: 1) design of umibilical to incorporate repairable weak link to allow for shorter repair time and reduced cost of failure 2) A salvage/emergency response plan to be defined prior to first deployment, stating the mitigating actions for the failure and the expected time window for the operation(s) to be carried out. It needs to be demonstrated that the expected time window is achievable for the sudden occurrence of the event 3) Design to demonstrate that the mooring lines are to break first in the event of excessive loading in order to prevent any damage to the connection points on the WEC hull area such that dry dock repair is not necessary in the event of line failure | Y37: 1) Marine contractor feasibility study 2) Marine contractor | AF37: =IF(AND(ISNUMBER(AB37),ISNUMBER($AA37)),OFFSET(RiskMatrixRef,-$AA37+1,AB37-1),"") | AG37: =IF(AND(ISNUMBER(AC37),ISNUMBER($AA37)),OFFSET(RiskMatrixRef,-$AA37+1,AC37-1),"") | AH37: =IF(AND(ISNUMBER(AD37),ISNUMBER($AA37)),OFFSET(RiskMatrixRef,-$AA37+1,AD37-1),"") | AI37: =IF(AND(ISNUMBER(AE37),ISNUMBER($AA37)),OFFSET(RiskMatrixRef,-$AA37+1,AE37-1),"") | AR37: =IF(AND(ISNUMBER(AN37),ISNUMBER($AM37)),OFFSET(RiskMatrixRef,-$AM37+1,AN37-1),"") | AS37: =IF(AND(ISNUMBER(AO37),ISNUMBER($AM37)),OFFSET(RiskMatrixRef,-$AM37+1,AO37-1),"") | AT37: =IF(AND(ISNUMBER(AP37),ISNUMBER($AM37)),OFFSET(RiskMatrixRef,-$AM37+1,AP37-1),"") | AU37: =IF(AND(ISNUMBER(AQ37),ISNUMBER($AM37)),OFFSET(RiskMatrixRef,-$AM37+1,AQ37-1),"") | AW37: 1) Assumes that buoy on beach results in significant damage to the structure
B38: 0720-2 | C38: Bridle (hawswer lines and hardware) | D38: Constrain WEC to weathervane about the single point Yaw stability | E38: 2 | F38: Loading | G38: Double bridle line failure (including hardware failure) | H38: 1) Loss of station keeping 2) Loss of umbilical connectivity (see 0800) 3) BOB - buoy on beach or BOTS - buoy out to sea 4) Entanglement of WEC in mooring system 5) Damage to mooring connection point at the hull area | I38: Snap loads | J38: Normal | K38: none | L38: none | M38: 1) GPS watch circle alarm 2) Yaw direction detection 3) Mooring load cells 4) Visual detection 5) Loss of umbilical connectivity | N38: Mooring: Repair/replace on site Umbilical: Repair/replace on site… but long lead time (~12mo) WEC Hull: recover WEC, dry dock repair | O38: 3 | P38: 4 | Q38: 7 | R38: 9 | S38: 9 | T38: =IF(AND(ISNUMBER(P38),ISNUMBER($O38)),OFFSET(RiskMatrixRef,-$O38+1,P38-1),"") -> Low | U38: =IF(AND(ISNUMBER(Q38),ISNUMBER($O38)),OFFSET(RiskMatrixRef,-$O38+1,Q38-1),"") -> Low | V38: =IF(AND(ISNUMBER(R38),ISNUMBER($O38)),OFFSET(RiskMatrixRef,-$O38+1,R38-1),"") -> Med | W38: =IF(AND(ISNUMBER(S38),ISNUMBER($O38)),OFFSET(RiskMatrixRef,-$O38+1,S38-1),"") -> Med | X38: 1) design of umibilical to incorporate repairable weak link to allow for shorter repair time and reduced cost of failure 2) A salvage/emergency response plan to be defined prior to first deployment, stating the mitigating actions for the failure and the expected time window for the operation(s) to be carried out. It needs to be demonstrated that the expected time window is achievable for the sudden occurrence of the event 3) Design to demonstrate that the mooring lines are to break first in the event of excessive loading in order to prevent any damage to the connection points on the WEC hull area such that dry dock repair is not necessary in the event of line failure 4) load cases to include investigation of snap loading | AW38: 1) Assumes that buoy on beach results in significant damage to the structure
B39: 0720-3 | C39: Bridle (hawswer lines and hardware) | D39: Constrain WEC to weathervane about the single point Yaw stability | E39: 2 | F39: Loading | G39: Double bridle line failure (including hardware failure) | H39: 1) Loss of station keeping 2) Loss of umbilical connectivity (see 0800) 3) BOB - buoy on beach or BOTS - buoy out to sea 4) Entanglement of WEC in mooring system | I39: Corrosion, wear, fatigue induced damage | J39: Normal | K39: 1) Material selection and component sizing | L39: Regularly scheduled visual inspection, with repair/ replacement as needed | M39: 1) GPS watch circle alarm 2) Yaw direction detection 3) Mooring load cells 4) Visual detection 5) Loss of umbilical connectivity | N39: Mooring: Repair/replace on site Umbilical: Repair/replace on site… but long lead time (~12mo) | O39: 7 | P39: 4 | Q39: 7 | R39: 9 | S39: 9 | T39: =IF(AND(ISNUMBER(P39),ISNUMBER($O39)),OFFSET(RiskMatrixRef,-$O39+1,P39-1),"") -> Low | U39: =IF(AND(ISNUMBER(Q39),ISNUMBER($O39)),OFFSET(RiskMatrixRef,-$O39+1,Q39-1),"") -> Med | V39: =IF(AND(ISNUMBER(R39),ISNUMBER($O39)),OFFSET(RiskMatrixRef,-$O39+1,R39-1),"") -> High | W39: =IF(AND(ISNUMBER(S39),ISNUMBER($O39)),OFFSET(RiskMatrixRef,-$O39+1,S39-1),"") -> High | X39: 1) design of umibilical to incorporate repairable weak link to allow for shorter repair time and reduced cost of failure 2) A salvage/emergency response plan to be defined prior to first deployment, stating the mitigating actions for the failure and the expected time window for the operation(s) to be carried out. It needs to be demonstrated that the expected time window is achievable for the sudden occurrence of the event | Y39: 1) Marine contractor feasibility study 2) Marine contractor | AF39: =IF(AND(ISNUMBER(AB39),ISNUMBER($AA39)),OFFSET(RiskMatrixRef,-$AA39+1,AB39-1),"") | AG39: =IF(AND(ISNUMBER(AC39),ISNUMBER($AA39)),OFFSET(RiskMatrixRef,-$AA39+1,AC39-1),"") | AH39: =IF(AND(ISNUMBER(AD39),ISNUMBER($AA39)),OFFSET(RiskMatrixRef,-$AA39+1,AD39-1),"") | AI39: =IF(AND(ISNUMBER(AE39),ISNUMBER($AA39)),OFFSET(RiskMatrixRef,-$AA39+1,AE39-1),"") | AR39: =IF(AND(ISNUMBER(AN39),ISNUMBER($AM39)),OFFSET(RiskMatrixRef,-$AM39+1,AN39-1),"") | AS39: =IF(AND(ISNUMBER(AO39),ISNUMBER($AM39)),OFFSET(RiskMatrixRef,-$AM39+1,AO39-1),"") | AT39: =IF(AND(ISNUMBER(AP39),ISNUMBER($AM39)),OFFSET(RiskMatrixRef,-$AM39+1,AP39-1),"") | AU39: =IF(AND(ISNUMBER(AQ39),ISNUMBER($AM39)),OFFSET(RiskMatrixRef,-$AM39+1,AQ39-1),"") | AW39: 1) Assumes that buoy on beach results in significant damage to the structure
B40: 0720-4 | C40: Bridle (hawswer lines and hardware) | D40: Constrain WEC to weathervane about the single point Yaw stability | E40: 2 | F40: Loading | G40: Double bridle line failure (including hardware failure) | H40: 1) Loss of station keeping 2) Loss of umbilical connectivity (see 0800) 3) BOB - buoy on beach or BOTS - buoy out to sea 4) Entanglement of WEC in mooring system 5) Damage to mooring connection point at the hull area | I40: Non-service ship strike | J40: Normal | K40: 1) Lights, radar reflectors (e.g. visibility) 2) Bridle is below ship draft (~19m) | L40: none | M40: 1) GPS watch circle alarm 2) Yaw direction detection 3) Mooring load cells 4) Visual detection 5) Loss of umbilical connectivity | N40: Mooring: Repair/replace on site Umbilical: Repair/replace on site… but long lead time (~12mo) WEC Hull: recover WEC, dry dock repair | O40: 1 | P40: 4 | Q40: 7 | R40: 9 | S40: 9 | T40: =IF(AND(ISNUMBER(P40),ISNUMBER($O40)),OFFSET(RiskMatrixRef,-$O40+1,P40-1),"") -> Low | U40: =IF(AND(ISNUMBER(Q40),ISNUMBER($O40)),OFFSET(RiskMatrixRef,-$O40+1,Q40-1),"") -> Low | V40: =IF(AND(ISNUMBER(R40),ISNUMBER($O40)),OFFSET(RiskMatrixRef,-$O40+1,R40-1),"") -> Low | W40: =IF(AND(ISNUMBER(S40),ISNUMBER($O40)),OFFSET(RiskMatrixRef,-$O40+1,S40-1),"") -> Low | X40: 1) design of umibilical to incorporate repairable weak link to allow for shorter repair time and reduced cost of failure 2) A salvage/emergency response plan to be defined prior to first deployment, stating the mitigating actions for the failure and the expected time window for the operation(s) to be carried out. It needs to be demonstrated that the expected time window is achievable for the sudden occurrence of the event 3) Design to demonstrate that the mooring lines are to break first in the event of excessive loading in order to prevent any damage to the connection points on the WEC hull area such that dry dock repair is not necessary in the event of line failure 4) establish exclusion zone at deployed area | AF40: =IF(AND(ISNUMBER(AB40),ISNUMBER($AA40)),OFFSET(RiskMatrixRef,-$AA40+1,AB40-1),"") | AG40: =IF(AND(ISNUMBER(AC40),ISNUMBER($AA40)),OFFSET(RiskMatrixRef,-$AA40+1,AC40-1),"") | AH40: =IF(AND(ISNUMBER(AD40),ISNUMBER($AA40)),OFFSET(RiskMatrixRef,-$AA40+1,AD40-1),"") | AI40: =IF(AND(ISNUMBER(AE40),ISNUMBER($AA40)),OFFSET(RiskMatrixRef,-$AA40+1,AE40-1),"") | AR40: =IF(AND(ISNUMBER(AN40),ISNUMBER($AM40)),OFFSET(RiskMatrixRef,-$AM40+1,AN40-1),"") | AS40: =IF(AND(ISNUMBER(AO40),ISNUMBER($AM40)),OFFSET(RiskMatrixRef,-$AM40+1,AO40-1),"") | AT40: =IF(AND(ISNUMBER(AP40),ISNUMBER($AM40)),OFFSET(RiskMatrixRef,-$AM40+1,AP40-1),"") | AU40: =IF(AND(ISNUMBER(AQ40),ISNUMBER($AM40)),OFFSET(RiskMatrixRef,-$AM40+1,AQ40-1),"") | AW40: 1) Assumes that buoy on beach results in significant damage to the structure 2) CPwr to clarify the maximum draft of ships in the area
B41: 0720-5 | C41: Bridle (hawswer lines and hardware) | D41: Constrain WEC to weathervane about the single point Yaw stability | E41: 2 | F41: Loading | G41: Double bridle line failure (including hardware failure) | H41: 1) Loss of station keeping 2) Loss of umbilical connectivity (see 0800) 3) BOB - buoy on beach or BOTS - buoy out to sea 4) Entanglement of WEC in mooring system 5) Damage to mooring connection point at the hull area | I41: Vandalism/ negligence | J41: Normal | K41: 1) Surveillance system 2) Bridle is below easy access (~19m) | L41: none | M41: 1) GPS watch circle alarm 2) Yaw direction detection 3) Mooring load cells 4) Visual detection 5) Loss of umbilical connectivity | N41: Mooring: Repair/replace on site Umbilical: Repair/replace on site… but long lead time (~12mo) WEC Hull: recover WEC, dry dock repair | O41: 1 | P41: 4 | Q41: 7 | R41: 9 | S41: 9 | T41: =IF(AND(ISNUMBER(P41),ISNUMBER($O41)),OFFSET(RiskMatrixRef,-$O41+1,P41-1),"") -> Low | U41: =IF(AND(ISNUMBER(Q41),ISNUMBER($O41)),OFFSET(RiskMatrixRef,-$O41+1,Q41-1),"") -> Low | V41: =IF(AND(ISNUMBER(R41),ISNUMBER($O41)),OFFSET(RiskMatrixRef,-$O41+1,R41-1),"") -> Low | W41: =IF(AND(ISNUMBER(S41),ISNUMBER($O41)),OFFSET(RiskMatrixRef,-$O41+1,S41-1),"") -> Low | X41: 1) design of umibilical to incorporate repairable weak link to allow for shorter repair time and reduced cost of failure 2) A salvage/emergency response plan to be defined prior to first deployment, stating the mitigating actions for the failure and the expected time window for the operation(s) to be carried out. It needs to be demonstrated that the expected time window is achievable for the sudden occurrence of the event 3) Design to demonstrate that the mooring lines are to break first in the event of excessive loading in order to prevent any damage to the connection points on the WEC hull area such that dry dock repair is not necessary in the event of line failure | AF41: =IF(AND(ISNUMBER(AB41),ISNUMBER($AA41)),OFFSET(RiskMatrixRef,-$AA41+1,AB41-1),"") | AG41: =IF(AND(ISNUMBER(AC41),ISNUMBER($AA41)),OFFSET(RiskMatrixRef,-$AA41+1,AC41-1),"") | AH41: =IF(AND(ISNUMBER(AD41),ISNUMBER($AA41)),OFFSET(RiskMatrixRef,-$AA41+1,AD41-1),"") | AI41: =IF(AND(ISNUMBER(AE41),ISNUMBER($AA41)),OFFSET(RiskMatrixRef,-$AA41+1,AE41-1),"") | AR41: =IF(AND(ISNUMBER(AN41),ISNUMBER($AM41)),OFFSET(RiskMatrixRef,-$AM41+1,AN41-1),"") | AS41: =IF(AND(ISNUMBER(AO41),ISNUMBER($AM41)),OFFSET(RiskMatrixRef,-$AM41+1,AO41-1),"") | AT41: =IF(AND(ISNUMBER(AP41),ISNUMBER($AM41)),OFFSET(RiskMatrixRef,-$AM41+1,AP41-1),"") | AU41: =IF(AND(ISNUMBER(AQ41),ISNUMBER($AM41)),OFFSET(RiskMatrixRef,-$AM41+1,AQ41-1),"") | AW41: 1) Assumes that buoy on beach results in significant damage to the structure
