Workbook
Name RiskMatrixRef: '[2]set up'!$C$14
Name RiskMatrixRef: 'set up'!$C$14

Sheet Data Rights Notice

Sheet 0570 Bilge Pumping System
O2: Risk Ranking | AA2: Updated Risk Ranking | AM2: 2nd Updated Risk Ranking
B4: 0570 Bilge Pumping SystemFMECA Table | P4: Severity Class | T4: Risk Class | AB4: Severity Class | AF4: Risk Class | AN4: Severity Class | AR4: Risk Class
B5: Risk ID | C5: Item Description | D5: Function | E5: Tech. Class | F5: Novel Aspects | G5: Failure Mode | H5: Failure Effects (Local, WEC, System) | I5: Failure Cause(s) | J5: Initial Mode of Operation | K5: Risk Reduction Design | L5: Preventative Detection | M5: Post Failure Detection | N5: Post Failure Repair Strategy (automated, manual) | O5: Occurrence | P5: Human Safety | Q5: Environment | R5: Operation | S5: Assets | T5: Human Safety | U5: Environment | V5: Operation | W5: Assets | X5: Recommended Actions | Y5: Responsible Party | Z5: Actions Taken | AA5: Occurrence | AB5: Human Safety | AC5: Environment | AD5: Operation | AE5: Assets | AF5: Human Safety | AG5: Environment | AH5: Operation | AI5: Assets | AJ5: 2nd Recommended Actions | AK5: Responsible Party (2nd) | AL5: Actions Taken (2nd) | AM5: Occurrence | AN5: Human Safety | AO5: Environment | AP5: Operation | AQ5: Assets | AR5: Human Safety | AS5: Environment | AT5: Operation | AU5: Assets | AV5: Status (open or closed) | AW5: Notes
B6: 0571/0572 -1 | C6: Stbd/Port Spar Bilge Pumps & Controllers | D6: Remove water from WEC collected from port/stbd PTO or Control Room. (Two pumps per side - redundant cross connected power) | E6: 1 | F6: none | G6: Electrical Fault - Pump | H6: 1) Loss of one bilge pump 2) In the case of water being present, second bilge pump runs to remove normal bilge collection | I6: 1) Manufacturing defect 2) Fatigue or degradation over time 3) Contamination leads to fault 4) Component corrosion leads to fault 5) Control fault 6) Installation error | J6: Normal | K6: Redundent design 1) Two pumps 2) 4 power sources (Port/Stbd PTO, Grid, & UPS) 3) Cross connected electrical distribution | L6: 1) V&V (QC) 2) Inspections | M6: 1) Secondary bilge pump running 2) SCADA diagnostics | N6: In-situ repair | O6: 4 | P6: 1 | Q6: 1 | R6: 5 | S6: 4 | T6: =IF(AND(ISNUMBER(P6),ISNUMBER($O6)),OFFSET(RiskMatrixRef,-$O6+1,P6-1),"") -> Low | U6: =IF(AND(ISNUMBER(Q6),ISNUMBER($O6)),OFFSET(RiskMatrixRef,-$O6+1,Q6-1),"") -> Low | V6: =IF(AND(ISNUMBER(R6),ISNUMBER($O6)),OFFSET(RiskMatrixRef,-$O6+1,R6-1),"") -> Low | W6: =IF(AND(ISNUMBER(S6),ISNUMBER($O6)),OFFSET(RiskMatrixRef,-$O6+1,S6-1),"") -> Low | AF6: =IF(AND(ISNUMBER(AB6),ISNUMBER($AA6)),OFFSET(RiskMatrixRef,-$AA6+1,AB6-1),"") | AG6: =IF(AND(ISNUMBER(AC6),ISNUMBER($AA6)),OFFSET(RiskMatrixRef,-$AA6+1,AC6-1),"") | AH6: =IF(AND(ISNUMBER(AD6),ISNUMBER($AA6)),OFFSET(RiskMatrixRef,-$AA6+1,AD6-1),"") | AI6: =IF(AND(ISNUMBER(AE6),ISNUMBER($AA6)),OFFSET(RiskMatrixRef,-$AA6+1,AE6-1),"") | AR6: =IF(AND(ISNUMBER(AN6),ISNUMBER($AM6)),OFFSET(RiskMatrixRef,-$AM6+1,AN6-1),"") | AS6: =IF(AND(ISNUMBER(AO6),ISNUMBER($AM6)),OFFSET(RiskMatrixRef,-$AM6+1,AO6-1),"") | AT6: =IF(AND(ISNUMBER(AP6),ISNUMBER($AM6)),OFFSET(RiskMatrixRef,-$AM6+1,AP6-1),"") | AU6: =IF(AND(ISNUMBER(AQ6),ISNUMBER($AM6)),OFFSET(RiskMatrixRef,-$AM6+1,AQ6-1),"")
B7: 0571/0572 -2 | C7: Stbd/Port Spar Bilge Pumps & Controllers | D7: Remove water from WEC collected from port/stbd PTO or Control Room. (Two pumps per side - redundant cross connected power) | E7: 1 | F7: none | G7: Electrical Fault - Controller | H7: 1) Loss of one bilge pump 2) In the case of water being present, second bilge pump runs to remove normal bilge collection | I7: 1) Manufacturing defect 2) Fatigue or degradation over time 3) Contamination leads to fault 4) Component corrosion leads to fault 5) Control fault 6) Installation error | J7: Normal | K7: Redundent design 1) Two pumps 2) 4 power sources (Port/Stbd PTO, Grid, & UPS) 3) Cross connected electrical distribution | L7: 1) V&V (QC) 2) Inspections | M7: 1) Secondary bilge pump running 2) SCADA diagnostics | N7: In-situ repair | O7: 4 | P7: 1 | Q7: 1 | R7: 5 | S7: 4 | T7: =IF(AND(ISNUMBER(P7),ISNUMBER($O7)),OFFSET(RiskMatrixRef,-$O7+1,P7-1),"") -> Low | U7: =IF(AND(ISNUMBER(Q7),ISNUMBER($O7)),OFFSET(RiskMatrixRef,-$O7+1,Q7-1),"") -> Low | V7: =IF(AND(ISNUMBER(R7),ISNUMBER($O7)),OFFSET(RiskMatrixRef,-$O7+1,R7-1),"") -> Low | W7: =IF(AND(ISNUMBER(S7),ISNUMBER($O7)),OFFSET(RiskMatrixRef,-$O7+1,S7-1),"") -> Low | AF7: =IF(AND(ISNUMBER(AB7),ISNUMBER($AA7)),OFFSET(RiskMatrixRef,-$AA7+1,AB7-1),"") | AG7: =IF(AND(ISNUMBER(AC7),ISNUMBER($AA7)),OFFSET(RiskMatrixRef,-$AA7+1,AC7-1),"") | AH7: =IF(AND(ISNUMBER(AD7),ISNUMBER($AA7)),OFFSET(RiskMatrixRef,-$AA7+1,AD7-1),"") | AI7: =IF(AND(ISNUMBER(AE7),ISNUMBER($AA7)),OFFSET(RiskMatrixRef,-$AA7+1,AE7-1),"") | AR7: =IF(AND(ISNUMBER(AN7),ISNUMBER($AM7)),OFFSET(RiskMatrixRef,-$AM7+1,AN7-1),"") | AS7: =IF(AND(ISNUMBER(AO7),ISNUMBER($AM7)),OFFSET(RiskMatrixRef,-$AM7+1,AO7-1),"") | AT7: =IF(AND(ISNUMBER(AP7),ISNUMBER($AM7)),OFFSET(RiskMatrixRef,-$AM7+1,AP7-1),"") | AU7: =IF(AND(ISNUMBER(AQ7),ISNUMBER($AM7)),OFFSET(RiskMatrixRef,-$AM7+1,AQ7-1),"")
B8: 0571/0572 -3 | C8: Stbd/Port Spar Bilge Pumps & Controllers | D8: Remove water from WEC collected from port/stbd PTO or Control Room. (Two pumps per side - redundant cross connected power) | E8: 1 | F8: none | G8: Mechanical failure in pump | H8: 1) Loss of one bilge pump 2) In the case of water being present, second bilge pump runs to remove normal bilge collection | I8: 1) Manufacturing defect 2) Fatigue or degradation over time 3) Contamination leads to fault 4) Component corrosion leads to fault 5) Control fault 6) Installation error | J8: Normal | K8: Redundent design 1) Two pumps 2) 4 power sources (Port/Stbd PTO, Grid, & UPS) 3) Cross connected electrical distribution | L8: 1) V&V (QC) 2) Inspections | M8: 1) Secondary bilge pump running 2) SCADA diagnostics | N8: In-situ repair | O8: 4 | P8: 1 | Q8: 1 | R8: 5 | S8: 4 | T8: =IF(AND(ISNUMBER(P8),ISNUMBER($O8)),OFFSET(RiskMatrixRef,-$O8+1,P8-1),"") -> Low | U8: =IF(AND(ISNUMBER(Q8),ISNUMBER($O8)),OFFSET(RiskMatrixRef,-$O8+1,Q8-1),"") -> Low | V8: =IF(AND(ISNUMBER(R8),ISNUMBER($O8)),OFFSET(RiskMatrixRef,-$O8+1,R8-1),"") -> Low | W8: =IF(AND(ISNUMBER(S8),ISNUMBER($O8)),OFFSET(RiskMatrixRef,-$O8+1,S8-1),"") -> Low | AF8: =IF(AND(ISNUMBER(AB8),ISNUMBER($AA8)),OFFSET(RiskMatrixRef,-$AA8+1,AB8-1),"") | AG8: =IF(AND(ISNUMBER(AC8),ISNUMBER($AA8)),OFFSET(RiskMatrixRef,-$AA8+1,AC8-1),"") | AH8: =IF(AND(ISNUMBER(AD8),ISNUMBER($AA8)),OFFSET(RiskMatrixRef,-$AA8+1,AD8-1),"") | AI8: =IF(AND(ISNUMBER(AE8),ISNUMBER($AA8)),OFFSET(RiskMatrixRef,-$AA8+1,AE8-1),"") | AR8: =IF(AND(ISNUMBER(AN8),ISNUMBER($AM8)),OFFSET(RiskMatrixRef,-$AM8+1,AN8-1),"") | AS8: =IF(AND(ISNUMBER(AO8),ISNUMBER($AM8)),OFFSET(RiskMatrixRef,-$AM8+1,AO8-1),"") | AT8: =IF(AND(ISNUMBER(AP8),ISNUMBER($AM8)),OFFSET(RiskMatrixRef,-$AM8+1,AP8-1),"") | AU8: =IF(AND(ISNUMBER(AQ8),ISNUMBER($AM8)),OFFSET(RiskMatrixRef,-$AM8+1,AQ8-1),"")
B9: 0571/0572 -4 | C9: Stbd/Port Spar Bilge Pumps & Controllers | D9: Remove water from WEC collected from port/stbd PTO or Control Room. (Two pumps per side - redundant cross connected power) | E9: 1 | F9: none | G9: Mechanical failure in switch | H9: 1) Loss of one bilge pump 2) In the case of water being present, second bilge pump runs to remove normal bilge collection | I9: 1) Manufacturing defect 2) Fatigue or degradation over time 3) Contamination leads to fault 4) Component corrosion leads to fault 5) Control fault 6) Installation error | J9: Normal | K9: Redundent design 1) Two pumps 2) 4 power sources (Port/Stbd PTO, Grid, & UPS) 3) Cross connected electrical distribution | L9: 1) V&V (QC) 2) Inspections | M9: 1) Secondary bilge pump running 2) SCADA diagnostics | N9: In-situ repair | O9: 4 | P9: 1 | Q9: 1 | R9: 5 | S9: 4 | T9: =IF(AND(ISNUMBER(P9),ISNUMBER($O9)),OFFSET(RiskMatrixRef,-$O9+1,P9-1),"") -> Low | U9: =IF(AND(ISNUMBER(Q9),ISNUMBER($O9)),OFFSET(RiskMatrixRef,-$O9+1,Q9-1),"") -> Low | V9: =IF(AND(ISNUMBER(R9),ISNUMBER($O9)),OFFSET(RiskMatrixRef,-$O9+1,R9-1),"") -> Low | W9: =IF(AND(ISNUMBER(S9),ISNUMBER($O9)),OFFSET(RiskMatrixRef,-$O9+1,S9-1),"") -> Low | AF9: =IF(AND(ISNUMBER(AB9),ISNUMBER($AA9)),OFFSET(RiskMatrixRef,-$AA9+1,AB9-1),"") | AG9: =IF(AND(ISNUMBER(AC9),ISNUMBER($AA9)),OFFSET(RiskMatrixRef,-$AA9+1,AC9-1),"") | AH9: =IF(AND(ISNUMBER(AD9),ISNUMBER($AA9)),OFFSET(RiskMatrixRef,-$AA9+1,AD9-1),"") | AI9: =IF(AND(ISNUMBER(AE9),ISNUMBER($AA9)),OFFSET(RiskMatrixRef,-$AA9+1,AE9-1),"") | AR9: =IF(AND(ISNUMBER(AN9),ISNUMBER($AM9)),OFFSET(RiskMatrixRef,-$AM9+1,AN9-1),"") | AS9: =IF(AND(ISNUMBER(AO9),ISNUMBER($AM9)),OFFSET(RiskMatrixRef,-$AM9+1,AO9-1),"") | AT9: =IF(AND(ISNUMBER(AP9),ISNUMBER($AM9)),OFFSET(RiskMatrixRef,-$AM9+1,AP9-1),"") | AU9: =IF(AND(ISNUMBER(AQ9),ISNUMBER($AM9)),OFFSET(RiskMatrixRef,-$AM9+1,AQ9-1),"")
B10: 0571/0572 -5 | C10: Stbd/Port Spar Bilge Pumps & Controllers | D10: Remove water from WEC collected from port/stbd PTO or Control Room. (Two pumps per side - redundant cross connected power) | E10: 1 | F10: none | G10: Electrical Fault - smoke/fire | H10: 1) Electrical isolation - loss of port/stbd spar bilge pumps | I10: 1) Manufacturing defect 2) Fatigue or degradation over time 3) Contamination leads to fault 4) Component corrosion leads to fault 5) Control fault 6) Installation error | J10: Normal | K10: Sealed bilge chamber | L10: 1) V&V (QC) 2) Inspections | M10: 1) Secondary bilge pump running 2) SCADA diagnostics | N10: In-situ repair | O10: 4 | P10: 1 | Q10: 1 | R10: 5 | S10: 4 | T10: =IF(AND(ISNUMBER(P10),ISNUMBER($O10)),OFFSET(RiskMatrixRef,-$O10+1,P10-1),"") -> Low | U10: =IF(AND(ISNUMBER(Q10),ISNUMBER($O10)),OFFSET(RiskMatrixRef,-$O10+1,Q10-1),"") -> Low | V10: =IF(AND(ISNUMBER(R10),ISNUMBER($O10)),OFFSET(RiskMatrixRef,-$O10+1,R10-1),"") -> Low | W10: =IF(AND(ISNUMBER(S10),ISNUMBER($O10)),OFFSET(RiskMatrixRef,-$O10+1,S10-1),"") -> Low | AF10: =IF(AND(ISNUMBER(AB10),ISNUMBER($AA10)),OFFSET(RiskMatrixRef,-$AA10+1,AB10-1),"") | AG10: =IF(AND(ISNUMBER(AC10),ISNUMBER($AA10)),OFFSET(RiskMatrixRef,-$AA10+1,AC10-1),"") | AH10: =IF(AND(ISNUMBER(AD10),ISNUMBER($AA10)),OFFSET(RiskMatrixRef,-$AA10+1,AD10-1),"") | AI10: =IF(AND(ISNUMBER(AE10),ISNUMBER($AA10)),OFFSET(RiskMatrixRef,-$AA10+1,AE10-1),"") | AR10: =IF(AND(ISNUMBER(AN10),ISNUMBER($AM10)),OFFSET(RiskMatrixRef,-$AM10+1,AN10-1),"") | AS10: =IF(AND(ISNUMBER(AO10),ISNUMBER($AM10)),OFFSET(RiskMatrixRef,-$AM10+1,AO10-1),"") | AT10: =IF(AND(ISNUMBER(AP10),ISNUMBER($AM10)),OFFSET(RiskMatrixRef,-$AM10+1,AP10-1),"") | AU10: =IF(AND(ISNUMBER(AQ10),ISNUMBER($AM10)),OFFSET(RiskMatrixRef,-$AM10+1,AQ10-1),"")
B11: 0571/0572 -5 | C11: Stbd/Port Spar Bilge Pumps & Controllers | D11: Remove water from WEC collected from port/stbd PTO or Control Room. (Two pumps per side - redundant cross connected power) | E11: 1 | F11: none | G11: Electrical Fault - smoke/fire | H11: 1) Electrical isolation - loss of port/stbd spar bilge pumps 2) Water raises in sealed bilge, filling bilge chamber. 3) Water flow overboard due to pressure differential via check valve | I11: 1) Manufacturing defect 2) Fatigue or degradation over time 3) Contamination leads to fault 4) Component corrosion leads to fault 5) Control fault 6) Installation error | J11: Emergency - Seal Failure Pump is running, bilge system working | K11: 1) Sealed bilge chamber 2) Electrical isolation breakers 3) Automatic fire suppression 4) V&V (QC) 5) 0520 Emergency Systems | L11: 1) V&V (QC) 2) Inspections | M11: 1) 0520 Emergency System 2) SCADA Diagnostics | N11: In-situ inspection for repair, repair at dry dock as necessary | O11: 5 | P11: 1 | Q11: 1 | R11: 8 | S11: 8 | T11: =IF(AND(ISNUMBER(P11),ISNUMBER($O11)),OFFSET(RiskMatrixRef,-$O11+1,P11-1),"") -> Low | U11: =IF(AND(ISNUMBER(Q11),ISNUMBER($O11)),OFFSET(RiskMatrixRef,-$O11+1,Q11-1),"") -> Low | V11: =IF(AND(ISNUMBER(R11),ISNUMBER($O11)),OFFSET(RiskMatrixRef,-$O11+1,R11-1),"") -> Med | W11: =IF(AND(ISNUMBER(S11),ISNUMBER($O11)),OFFSET(RiskMatrixRef,-$O11+1,S11-1),"") -> Med | AF11: =IF(AND(ISNUMBER(AB11),ISNUMBER($AA11)),OFFSET(RiskMatrixRef,-$AA11+1,AB11-1),"") | AG11: =IF(AND(ISNUMBER(AC11),ISNUMBER($AA11)),OFFSET(RiskMatrixRef,-$AA11+1,AC11-1),"") | AH11: =IF(AND(ISNUMBER(AD11),ISNUMBER($AA11)),OFFSET(RiskMatrixRef,-$AA11+1,AD11-1),"") | AI11: =IF(AND(ISNUMBER(AE11),ISNUMBER($AA11)),OFFSET(RiskMatrixRef,-$AA11+1,AE11-1),"") | AR11: =IF(AND(ISNUMBER(AN11),ISNUMBER($AM11)),OFFSET(RiskMatrixRef,-$AM11+1,AN11-1),"") | AS11: =IF(AND(ISNUMBER(AO11),ISNUMBER($AM11)),OFFSET(RiskMatrixRef,-$AM11+1,AO11-1),"") | AT11: =IF(AND(ISNUMBER(AP11),ISNUMBER($AM11)),OFFSET(RiskMatrixRef,-$AM11+1,AP11-1),"") | AU11: =IF(AND(ISNUMBER(AQ11),ISNUMBER($AM11)),OFFSET(RiskMatrixRef,-$AM11+1,AQ11-1),"") | AW11: Second level contingency - flooding followed by fault in system
B12: 0573/0574 -1 | C12: Stbd/Port PTO Seal Bilge Pumps & Controllers | D12: Remove water from PTO seal bilge tank and transfer to the spar bilge tank | E12: 1 | F12: none | G12: Electrical Fault - Pump | H12: 1) Loss of PTO Seal bilge pump 2) PTO Sealed bilge transfers water to spar bilge via check-valve and pressure differential | I12: 1) Manufacturing defect 2) Fatigue or degradation over time 3) Contamination leads to fault 4) Component corrosion leads to fault 5) Control fault 6) Installation error | J12: Normal | K12: 1) Sealed PTO seal bilge compartment allow for natural flow once pressure differential is reached to open check valve. 3) Location of sealed bilge works in both deployed and normal operating conditions | L12: 1) V&V (QC) 2) Inspections | M12: SCADA Diagnostics | N12: in-situ repair during service | O12: 4 | P12: 1 | Q12: 1 | R12: 5 | S12: 4 | T12: =IF(AND(ISNUMBER(P12),ISNUMBER($O12)),OFFSET(RiskMatrixRef,-$O12+1,P12-1),"") -> Low | U12: =IF(AND(ISNUMBER(Q12),ISNUMBER($O12)),OFFSET(RiskMatrixRef,-$O12+1,Q12-1),"") -> Low | V12: =IF(AND(ISNUMBER(R12),ISNUMBER($O12)),OFFSET(RiskMatrixRef,-$O12+1,R12-1),"") -> Low | W12: =IF(AND(ISNUMBER(S12),ISNUMBER($O12)),OFFSET(RiskMatrixRef,-$O12+1,S12-1),"") -> Low | AF12: =IF(AND(ISNUMBER(AB12),ISNUMBER($AA12)),OFFSET(RiskMatrixRef,-$AA12+1,AB12-1),"") | AG12: =IF(AND(ISNUMBER(AC12),ISNUMBER($AA12)),OFFSET(RiskMatrixRef,-$AA12+1,AC12-1),"") | AH12: =IF(AND(ISNUMBER(AD12),ISNUMBER($AA12)),OFFSET(RiskMatrixRef,-$AA12+1,AD12-1),"") | AI12: =IF(AND(ISNUMBER(AE12),ISNUMBER($AA12)),OFFSET(RiskMatrixRef,-$AA12+1,AE12-1),"") | AR12: =IF(AND(ISNUMBER(AN12),ISNUMBER($AM12)),OFFSET(RiskMatrixRef,-$AM12+1,AN12-1),"") | AS12: =IF(AND(ISNUMBER(AO12),ISNUMBER($AM12)),OFFSET(RiskMatrixRef,-$AM12+1,AO12-1),"") | AT12: =IF(AND(ISNUMBER(AP12),ISNUMBER($AM12)),OFFSET(RiskMatrixRef,-$AM12+1,AP12-1),"") | AU12: =IF(AND(ISNUMBER(AQ12),ISNUMBER($AM12)),OFFSET(RiskMatrixRef,-$AM12+1,AQ12-1),"")
B13: 0573/0574 -2 | C13: Stbd/Port PTO Seal Bilge Pumps & Controllers | D13: Remove water from PTO seal bilge tank and transfer to the spar bilge tank | E13: 1 | F13: none | G13: Electrical Fault - Controller | H13: 1) Loss of PTO Seal bilge pump 2) PTO Sealed bilge transfers water to spar bilge via check-valve and pressure differential | I13: 1) Manufacturing defect 2) Fatigue or degradation over time 3) Contamination leads to fault 4) Component corrosion leads to fault 5) Control fault 6) Installation error | J13: Normal | K13: 1) Sealed PTO seal bilge compartment allow for natural flow once pressure differential is reached to open check valve. 3) Location of sealed bilge works in both deployed and normal operating conditions | L13: 1) V&V (QC) 2) Inspections | M13: SCADA Diagnostics | N13: in-situ repair during service | O13: 4 | P13: 1 | Q13: 1 | R13: 5 | S13: 4 | T13: =IF(AND(ISNUMBER(P13),ISNUMBER($O13)),OFFSET(RiskMatrixRef,-$O13+1,P13-1),"") -> Low | U13: =IF(AND(ISNUMBER(Q13),ISNUMBER($O13)),OFFSET(RiskMatrixRef,-$O13+1,Q13-1),"") -> Low | V13: =IF(AND(ISNUMBER(R13),ISNUMBER($O13)),OFFSET(RiskMatrixRef,-$O13+1,R13-1),"") -> Low | W13: =IF(AND(ISNUMBER(S13),ISNUMBER($O13)),OFFSET(RiskMatrixRef,-$O13+1,S13-1),"") -> Low | AF13: =IF(AND(ISNUMBER(AB13),ISNUMBER($AA13)),OFFSET(RiskMatrixRef,-$AA13+1,AB13-1),"") | AG13: =IF(AND(ISNUMBER(AC13),ISNUMBER($AA13)),OFFSET(RiskMatrixRef,-$AA13+1,AC13-1),"") | AH13: =IF(AND(ISNUMBER(AD13),ISNUMBER($AA13)),OFFSET(RiskMatrixRef,-$AA13+1,AD13-1),"") | AI13: =IF(AND(ISNUMBER(AE13),ISNUMBER($AA13)),OFFSET(RiskMatrixRef,-$AA13+1,AE13-1),"") | AR13: =IF(AND(ISNUMBER(AN13),ISNUMBER($AM13)),OFFSET(RiskMatrixRef,-$AM13+1,AN13-1),"") | AS13: =IF(AND(ISNUMBER(AO13),ISNUMBER($AM13)),OFFSET(RiskMatrixRef,-$AM13+1,AO13-1),"") | AT13: =IF(AND(ISNUMBER(AP13),ISNUMBER($AM13)),OFFSET(RiskMatrixRef,-$AM13+1,AP13-1),"") | AU13: =IF(AND(ISNUMBER(AQ13),ISNUMBER($AM13)),OFFSET(RiskMatrixRef,-$AM13+1,AQ13-1),"")
B14: 0573/0574 -3 | C14: Stbd/Port PTO Seal Bilge Pumps & Controllers | D14: Remove water from PTO seal bilge tank and transfer to the spar bilge tank | E14: 1 | F14: none | G14: Mechanical failure in pump | H14: 1) Loss of PTO Seal bilge pump 2) PTO Sealed bilge transfers water to spar bilge via check-valve and pressure differential | I14: 1) Manufacturing defect 2) Fatigue or degradation over time 3) Contamination leads to fault 4) Component corrosion leads to fault 5) Control fault 6) Installation error | J14: Normal | K14: 1) Sealed PTO seal bilge compartment allow for natural flow once pressure differential is reached to open check valve. 3) Location of sealed bilge works in both deployed and normal operating conditions | L14: 1) V&V (QC) 2) Inspections | M14: SCADA Diagnostics | N14: in-situ repair during service | O14: 4 | P14: 1 | Q14: 1 | R14: 5 | S14: 4 | T14: =IF(AND(ISNUMBER(P14),ISNUMBER($O14)),OFFSET(RiskMatrixRef,-$O14+1,P14-1),"") -> Low | U14: =IF(AND(ISNUMBER(Q14),ISNUMBER($O14)),OFFSET(RiskMatrixRef,-$O14+1,Q14-1),"") -> Low | V14: =IF(AND(ISNUMBER(R14),ISNUMBER($O14)),OFFSET(RiskMatrixRef,-$O14+1,R14-1),"") -> Low | W14: =IF(AND(ISNUMBER(S14),ISNUMBER($O14)),OFFSET(RiskMatrixRef,-$O14+1,S14-1),"") -> Low | AF14: =IF(AND(ISNUMBER(AB14),ISNUMBER($AA14)),OFFSET(RiskMatrixRef,-$AA14+1,AB14-1),"") | AG14: =IF(AND(ISNUMBER(AC14),ISNUMBER($AA14)),OFFSET(RiskMatrixRef,-$AA14+1,AC14-1),"") | AH14: =IF(AND(ISNUMBER(AD14),ISNUMBER($AA14)),OFFSET(RiskMatrixRef,-$AA14+1,AD14-1),"") | AI14: =IF(AND(ISNUMBER(AE14),ISNUMBER($AA14)),OFFSET(RiskMatrixRef,-$AA14+1,AE14-1),"") | AR14: =IF(AND(ISNUMBER(AN14),ISNUMBER($AM14)),OFFSET(RiskMatrixRef,-$AM14+1,AN14-1),"") | AS14: =IF(AND(ISNUMBER(AO14),ISNUMBER($AM14)),OFFSET(RiskMatrixRef,-$AM14+1,AO14-1),"") | AT14: =IF(AND(ISNUMBER(AP14),ISNUMBER($AM14)),OFFSET(RiskMatrixRef,-$AM14+1,AP14-1),"") | AU14: =IF(AND(ISNUMBER(AQ14),ISNUMBER($AM14)),OFFSET(RiskMatrixRef,-$AM14+1,AQ14-1),"")
B15: 0573/0574 -4 | C15: Stbd/Port PTO Seal Bilge Pumps & Controllers | D15: Remove water from PTO seal bilge tank and transfer to the spar bilge tank | E15: 1 | F15: none | G15: Mechanical failure in switch | H15: 1) Loss of PTO Seal bilge pump 2) PTO Sealed bilge transfers water to spar bilge via check-valve and pressure differential | I15: 1) Manufacturing defect 2) Fatigue or degradation over time 3) Contamination leads to fault 4) Component corrosion leads to fault 5) Control fault 6) Installation error | J15: Normal | K15: 1) Sealed PTO seal bilge compartment allow for natural flow once pressure differential is reached to open check valve. 3) Location of sealed bilge works in both deployed and normal operating conditions | L15: 1) V&V (QC) 2) Inspections | M15: SCADA Diagnostics | N15: in-situ repair during service | O15: 4 | P15: 1 | Q15: 1 | R15: 5 | S15: 4 | T15: =IF(AND(ISNUMBER(P15),ISNUMBER($O15)),OFFSET(RiskMatrixRef,-$O15+1,P15-1),"") -> Low | U15: =IF(AND(ISNUMBER(Q15),ISNUMBER($O15)),OFFSET(RiskMatrixRef,-$O15+1,Q15-1),"") -> Low | V15: =IF(AND(ISNUMBER(R15),ISNUMBER($O15)),OFFSET(RiskMatrixRef,-$O15+1,R15-1),"") -> Low | W15: =IF(AND(ISNUMBER(S15),ISNUMBER($O15)),OFFSET(RiskMatrixRef,-$O15+1,S15-1),"") -> Low | AF15: =IF(AND(ISNUMBER(AB15),ISNUMBER($AA15)),OFFSET(RiskMatrixRef,-$AA15+1,AB15-1),"") | AG15: =IF(AND(ISNUMBER(AC15),ISNUMBER($AA15)),OFFSET(RiskMatrixRef,-$AA15+1,AC15-1),"") | AH15: =IF(AND(ISNUMBER(AD15),ISNUMBER($AA15)),OFFSET(RiskMatrixRef,-$AA15+1,AD15-1),"") | AI15: =IF(AND(ISNUMBER(AE15),ISNUMBER($AA15)),OFFSET(RiskMatrixRef,-$AA15+1,AE15-1),"") | AR15: =IF(AND(ISNUMBER(AN15),ISNUMBER($AM15)),OFFSET(RiskMatrixRef,-$AM15+1,AN15-1),"") | AS15: =IF(AND(ISNUMBER(AO15),ISNUMBER($AM15)),OFFSET(RiskMatrixRef,-$AM15+1,AO15-1),"") | AT15: =IF(AND(ISNUMBER(AP15),ISNUMBER($AM15)),OFFSET(RiskMatrixRef,-$AM15+1,AP15-1),"") | AU15: =IF(AND(ISNUMBER(AQ15),ISNUMBER($AM15)),OFFSET(RiskMatrixRef,-$AM15+1,AQ15-1),"")
B16: 0573/0574 -5 | C16: Stbd/Port PTO Seal Bilge Pumps & Controllers | D16: Remove water from PTO seal bilge tank and transfer to the spar bilge tank | E16: 1 | F16: none | G16: Electrical Fault - smoke/fire | H16: 1) PTO floods up to secondary bilge level from leak 2) Stator segment damage from water | I16: 1) Manufacturing defect 2) Fatigue or degradation over time 3) Contamination leads to fault 4) Component corrosion leads to fault 5) Control fault 6) Installation error | J16: Normal | K16: Two pumps per compartment | L16: 1) V&V (QC) 2) Inspections | M16: SCADA Diagnostics | N16: in-situ repair during service | O16: 4 | P16: 1 | Q16: 1 | R16: 5 | S16: 4 | T16: =IF(AND(ISNUMBER(P16),ISNUMBER($O16)),OFFSET(RiskMatrixRef,-$O16+1,P16-1),"") -> Low | U16: =IF(AND(ISNUMBER(Q16),ISNUMBER($O16)),OFFSET(RiskMatrixRef,-$O16+1,Q16-1),"") -> Low | V16: =IF(AND(ISNUMBER(R16),ISNUMBER($O16)),OFFSET(RiskMatrixRef,-$O16+1,R16-1),"") -> Low | W16: =IF(AND(ISNUMBER(S16),ISNUMBER($O16)),OFFSET(RiskMatrixRef,-$O16+1,S16-1),"") -> Low | AF16: =IF(AND(ISNUMBER(AB16),ISNUMBER($AA16)),OFFSET(RiskMatrixRef,-$AA16+1,AB16-1),"") | AG16: =IF(AND(ISNUMBER(AC16),ISNUMBER($AA16)),OFFSET(RiskMatrixRef,-$AA16+1,AC16-1),"") | AH16: =IF(AND(ISNUMBER(AD16),ISNUMBER($AA16)),OFFSET(RiskMatrixRef,-$AA16+1,AD16-1),"") | AI16: =IF(AND(ISNUMBER(AE16),ISNUMBER($AA16)),OFFSET(RiskMatrixRef,-$AA16+1,AE16-1),"") | AR16: =IF(AND(ISNUMBER(AN16),ISNUMBER($AM16)),OFFSET(RiskMatrixRef,-$AM16+1,AN16-1),"") | AS16: =IF(AND(ISNUMBER(AO16),ISNUMBER($AM16)),OFFSET(RiskMatrixRef,-$AM16+1,AO16-1),"") | AT16: =IF(AND(ISNUMBER(AP16),ISNUMBER($AM16)),OFFSET(RiskMatrixRef,-$AM16+1,AP16-1),"") | AU16: =IF(AND(ISNUMBER(AQ16),ISNUMBER($AM16)),OFFSET(RiskMatrixRef,-$AM16+1,AQ16-1),"")
B17: 0573/0574 -6 | C17: Stbd/Port PTO Seal Bilge Pumps & Controllers | D17: Remove water from PTO seal bilge tank and transfer to the spar bilge tank | E17: 2 | F17: none | G17: Electrical Fault - smoke/fire | H17: 1) PTO seal bilge pump does not transfer water 2) Water is transferred to spar bilge once pressure differentail opens check valve | I17: 1) Manufacturing defect 2) Fatigue or degradation over time 3) Contamination leads to fault 4) Component corrosion leads to fault 5) Control fault 6) Installation error | J17: Emergency - Seal Failure Pump is running, bilge system working | K17: 1) Sealed bilge chamber 2) Electrical isolation breakers 3) Automatic fire suppression 4) V&V (QC) 5) 0520 Emergency Systems | L17: 1) V&V (QC) 2) Inspections | M17: 1) 0520 Emergency System 2) SCADA Diagnostics | N17: In-situ inspection for repair, repair at dry dock as necessary | O17: 5 | P17: 1 | Q17: 1 | R17: 8 | S17: 8 | T17: =IF(AND(ISNUMBER(P17),ISNUMBER($O17)),OFFSET(RiskMatrixRef,-$O17+1,P17-1),"") -> Low | U17: =IF(AND(ISNUMBER(Q17),ISNUMBER($O17)),OFFSET(RiskMatrixRef,-$O17+1,Q17-1),"") -> Low | V17: =IF(AND(ISNUMBER(R17),ISNUMBER($O17)),OFFSET(RiskMatrixRef,-$O17+1,R17-1),"") -> Med | W17: =IF(AND(ISNUMBER(S17),ISNUMBER($O17)),OFFSET(RiskMatrixRef,-$O17+1,S17-1),"") -> Med | AF17: =IF(AND(ISNUMBER(AB17),ISNUMBER($AA17)),OFFSET(RiskMatrixRef,-$AA17+1,AB17-1),"") | AG17: =IF(AND(ISNUMBER(AC17),ISNUMBER($AA17)),OFFSET(RiskMatrixRef,-$AA17+1,AC17-1),"") | AH17: =IF(AND(ISNUMBER(AD17),ISNUMBER($AA17)),OFFSET(RiskMatrixRef,-$AA17+1,AD17-1),"") | AI17: =IF(AND(ISNUMBER(AE17),ISNUMBER($AA17)),OFFSET(RiskMatrixRef,-$AA17+1,AE17-1),"") | AR17: =IF(AND(ISNUMBER(AN17),ISNUMBER($AM17)),OFFSET(RiskMatrixRef,-$AM17+1,AN17-1),"") | AS17: =IF(AND(ISNUMBER(AO17),ISNUMBER($AM17)),OFFSET(RiskMatrixRef,-$AM17+1,AO17-1),"") | AT17: =IF(AND(ISNUMBER(AP17),ISNUMBER($AM17)),OFFSET(RiskMatrixRef,-$AM17+1,AP17-1),"") | AU17: =IF(AND(ISNUMBER(AQ17),ISNUMBER($AM17)),OFFSET(RiskMatrixRef,-$AM17+1,AQ17-1),"")
B18: 0575/0576 -1 | C18: Stbd/Port PTO Bilge Pumps & Controllers | D18: Port/Stbd identical systems: Remove bilge water from the lowest point of the PTO module, transfering the water to the spar bilge | E18: 1 | F18: none | G18: Electrical Fault - Pump | H18: 1) Loss of bilge pump 2) Any residual bilge collection is not pumped to spar bilge | I18: 1) Manufacturing defect 2) Fatigue or degradation over time 3) Contamination leads to fault 4) Component corrosion leads to fault 5) Control fault 6) Installation error | J18: Normal | K18: 1) Three bilge pumps in PTO compartment 2) Check valve flow direction restrictions 3) Bilge level sensors 4) Surveillance 5) Air quality monitoring for moisture content. | L18: 1) V&V (QC) 2) Inspections | M18: 1) SCADA diagnostic 2) Surveillance | N18: in-situ repair | O18: 4 | P18: 1 | Q18: 1 | R18: 5 | S18: 4 | T18: =IF(AND(ISNUMBER(P18),ISNUMBER($O18)),OFFSET(RiskMatrixRef,-$O18+1,P18-1),"") -> Low | U18: =IF(AND(ISNUMBER(Q18),ISNUMBER($O18)),OFFSET(RiskMatrixRef,-$O18+1,Q18-1),"") -> Low | V18: =IF(AND(ISNUMBER(R18),ISNUMBER($O18)),OFFSET(RiskMatrixRef,-$O18+1,R18-1),"") -> Low | W18: =IF(AND(ISNUMBER(S18),ISNUMBER($O18)),OFFSET(RiskMatrixRef,-$O18+1,S18-1),"") -> Low | AF18: =IF(AND(ISNUMBER(AB18),ISNUMBER($AA18)),OFFSET(RiskMatrixRef,-$AA18+1,AB18-1),"") | AG18: =IF(AND(ISNUMBER(AC18),ISNUMBER($AA18)),OFFSET(RiskMatrixRef,-$AA18+1,AC18-1),"") | AH18: =IF(AND(ISNUMBER(AD18),ISNUMBER($AA18)),OFFSET(RiskMatrixRef,-$AA18+1,AD18-1),"") | AI18: =IF(AND(ISNUMBER(AE18),ISNUMBER($AA18)),OFFSET(RiskMatrixRef,-$AA18+1,AE18-1),"") | AR18: =IF(AND(ISNUMBER(AN18),ISNUMBER($AM18)),OFFSET(RiskMatrixRef,-$AM18+1,AN18-1),"") | AS18: =IF(AND(ISNUMBER(AO18),ISNUMBER($AM18)),OFFSET(RiskMatrixRef,-$AM18+1,AO18-1),"") | AT18: =IF(AND(ISNUMBER(AP18),ISNUMBER($AM18)),OFFSET(RiskMatrixRef,-$AM18+1,AP18-1),"") | AU18: =IF(AND(ISNUMBER(AQ18),ISNUMBER($AM18)),OFFSET(RiskMatrixRef,-$AM18+1,AQ18-1),"")
B19: 0575/0576 -2 | C19: Stbd/Port PTO Bilge Pumps & Controllers | D19: Port/Stbd identical systems: Remove bilge water from the lowest point of the PTO module, transfering the water to the spar bilge | E19: 1 | F19: none | G19: Electrical Fault - Controller | H19: 1) Loss of bilge pump 2) Any residual bilge collection is not pumped to spar bilge | I19: 1) Manufacturing defect 2) Fatigue or degradation over time 3) Contamination leads to fault 4) Component corrosion leads to fault 5) Control fault 6) Installation error | J19: Normal | K19: 1) Three bilge pumps in PTO compartment 2) Check valve flow direction restrictions 3) Bilge level sensors 4) Surveillance 5) Air quality monitoring for moisture content. | L19: 1) V&V (QC) 2) Inspections | M19: 1) SCADA diagnostic 2) Surveillance | N19: in-situ repair | O19: 4 | P19: 1 | Q19: 1 | R19: 5 | S19: 4 | T19: =IF(AND(ISNUMBER(P19),ISNUMBER($O19)),OFFSET(RiskMatrixRef,-$O19+1,P19-1),"") -> Low | U19: =IF(AND(ISNUMBER(Q19),ISNUMBER($O19)),OFFSET(RiskMatrixRef,-$O19+1,Q19-1),"") -> Low | V19: =IF(AND(ISNUMBER(R19),ISNUMBER($O19)),OFFSET(RiskMatrixRef,-$O19+1,R19-1),"") -> Low | W19: =IF(AND(ISNUMBER(S19),ISNUMBER($O19)),OFFSET(RiskMatrixRef,-$O19+1,S19-1),"") -> Low | AF19: =IF(AND(ISNUMBER(AB19),ISNUMBER($AA19)),OFFSET(RiskMatrixRef,-$AA19+1,AB19-1),"") | AG19: =IF(AND(ISNUMBER(AC19),ISNUMBER($AA19)),OFFSET(RiskMatrixRef,-$AA19+1,AC19-1),"") | AH19: =IF(AND(ISNUMBER(AD19),ISNUMBER($AA19)),OFFSET(RiskMatrixRef,-$AA19+1,AD19-1),"") | AI19: =IF(AND(ISNUMBER(AE19),ISNUMBER($AA19)),OFFSET(RiskMatrixRef,-$AA19+1,AE19-1),"") | AR19: =IF(AND(ISNUMBER(AN19),ISNUMBER($AM19)),OFFSET(RiskMatrixRef,-$AM19+1,AN19-1),"") | AS19: =IF(AND(ISNUMBER(AO19),ISNUMBER($AM19)),OFFSET(RiskMatrixRef,-$AM19+1,AO19-1),"") | AT19: =IF(AND(ISNUMBER(AP19),ISNUMBER($AM19)),OFFSET(RiskMatrixRef,-$AM19+1,AP19-1),"") | AU19: =IF(AND(ISNUMBER(AQ19),ISNUMBER($AM19)),OFFSET(RiskMatrixRef,-$AM19+1,AQ19-1),"")
B20: 0575/0576 -3 | C20: Stbd/Port PTO Bilge Pumps & Controllers | D20: Port/Stbd identical systems: Remove bilge water from the lowest point of the PTO module, transfering the water to the spar bilge | E20: 1 | F20: none | G20: Mechanical failure in pump | H20: 1) Loss of bilge pump 2) Any residual bilge collection is not pumped to spar bilge | I20: 1) Manufacturing defect 2) Fatigue or degradation over time 3) Contamination leads to fault 4) Component corrosion leads to fault 5) Control fault 6) Installation error | J20: Normal | K20: 1) Three bilge pumps in PTO compartment 2) Check valve flow direction restrictions 3) Bilge level sensors 4) Surveillance 5) Air quality monitoring for moisture content. | L20: 1) V&V (QC) 2) Inspections | M20: 1) SCADA diagnostic 2) Surveillance | N20: in-situ repair | O20: 4 | P20: 1 | Q20: 1 | R20: 5 | S20: 4 | T20: =IF(AND(ISNUMBER(P20),ISNUMBER($O20)),OFFSET(RiskMatrixRef,-$O20+1,P20-1),"") -> Low | U20: =IF(AND(ISNUMBER(Q20),ISNUMBER($O20)),OFFSET(RiskMatrixRef,-$O20+1,Q20-1),"") -> Low | V20: =IF(AND(ISNUMBER(R20),ISNUMBER($O20)),OFFSET(RiskMatrixRef,-$O20+1,R20-1),"") -> Low | W20: =IF(AND(ISNUMBER(S20),ISNUMBER($O20)),OFFSET(RiskMatrixRef,-$O20+1,S20-1),"") -> Low | AF20: =IF(AND(ISNUMBER(AB20),ISNUMBER($AA20)),OFFSET(RiskMatrixRef,-$AA20+1,AB20-1),"") | AG20: =IF(AND(ISNUMBER(AC20),ISNUMBER($AA20)),OFFSET(RiskMatrixRef,-$AA20+1,AC20-1),"") | AH20: =IF(AND(ISNUMBER(AD20),ISNUMBER($AA20)),OFFSET(RiskMatrixRef,-$AA20+1,AD20-1),"") | AI20: =IF(AND(ISNUMBER(AE20),ISNUMBER($AA20)),OFFSET(RiskMatrixRef,-$AA20+1,AE20-1),"") | AR20: =IF(AND(ISNUMBER(AN20),ISNUMBER($AM20)),OFFSET(RiskMatrixRef,-$AM20+1,AN20-1),"") | AS20: =IF(AND(ISNUMBER(AO20),ISNUMBER($AM20)),OFFSET(RiskMatrixRef,-$AM20+1,AO20-1),"") | AT20: =IF(AND(ISNUMBER(AP20),ISNUMBER($AM20)),OFFSET(RiskMatrixRef,-$AM20+1,AP20-1),"") | AU20: =IF(AND(ISNUMBER(AQ20),ISNUMBER($AM20)),OFFSET(RiskMatrixRef,-$AM20+1,AQ20-1),"")
B21: 0575/0576 -4 | C21: Stbd/Port PTO Bilge Pumps & Controllers | D21: Port/Stbd identical systems: Remove bilge water from the lowest point of the PTO module, transfering the water to the spar bilge | E21: 1 | F21: none | G21: Mechanical failure in switch | H21: 1) Loss of bilge pump 2) Any residual bilge collection is not pumped to spar bilge | I21: 1) Manufacturing defect 2) Fatigue or degradation over time 3) Contamination leads to fault 4) Component corrosion leads to fault 5) Control fault 6) Installation error | J21: Normal | K21: 1) Three bilge pumps in PTO compartment 2) Check valve flow direction restrictions 3) Bilge level sensors 4) Surveillance 5) Air quality monitoring for moisture content. | L21: 1) V&V (QC) 2) Inspections | M21: 1) SCADA diagnostic 2) Surveillance | N21: in-situ repair | O21: 4 | P21: 1 | Q21: 1 | R21: 5 | S21: 4 | T21: =IF(AND(ISNUMBER(P21),ISNUMBER($O21)),OFFSET(RiskMatrixRef,-$O21+1,P21-1),"") -> Low | U21: =IF(AND(ISNUMBER(Q21),ISNUMBER($O21)),OFFSET(RiskMatrixRef,-$O21+1,Q21-1),"") -> Low | V21: =IF(AND(ISNUMBER(R21),ISNUMBER($O21)),OFFSET(RiskMatrixRef,-$O21+1,R21-1),"") -> Low | W21: =IF(AND(ISNUMBER(S21),ISNUMBER($O21)),OFFSET(RiskMatrixRef,-$O21+1,S21-1),"") -> Low | AF21: =IF(AND(ISNUMBER(AB21),ISNUMBER($AA21)),OFFSET(RiskMatrixRef,-$AA21+1,AB21-1),"") | AG21: =IF(AND(ISNUMBER(AC21),ISNUMBER($AA21)),OFFSET(RiskMatrixRef,-$AA21+1,AC21-1),"") | AH21: =IF(AND(ISNUMBER(AD21),ISNUMBER($AA21)),OFFSET(RiskMatrixRef,-$AA21+1,AD21-1),"") | AI21: =IF(AND(ISNUMBER(AE21),ISNUMBER($AA21)),OFFSET(RiskMatrixRef,-$AA21+1,AE21-1),"") | AR21: =IF(AND(ISNUMBER(AN21),ISNUMBER($AM21)),OFFSET(RiskMatrixRef,-$AM21+1,AN21-1),"") | AS21: =IF(AND(ISNUMBER(AO21),ISNUMBER($AM21)),OFFSET(RiskMatrixRef,-$AM21+1,AO21-1),"") | AT21: =IF(AND(ISNUMBER(AP21),ISNUMBER($AM21)),OFFSET(RiskMatrixRef,-$AM21+1,AP21-1),"") | AU21: =IF(AND(ISNUMBER(AQ21),ISNUMBER($AM21)),OFFSET(RiskMatrixRef,-$AM21+1,AQ21-1),"")
B22: 0575/0576 -5 | C22: Stbd/Port PTO Bilge Pumps & Controllers | D22: Port/Stbd identical systems: Remove bilge water from the lowest point of the PTO module, transfering the water to the spar bilge | E22: 1 | F22: none | G22: Electrical Fault - smoke/fire | H22: 1) Loss of bilge pump 2) Any residual bilge collection is not pumped to spar bilge | I22: 1) Manufacturing defect 2) Fatigue or degradation over time 3) Contamination leads to fault 4) Component corrosion leads to fault 5) Control fault 6) Installation error | J22: Normal | K22: 1) Three bilge pumps in PTO compartment 2) Check valve flow direction restrictions 3) Bilge level sensors 4) Surveillance 5) Air quality monitoring for moisture content. | L22: 1) V&V (QC) 2) Inspections | M22: 1) SCADA diagnostic 2) Surveillance | N22: in-situ repair | O22: 4 | P22: 1 | Q22: 1 | R22: 5 | S22: 4 | T22: =IF(AND(ISNUMBER(P22),ISNUMBER($O22)),OFFSET(RiskMatrixRef,-$O22+1,P22-1),"") -> Low | U22: =IF(AND(ISNUMBER(Q22),ISNUMBER($O22)),OFFSET(RiskMatrixRef,-$O22+1,Q22-1),"") -> Low | V22: =IF(AND(ISNUMBER(R22),ISNUMBER($O22)),OFFSET(RiskMatrixRef,-$O22+1,R22-1),"") -> Low | W22: =IF(AND(ISNUMBER(S22),ISNUMBER($O22)),OFFSET(RiskMatrixRef,-$O22+1,S22-1),"") -> Low | AF22: =IF(AND(ISNUMBER(AB22),ISNUMBER($AA22)),OFFSET(RiskMatrixRef,-$AA22+1,AB22-1),"") | AG22: =IF(AND(ISNUMBER(AC22),ISNUMBER($AA22)),OFFSET(RiskMatrixRef,-$AA22+1,AC22-1),"") | AH22: =IF(AND(ISNUMBER(AD22),ISNUMBER($AA22)),OFFSET(RiskMatrixRef,-$AA22+1,AD22-1),"") | AI22: =IF(AND(ISNUMBER(AE22),ISNUMBER($AA22)),OFFSET(RiskMatrixRef,-$AA22+1,AE22-1),"") | AR22: =IF(AND(ISNUMBER(AN22),ISNUMBER($AM22)),OFFSET(RiskMatrixRef,-$AM22+1,AN22-1),"") | AS22: =IF(AND(ISNUMBER(AO22),ISNUMBER($AM22)),OFFSET(RiskMatrixRef,-$AM22+1,AO22-1),"") | AT22: =IF(AND(ISNUMBER(AP22),ISNUMBER($AM22)),OFFSET(RiskMatrixRef,-$AM22+1,AP22-1),"") | AU22: =IF(AND(ISNUMBER(AQ22),ISNUMBER($AM22)),OFFSET(RiskMatrixRef,-$AM22+1,AQ22-1),"")
B23: 0575/0576 -5 | C23: Stbd/Port PTO Bilge Pumps & Controllers | D23: Port/Stbd identical systems: Remove bilge water from the lowest point of the PTO module, transfering the water to the spar bilge | E23: 2 | F23: none | G23: Electrical Fault - smoke/fire | H23: 1) Loss of bilge pump 2) Any residual bilge collection is not pumped to spar bilge | I23: 1) Manufacturing defect 2) Fatigue or degradation over time 3) Contamination leads to fault 4) Component corrosion leads to fault 5) Control fault 6) Installation error | J23: Emergency - Seal Failure Pump is running, bilge system working | M23: 1) SCADA diagnostic 2) Surveillance | N23: in-situ repair | O23: 4 | P23: 1 | Q23: 1 | R23: 5 | S23: 4 | T23: =IF(AND(ISNUMBER(P23),ISNUMBER($O23)),OFFSET(RiskMatrixRef,-$O23+1,P23-1),"") -> Low | U23: =IF(AND(ISNUMBER(Q23),ISNUMBER($O23)),OFFSET(RiskMatrixRef,-$O23+1,Q23-1),"") -> Low | V23: =IF(AND(ISNUMBER(R23),ISNUMBER($O23)),OFFSET(RiskMatrixRef,-$O23+1,R23-1),"") -> Low | W23: =IF(AND(ISNUMBER(S23),ISNUMBER($O23)),OFFSET(RiskMatrixRef,-$O23+1,S23-1),"") -> Low | AF23: =IF(AND(ISNUMBER(AB23),ISNUMBER($AA23)),OFFSET(RiskMatrixRef,-$AA23+1,AB23-1),"") | AG23: =IF(AND(ISNUMBER(AC23),ISNUMBER($AA23)),OFFSET(RiskMatrixRef,-$AA23+1,AC23-1),"") | AH23: =IF(AND(ISNUMBER(AD23),ISNUMBER($AA23)),OFFSET(RiskMatrixRef,-$AA23+1,AD23-1),"") | AI23: =IF(AND(ISNUMBER(AE23),ISNUMBER($AA23)),OFFSET(RiskMatrixRef,-$AA23+1,AE23-1),"") | AR23: =IF(AND(ISNUMBER(AN23),ISNUMBER($AM23)),OFFSET(RiskMatrixRef,-$AM23+1,AN23-1),"") | AS23: =IF(AND(ISNUMBER(AO23),ISNUMBER($AM23)),OFFSET(RiskMatrixRef,-$AM23+1,AO23-1),"") | AT23: =IF(AND(ISNUMBER(AP23),ISNUMBER($AM23)),OFFSET(RiskMatrixRef,-$AM23+1,AP23-1),"") | AU23: =IF(AND(ISNUMBER(AQ23),ISNUMBER($AM23)),OFFSET(RiskMatrixRef,-$AM23+1,AQ23-1),"")
B24: 0577-1 | C24: Deployment Pumping Systems | D24: During deployment, when WEC is near horizontal oreientation, remove water from port/stbd low point of PTO module, and control room. - (Pump + Control for Port PTO, Stbd PTO, Stbd side control room, Port side control room) | E24: 1 | F24: none | G24: Electrical Fault - Pump | H24: 1) Loss of bilge pump 2) Any residual bilge collection is not pumped to spar bilge | I24: 1) Manufacturing defect 2) Fatigue or degradation over time 3) Contamination leads to fault 4) Component corrosion leads to fault 5) Control fault 6) Installation error | J24: Deployment | K24: 1) water level/leek sensors 2) Tending vessel | L24: V&V(QC) | M24: 1) SCADA diagnostic 2) Surveillance | N24: in-situ repair | O24: 4 | P24: 1 | Q24: 1 | R24: 5 | S24: 4 | T24: =IF(AND(ISNUMBER(P24),ISNUMBER($O24)),OFFSET(RiskMatrixRef,-$O24+1,P24-1),"") -> Low | U24: =IF(AND(ISNUMBER(Q24),ISNUMBER($O24)),OFFSET(RiskMatrixRef,-$O24+1,Q24-1),"") -> Low | V24: =IF(AND(ISNUMBER(R24),ISNUMBER($O24)),OFFSET(RiskMatrixRef,-$O24+1,R24-1),"") -> Low | W24: =IF(AND(ISNUMBER(S24),ISNUMBER($O24)),OFFSET(RiskMatrixRef,-$O24+1,S24-1),"") -> Low | AF24: =IF(AND(ISNUMBER(AB24),ISNUMBER($AA24)),OFFSET(RiskMatrixRef,-$AA24+1,AB24-1),"") | AG24: =IF(AND(ISNUMBER(AC24),ISNUMBER($AA24)),OFFSET(RiskMatrixRef,-$AA24+1,AC24-1),"") | AH24: =IF(AND(ISNUMBER(AD24),ISNUMBER($AA24)),OFFSET(RiskMatrixRef,-$AA24+1,AD24-1),"") | AI24: =IF(AND(ISNUMBER(AE24),ISNUMBER($AA24)),OFFSET(RiskMatrixRef,-$AA24+1,AE24-1),"") | AR24: =IF(AND(ISNUMBER(AN24),ISNUMBER($AM24)),OFFSET(RiskMatrixRef,-$AM24+1,AN24-1),"") | AS24: =IF(AND(ISNUMBER(AO24),ISNUMBER($AM24)),OFFSET(RiskMatrixRef,-$AM24+1,AO24-1),"") | AT24: =IF(AND(ISNUMBER(AP24),ISNUMBER($AM24)),OFFSET(RiskMatrixRef,-$AM24+1,AP24-1),"") | AU24: =IF(AND(ISNUMBER(AQ24),ISNUMBER($AM24)),OFFSET(RiskMatrixRef,-$AM24+1,AQ24-1),"")
B25: 0577-2 | C25: Deployment Pumping Systems | D25: During deployment, when WEC is near horizontal oreientation, remove water from port/stbd low point of PTO module, and control room. - (Pump + Control for Port PTO, Stbd PTO, Stbd side control room, Port side control room) | E25: 1 | F25: none | G25: Electrical Fault - Controller | H25: 1) Loss of bilge pump 2) Any residual bilge collection is not pumped to spar bilge | I25: 1) Manufacturing defect 2) Fatigue or degradation over time 3) Contamination leads to fault 4) Component corrosion leads to fault 5) Control fault 6) Installation error | J25: Deployment | K25: 1) water level/leek sensors 2) Tending vessel | L25: V&V(QC) | M25: 1) SCADA diagnostic 2) Surveillance | N25: in-situ repair | O25: 4 | P25: 1 | Q25: 1 | R25: 5 | S25: 4 | T25: =IF(AND(ISNUMBER(P25),ISNUMBER($O25)),OFFSET(RiskMatrixRef,-$O25+1,P25-1),"") -> Low | U25: =IF(AND(ISNUMBER(Q25),ISNUMBER($O25)),OFFSET(RiskMatrixRef,-$O25+1,Q25-1),"") -> Low | V25: =IF(AND(ISNUMBER(R25),ISNUMBER($O25)),OFFSET(RiskMatrixRef,-$O25+1,R25-1),"") -> Low | W25: =IF(AND(ISNUMBER(S25),ISNUMBER($O25)),OFFSET(RiskMatrixRef,-$O25+1,S25-1),"") -> Low | AF25: =IF(AND(ISNUMBER(AB25),ISNUMBER($AA25)),OFFSET(RiskMatrixRef,-$AA25+1,AB25-1),"") | AG25: =IF(AND(ISNUMBER(AC25),ISNUMBER($AA25)),OFFSET(RiskMatrixRef,-$AA25+1,AC25-1),"") | AH25: =IF(AND(ISNUMBER(AD25),ISNUMBER($AA25)),OFFSET(RiskMatrixRef,-$AA25+1,AD25-1),"") | AI25: =IF(AND(ISNUMBER(AE25),ISNUMBER($AA25)),OFFSET(RiskMatrixRef,-$AA25+1,AE25-1),"") | AR25: =IF(AND(ISNUMBER(AN25),ISNUMBER($AM25)),OFFSET(RiskMatrixRef,-$AM25+1,AN25-1),"") | AS25: =IF(AND(ISNUMBER(AO25),ISNUMBER($AM25)),OFFSET(RiskMatrixRef,-$AM25+1,AO25-1),"") | AT25: =IF(AND(ISNUMBER(AP25),ISNUMBER($AM25)),OFFSET(RiskMatrixRef,-$AM25+1,AP25-1),"") | AU25: =IF(AND(ISNUMBER(AQ25),ISNUMBER($AM25)),OFFSET(RiskMatrixRef,-$AM25+1,AQ25-1),"")
B26: 0577-3 | C26: Deployment Pumping Systems | D26: During deployment, when WEC is near horizontal oreientation, remove water from port/stbd low point of PTO module, and control room. - (Pump + Control for Port PTO, Stbd PTO, Stbd side control room, Port side control room) | E26: 1 | F26: none | G26: Mechanical failure in pump | H26: 1) Loss of bilge pump 2) Any residual bilge collection is not pumped to spar bilge | I26: 1) Manufacturing defect 2) Fatigue or degradation over time 3) Contamination leads to fault 4) Component corrosion leads to fault 5) Control fault 6) Installation error | J26: Deployment | K26: 1) water level/leek sensors 2) Tending vessel | L26: V&V(QC) | M26: 1) SCADA diagnostic 2) Surveillance | N26: in-situ repair | O26: 4 | P26: 1 | Q26: 1 | R26: 5 | S26: 4 | T26: =IF(AND(ISNUMBER(P26),ISNUMBER($O26)),OFFSET(RiskMatrixRef,-$O26+1,P26-1),"") -> Low | U26: =IF(AND(ISNUMBER(Q26),ISNUMBER($O26)),OFFSET(RiskMatrixRef,-$O26+1,Q26-1),"") -> Low | V26: =IF(AND(ISNUMBER(R26),ISNUMBER($O26)),OFFSET(RiskMatrixRef,-$O26+1,R26-1),"") -> Low | W26: =IF(AND(ISNUMBER(S26),ISNUMBER($O26)),OFFSET(RiskMatrixRef,-$O26+1,S26-1),"") -> Low | AF26: =IF(AND(ISNUMBER(AB26),ISNUMBER($AA26)),OFFSET(RiskMatrixRef,-$AA26+1,AB26-1),"") | AG26: =IF(AND(ISNUMBER(AC26),ISNUMBER($AA26)),OFFSET(RiskMatrixRef,-$AA26+1,AC26-1),"") | AH26: =IF(AND(ISNUMBER(AD26),ISNUMBER($AA26)),OFFSET(RiskMatrixRef,-$AA26+1,AD26-1),"") | AI26: =IF(AND(ISNUMBER(AE26),ISNUMBER($AA26)),OFFSET(RiskMatrixRef,-$AA26+1,AE26-1),"") | AR26: =IF(AND(ISNUMBER(AN26),ISNUMBER($AM26)),OFFSET(RiskMatrixRef,-$AM26+1,AN26-1),"") | AS26: =IF(AND(ISNUMBER(AO26),ISNUMBER($AM26)),OFFSET(RiskMatrixRef,-$AM26+1,AO26-1),"") | AT26: =IF(AND(ISNUMBER(AP26),ISNUMBER($AM26)),OFFSET(RiskMatrixRef,-$AM26+1,AP26-1),"") | AU26: =IF(AND(ISNUMBER(AQ26),ISNUMBER($AM26)),OFFSET(RiskMatrixRef,-$AM26+1,AQ26-1),"")
B27: 0577-4 | C27: Deployment Pumping Systems | D27: During deployment, when WEC is near horizontal oreientation, remove water from port/stbd low point of PTO module, and control room. - (Pump + Control for Port PTO, Stbd PTO, Stbd side control room, Port side control room) | E27: 1 | F27: none | G27: Mechanical failure in switch | H27: 1) Loss of bilge pump 2) Any residual bilge collection is not pumped to spar bilge | I27: 1) Manufacturing defect 2) Fatigue or degradation over time 3) Contamination leads to fault 4) Component corrosion leads to fault 5) Control fault 6) Installation error | J27: Deployment | K27: 1) water level/leek sensors 2) Tending vessel | L27: V&V(QC) | M27: 1) SCADA diagnostic 2) Surveillance | N27: in-situ repair | O27: 4 | P27: 1 | Q27: 1 | R27: 5 | S27: 4 | T27: =IF(AND(ISNUMBER(P27),ISNUMBER($O27)),OFFSET(RiskMatrixRef,-$O27+1,P27-1),"") -> Low | U27: =IF(AND(ISNUMBER(Q27),ISNUMBER($O27)),OFFSET(RiskMatrixRef,-$O27+1,Q27-1),"") -> Low | V27: =IF(AND(ISNUMBER(R27),ISNUMBER($O27)),OFFSET(RiskMatrixRef,-$O27+1,R27-1),"") -> Low | W27: =IF(AND(ISNUMBER(S27),ISNUMBER($O27)),OFFSET(RiskMatrixRef,-$O27+1,S27-1),"") -> Low | AF27: =IF(AND(ISNUMBER(AB27),ISNUMBER($AA27)),OFFSET(RiskMatrixRef,-$AA27+1,AB27-1),"") | AG27: =IF(AND(ISNUMBER(AC27),ISNUMBER($AA27)),OFFSET(RiskMatrixRef,-$AA27+1,AC27-1),"") | AH27: =IF(AND(ISNUMBER(AD27),ISNUMBER($AA27)),OFFSET(RiskMatrixRef,-$AA27+1,AD27-1),"") | AI27: =IF(AND(ISNUMBER(AE27),ISNUMBER($AA27)),OFFSET(RiskMatrixRef,-$AA27+1,AE27-1),"") | AR27: =IF(AND(ISNUMBER(AN27),ISNUMBER($AM27)),OFFSET(RiskMatrixRef,-$AM27+1,AN27-1),"") | AS27: =IF(AND(ISNUMBER(AO27),ISNUMBER($AM27)),OFFSET(RiskMatrixRef,-$AM27+1,AO27-1),"") | AT27: =IF(AND(ISNUMBER(AP27),ISNUMBER($AM27)),OFFSET(RiskMatrixRef,-$AM27+1,AP27-1),"") | AU27: =IF(AND(ISNUMBER(AQ27),ISNUMBER($AM27)),OFFSET(RiskMatrixRef,-$AM27+1,AQ27-1),"")
B28: 0577-5 | C28: Deployment Pumping Systems | D28: During deployment, when WEC is near horizontal oreientation, remove water from port/stbd low point of PTO module, and control room. - (Pump + Control for Port PTO, Stbd PTO, Stbd side control room, Port side control room) | E28: 1 | F28: none | G28: Electrical Fault - smoke/fire | H28: 1) Loss of bilge pump 2) Any residual bilge collection is not pumped to spar bilge | I28: 1) Manufacturing defect 2) Fatigue or degradation over time 3) Contamination leads to fault 4) Component corrosion leads to fault 5) Control fault 6) Installation error | J28: Deployment | K28: 1) water level/leek sensors 2) Tending vessel | L28: V&V(QC) | M28: 1) SCADA diagnostic 2) Surveillance | N28: in-situ repair | O28: 4 | P28: 1 | Q28: 1 | R28: 5 | S28: 4 | T28: =IF(AND(ISNUMBER(P28),ISNUMBER($O28)),OFFSET(RiskMatrixRef,-$O28+1,P28-1),"") -> Low | U28: =IF(AND(ISNUMBER(Q28),ISNUMBER($O28)),OFFSET(RiskMatrixRef,-$O28+1,Q28-1),"") -> Low | V28: =IF(AND(ISNUMBER(R28),ISNUMBER($O28)),OFFSET(RiskMatrixRef,-$O28+1,R28-1),"") -> Low | W28: =IF(AND(ISNUMBER(S28),ISNUMBER($O28)),OFFSET(RiskMatrixRef,-$O28+1,S28-1),"") -> Low | AF28: =IF(AND(ISNUMBER(AB28),ISNUMBER($AA28)),OFFSET(RiskMatrixRef,-$AA28+1,AB28-1),"") | AG28: =IF(AND(ISNUMBER(AC28),ISNUMBER($AA28)),OFFSET(RiskMatrixRef,-$AA28+1,AC28-1),"") | AH28: =IF(AND(ISNUMBER(AD28),ISNUMBER($AA28)),OFFSET(RiskMatrixRef,-$AA28+1,AD28-1),"") | AI28: =IF(AND(ISNUMBER(AE28),ISNUMBER($AA28)),OFFSET(RiskMatrixRef,-$AA28+1,AE28-1),"") | AR28: =IF(AND(ISNUMBER(AN28),ISNUMBER($AM28)),OFFSET(RiskMatrixRef,-$AM28+1,AN28-1),"") | AS28: =IF(AND(ISNUMBER(AO28),ISNUMBER($AM28)),OFFSET(RiskMatrixRef,-$AM28+1,AO28-1),"") | AT28: =IF(AND(ISNUMBER(AP28),ISNUMBER($AM28)),OFFSET(RiskMatrixRef,-$AM28+1,AP28-1),"") | AU28: =IF(AND(ISNUMBER(AQ28),ISNUMBER($AM28)),OFFSET(RiskMatrixRef,-$AM28+1,AQ28-1),"")
B29: 0577-6 | C29: Deployment Pumping Systems | D29: During deployment, when WEC is near horizontal oreientation, remove water from port/stbd low point of PTO module, and control room. - (Pump + Control for Port PTO, Stbd PTO, Stbd side control room, Port side control room) | E29: 1 | F29: none | G29: Electrical Fault - smoke/fire | I29: 1) Manufacturing defect 2) Fatigue or degradation over time 3) Contamination leads to fault 4) Component corrosion leads to fault 5) Control fault 6) Installation error | J29: Deployment & Emergency Leak/Flood -Bilge pumping working to remove water | K29: Two pumps per compartment | M29: 1) SCADA diagnostic 2) Surveillance | N29: in-situ repair | O29: 4 | P29: 1 | Q29: 1 | R29: 5 | S29: 4 | T29: =IF(AND(ISNUMBER(P29),ISNUMBER($O29)),OFFSET(RiskMatrixRef,-$O29+1,P29-1),"") -> Low | U29: =IF(AND(ISNUMBER(Q29),ISNUMBER($O29)),OFFSET(RiskMatrixRef,-$O29+1,Q29-1),"") -> Low | V29: =IF(AND(ISNUMBER(R29),ISNUMBER($O29)),OFFSET(RiskMatrixRef,-$O29+1,R29-1),"") -> Low | W29: =IF(AND(ISNUMBER(S29),ISNUMBER($O29)),OFFSET(RiskMatrixRef,-$O29+1,S29-1),"") -> Low | AF29: =IF(AND(ISNUMBER(AB29),ISNUMBER($AA29)),OFFSET(RiskMatrixRef,-$AA29+1,AB29-1),"") | AG29: =IF(AND(ISNUMBER(AC29),ISNUMBER($AA29)),OFFSET(RiskMatrixRef,-$AA29+1,AC29-1),"") | AH29: =IF(AND(ISNUMBER(AD29),ISNUMBER($AA29)),OFFSET(RiskMatrixRef,-$AA29+1,AD29-1),"") | AI29: =IF(AND(ISNUMBER(AE29),ISNUMBER($AA29)),OFFSET(RiskMatrixRef,-$AA29+1,AE29-1),"") | AR29: =IF(AND(ISNUMBER(AN29),ISNUMBER($AM29)),OFFSET(RiskMatrixRef,-$AM29+1,AN29-1),"") | AS29: =IF(AND(ISNUMBER(AO29),ISNUMBER($AM29)),OFFSET(RiskMatrixRef,-$AM29+1,AO29-1),"") | AT29: =IF(AND(ISNUMBER(AP29),ISNUMBER($AM29)),OFFSET(RiskMatrixRef,-$AM29+1,AP29-1),"") | AU29: =IF(AND(ISNUMBER(AQ29),ISNUMBER($AM29)),OFFSET(RiskMatrixRef,-$AM29+1,AQ29-1),"")
B30: 0578/0579 | C30: Values & Fittings / Pipping | D30: Remove infiltrated water from PTO module | E30: 1 | F30: none | G30: Leak in Values & Fittings / Pipping | H30: 1) Not detectable until water is pumped 2) water drains back to a bilge | I30: 1) Manufacturing defect 2) Fatigue or degradation over time 3) Contamination leads to fault 4) Component corrosion leads to fault 5) Control fault 6) Installation error | J30: Normal | K30: 1) V& V (QC) | L30: 1) Inspections | M30: 1) SCADA diagnostic 2) Surveillance | N30: in-situ repair | O30: 4 | P30: 1 | Q30: 1 | R30: 5 | S30: 4 | T30: =IF(AND(ISNUMBER(P30),ISNUMBER($O30)),OFFSET(RiskMatrixRef,-$O30+1,P30-1),"") -> Low | U30: =IF(AND(ISNUMBER(Q30),ISNUMBER($O30)),OFFSET(RiskMatrixRef,-$O30+1,Q30-1),"") -> Low | V30: =IF(AND(ISNUMBER(R30),ISNUMBER($O30)),OFFSET(RiskMatrixRef,-$O30+1,R30-1),"") -> Low | W30: =IF(AND(ISNUMBER(S30),ISNUMBER($O30)),OFFSET(RiskMatrixRef,-$O30+1,S30-1),"") -> Low | AF30: =IF(AND(ISNUMBER(AB30),ISNUMBER($AA30)),OFFSET(RiskMatrixRef,-$AA30+1,AB30-1),"") | AG30: =IF(AND(ISNUMBER(AC30),ISNUMBER($AA30)),OFFSET(RiskMatrixRef,-$AA30+1,AC30-1),"") | AH30: =IF(AND(ISNUMBER(AD30),ISNUMBER($AA30)),OFFSET(RiskMatrixRef,-$AA30+1,AD30-1),"") | AI30: =IF(AND(ISNUMBER(AE30),ISNUMBER($AA30)),OFFSET(RiskMatrixRef,-$AA30+1,AE30-1),"") | AR30: =IF(AND(ISNUMBER(AN30),ISNUMBER($AM30)),OFFSET(RiskMatrixRef,-$AM30+1,AN30-1),"") | AS30: =IF(AND(ISNUMBER(AO30),ISNUMBER($AM30)),OFFSET(RiskMatrixRef,-$AM30+1,AO30-1),"") | AT30: =IF(AND(ISNUMBER(AP30),ISNUMBER($AM30)),OFFSET(RiskMatrixRef,-$AM30+1,AP30-1),"") | AU30: =IF(AND(ISNUMBER(AQ30),ISNUMBER($AM30)),OFFSET(RiskMatrixRef,-$AM30+1,AQ30-1),"")
B31: 0578/0579 | C31: Values & Fittings / Pipping | D31: Remove infiltrated water from PTO module | E31: 1 | F31: none | G31: Leak in Values & Fittings / Pipping | H31: 1) Not detectable until water is pumped 2) water drains back to a bilge | I31: 1) Manufacturing defect 2) Fatigue or degradation over time 3) Contamination leads to fault 4) Component corrosion leads to fault 5) Control fault 6) Installation error | J31: Normal | K31: 1) V& V (QC) | L31: 1) Inspections | M31: 1) SCADA diagnostic 2) Surveillance | N31: in-situ repair | O31: 4 | P31: 1 | Q31: 1 | R31: 5 | S31: 4 | T31: =IF(AND(ISNUMBER(P31),ISNUMBER($O31)),OFFSET(RiskMatrixRef,-$O31+1,P31-1),"") -> Low | U31: =IF(AND(ISNUMBER(Q31),ISNUMBER($O31)),OFFSET(RiskMatrixRef,-$O31+1,Q31-1),"") -> Low | V31: =IF(AND(ISNUMBER(R31),ISNUMBER($O31)),OFFSET(RiskMatrixRef,-$O31+1,R31-1),"") -> Low | W31: =IF(AND(ISNUMBER(S31),ISNUMBER($O31)),OFFSET(RiskMatrixRef,-$O31+1,S31-1),"") -> Low | AF31: =IF(AND(ISNUMBER(AB31),ISNUMBER($AA31)),OFFSET(RiskMatrixRef,-$AA31+1,AB31-1),"") | AG31: =IF(AND(ISNUMBER(AC31),ISNUMBER($AA31)),OFFSET(RiskMatrixRef,-$AA31+1,AC31-1),"") | AH31: =IF(AND(ISNUMBER(AD31),ISNUMBER($AA31)),OFFSET(RiskMatrixRef,-$AA31+1,AD31-1),"") | AI31: =IF(AND(ISNUMBER(AE31),ISNUMBER($AA31)),OFFSET(RiskMatrixRef,-$AA31+1,AE31-1),"") | AR31: =IF(AND(ISNUMBER(AN31),ISNUMBER($AM31)),OFFSET(RiskMatrixRef,-$AM31+1,AN31-1),"") | AS31: =IF(AND(ISNUMBER(AO31),ISNUMBER($AM31)),OFFSET(RiskMatrixRef,-$AM31+1,AO31-1),"") | AT31: =IF(AND(ISNUMBER(AP31),ISNUMBER($AM31)),OFFSET(RiskMatrixRef,-$AM31+1,AP31-1),"") | AU31: =IF(AND(ISNUMBER(AQ31),ISNUMBER($AM31)),OFFSET(RiskMatrixRef,-$AM31+1,AQ31-1),"")
B32: 0578/0589 | C32: Values & Fittings / Pipping | D32: Remove infiltrated water from PTO module | E32: 1 | F32: none | G32: Leak in Values & Fittings / Pipping | H32: 1) Not detectable until water is pumped 2) water drains back to a bilge | I32: 1) Manufacturing defect 2) Fatigue or degradation over time 3) Contamination leads to fault 4) Component corrosion leads to fault 5) Control fault 6) Installation error | J32: Deployment & Emergency Leak/Flood -Bilge pumping working to remove water | K32: 1) V& V (QC) | L32: 1) Inspections | M32: 1) SCADA diagnostic 2) Surveillance | N32: in-situ repair | O32: 4 | P32: 1 | Q32: 1 | R32: 5 | S32: 4 | T32: =IF(AND(ISNUMBER(P32),ISNUMBER($O32)),OFFSET(RiskMatrixRef,-$O32+1,P32-1),"") -> Low | U32: =IF(AND(ISNUMBER(Q32),ISNUMBER($O32)),OFFSET(RiskMatrixRef,-$O32+1,Q32-1),"") -> Low | V32: =IF(AND(ISNUMBER(R32),ISNUMBER($O32)),OFFSET(RiskMatrixRef,-$O32+1,R32-1),"") -> Low | W32: =IF(AND(ISNUMBER(S32),ISNUMBER($O32)),OFFSET(RiskMatrixRef,-$O32+1,S32-1),"") -> Low | AF32: =IF(AND(ISNUMBER(AB32),ISNUMBER($AA32)),OFFSET(RiskMatrixRef,-$AA32+1,AB32-1),"") | AG32: =IF(AND(ISNUMBER(AC32),ISNUMBER($AA32)),OFFSET(RiskMatrixRef,-$AA32+1,AC32-1),"") | AH32: =IF(AND(ISNUMBER(AD32),ISNUMBER($AA32)),OFFSET(RiskMatrixRef,-$AA32+1,AD32-1),"") | AI32: =IF(AND(ISNUMBER(AE32),ISNUMBER($AA32)),OFFSET(RiskMatrixRef,-$AA32+1,AE32-1),"") | AR32: =IF(AND(ISNUMBER(AN32),ISNUMBER($AM32)),OFFSET(RiskMatrixRef,-$AM32+1,AN32-1),"") | AS32: =IF(AND(ISNUMBER(AO32),ISNUMBER($AM32)),OFFSET(RiskMatrixRef,-$AM32+1,AO32-1),"") | AT32: =IF(AND(ISNUMBER(AP32),ISNUMBER($AM32)),OFFSET(RiskMatrixRef,-$AM32+1,AP32-1),"") | AU32: =IF(AND(ISNUMBER(AQ32),ISNUMBER($AM32)),OFFSET(RiskMatrixRef,-$AM32+1,AQ32-1),"")
T33: =IF(AND(ISNUMBER(P33),ISNUMBER($O33)),OFFSET(RiskMatrixRef,-$O33+1,P33-1),"") | U33: =IF(AND(ISNUMBER(Q33),ISNUMBER($O33)),OFFSET(RiskMatrixRef,-$O33+1,Q33-1),"") | V33: =IF(AND(ISNUMBER(R33),ISNUMBER($O33)),OFFSET(RiskMatrixRef,-$O33+1,R33-1),"") | W33: =IF(AND(ISNUMBER(S33),ISNUMBER($O33)),OFFSET(RiskMatrixRef,-$O33+1,S33-1),"") | AF33: =IF(AND(ISNUMBER(AB33),ISNUMBER($AA33)),OFFSET(RiskMatrixRef,-$AA33+1,AB33-1),"") | AG33: =IF(AND(ISNUMBER(AC33),ISNUMBER($AA33)),OFFSET(RiskMatrixRef,-$AA33+1,AC33-1),"") | AH33: =IF(AND(ISNUMBER(AD33),ISNUMBER($AA33)),OFFSET(RiskMatrixRef,-$AA33+1,AD33-1),"") | AI33: =IF(AND(ISNUMBER(AE33),ISNUMBER($AA33)),OFFSET(RiskMatrixRef,-$AA33+1,AE33-1),"") | AR33: =IF(AND(ISNUMBER(AN33),ISNUMBER($AM33)),OFFSET(RiskMatrixRef,-$AM33+1,AN33-1),"") | AS33: =IF(AND(ISNUMBER(AO33),ISNUMBER($AM33)),OFFSET(RiskMatrixRef,-$AM33+1,AO33-1),"") | AT33: =IF(AND(ISNUMBER(AP33),ISNUMBER($AM33)),OFFSET(RiskMatrixRef,-$AM33+1,AP33-1),"") | AU33: =IF(AND(ISNUMBER(AQ33),ISNUMBER($AM33)),OFFSET(RiskMatrixRef,-$AM33+1,AQ33-1),"")
T34: =IF(AND(ISNUMBER(P34),ISNUMBER($O34)),OFFSET(RiskMatrixRef,-$O34+1,P34-1),"") | U34: =IF(AND(ISNUMBER(Q34),ISNUMBER($O34)),OFFSET(RiskMatrixRef,-$O34+1,Q34-1),"") | V34: =IF(AND(ISNUMBER(R34),ISNUMBER($O34)),OFFSET(RiskMatrixRef,-$O34+1,R34-1),"") | W34: =IF(AND(ISNUMBER(S34),ISNUMBER($O34)),OFFSET(RiskMatrixRef,-$O34+1,S34-1),"") | AF34: =IF(AND(ISNUMBER(AB34),ISNUMBER($AA34)),OFFSET(RiskMatrixRef,-$AA34+1,AB34-1),"") | AG34: =IF(AND(ISNUMBER(AC34),ISNUMBER($AA34)),OFFSET(RiskMatrixRef,-$AA34+1,AC34-1),"") | AH34: =IF(AND(ISNUMBER(AD34),ISNUMBER($AA34)),OFFSET(RiskMatrixRef,-$AA34+1,AD34-1),"") | AI34: =IF(AND(ISNUMBER(AE34),ISNUMBER($AA34)),OFFSET(RiskMatrixRef,-$AA34+1,AE34-1),"") | AR34: =IF(AND(ISNUMBER(AN34),ISNUMBER($AM34)),OFFSET(RiskMatrixRef,-$AM34+1,AN34-1),"") | AS34: =IF(AND(ISNUMBER(AO34),ISNUMBER($AM34)),OFFSET(RiskMatrixRef,-$AM34+1,AO34-1),"") | AT34: =IF(AND(ISNUMBER(AP34),ISNUMBER($AM34)),OFFSET(RiskMatrixRef,-$AM34+1,AP34-1),"") | AU34: =IF(AND(ISNUMBER(AQ34),ISNUMBER($AM34)),OFFSET(RiskMatrixRef,-$AM34+1,AQ34-1),"")

Sheet version history
A1: Title | B1: StingRAY Bilge Pumping FMECA
A2: Doc No | B2: SR-0570-RR
A3: Version | B3: 3.0
A4: Authored | B4: E Hammagren
A5: Reviewed
A6: Approved Dist.
A7: Approved Final
A10: Version | B10: Date | C10: Summary
A11: 1.0 | B11: 41586 | C11: Preliminary, not released
A12: 2.0 | B12: 42401 | C12: release to RC for review
A13: 3.0 | B13: 42576 | C13: Updated risk matrix, updated for WEC v3.3 technology
A22: The following contains PROTECTED DATA of Columbia Power Technologies, Inc. not for distribution.

Sheet set up
C2: =linkedPage!C2 -> Risk = Occ + Sev | O2: =linkedPage!T2 -> Note:
C3: =linkedPage!C3 -> Severity | O3: =linkedPage!T3 -> - 'set up' and 'linkedPage' are both linked to workbook 'FMECA Master v3.xlsx'
B4: =IF(linkedPage!B4=0,"",linkedPage!B4) -> Occ | C4: =IF(linkedPage!C4=0,"",linkedPage!C4) -> 1 | D4: =IF(linkedPage!D4=0,"",linkedPage!D4) -> 2 | E4: =IF(linkedPage!E4=0,"",linkedPage!E4) -> 3 | F4: =IF(linkedPage!F4=0,"",linkedPage!F4) -> 4 | G4: =IF(linkedPage!G4=0,"",linkedPage!G4) -> 5 | H4: =IF(linkedPage!H4=0,"",linkedPage!H4) -> 6 | I4: =IF(linkedPage!I4=0,"",linkedPage!I4) -> 7 | ... N4: =IF(linkedPage!N4=0,"",linkedPage!N4) | O4: =linkedPage!T4 -> - changes to the tables, risk scores, etc must be made in 'FMECA Master v3.xlsx'
B5: =IF(linkedPage!B5=0,"",linkedPage!B5) -> 10 | C5: =IF(linkedPage!C5=0,"",linkedPage!C5) -> Low | D5: =IF(linkedPage!D5=0,"",linkedPage!D5) -> Med | E5: =IF(linkedPage!E5=0,"",linkedPage!E5) -> Med | F5: =IF(linkedPage!F5=0,"",linkedPage!F5) -> Med | G5: =IF(linkedPage!G5=0,"",linkedPage!G5) -> Med | H5: =IF(linkedPage!H5=0,"",linkedPage!H5) -> High | I5: =IF(linkedPage!I5=0,"",linkedPage!I5) -> High | ... O5: =IF(linkedPage!O5=0,"",linkedPage!O5)
B6: =IF(linkedPage!B6=0,"",linkedPage!B6) -> 9 | C6: =IF(linkedPage!C6=0,"",linkedPage!C6) -> Low | D6: =IF(linkedPage!D6=0,"",linkedPage!D6) -> Low | E6: =IF(linkedPage!E6=0,"",linkedPage!E6) -> Med | F6: =IF(linkedPage!F6=0,"",linkedPage!F6) -> Med | G6: =IF(linkedPage!G6=0,"",linkedPage!G6) -> Med | H6: =IF(linkedPage!H6=0,"",linkedPage!H6) -> Med | I6: =IF(linkedPage!I6=0,"",linkedPage!I6) -> High | ... O6: =IF(linkedPage!O6=0,"",linkedPage!O6)
B7: =IF(linkedPage!B7=0,"",linkedPage!B7) -> 8 | C7: =IF(linkedPage!C7=0,"",linkedPage!C7) -> Low | D7: =IF(linkedPage!D7=0,"",linkedPage!D7) -> Low | E7: =IF(linkedPage!E7=0,"",linkedPage!E7) -> Low | F7: =IF(linkedPage!F7=0,"",linkedPage!F7) -> Med | G7: =IF(linkedPage!G7=0,"",linkedPage!G7) -> Med | H7: =IF(linkedPage!H7=0,"",linkedPage!H7) -> Med | I7: =IF(linkedPage!I7=0,"",linkedPage!I7) -> Med | ... O7: =IF(linkedPage!O7=0,"",linkedPage!O7)
B8: =IF(linkedPage!B8=0,"",linkedPage!B8) -> 7 | C8: =IF(linkedPage!C8=0,"",linkedPage!C8) -> Low | D8: =IF(linkedPage!D8=0,"",linkedPage!D8) -> Low | E8: =IF(linkedPage!E8=0,"",linkedPage!E8) -> Low | F8: =IF(linkedPage!F8=0,"",linkedPage!F8) -> Low | G8: =IF(linkedPage!G8=0,"",linkedPage!G8) -> Med | H8: =IF(linkedPage!H8=0,"",linkedPage!H8) -> Med | I8: =IF(linkedPage!I8=0,"",linkedPage!I8) -> Med | ... O8: =IF(linkedPage!O8=0,"",linkedPage!O8)
B9: =IF(linkedPage!B9=0,"",linkedPage!B9) -> 6 | C9: =IF(linkedPage!C9=0,"",linkedPage!C9) -> Low | D9: =IF(linkedPage!D9=0,"",linkedPage!D9) -> Low | E9: =IF(linkedPage!E9=0,"",linkedPage!E9) -> Low | F9: =IF(linkedPage!F9=0,"",linkedPage!F9) -> Low | G9: =IF(linkedPage!G9=0,"",linkedPage!G9) -> Low | H9: =IF(linkedPage!H9=0,"",linkedPage!H9) -> Med | I9: =IF(linkedPage!I9=0,"",linkedPage!I9) -> Med | ... O9: =IF(linkedPage!O9=0,"",linkedPage!O9)
B10: =IF(linkedPage!B10=0,"",linkedPage!B10) -> 5 | C10: =IF(linkedPage!C10=0,"",linkedPage!C10) -> Low | D10: =IF(linkedPage!D10=0,"",linkedPage!D10) -> Low | E10: =IF(linkedPage!E10=0,"",linkedPage!E10) -> Low | F10: =IF(linkedPage!F10=0,"",linkedPage!F10) -> Low | G10: =IF(linkedPage!G10=0,"",linkedPage!G10) -> Low | H10: =IF(linkedPage!H10=0,"",linkedPage!H10) -> Low | I10: =IF(linkedPage!I10=0,"",linkedPage!I10) -> Med | ... O10: =IF(linkedPage!O10=0,"",linkedPage!O10)
B11: =IF(linkedPage!B11=0,"",linkedPage!B11) -> 4 | C11: =IF(linkedPage!C11=0,"",linkedPage!C11) -> Low | D11: =IF(linkedPage!D11=0,"",linkedPage!D11) -> Low | E11: =IF(linkedPage!E11=0,"",linkedPage!E11) -> Low | F11: =IF(linkedPage!F11=0,"",linkedPage!F11) -> Low | G11: =IF(linkedPage!G11=0,"",linkedPage!G11) -> Low | H11: =IF(linkedPage!H11=0,"",linkedPage!H11) -> Low | I11: =IF(linkedPage!I11=0,"",linkedPage!I11) -> Low | ... O11: =IF(linkedPage!O11=0,"",linkedPage!O11) -> Tolerable, no engineer action required
B12: =IF(linkedPage!B12=0,"",linkedPage!B12) -> 3 | C12: =IF(linkedPage!C12=0,"",linkedPage!C12) -> Low | D12: =IF(linkedPage!D12=0,"",linkedPage!D12) -> Low | E12: =IF(linkedPage!E12=0,"",linkedPage!E12) -> Low | F12: =IF(linkedPage!F12=0,"",linkedPage!F12) -> Low | G12: =IF(linkedPage!G12=0,"",linkedPage!G12) -> Low | H12: =IF(linkedPage!H12=0,"",linkedPage!H12) -> Low | I12: =IF(linkedPage!I12=0,"",linkedPage!I12) -> Low | ... O12: =IF(linkedPage!O12=0,"",linkedPage!O12) -> Undesirable, consider engineer actions to mitigate risk
