Workbook
Name RiskMatrixRef: 'set up'!$C$14

Sheet Data Rights Notice

Sheet 0100 Hull System
O2: Risk Ranking | AB2: Updated Risk Ranking | AN2: 2nd Updated Risk Ranking
B4: 0100 Hull Structure FMECA Table | P4: Severity Class | T4: Risk Class | AC4: Severity Class | AG4: Risk Class | AO4: Severity Class | AS4: Risk Class
B5: Risk ID | C5: Item Description | D5: Function | E5: Tech. Class | F5: Novel Aspects | G5: Failure Mode | H5: Failure Effects (Local, WEC, System) | I5: Failure Cause(s) | J5: Initial Mode of Operation | K5: Risk Reduction Design | L5: Preventative Detection | M5: Post Failure Detection | N5: Post Failure Repair Strategy (automated, manual) | O5: Occurrence | P5: Human Safety | Q5: Environment | R5: Operation | S5: Assets | T5: Human Safety | U5: Environment | V5: Operation | W5: Assets | X5: Recommended Actions | Y5: DNV GL comment | Z5: Responsible Party | AA5: Actions Taken | AB5: Occurrence | AC5: Human Safety | AD5: Environment | AE5: Operation | AF5: Assets | AG5: Human Safety | AH5: Environment | AI5: Operation | AJ5: Assets | AK5: 2nd Recommended Actions | AL5: Responsible Party (2nd) | AM5: Actions Taken (2nd) | AN5: Occurrence | AO5: Human Safety | AP5: Environment | AQ5: Operation | AR5: Assets | AS5: Human Safety | AT5: Environment | AU5: Operation | AV5: Assets | AW5: Status (open or closed) | AX5: Notes
B6: 0100-1 | C6: Hull | D6: Wave activated body Provision of watertight compartment Structural connectivity & load transfer Ballast containment | E6: 2 | F6: Loading in wave environment, with large motions | G6: Severe structural failure | H6: Severe structural failure WEC is no longer functioning | I6: Extreme wave event loading (Overloading) | J6: Normal | K6: none | L6: none | M6: 1) Surveillance 2) SCADA 3) etc | N6: Dry dock repair if possible, if not loss of projects | O6: 3 | P6: 4 | Q6: 7 | R6: 9 | S6: 9 | T6: =IF(AND(ISNUMBER(P6),ISNUMBER($O6)),OFFSET(RiskMatrixRef,-$O6+1,P6-1),"") -> Low | U6: =IF(AND(ISNUMBER(Q6),ISNUMBER($O6)),OFFSET(RiskMatrixRef,-$O6+1,Q6-1),"") -> Low | V6: =IF(AND(ISNUMBER(R6),ISNUMBER($O6)),OFFSET(RiskMatrixRef,-$O6+1,R6-1),"") -> Med | W6: =IF(AND(ISNUMBER(S6),ISNUMBER($O6)),OFFSET(RiskMatrixRef,-$O6+1,S6-1),"") -> Med | X6: 1) Load derivation methodology to take into account the uncertainties in the loading due to site characterisation measurements and hydrodynamic modelling. 2) Uncertainty of loading estimates to be reduced by comparison of hydrodynamic behavior in simulation versus tank testing. 3) Design load cases to be defined considering all phases (e.g. operating w/ fault, installation, etc.), and to include investigation of localized loading from e.g. slamming. 4) Derivation of localized loading to be developed, and validated via instrumentation of prototype at-sea deployment. | Y6: Suggested text for recommended action: The uncertainty about loading needs to be reduced by tank testing and development (and comparison) of simulation of hydrodynamic behaviour considering PTO and controls as well as implementation of structural calculations to derive design stresses. Derivation of localised loading such as slamming or other aspects associated with tolerances and local distribution of loading as well as events associated with faults has to be developed and validated. The design load cases have to be defined considering all phases such as Operating, Operating with fault, Survival, Survival with fault, Damaged, Transport and Installation, etc. | AG6: =IF(AND(ISNUMBER(AC6),ISNUMBER($AB6)),OFFSET(RiskMatrixRef,-$AB6+1,AC6-1),"") | AH6: =IF(AND(ISNUMBER(AD6),ISNUMBER($AB6)),OFFSET(RiskMatrixRef,-$AB6+1,AD6-1),"") | AI6: =IF(AND(ISNUMBER(AE6),ISNUMBER($AB6)),OFFSET(RiskMatrixRef,-$AB6+1,AE6-1),"") | AJ6: =IF(AND(ISNUMBER(AF6),ISNUMBER($AB6)),OFFSET(RiskMatrixRef,-$AB6+1,AF6-1),"") | AS6: =IF(AND(ISNUMBER(AO6),ISNUMBER($AN6)),OFFSET(RiskMatrixRef,-$AN6+1,AO6-1),"") | AT6: =IF(AND(ISNUMBER(AP6),ISNUMBER($AN6)),OFFSET(RiskMatrixRef,-$AN6+1,AP6-1),"") | AU6: =IF(AND(ISNUMBER(AQ6),ISNUMBER($AN6)),OFFSET(RiskMatrixRef,-$AN6+1,AQ6-1),"") | AV6: =IF(AND(ISNUMBER(AR6),ISNUMBER($AN6)),OFFSET(RiskMatrixRef,-$AN6+1,AR6-1),"")
B7: 0100-2 | C7: Hull | D7: Wave activated body Provision of watertight compartment Structural connectivity & load transfer Ballast containment | E7: 2 | F7: Loading in wave environment, with large motions | G7: Severe structural failure | H7: Severe structural failure WEC is no longer functioning | I7: Fatigue and other degradation mechanisms | J7: Normal | K7: none | L7: none | M7: 1) Surveillance 2) SCADA 3) etc | N7: Dry dock repair if possible, if not loss of projects | O7: 7 | P7: 4 | Q7: 7 | R7: 9 | S7: 9 | T7: =IF(AND(ISNUMBER(P7),ISNUMBER($O7)),OFFSET(RiskMatrixRef,-$O7+1,P7-1),"") -> Low | U7: =IF(AND(ISNUMBER(Q7),ISNUMBER($O7)),OFFSET(RiskMatrixRef,-$O7+1,Q7-1),"") -> Med | V7: =IF(AND(ISNUMBER(R7),ISNUMBER($O7)),OFFSET(RiskMatrixRef,-$O7+1,R7-1),"") -> High | W7: =IF(AND(ISNUMBER(S7),ISNUMBER($O7)),OFFSET(RiskMatrixRef,-$O7+1,S7-1),"") -> High | X7: 1) Load derivation methodology to take into account the uncertainties in the loading due to site characterisation measurements and hydrodynamic modelling. 2) Uncertainty of loading estimates to be reduced by comparison of hydrodynamic behavior in simulation versus tank testing. 3) Design load cases to be defined considering all phases (e.g. operating w/ fault, installation, etc.), and to include investigation of localized loading from e.g. slamming. 4) Derivation of localized loading to be developed, and validated via instrumentation of prototype at-sea deployment. 5) Design fatigue factors (DFF) shall be applied to reduce probability of fatigue failure. 6) Design to incorporate cathodic protection and coating as appropriate (under subsystem 0645 Marinization and Corrosion, External) 7) Establish inspection plan | Y7: Probability class increased to be compatible with FLS design. Suggested text for recommended action: Increase DFF, implementation of cathodic protection and coating, inspection plan. The uncertainty about loading needs to be reduced by tank testing and development (and comparison) of simulation of hydrodynamic behaviour considering PTO and controls as well as implementation of structural calculations to derive design stresses. Derivation of localised loading such as slamming or other aspects associated with tolerances and local distribution of loading as well as events associated with faults has to be developed and validated. The design load cases have to be defined considering all phases such as Operating, Operating with fault, Survival, Survival with fault, Damaged, Transport and Installation, etc. | AG7: =IF(AND(ISNUMBER(AC7),ISNUMBER($AB7)),OFFSET(RiskMatrixRef,-$AB7+1,AC7-1),"") | AH7: =IF(AND(ISNUMBER(AD7),ISNUMBER($AB7)),OFFSET(RiskMatrixRef,-$AB7+1,AD7-1),"") | AI7: =IF(AND(ISNUMBER(AE7),ISNUMBER($AB7)),OFFSET(RiskMatrixRef,-$AB7+1,AE7-1),"") | AJ7: =IF(AND(ISNUMBER(AF7),ISNUMBER($AB7)),OFFSET(RiskMatrixRef,-$AB7+1,AF7-1),"") | AS7: =IF(AND(ISNUMBER(AO7),ISNUMBER($AN7)),OFFSET(RiskMatrixRef,-$AN7+1,AO7-1),"") | AT7: =IF(AND(ISNUMBER(AP7),ISNUMBER($AN7)),OFFSET(RiskMatrixRef,-$AN7+1,AP7-1),"") | AU7: =IF(AND(ISNUMBER(AQ7),ISNUMBER($AN7)),OFFSET(RiskMatrixRef,-$AN7+1,AQ7-1),"") | AV7: =IF(AND(ISNUMBER(AR7),ISNUMBER($AN7)),OFFSET(RiskMatrixRef,-$AN7+1,AR7-1),"")
B8: 0111-1 0121-1 | C8: Forward float Aft float | D8: Wave activated body Provision of watertight compartment | E8: 2 | F8: Loading in wave environment, with large motions | G8: Crack/hole in float (leading to water drainage) | H8: 1) Sub-optimal performance 2) change in buoyancy 3) only a portion of water may drain (see note) | I8: Leak in FRP (e.g. manufacturing flaw, assembly) *not boat strikes* | J8: Normal | K8: 1) vacuum test all water tight compartments 2) All ballast water below waterline 3) Foam fill open voids 4) V&V for manufacturing and assembly | M8: 1) visual inspection of draft line on floats 2) average angle of the floats seen by encoders | N8: Dry dock for FRP repair | O8: 4 | P8: 1 | Q8: 1 | R8: 7 | S8: 7 | T8: =IF(AND(ISNUMBER(P8),ISNUMBER($O8)),OFFSET(RiskMatrixRef,-$O8+1,P8-1),"") -> Low | U8: =IF(AND(ISNUMBER(Q8),ISNUMBER($O8)),OFFSET(RiskMatrixRef,-$O8+1,Q8-1),"") -> Low | V8: =IF(AND(ISNUMBER(R8),ISNUMBER($O8)),OFFSET(RiskMatrixRef,-$O8+1,R8-1),"") -> Low | W8: =IF(AND(ISNUMBER(S8),ISNUMBER($O8)),OFFSET(RiskMatrixRef,-$O8+1,S8-1),"") -> Low | X8: 1) V&V procedures to be defined and followed, which shall mitigate risk of defective component up to commissioning. | Y8: See comment on failure effects and causes | AG8: =IF(AND(ISNUMBER(AC8),ISNUMBER($AB8)),OFFSET(RiskMatrixRef,-$AB8+1,AC8-1),"") | AH8: =IF(AND(ISNUMBER(AD8),ISNUMBER($AB8)),OFFSET(RiskMatrixRef,-$AB8+1,AD8-1),"") | AI8: =IF(AND(ISNUMBER(AE8),ISNUMBER($AB8)),OFFSET(RiskMatrixRef,-$AB8+1,AE8-1),"") | AJ8: =IF(AND(ISNUMBER(AF8),ISNUMBER($AB8)),OFFSET(RiskMatrixRef,-$AB8+1,AF8-1),"") | AS8: =IF(AND(ISNUMBER(AO8),ISNUMBER($AN8)),OFFSET(RiskMatrixRef,-$AN8+1,AO8-1),"") | AT8: =IF(AND(ISNUMBER(AP8),ISNUMBER($AN8)),OFFSET(RiskMatrixRef,-$AN8+1,AP8-1),"") | AU8: =IF(AND(ISNUMBER(AQ8),ISNUMBER($AN8)),OFFSET(RiskMatrixRef,-$AN8+1,AQ8-1),"") | AV8: =IF(AND(ISNUMBER(AR8),ISNUMBER($AN8)),OFFSET(RiskMatrixRef,-$AN8+1,AR8-1),"") | AX8: only a small portion of water may drain, as ballast water will be below still water line
B9: 0111-2 0121-2 | C9: Forward float Aft float | D9: Wave activated body Provision of watertight compartment | E9: 2 | F9: Loading in wave environment, with large motions | G9: Crack/hole in float (leading to water drainage) | H9: 1) Sub-optimal performance 2) change in buoyancy 3) only a portion of water may drain (see note) | I9: Leak in FRP - fatigue crack due to uncertainties in loading | J9: Normal | K9: 1) All ballast water below waterline 2) Foam fill open voids | M9: 1) visual inspection of draft line on floats 2) average angle of the floats seen by encoders | N9: Dry dock for FRP repair | O9: 7 | P9: 1 | Q9: 1 | R9: 7 | S9: 7 | T9: =IF(AND(ISNUMBER(P9),ISNUMBER($O9)),OFFSET(RiskMatrixRef,-$O9+1,P9-1),"") -> Low | U9: =IF(AND(ISNUMBER(Q9),ISNUMBER($O9)),OFFSET(RiskMatrixRef,-$O9+1,Q9-1),"") -> Low | V9: =IF(AND(ISNUMBER(R9),ISNUMBER($O9)),OFFSET(RiskMatrixRef,-$O9+1,R9-1),"") -> Med | W9: =IF(AND(ISNUMBER(S9),ISNUMBER($O9)),OFFSET(RiskMatrixRef,-$O9+1,S9-1),"") -> Med | X9: 1) Load derivation methodology to take into account the uncertainties in the loading due to site characterisation measurements and hydrodynamic modelling. 2) Uncertainty of loading estimates to be reduced by comparison of hydrodynamic behavior in simulation versus tank testing. 3) Design load cases to be defined considering all phases (e.g. operating w/ fault, installation, etc.), and to include investigation of localized loading from e.g. slamming. 4) Derivation of localized loading to be developed, and validated via instrumentation of prototype at-sea deployment. 5) Design fatigue factors (DFF) shall be applied to reduce probability of fatigue failure. 6) Establish inspection plan | Y9: Action the same as "Fatigue and other degradation mechanisms" for hull. | AG9: =IF(AND(ISNUMBER(AC9),ISNUMBER($AB9)),OFFSET(RiskMatrixRef,-$AB9+1,AC9-1),"") | AH9: =IF(AND(ISNUMBER(AD9),ISNUMBER($AB9)),OFFSET(RiskMatrixRef,-$AB9+1,AD9-1),"") | AI9: =IF(AND(ISNUMBER(AE9),ISNUMBER($AB9)),OFFSET(RiskMatrixRef,-$AB9+1,AE9-1),"") | AJ9: =IF(AND(ISNUMBER(AF9),ISNUMBER($AB9)),OFFSET(RiskMatrixRef,-$AB9+1,AF9-1),"") | AS9: =IF(AND(ISNUMBER(AO9),ISNUMBER($AN9)),OFFSET(RiskMatrixRef,-$AN9+1,AO9-1),"") | AT9: =IF(AND(ISNUMBER(AP9),ISNUMBER($AN9)),OFFSET(RiskMatrixRef,-$AN9+1,AP9-1),"") | AU9: =IF(AND(ISNUMBER(AQ9),ISNUMBER($AN9)),OFFSET(RiskMatrixRef,-$AN9+1,AQ9-1),"") | AV9: =IF(AND(ISNUMBER(AR9),ISNUMBER($AN9)),OFFSET(RiskMatrixRef,-$AN9+1,AR9-1),"") | AX9: only a small portion of water may drain, as ballast water will be below still water line
B10: 0111-3 0121-3 | C10: Forward float Aft float | D10: Wave activated body Provision of watertight compartment | E10: 2 | F10: Loading in wave environment, with large motions | G10: Locked / reduced motion | H10: 1) Float becomes locked or reduced motion w.r.t. nacelle | I10: Debris caught between float and nacelle (or spar) | J10: Normal | K10: smooth edges | L10: surveillance camera checks/visual inspection | M10: 1) PTO not moving or reduced motion 2) Surveillance cameras | N10: Remove debris In situ or dry dock repair of FRP if warranted | O10: 6 | P10: 1 | Q10: 1 | R10: 7 | S10: 7 | T10: =IF(AND(ISNUMBER(P10),ISNUMBER($O10)),OFFSET(RiskMatrixRef,-$O10+1,P10-1),"") -> Low | U10: =IF(AND(ISNUMBER(Q10),ISNUMBER($O10)),OFFSET(RiskMatrixRef,-$O10+1,Q10-1),"") -> Low | V10: =IF(AND(ISNUMBER(R10),ISNUMBER($O10)),OFFSET(RiskMatrixRef,-$O10+1,R10-1),"") -> Med | W10: =IF(AND(ISNUMBER(S10),ISNUMBER($O10)),OFFSET(RiskMatrixRef,-$O10+1,S10-1),"") -> Med | X10: 1) Probability of occurrence of debris to be verified for site conditions 2) Type and dimensions of problem debris to be specified for the site | Y10: The probability of occurrence is to be verified for the site conditions and it is also necessary to define the type of debris and dimension that would be a problem. | AG10: =IF(AND(ISNUMBER(AC10),ISNUMBER($AB10)),OFFSET(RiskMatrixRef,-$AB10+1,AC10-1),"") | AH10: =IF(AND(ISNUMBER(AD10),ISNUMBER($AB10)),OFFSET(RiskMatrixRef,-$AB10+1,AD10-1),"") | AI10: =IF(AND(ISNUMBER(AE10),ISNUMBER($AB10)),OFFSET(RiskMatrixRef,-$AB10+1,AE10-1),"") | AJ10: =IF(AND(ISNUMBER(AF10),ISNUMBER($AB10)),OFFSET(RiskMatrixRef,-$AB10+1,AF10-1),"") | AS10: =IF(AND(ISNUMBER(AO10),ISNUMBER($AN10)),OFFSET(RiskMatrixRef,-$AN10+1,AO10-1),"") | AT10: =IF(AND(ISNUMBER(AP10),ISNUMBER($AN10)),OFFSET(RiskMatrixRef,-$AN10+1,AP10-1),"") | AU10: =IF(AND(ISNUMBER(AQ10),ISNUMBER($AN10)),OFFSET(RiskMatrixRef,-$AN10+1,AQ10-1),"") | AV10: =IF(AND(ISNUMBER(AR10),ISNUMBER($AN10)),OFFSET(RiskMatrixRef,-$AN10+1,AR10-1),"")
B11: 0111-4 0121-4 | C11: Forward float Aft float | D11: Wave activated body Provision of watertight compartment | E11: 2 | F11: Loading in wave environment, with large motions | G11: Locked / reduced motion | H11: 1) Float becomes locked or reduced motion w.r.t. nacelle | I11: Large mammal caught betweeen float and nacelle (or spar) | J11: Normal | K11: smooth edges | M11: 1) PTO not moving or reduced motion 2) Surveillance cameras | N11: Remove mammal | O11: 3 | P11: 1 | Q11: 5 | R11: 5 | S11: 5 | T11: =IF(AND(ISNUMBER(P11),ISNUMBER($O11)),OFFSET(RiskMatrixRef,-$O11+1,P11-1),"") -> Low | U11: =IF(AND(ISNUMBER(Q11),ISNUMBER($O11)),OFFSET(RiskMatrixRef,-$O11+1,Q11-1),"") -> Low | V11: =IF(AND(ISNUMBER(R11),ISNUMBER($O11)),OFFSET(RiskMatrixRef,-$O11+1,R11-1),"") -> Low | W11: =IF(AND(ISNUMBER(S11),ISNUMBER($O11)),OFFSET(RiskMatrixRef,-$O11+1,S11-1),"") -> Low | X11: 1) Probability of occurrence to be evaluated by the assessment of presence and behavior of mammals on site. | Y11: Probability of occurrence to be evaluated by the assessment of presence of mammals on site. | AG11: =IF(AND(ISNUMBER(AC11),ISNUMBER($AB11)),OFFSET(RiskMatrixRef,-$AB11+1,AC11-1),"") | AH11: =IF(AND(ISNUMBER(AD11),ISNUMBER($AB11)),OFFSET(RiskMatrixRef,-$AB11+1,AD11-1),"") | AI11: =IF(AND(ISNUMBER(AE11),ISNUMBER($AB11)),OFFSET(RiskMatrixRef,-$AB11+1,AE11-1),"") | AJ11: =IF(AND(ISNUMBER(AF11),ISNUMBER($AB11)),OFFSET(RiskMatrixRef,-$AB11+1,AF11-1),"") | AS11: =IF(AND(ISNUMBER(AO11),ISNUMBER($AN11)),OFFSET(RiskMatrixRef,-$AN11+1,AO11-1),"") | AT11: =IF(AND(ISNUMBER(AP11),ISNUMBER($AN11)),OFFSET(RiskMatrixRef,-$AN11+1,AP11-1),"") | AU11: =IF(AND(ISNUMBER(AQ11),ISNUMBER($AN11)),OFFSET(RiskMatrixRef,-$AN11+1,AQ11-1),"") | AV11: =IF(AND(ISNUMBER(AR11),ISNUMBER($AN11)),OFFSET(RiskMatrixRef,-$AN11+1,AR11-1),"")
B12: 0111-5 0121-5 | C12: Forward float Aft float | D12: Wave activated body Provision of watertight compartment | E12: 2 | F12: Loading in wave environment, with large motions | G12: Mammal take | H12: 1) mammal take | I12: Large mammal caught betweeen float and nacelle (or spar) | J12: Normal | K12: smooth edges | M12: 1) Surveillance cameras | N12: Remove mammal | O12: 6 | P12: 1 | Q12: 5 | R12: 5 | S12: 5 | T12: =IF(AND(ISNUMBER(P12),ISNUMBER($O12)),OFFSET(RiskMatrixRef,-$O12+1,P12-1),"") -> Low | U12: =IF(AND(ISNUMBER(Q12),ISNUMBER($O12)),OFFSET(RiskMatrixRef,-$O12+1,Q12-1),"") -> Low | V12: =IF(AND(ISNUMBER(R12),ISNUMBER($O12)),OFFSET(RiskMatrixRef,-$O12+1,R12-1),"") -> Low | W12: =IF(AND(ISNUMBER(S12),ISNUMBER($O12)),OFFSET(RiskMatrixRef,-$O12+1,S12-1),"") -> Low | X12: 1) Probability of occurrence to be evaluated by the assessment of presence and behavior of mammals on site. | Y12: Probability of occurrence to be evaluated by the assessment of presence of mammals on site. | AG12: =IF(AND(ISNUMBER(AC12),ISNUMBER($AB12)),OFFSET(RiskMatrixRef,-$AB12+1,AC12-1),"") | AH12: =IF(AND(ISNUMBER(AD12),ISNUMBER($AB12)),OFFSET(RiskMatrixRef,-$AB12+1,AD12-1),"") | AI12: =IF(AND(ISNUMBER(AE12),ISNUMBER($AB12)),OFFSET(RiskMatrixRef,-$AB12+1,AE12-1),"") | AJ12: =IF(AND(ISNUMBER(AF12),ISNUMBER($AB12)),OFFSET(RiskMatrixRef,-$AB12+1,AF12-1),"") | AS12: =IF(AND(ISNUMBER(AO12),ISNUMBER($AN12)),OFFSET(RiskMatrixRef,-$AN12+1,AO12-1),"") | AT12: =IF(AND(ISNUMBER(AP12),ISNUMBER($AN12)),OFFSET(RiskMatrixRef,-$AN12+1,AP12-1),"") | AU12: =IF(AND(ISNUMBER(AQ12),ISNUMBER($AN12)),OFFSET(RiskMatrixRef,-$AN12+1,AQ12-1),"") | AV12: =IF(AND(ISNUMBER(AR12),ISNUMBER($AN12)),OFFSET(RiskMatrixRef,-$AN12+1,AR12-1),"")
B13: 0111-6 0121-6 | C13: Forward float Aft float | D13: Wave activated body Provision of watertight compartment | E13: 2 | F13: Loading in wave environment, with large motions | G13: Service human trapped | H13: 1) Human trapped 2) Potential fatality | I13: service worker falls inbetween fwd float and nacelle | J13: Normal | K13: none | M13: 1) Surveillance cameras | O13: 3 | P13: 10 | Q13: 1 | R13: 1 | S13: 1 | T13: =IF(AND(ISNUMBER(P13),ISNUMBER($O13)),OFFSET(RiskMatrixRef,-$O13+1,P13-1),"") -> Med | U13: =IF(AND(ISNUMBER(Q13),ISNUMBER($O13)),OFFSET(RiskMatrixRef,-$O13+1,Q13-1),"") -> Low | V13: =IF(AND(ISNUMBER(R13),ISNUMBER($O13)),OFFSET(RiskMatrixRef,-$O13+1,R13-1),"") -> Low | W13: =IF(AND(ISNUMBER(S13),ISNUMBER($O13)),OFFSET(RiskMatrixRef,-$O13+1,S13-1),"") -> Low | X13: 1) Design guard netting to significantly reduce the liklihood of entrapment and/or death 2) The probability of occurrence is to be verified against procedures for access and how the integrity of the net is maintained. | Y13: The probability of occurrence is to be verified against procedures for access and how the integrity of the net is maintained. | AG13: =IF(AND(ISNUMBER(AC13),ISNUMBER($AB13)),OFFSET(RiskMatrixRef,-$AB13+1,AC13-1),"") | AH13: =IF(AND(ISNUMBER(AD13),ISNUMBER($AB13)),OFFSET(RiskMatrixRef,-$AB13+1,AD13-1),"") | AI13: =IF(AND(ISNUMBER(AE13),ISNUMBER($AB13)),OFFSET(RiskMatrixRef,-$AB13+1,AE13-1),"") | AJ13: =IF(AND(ISNUMBER(AF13),ISNUMBER($AB13)),OFFSET(RiskMatrixRef,-$AB13+1,AF13-1),"") | AS13: =IF(AND(ISNUMBER(AO13),ISNUMBER($AN13)),OFFSET(RiskMatrixRef,-$AN13+1,AO13-1),"") | AT13: =IF(AND(ISNUMBER(AP13),ISNUMBER($AN13)),OFFSET(RiskMatrixRef,-$AN13+1,AP13-1),"") | AU13: =IF(AND(ISNUMBER(AQ13),ISNUMBER($AN13)),OFFSET(RiskMatrixRef,-$AN13+1,AQ13-1),"") | AV13: =IF(AND(ISNUMBER(AR13),ISNUMBER($AN13)),OFFSET(RiskMatrixRef,-$AN13+1,AR13-1),"")
B14: 0111-7 0121-7 | C14: Forward float Aft float | D14: Wave activated body Provision of watertight compartment | E14: 2 | F14: Loading in wave environment, with large motions | G14: Public human trapped | H14: 1) Human trapped 2) Potential fatality | I14: unauthorized personel falls inbetween fwd float and nacelle | J14: Normal | K14: none | M14: 1) Surveillance cameras | O14: 3 | P14: 10 | Q14: 1 | R14: 1 | S14: 1 | T14: =IF(AND(ISNUMBER(P14),ISNUMBER($O14)),OFFSET(RiskMatrixRef,-$O14+1,P14-1),"") -> Med | U14: =IF(AND(ISNUMBER(Q14),ISNUMBER($O14)),OFFSET(RiskMatrixRef,-$O14+1,Q14-1),"") -> Low | V14: =IF(AND(ISNUMBER(R14),ISNUMBER($O14)),OFFSET(RiskMatrixRef,-$O14+1,R14-1),"") -> Low | W14: =IF(AND(ISNUMBER(S14),ISNUMBER($O14)),OFFSET(RiskMatrixRef,-$O14+1,S14-1),"") -> Low | X14: 1) Design guard netting to significantly reduce the liklihood of entrapment and/or death 2) Design of the net to demonstrate that its integrity is maintained throughout its life time. | Y14: Suggest text for recommended action: Design of the net to demonstrate that its integrity is maintained throughout its life time. | AG14: =IF(AND(ISNUMBER(AC14),ISNUMBER($AB14)),OFFSET(RiskMatrixRef,-$AB14+1,AC14-1),"") | AH14: =IF(AND(ISNUMBER(AD14),ISNUMBER($AB14)),OFFSET(RiskMatrixRef,-$AB14+1,AD14-1),"") | AI14: =IF(AND(ISNUMBER(AE14),ISNUMBER($AB14)),OFFSET(RiskMatrixRef,-$AB14+1,AE14-1),"") | AJ14: =IF(AND(ISNUMBER(AF14),ISNUMBER($AB14)),OFFSET(RiskMatrixRef,-$AB14+1,AF14-1),"") | AS14: =IF(AND(ISNUMBER(AO14),ISNUMBER($AN14)),OFFSET(RiskMatrixRef,-$AN14+1,AO14-1),"") | AT14: =IF(AND(ISNUMBER(AP14),ISNUMBER($AN14)),OFFSET(RiskMatrixRef,-$AN14+1,AP14-1),"") | AU14: =IF(AND(ISNUMBER(AQ14),ISNUMBER($AN14)),OFFSET(RiskMatrixRef,-$AN14+1,AQ14-1),"") | AV14: =IF(AND(ISNUMBER(AR14),ISNUMBER($AN14)),OFFSET(RiskMatrixRef,-$AN14+1,AR14-1),"")
B15: 0111-8 0121-8 | C15: Forward float Aft float | D15: Wave activated body Provision of watertight compartment | E15: 2 | F15: Loading in wave environment, with large motions | G15: Hole in float (leading to water drainage) | H15: 1) Loss of performance 2) Loss of known physical parameters (weight of each component) 3) change in buoyancy | I15: Debris caught between float and another body, leading to wear that creates a hole that changes buoyancy | J15: Normal | K15: smooth edges | L15: surveillance camera checks/visual inspection | M15: 1) visual inspection of draft line on floats 2) average angle of the floats seen by encoders | N15: Dry dock for FRP repair | O15: 5 | P15: 1 | Q15: 1 | R15: 6 | S15: 7 | T15: =IF(AND(ISNUMBER(P15),ISNUMBER($O15)),OFFSET(RiskMatrixRef,-$O15+1,P15-1),"") -> Low | U15: =IF(AND(ISNUMBER(Q15),ISNUMBER($O15)),OFFSET(RiskMatrixRef,-$O15+1,Q15-1),"") -> Low | V15: =IF(AND(ISNUMBER(R15),ISNUMBER($O15)),OFFSET(RiskMatrixRef,-$O15+1,R15-1),"") -> Low | W15: =IF(AND(ISNUMBER(S15),ISNUMBER($O15)),OFFSET(RiskMatrixRef,-$O15+1,S15-1),"") -> Med | X15: 1) Probability of occurrence of debris to be verified for site conditions 2) Type and dimensions of problem debris to be specified for the site 3) Additional thickness to be considered in areas that wear could occur. 4) Identify the magnitude of wear and time to inspect / repair. 5) Design to demonstrate wear rate due to debris is within the acceptance criteria for the long term structural integrity of the hull | Y15: Suggest text for recommended action: Additional thickness to be considered in areas that wear could occur. Identify the magnitude of wear and time to inspect / repair. If the wear is created by the debris, the type of debris that could be a problem and their existence on site to be verified. Design to demonstrate wear rate due to debris is within the acceptance criteria for the long term structural integrity of the hull | AG15: =IF(AND(ISNUMBER(AC15),ISNUMBER($AB15)),OFFSET(RiskMatrixRef,-$AB15+1,AC15-1),"") | AH15: =IF(AND(ISNUMBER(AD15),ISNUMBER($AB15)),OFFSET(RiskMatrixRef,-$AB15+1,AD15-1),"") | AI15: =IF(AND(ISNUMBER(AE15),ISNUMBER($AB15)),OFFSET(RiskMatrixRef,-$AB15+1,AE15-1),"") | AJ15: =IF(AND(ISNUMBER(AF15),ISNUMBER($AB15)),OFFSET(RiskMatrixRef,-$AB15+1,AF15-1),"") | AS15: =IF(AND(ISNUMBER(AO15),ISNUMBER($AN15)),OFFSET(RiskMatrixRef,-$AN15+1,AO15-1),"") | AT15: =IF(AND(ISNUMBER(AP15),ISNUMBER($AN15)),OFFSET(RiskMatrixRef,-$AN15+1,AP15-1),"") | AU15: =IF(AND(ISNUMBER(AQ15),ISNUMBER($AN15)),OFFSET(RiskMatrixRef,-$AN15+1,AQ15-1),"") | AV15: =IF(AND(ISNUMBER(AR15),ISNUMBER($AN15)),OFFSET(RiskMatrixRef,-$AN15+1,AR15-1),"")
B16: 0111-9 0121-9 | C16: Forward float Aft float | D16: Wave activated body Provision of watertight compartment | E16: 2 | F16: Loading in wave environment, with large motions | G16: Hole in float (leading to water drainage) | H16: 1) Loss of performance 2) Loss of known physical parameters (weight of each component) 3) change in buoyancy | I16: Float arms flexed more than expected. Wear creates a hole that changes buoyancy | J16: Normal | K16: none | L16: surveillance camera checks/visual inspection | M16: 1) visual inspection of draft line on floats 2) average angle of the floats seen by encoders | N16: Dry dock for FRP repair | O16: 5 | P16: 1 | Q16: 1 | R16: 6 | S16: 7 | T16: =IF(AND(ISNUMBER(P16),ISNUMBER($O16)),OFFSET(RiskMatrixRef,-$O16+1,P16-1),"") -> Low | U16: =IF(AND(ISNUMBER(Q16),ISNUMBER($O16)),OFFSET(RiskMatrixRef,-$O16+1,Q16-1),"") -> Low | V16: =IF(AND(ISNUMBER(R16),ISNUMBER($O16)),OFFSET(RiskMatrixRef,-$O16+1,R16-1),"") -> Low | W16: =IF(AND(ISNUMBER(S16),ISNUMBER($O16)),OFFSET(RiskMatrixRef,-$O16+1,S16-1),"") -> Med | X16: 1) Additional thickness to be considered in areas that wear could occur. 2) Identify the expected magnitude of wear and time to inspect / repair. 3) Specify inspection plan to be implemented after deployment. 4) Design to consider addition safety margin on space between components (where rubbing and wear is possible) to allow for uncertainty of loading and structural stiffness. | Y16: Suggest text for recommended action: Additional thickness to be considered in areas that wear could occur. Identify the magnitude of wear and time to inspect / repair. Inspection plan to be implemented after deployment. Design to consider addition safety margin on air gap to allow for uncertainty on loading and structural stiffness. | AG16: =IF(AND(ISNUMBER(AC16),ISNUMBER($AB16)),OFFSET(RiskMatrixRef,-$AB16+1,AC16-1),"") | AH16: =IF(AND(ISNUMBER(AD16),ISNUMBER($AB16)),OFFSET(RiskMatrixRef,-$AB16+1,AD16-1),"") | AI16: =IF(AND(ISNUMBER(AE16),ISNUMBER($AB16)),OFFSET(RiskMatrixRef,-$AB16+1,AE16-1),"") | AJ16: =IF(AND(ISNUMBER(AF16),ISNUMBER($AB16)),OFFSET(RiskMatrixRef,-$AB16+1,AF16-1),"") | AS16: =IF(AND(ISNUMBER(AO16),ISNUMBER($AN16)),OFFSET(RiskMatrixRef,-$AN16+1,AO16-1),"") | AT16: =IF(AND(ISNUMBER(AP16),ISNUMBER($AN16)),OFFSET(RiskMatrixRef,-$AN16+1,AP16-1),"") | AU16: =IF(AND(ISNUMBER(AQ16),ISNUMBER($AN16)),OFFSET(RiskMatrixRef,-$AN16+1,AQ16-1),"") | AV16: =IF(AND(ISNUMBER(AR16),ISNUMBER($AN16)),OFFSET(RiskMatrixRef,-$AN16+1,AR16-1),"")
B17: 0111-10 0121-10 | C17: Forward float Aft float | D17: Wave activated body Provision of watertight compartment | E17: 2 | F17: Loading in wave environment, with large motions | G17: Hole in float (leading to water drainage) | H17: 1) Sub-optimal performance 2) Increased generator speed (>20RPM) during strike event 3) change in buoyancy | I17: Non-service Boat Strike | J17: Normal | K17: 1) Lights, radar reflectors (e.g. visibility) | L17: none | M17: 1) visual inspection of draft line on floats 2) average angle of the floats seen by encoders | N17: In situ FRP repair if possible (hole above waterline and known location) Worst case: Dry dock inspection and repair of WEC. | O17: 8 | P17: 4 | Q17: 1 | R17: 6 | S17: 7 | T17: =IF(AND(ISNUMBER(P17),ISNUMBER($O17)),OFFSET(RiskMatrixRef,-$O17+1,P17-1),"") -> Med | U17: =IF(AND(ISNUMBER(Q17),ISNUMBER($O17)),OFFSET(RiskMatrixRef,-$O17+1,Q17-1),"") -> Low | V17: =IF(AND(ISNUMBER(R17),ISNUMBER($O17)),OFFSET(RiskMatrixRef,-$O17+1,R17-1),"") -> Med | W17: =IF(AND(ISNUMBER(S17),ISNUMBER($O17)),OFFSET(RiskMatrixRef,-$O17+1,S17-1),"") -> Med | X17: 1) In-situ FRP repair procedure to be developed. The repair is to be qualified to the conditions of implementation (moving parts, deformation within the area of repair and splash of seawater). The durability of repair will depend if it is supposed to be permanent, temporary to allow to reach the next maintenance period or only to allow for recovery. 2) For damage below the water line, assessment of consequence to be made and design strategy to be considered to reduce probability of damage and also to improve retrieval operation. 3) establish exclusion zone at deployed area 4) The probability of occurrence to be verified considering conditions at the site and vessels in the area | Y17: Suggest text for recommended action: In-situ FRP repair procedure to be developed. The repair is to be qualified to the conditions of implementation (moving parts, deformation within the area of repair and splash of seawater. The durability of repair will depend if it is supposed to be permanent, temporary to allow to reach the next maintenance period or only to allow for recovery. for damage below the water line, assessment of consequence to be made and design strategy to be considered to reduce probability of damage and also to improve retrieval operation. | AG17: =IF(AND(ISNUMBER(AC17),ISNUMBER($AB17)),OFFSET(RiskMatrixRef,-$AB17+1,AC17-1),"") | AH17: =IF(AND(ISNUMBER(AD17),ISNUMBER($AB17)),OFFSET(RiskMatrixRef,-$AB17+1,AD17-1),"") | AI17: =IF(AND(ISNUMBER(AE17),ISNUMBER($AB17)),OFFSET(RiskMatrixRef,-$AB17+1,AE17-1),"") | AJ17: =IF(AND(ISNUMBER(AF17),ISNUMBER($AB17)),OFFSET(RiskMatrixRef,-$AB17+1,AF17-1),"") | AS17: =IF(AND(ISNUMBER(AO17),ISNUMBER($AN17)),OFFSET(RiskMatrixRef,-$AN17+1,AO17-1),"") | AT17: =IF(AND(ISNUMBER(AP17),ISNUMBER($AN17)),OFFSET(RiskMatrixRef,-$AN17+1,AP17-1),"") | AU17: =IF(AND(ISNUMBER(AQ17),ISNUMBER($AN17)),OFFSET(RiskMatrixRef,-$AN17+1,AQ17-1),"") | AV17: =IF(AND(ISNUMBER(AR17),ISNUMBER($AN17)),OFFSET(RiskMatrixRef,-$AN17+1,AR17-1),"")
B18: 0111-11 0121-11 | C18: Forward float Aft float | D18: Wave activated body Provision of watertight compartment | E18: 2 | F18: Loading in wave environment, with large motions | G18: fore/aft float breaks off | H18: 1) Wave loading of float is no longer transferred to rotor 2) Loss of power production 3) Float on Beach/Float out to sea | I18: One arm breaks off and causes higher stress on other arm so both break and float is free | J18: Normal | K18: none | L18: 1) Surveillance 2) Visual Detection 3) Dry dock before second arm breaks | M18: 1) Average angle of the floats seen by encoders 2) Surveillance | N18: 1) Recover float 2) drydock reatachment if possible | O18: 4 | P18: 4 | Q18: 5 | R18: 9 | S18: 8 | T18: =IF(AND(ISNUMBER(P18),ISNUMBER($O18)),OFFSET(RiskMatrixRef,-$O18+1,P18-1),"") -> Low | U18: =IF(AND(ISNUMBER(Q18),ISNUMBER($O18)),OFFSET(RiskMatrixRef,-$O18+1,Q18-1),"") -> Low | V18: =IF(AND(ISNUMBER(R18),ISNUMBER($O18)),OFFSET(RiskMatrixRef,-$O18+1,R18-1),"") -> Med | W18: =IF(AND(ISNUMBER(S18),ISNUMBER($O18)),OFFSET(RiskMatrixRef,-$O18+1,S18-1),"") -> Med | X18: 1) Load derivation methodology to take into account the uncertainties in the loading due to site characterisation measurements and hydrodynamic modelling. 2) Uncertainty of loading estimates to be reduced by comparison of hydrodynamic behavior in simulation versus tank testing. 3) Design load cases to be defined considering all phases (e.g. operating w/ fault, installation, etc.), and to include investigation of localized loading from e.g. slamming. 4) Derivation of localized loading to be developed, and validated via instrumentation of prototype at-sea deployment. 5) Design to consider increasing safety factors to high safety class. | Y18: Suggest text for recommended action: Increasing the safety factors to high safety class. Uncertainties on loads and structural response to be addressed as defined above (see "Extreme wave event loading" for hull.) | AG18: =IF(AND(ISNUMBER(AC18),ISNUMBER($AB18)),OFFSET(RiskMatrixRef,-$AB18+1,AC18-1),"") | AH18: =IF(AND(ISNUMBER(AD18),ISNUMBER($AB18)),OFFSET(RiskMatrixRef,-$AB18+1,AD18-1),"") | AI18: =IF(AND(ISNUMBER(AE18),ISNUMBER($AB18)),OFFSET(RiskMatrixRef,-$AB18+1,AE18-1),"") | AJ18: =IF(AND(ISNUMBER(AF18),ISNUMBER($AB18)),OFFSET(RiskMatrixRef,-$AB18+1,AF18-1),"") | AS18: =IF(AND(ISNUMBER(AO18),ISNUMBER($AN18)),OFFSET(RiskMatrixRef,-$AN18+1,AO18-1),"") | AT18: =IF(AND(ISNUMBER(AP18),ISNUMBER($AN18)),OFFSET(RiskMatrixRef,-$AN18+1,AP18-1),"") | AU18: =IF(AND(ISNUMBER(AQ18),ISNUMBER($AN18)),OFFSET(RiskMatrixRef,-$AN18+1,AQ18-1),"") | AV18: =IF(AND(ISNUMBER(AR18),ISNUMBER($AN18)),OFFSET(RiskMatrixRef,-$AN18+1,AR18-1),"")
B19: 0112-1 0122-1 | C19: Fwd float drive arm Aft float drive arm | D19: Drive starboard/port generator rotor Constrain float to relative pitch about nacelle | E19: 2 | F19: Loading in wave environment, with large motions | G19: Drive arm broken | H19: 1) Wave loading of float is no longer transferred to rotor 2) Loss of power production 3) Addtl loading on idler arm | I19: Fatigue of float arm due to uncertainties in loading | J19: Normal | K19: none | L19: none | M19: 1) PTO not moving 2) Surveillance cameras | N19: Dry dock reattachment of float arm to WEC | O19: 7 | P19: 1 | Q19: 1 | R19: 6 | S19: 7 | T19: =IF(AND(ISNUMBER(P19),ISNUMBER($O19)),OFFSET(RiskMatrixRef,-$O19+1,P19-1),"") -> Low | U19: =IF(AND(ISNUMBER(Q19),ISNUMBER($O19)),OFFSET(RiskMatrixRef,-$O19+1,Q19-1),"") -> Low | V19: =IF(AND(ISNUMBER(R19),ISNUMBER($O19)),OFFSET(RiskMatrixRef,-$O19+1,R19-1),"") -> Med | W19: =IF(AND(ISNUMBER(S19),ISNUMBER($O19)),OFFSET(RiskMatrixRef,-$O19+1,S19-1),"") -> Med | X19: 1) Load derivation methodology to take into account the uncertainties in the loading due to site characterisation measurements and hydrodynamic modelling. 2) Uncertainty of loading estimates to be reduced by comparison of hydrodynamic behavior in simulation versus tank testing. 3) Design load cases to be defined considering all phases (e.g. operating w/ fault, installation, etc.), and to include investigation of localized loading from e.g. slamming. 4) Derivation of localized loading to be developed, and validated via instrumentation of prototype at-sea deployment. 5) Design fatigue factors (DFF) shall be applied to reduce probability of fatigue failure. 6) Establish inspection plan | Y19: Action the same as "Fatigue and other degradation mechanisms" for hull. | AG19: =IF(AND(ISNUMBER(AC19),ISNUMBER($AB19)),OFFSET(RiskMatrixRef,-$AB19+1,AC19-1),"") | AH19: =IF(AND(ISNUMBER(AD19),ISNUMBER($AB19)),OFFSET(RiskMatrixRef,-$AB19+1,AD19-1),"") | AI19: =IF(AND(ISNUMBER(AE19),ISNUMBER($AB19)),OFFSET(RiskMatrixRef,-$AB19+1,AE19-1),"") | AJ19: =IF(AND(ISNUMBER(AF19),ISNUMBER($AB19)),OFFSET(RiskMatrixRef,-$AB19+1,AF19-1),"") | AS19: =IF(AND(ISNUMBER(AO19),ISNUMBER($AN19)),OFFSET(RiskMatrixRef,-$AN19+1,AO19-1),"") | AT19: =IF(AND(ISNUMBER(AP19),ISNUMBER($AN19)),OFFSET(RiskMatrixRef,-$AN19+1,AP19-1),"") | AU19: =IF(AND(ISNUMBER(AQ19),ISNUMBER($AN19)),OFFSET(RiskMatrixRef,-$AN19+1,AQ19-1),"") | AV19: =IF(AND(ISNUMBER(AR19),ISNUMBER($AN19)),OFFSET(RiskMatrixRef,-$AN19+1,AR19-1),"")
B20: 0112-2 0122-2 | C20: Fwd float drive arm Aft float drive arm | D20: Drive starboard/port generator rotor Constrain float to relative pitch about nacelle | E20: 2 | F20: Loading in wave environment, with large motions | G20: Drive arm broken | H20: 1) Wave loading of float is no longer transferred to rotor 2) Loss of power production 3) Addtl loading on idler arm | I20: Wearing of float arm, due to deflection | J20: Normal | K20: none | L20: Visual inspection, and repair if needed | M20: 1) PTO not moving 2) Surveillance cameras | N20: Dry dock reattachment of float arm to WEC | O20: 7 | P20: 1 | Q20: 1 | R20: 6 | S20: 7 | T20: =IF(AND(ISNUMBER(P20),ISNUMBER($O20)),OFFSET(RiskMatrixRef,-$O20+1,P20-1),"") -> Low | U20: =IF(AND(ISNUMBER(Q20),ISNUMBER($O20)),OFFSET(RiskMatrixRef,-$O20+1,Q20-1),"") -> Low | V20: =IF(AND(ISNUMBER(R20),ISNUMBER($O20)),OFFSET(RiskMatrixRef,-$O20+1,R20-1),"") -> Med | W20: =IF(AND(ISNUMBER(S20),ISNUMBER($O20)),OFFSET(RiskMatrixRef,-$O20+1,S20-1),"") -> Med | X20: 1) Additional thickness to be considered in areas that wear could occur. 2) Identify the expected magnitude of wear and time to inspect / repair. 3) Specify inspection plan to be implemented after deployment. 4) Design to consider additional safety margin on space between components (where rubbing and wear is possible) to allow for uncertainty of loading and structural stiffness. | Y20: Suggest text for recommended action: Additional thickness to be considered in areas that wear could occur. Identify the magnitude of wear and time to inspect / repair. Inspection plan to be implemented after deployment. Design to consider addition safety margin on air gap to allow for uncertainty on loading and structural stiffness. | AG20: =IF(AND(ISNUMBER(AC20),ISNUMBER($AB20)),OFFSET(RiskMatrixRef,-$AB20+1,AC20-1),"") | AH20: =IF(AND(ISNUMBER(AD20),ISNUMBER($AB20)),OFFSET(RiskMatrixRef,-$AB20+1,AD20-1),"") | AI20: =IF(AND(ISNUMBER(AE20),ISNUMBER($AB20)),OFFSET(RiskMatrixRef,-$AB20+1,AE20-1),"") | AJ20: =IF(AND(ISNUMBER(AF20),ISNUMBER($AB20)),OFFSET(RiskMatrixRef,-$AB20+1,AF20-1),"") | AS20: =IF(AND(ISNUMBER(AO20),ISNUMBER($AN20)),OFFSET(RiskMatrixRef,-$AN20+1,AO20-1),"") | AT20: =IF(AND(ISNUMBER(AP20),ISNUMBER($AN20)),OFFSET(RiskMatrixRef,-$AN20+1,AP20-1),"") | AU20: =IF(AND(ISNUMBER(AQ20),ISNUMBER($AN20)),OFFSET(RiskMatrixRef,-$AN20+1,AQ20-1),"") | AV20: =IF(AND(ISNUMBER(AR20),ISNUMBER($AN20)),OFFSET(RiskMatrixRef,-$AN20+1,AR20-1),"")
B21: 0112-3 0122-3 | C21: Fwd float drive arm Aft float drive arm | D21: Drive starboard/port generator rotor Constrain float to relative pitch about nacelle | E21: 2 | F21: Loading in wave environment, with large motions | G21: Drive arm broken | H21: 1) Wave loading of float is no longer transferred to rotor 2) Loss of power production 3) Addtl loading on idler arm | I21: Non-service boat strike | J21: Normal | K21: 1) Lights, radar reflectors (e.g. visibility) | L21: none | M21: 1) PTO not moving 2) Surveillance cameras | N21: Dry dock reattachment of float arm to WEC | O21: 4 | P21: 3 | Q21: 1 | R21: 6 | S21: 7 | T21: =IF(AND(ISNUMBER(P21),ISNUMBER($O21)),OFFSET(RiskMatrixRef,-$O21+1,P21-1),"") -> Low | U21: =IF(AND(ISNUMBER(Q21),ISNUMBER($O21)),OFFSET(RiskMatrixRef,-$O21+1,Q21-1),"") -> Low | V21: =IF(AND(ISNUMBER(R21),ISNUMBER($O21)),OFFSET(RiskMatrixRef,-$O21+1,R21-1),"") -> Low | W21: =IF(AND(ISNUMBER(S21),ISNUMBER($O21)),OFFSET(RiskMatrixRef,-$O21+1,S21-1),"") -> Low | X21: 1) establish exclusion zone at deployed area 2) The probability of occurrence to be verified considering conditions at the site and vessels in the area | Y21: The probability of occurrence to be verified considering conditions at the site and vessels in the area. | AG21: =IF(AND(ISNUMBER(AC21),ISNUMBER($AB21)),OFFSET(RiskMatrixRef,-$AB21+1,AC21-1),"") | AH21: =IF(AND(ISNUMBER(AD21),ISNUMBER($AB21)),OFFSET(RiskMatrixRef,-$AB21+1,AD21-1),"") | AI21: =IF(AND(ISNUMBER(AE21),ISNUMBER($AB21)),OFFSET(RiskMatrixRef,-$AB21+1,AE21-1),"") | AJ21: =IF(AND(ISNUMBER(AF21),ISNUMBER($AB21)),OFFSET(RiskMatrixRef,-$AB21+1,AF21-1),"") | AS21: =IF(AND(ISNUMBER(AO21),ISNUMBER($AN21)),OFFSET(RiskMatrixRef,-$AN21+1,AO21-1),"") | AT21: =IF(AND(ISNUMBER(AP21),ISNUMBER($AN21)),OFFSET(RiskMatrixRef,-$AN21+1,AP21-1),"") | AU21: =IF(AND(ISNUMBER(AQ21),ISNUMBER($AN21)),OFFSET(RiskMatrixRef,-$AN21+1,AQ21-1),"") | AV21: =IF(AND(ISNUMBER(AR21),ISNUMBER($AN21)),OFFSET(RiskMatrixRef,-$AN21+1,AR21-1),"")
B22: 0113-1 0123-1 | C22: Fwd float idler arm Aft float idler arm | D22: Constrain float to relative pitch about nacelle | E22: 2 | F22: Loading in wave environment, with large motions | G22: Idler arm broken | H22: 1) Wave loading of float is no longer transferred nacelle tube on idler side 2) Addtl loading on drive arm | I22: Fatigue of float arm due to uncertainties in loading | J22: Normal | K22: none | M22: 1) Surveillance cameras | N22: Dry dock reattachment of float arm to WEC | O22: 7 | P22: 1 | Q22: 1 | R22: 6 | S22: 7 | T22: =IF(AND(ISNUMBER(P22),ISNUMBER($O22)),OFFSET(RiskMatrixRef,-$O22+1,P22-1),"") -> Low | U22: =IF(AND(ISNUMBER(Q22),ISNUMBER($O22)),OFFSET(RiskMatrixRef,-$O22+1,Q22-1),"") -> Low | V22: =IF(AND(ISNUMBER(R22),ISNUMBER($O22)),OFFSET(RiskMatrixRef,-$O22+1,R22-1),"") -> Med | W22: =IF(AND(ISNUMBER(S22),ISNUMBER($O22)),OFFSET(RiskMatrixRef,-$O22+1,S22-1),"") -> Med | X22: 1) Load derivation methodology to take into account the uncertainties in the loading due to site characterisation measurements and hydrodynamic modelling. 2) Uncertainty of loading estimates to be reduced by comparison of hydrodynamic behavior in simulation versus tank testing. 3) Design load cases to be defined considering all phases (e.g. operating w/ fault, installation, etc.), and to include investigation of localized loading from e.g. slamming. 4) Derivation of localized loading to be developed, and validated via instrumentation of prototype at-sea deployment. 5) Design fatigue factors (DFF) shall be applied to reduce probability of fatigue failure. 6) Establish inspection plan | Y22: Suggest text for recommended action: Increasing the safety factors to high safety class. Uncertainties on loads and structural response to be addressed as defined above (see "Fatigue and other degradation mechanisms" for hull.) | AG22: =IF(AND(ISNUMBER(AC22),ISNUMBER($AB22)),OFFSET(RiskMatrixRef,-$AB22+1,AC22-1),"") | AH22: =IF(AND(ISNUMBER(AD22),ISNUMBER($AB22)),OFFSET(RiskMatrixRef,-$AB22+1,AD22-1),"") | AI22: =IF(AND(ISNUMBER(AE22),ISNUMBER($AB22)),OFFSET(RiskMatrixRef,-$AB22+1,AE22-1),"") | AJ22: =IF(AND(ISNUMBER(AF22),ISNUMBER($AB22)),OFFSET(RiskMatrixRef,-$AB22+1,AF22-1),"") | AS22: =IF(AND(ISNUMBER(AO22),ISNUMBER($AN22)),OFFSET(RiskMatrixRef,-$AN22+1,AO22-1),"") | AT22: =IF(AND(ISNUMBER(AP22),ISNUMBER($AN22)),OFFSET(RiskMatrixRef,-$AN22+1,AP22-1),"") | AU22: =IF(AND(ISNUMBER(AQ22),ISNUMBER($AN22)),OFFSET(RiskMatrixRef,-$AN22+1,AQ22-1),"") | AV22: =IF(AND(ISNUMBER(AR22),ISNUMBER($AN22)),OFFSET(RiskMatrixRef,-$AN22+1,AR22-1),"")
B23: 0113-2 0123-2 | C23: Fwd float idler arm Aft float idler arm | D23: Constrain float to relative pitch about nacelle | E23: 2 | F23: Loading in wave environment, with large motions | G23: Idler arm broken | H23: 1) Wave loading of float is no longer transferred nacelle tube on idler side 2) Addtl loading on drive arm | I23: Wearing of float arm, due to deflection | J23: Normal | K23: none | L23: Visual inspection, and repair if needed | M23: 1) Surveillance cameras | N23: Dry dock reattachment of float arm to WEC | O23: 7 | P23: 1 | Q23: 1 | R23: 6 | S23: 7 | T23: =IF(AND(ISNUMBER(P23),ISNUMBER($O23)),OFFSET(RiskMatrixRef,-$O23+1,P23-1),"") -> Low | U23: =IF(AND(ISNUMBER(Q23),ISNUMBER($O23)),OFFSET(RiskMatrixRef,-$O23+1,Q23-1),"") -> Low | V23: =IF(AND(ISNUMBER(R23),ISNUMBER($O23)),OFFSET(RiskMatrixRef,-$O23+1,R23-1),"") -> Med | W23: =IF(AND(ISNUMBER(S23),ISNUMBER($O23)),OFFSET(RiskMatrixRef,-$O23+1,S23-1),"") -> Med | X23: 1) Additional thickness to be considered in areas that wear could occur. 2) Identify the expected magnitude of wear and time to inspect / repair. 3) Specify inspection plan to be implemented after deployment. 4) Design to consider additional safety margin on space between components (where rubbing and wear is possible) to allow for uncertainty of loading and structural stiffness. | Y23: Suggest text for recommended action: Additional thickness to be considered in areas that wear could occur. Identify the magnitude of wear and time to inspect / repair. Inspection plan to be implemented after deployment. Design to consider addition safety margin on air gap to allow for uncertainty on loading and structural stiffness. | AG23: =IF(AND(ISNUMBER(AC23),ISNUMBER($AB23)),OFFSET(RiskMatrixRef,-$AB23+1,AC23-1),"") | AH23: =IF(AND(ISNUMBER(AD23),ISNUMBER($AB23)),OFFSET(RiskMatrixRef,-$AB23+1,AD23-1),"") | AI23: =IF(AND(ISNUMBER(AE23),ISNUMBER($AB23)),OFFSET(RiskMatrixRef,-$AB23+1,AE23-1),"") | AJ23: =IF(AND(ISNUMBER(AF23),ISNUMBER($AB23)),OFFSET(RiskMatrixRef,-$AB23+1,AF23-1),"") | AS23: =IF(AND(ISNUMBER(AO23),ISNUMBER($AN23)),OFFSET(RiskMatrixRef,-$AN23+1,AO23-1),"") | AT23: =IF(AND(ISNUMBER(AP23),ISNUMBER($AN23)),OFFSET(RiskMatrixRef,-$AN23+1,AP23-1),"") | AU23: =IF(AND(ISNUMBER(AQ23),ISNUMBER($AN23)),OFFSET(RiskMatrixRef,-$AN23+1,AQ23-1),"") | AV23: =IF(AND(ISNUMBER(AR23),ISNUMBER($AN23)),OFFSET(RiskMatrixRef,-$AN23+1,AR23-1),"")
B24: 0113-3 0123-3 | C24: Fwd float idler arm Aft float idler arm | D24: Constrain float to relative pitch about nacelle | E24: 2 | F24: Loading in wave environment, with large motions | G24: Idler arm broken | H24: 1) Wave loading of float is no longer transferred nacelle tube on idler side 2) Addtl loading on drive arm | I24: Non-service boat strike | J24: Normal | K24: 1) Lights, radar reflectors (e.g. visibility) | L24: none | M24: 1) Surveillance cameras | N24: Dry dock reattachment of float arm to WEC | O24: 4 | P24: 3 | Q24: 1 | R24: 6 | S24: 7 | T24: =IF(AND(ISNUMBER(P24),ISNUMBER($O24)),OFFSET(RiskMatrixRef,-$O24+1,P24-1),"") -> Low | U24: =IF(AND(ISNUMBER(Q24),ISNUMBER($O24)),OFFSET(RiskMatrixRef,-$O24+1,Q24-1),"") -> Low | V24: =IF(AND(ISNUMBER(R24),ISNUMBER($O24)),OFFSET(RiskMatrixRef,-$O24+1,R24-1),"") -> Low | W24: =IF(AND(ISNUMBER(S24),ISNUMBER($O24)),OFFSET(RiskMatrixRef,-$O24+1,S24-1),"") -> Low | X24: 1) establish exclusion zone at deployed area 2) The probability of occurrence to be verified considering conditions at the site and vessels in the area | Y24: The probability of occurrence to be verified considering conditions at the site and vessels in the area. | AG24: =IF(AND(ISNUMBER(AC24),ISNUMBER($AB24)),OFFSET(RiskMatrixRef,-$AB24+1,AC24-1),"") | AH24: =IF(AND(ISNUMBER(AD24),ISNUMBER($AB24)),OFFSET(RiskMatrixRef,-$AB24+1,AD24-1),"") | AI24: =IF(AND(ISNUMBER(AE24),ISNUMBER($AB24)),OFFSET(RiskMatrixRef,-$AB24+1,AE24-1),"") | AJ24: =IF(AND(ISNUMBER(AF24),ISNUMBER($AB24)),OFFSET(RiskMatrixRef,-$AB24+1,AF24-1),"") | AS24: =IF(AND(ISNUMBER(AO24),ISNUMBER($AN24)),OFFSET(RiskMatrixRef,-$AN24+1,AO24-1),"") | AT24: =IF(AND(ISNUMBER(AP24),ISNUMBER($AN24)),OFFSET(RiskMatrixRef,-$AN24+1,AP24-1),"") | AU24: =IF(AND(ISNUMBER(AQ24),ISNUMBER($AN24)),OFFSET(RiskMatrixRef,-$AN24+1,AQ24-1),"") | AV24: =IF(AND(ISNUMBER(AR24),ISNUMBER($AN24)),OFFSET(RiskMatrixRef,-$AN24+1,AR24-1),"")
B25: 0131-1 | C25: Nacelle Tube | D25: Rigid connection between nacelle assembly and spars Provide access pathway to nacelle Provision of watertight compartment Counterface for aft float (port) idler bearing (0265) | E25: 2 | F25: Loading in wave environment, with large motions | G25: Hole in single comparment | H25: 1) water ingress via hole 2) bilge removes water in nacelle tube and spar compartment | I25: Leak in FRP (e.g. manufacturing flaw, assembly) | J25: Normal | K25: 1) vacuum test all water tight compartments 2) Single empty compartment filling does not sink WEC 3) V&V for manufacturing and assembly 4) bilge pumps in every watertight compartment | M25: 1) bilge detection | N25: Repair in-situ | O25: 4 | P25: 1 | Q25: 1 | R25: 1 | S25: 3 | T25: =IF(AND(ISNUMBER(P25),ISNUMBER($O25)),OFFSET(RiskMatrixRef,-$O25+1,P25-1),"") -> Low | U25: =IF(AND(ISNUMBER(Q25),ISNUMBER($O25)),OFFSET(RiskMatrixRef,-$O25+1,Q25-1),"") -> Low | V25: =IF(AND(ISNUMBER(R25),ISNUMBER($O25)),OFFSET(RiskMatrixRef,-$O25+1,R25-1),"") -> Low | W25: =IF(AND(ISNUMBER(S25),ISNUMBER($O25)),OFFSET(RiskMatrixRef,-$O25+1,S25-1),"") -> Low | X25: 1) V&V procedures to be defined and followed, which shall mitigate risk of defective component up to commissioning. | Y25: See comment on failure effects and causes in 0111-1 | AG25: =IF(AND(ISNUMBER(AC25),ISNUMBER($AB25)),OFFSET(RiskMatrixRef,-$AB25+1,AC25-1),"") | AH25: =IF(AND(ISNUMBER(AD25),ISNUMBER($AB25)),OFFSET(RiskMatrixRef,-$AB25+1,AD25-1),"") | AI25: =IF(AND(ISNUMBER(AE25),ISNUMBER($AB25)),OFFSET(RiskMatrixRef,-$AB25+1,AE25-1),"") | AJ25: =IF(AND(ISNUMBER(AF25),ISNUMBER($AB25)),OFFSET(RiskMatrixRef,-$AB25+1,AF25-1),"") | AS25: =IF(AND(ISNUMBER(AO25),ISNUMBER($AN25)),OFFSET(RiskMatrixRef,-$AN25+1,AO25-1),"") | AT25: =IF(AND(ISNUMBER(AP25),ISNUMBER($AN25)),OFFSET(RiskMatrixRef,-$AN25+1,AP25-1),"") | AU25: =IF(AND(ISNUMBER(AQ25),ISNUMBER($AN25)),OFFSET(RiskMatrixRef,-$AN25+1,AQ25-1),"") | AV25: =IF(AND(ISNUMBER(AR25),ISNUMBER($AN25)),OFFSET(RiskMatrixRef,-$AN25+1,AR25-1),"") | AX25: non critical space bilge cost limit: 1/8 of bilge budget per spar compartment
B26: 0131-2 | C26: Nacelle Tube | D26: Rigid connection between nacelle assembly and spars Provide access pathway to nacelle Provision of watertight compartment Counterface for aft float (port) idler bearing (0265) | E26: 2 | F26: Loading in wave environment, with large motions | G26: Hole in single comparment | H26: 1) water ingress via hole 2) bilge removes water in nacelle tube and spar compartment | I26: Leak in FRP - fatigue crack due to uncertainties in loading | J26: Normal | K26: 1) Single empty compartment filling does not sink WEC 2) bilge pumps in every watertight compartment | M26: 1) bilge detection | N26: Dry dock for FRP repair and replacement of damaged components | O26: 7 | P26: 1 | Q26: 1 | R26: 6 | S26: 7 | T26: =IF(AND(ISNUMBER(P26),ISNUMBER($O26)),OFFSET(RiskMatrixRef,-$O26+1,P26-1),"") -> Low | U26: =IF(AND(ISNUMBER(Q26),ISNUMBER($O26)),OFFSET(RiskMatrixRef,-$O26+1,Q26-1),"") -> Low | V26: =IF(AND(ISNUMBER(R26),ISNUMBER($O26)),OFFSET(RiskMatrixRef,-$O26+1,R26-1),"") -> Med | W26: =IF(AND(ISNUMBER(S26),ISNUMBER($O26)),OFFSET(RiskMatrixRef,-$O26+1,S26-1),"") -> Med | X26: 1) Load derivation methodology to take into account the uncertainties in the loading due to site characterisation measurements and hydrodynamic modelling. 2) Uncertainty of loading estimates to be reduced by comparison of hydrodynamic behavior in simulation versus tank testing. 3) Design load cases to be defined considering all phases (e.g. operating w/ fault, installation, etc.), and to include investigation of localized loading from e.g. slamming. 4) Derivation of localized loading to be developed, and validated via instrumentation of prototype at-sea deployment. 5) Design fatigue factors (DFF) shall be applied to reduce probability of fatigue failure. 6) Establish inspection plan | Y26: See also comment on "improper design" (0111-1) Suggest text for recommended action Increase DFF For loading uncertainty and simulation accuracy see action for "Fatigue and other degradation mechanisms" for Hull. | AG26: =IF(AND(ISNUMBER(AC26),ISNUMBER($AB26)),OFFSET(RiskMatrixRef,-$AB26+1,AC26-1),"") | AH26: =IF(AND(ISNUMBER(AD26),ISNUMBER($AB26)),OFFSET(RiskMatrixRef,-$AB26+1,AD26-1),"") | AI26: =IF(AND(ISNUMBER(AE26),ISNUMBER($AB26)),OFFSET(RiskMatrixRef,-$AB26+1,AE26-1),"") | AJ26: =IF(AND(ISNUMBER(AF26),ISNUMBER($AB26)),OFFSET(RiskMatrixRef,-$AB26+1,AF26-1),"") | AS26: =IF(AND(ISNUMBER(AO26),ISNUMBER($AN26)),OFFSET(RiskMatrixRef,-$AN26+1,AO26-1),"") | AT26: =IF(AND(ISNUMBER(AP26),ISNUMBER($AN26)),OFFSET(RiskMatrixRef,-$AN26+1,AP26-1),"") | AU26: =IF(AND(ISNUMBER(AQ26),ISNUMBER($AN26)),OFFSET(RiskMatrixRef,-$AN26+1,AQ26-1),"") | AV26: =IF(AND(ISNUMBER(AR26),ISNUMBER($AN26)),OFFSET(RiskMatrixRef,-$AN26+1,AR26-1),"") | AX26: non critical space bilge cost limit: 1/8 of bilge budget per spar compartment
B27: 0132-1 | C27: Lower Nacelle | D27: Provision of watertight compartment | E27: 2 | F27: Loading in wave environment, with large motions | G27: Hole in single compartment | H27: Crack/hole in hull (No water ingress/egress) | I27: Leak in FRP (e.g. manufacturing flaw, assembly) | J27: Normal | K27: 1) No empty voids (full of foam) 2) vacuum test all water tight compartments 3) V&V for manufacturing and assembly 4) bilge pumps in every watertight compartment | M27: No detection | N27: No repair necessary | O27: 4 | P27: 1 | Q27: 1 | R27: 1 | S27: 1 | T27: =IF(AND(ISNUMBER(P27),ISNUMBER($O27)),OFFSET(RiskMatrixRef,-$O27+1,P27-1),"") -> Low | U27: =IF(AND(ISNUMBER(Q27),ISNUMBER($O27)),OFFSET(RiskMatrixRef,-$O27+1,Q27-1),"") -> Low | V27: =IF(AND(ISNUMBER(R27),ISNUMBER($O27)),OFFSET(RiskMatrixRef,-$O27+1,R27-1),"") -> Low | W27: =IF(AND(ISNUMBER(S27),ISNUMBER($O27)),OFFSET(RiskMatrixRef,-$O27+1,S27-1),"") -> Low | X27: 1) V&V procedures to be defined and followed, which shall mitigate risk of defective component up to commissioning. 2) Design to specify allowable water absorption (and degree of degradation due to water contact) of foam. | Y27: See comment on failure effects and causes in 0111-1 | AG27: =IF(AND(ISNUMBER(AC27),ISNUMBER($AB27)),OFFSET(RiskMatrixRef,-$AB27+1,AC27-1),"") | AH27: =IF(AND(ISNUMBER(AD27),ISNUMBER($AB27)),OFFSET(RiskMatrixRef,-$AB27+1,AD27-1),"") | AI27: =IF(AND(ISNUMBER(AE27),ISNUMBER($AB27)),OFFSET(RiskMatrixRef,-$AB27+1,AE27-1),"") | AJ27: =IF(AND(ISNUMBER(AF27),ISNUMBER($AB27)),OFFSET(RiskMatrixRef,-$AB27+1,AF27-1),"") | AS27: =IF(AND(ISNUMBER(AO27),ISNUMBER($AN27)),OFFSET(RiskMatrixRef,-$AN27+1,AO27-1),"") | AT27: =IF(AND(ISNUMBER(AP27),ISNUMBER($AN27)),OFFSET(RiskMatrixRef,-$AN27+1,AP27-1),"") | AU27: =IF(AND(ISNUMBER(AQ27),ISNUMBER($AN27)),OFFSET(RiskMatrixRef,-$AN27+1,AQ27-1),"") | AV27: =IF(AND(ISNUMBER(AR27),ISNUMBER($AN27)),OFFSET(RiskMatrixRef,-$AN27+1,AR27-1),"") | AX27: EDR specify foam does not allow greater than X% of water absorption Cohesive foam
B28: 0132-2 | C28: Lower Nacelle | D28: Provision of watertight compartment | E28: 2 | F28: Loading in wave environment, with large motions | G28: Hole in single compartment | H28: Crack/hole in hull (No water ingress/egress) | I28: Leak in FRP - fatigue crack due to uncertainties in loading | J28: Normal | K28: 1) No empty voids (full of foam) 2) Single empty compartment filling does not sink WEC 3) bilge pumps in every watertight compartment | M28: No detection | N28: No repair necessary | O28: 5 | P28: 1 | Q28: 1 | R28: 1 | S28: 1 | T28: =IF(AND(ISNUMBER(P28),ISNUMBER($O28)),OFFSET(RiskMatrixRef,-$O28+1,P28-1),"") -> Low | U28: =IF(AND(ISNUMBER(Q28),ISNUMBER($O28)),OFFSET(RiskMatrixRef,-$O28+1,Q28-1),"") -> Low | V28: =IF(AND(ISNUMBER(R28),ISNUMBER($O28)),OFFSET(RiskMatrixRef,-$O28+1,R28-1),"") -> Low | W28: =IF(AND(ISNUMBER(S28),ISNUMBER($O28)),OFFSET(RiskMatrixRef,-$O28+1,S28-1),"") -> Low | X28: 1) Load derivation methodology to take into account the uncertainties in the loading due to site characterisation measurements and hydrodynamic modelling. 2) Uncertainty of loading estimates to be reduced by comparison of hydrodynamic behavior in simulation versus tank testing. 3) Design load cases to be defined considering all phases (e.g. operating w/ fault, installation, etc.), and to include investigation of localized loading from e.g. slamming. 4) Derivation of localized loading to be developed, and validated via instrumentation of prototype at-sea deployment. 5) Design fatigue factors (DFF) shall be applied to reduce probability of fatigue failure. 6) Establish inspection plan 7) Design to specify allowable water absorption (and degree of degradation due to water contact) of foam. | Y28: See also comment on "improper design" (0111-1) Action the same as "Leak in FRP - fatigue crack due to improper design" for Nacelle Tube | AG28: =IF(AND(ISNUMBER(AC28),ISNUMBER($AB28)),OFFSET(RiskMatrixRef,-$AB28+1,AC28-1),"") | AH28: =IF(AND(ISNUMBER(AD28),ISNUMBER($AB28)),OFFSET(RiskMatrixRef,-$AB28+1,AD28-1),"") | AI28: =IF(AND(ISNUMBER(AE28),ISNUMBER($AB28)),OFFSET(RiskMatrixRef,-$AB28+1,AE28-1),"") | AJ28: =IF(AND(ISNUMBER(AF28),ISNUMBER($AB28)),OFFSET(RiskMatrixRef,-$AB28+1,AF28-1),"") | AS28: =IF(AND(ISNUMBER(AO28),ISNUMBER($AN28)),OFFSET(RiskMatrixRef,-$AN28+1,AO28-1),"") | AT28: =IF(AND(ISNUMBER(AP28),ISNUMBER($AN28)),OFFSET(RiskMatrixRef,-$AN28+1,AP28-1),"") | AU28: =IF(AND(ISNUMBER(AQ28),ISNUMBER($AN28)),OFFSET(RiskMatrixRef,-$AN28+1,AQ28-1),"") | AV28: =IF(AND(ISNUMBER(AR28),ISNUMBER($AN28)),OFFSET(RiskMatrixRef,-$AN28+1,AR28-1),"") | AX28: EDR specify foam does not allow greater than X% of water absorption Cohesive foam
B29: 0133-1 0134-1 | C29: PTO Hull - STBD PTO Hull - PORT | D29: Provision of watertight compartment | E29: 2 | F29: Loading in wave environment, with large motions | G29: Hole in single comparment | H29: 1) water ingress through hole (bilge removes water from compartment) | I29: Leak in FRP (e.g. manufacturing flaw, assembly) | J29: Normal | K29: 1) vacuum test all water tight compartments 2) Single empty compartment filling does not sink WEC 3) V&V for manufacturing and assembly 4) bilge pumps in every watertight compartment | M29: 1) bilge detection | N29: Repair in-situ | O29: 3 | P29: 1 | Q29: 1 | R29: 1 | S29: 3 | T29: =IF(AND(ISNUMBER(P29),ISNUMBER($O29)),OFFSET(RiskMatrixRef,-$O29+1,P29-1),"") -> Low | U29: =IF(AND(ISNUMBER(Q29),ISNUMBER($O29)),OFFSET(RiskMatrixRef,-$O29+1,Q29-1),"") -> Low | V29: =IF(AND(ISNUMBER(R29),ISNUMBER($O29)),OFFSET(RiskMatrixRef,-$O29+1,R29-1),"") -> Low | W29: =IF(AND(ISNUMBER(S29),ISNUMBER($O29)),OFFSET(RiskMatrixRef,-$O29+1,S29-1),"") -> Low | X29: 1) V&V procedures to be defined and followed, which shall mitigate risk of defective component up to commissioning. | Y29: See comment on failure effects and causes in 0111-1 | AG29: =IF(AND(ISNUMBER(AC29),ISNUMBER($AB29)),OFFSET(RiskMatrixRef,-$AB29+1,AC29-1),"") | AH29: =IF(AND(ISNUMBER(AD29),ISNUMBER($AB29)),OFFSET(RiskMatrixRef,-$AB29+1,AD29-1),"") | AI29: =IF(AND(ISNUMBER(AE29),ISNUMBER($AB29)),OFFSET(RiskMatrixRef,-$AB29+1,AE29-1),"") | AJ29: =IF(AND(ISNUMBER(AF29),ISNUMBER($AB29)),OFFSET(RiskMatrixRef,-$AB29+1,AF29-1),"") | AS29: =IF(AND(ISNUMBER(AO29),ISNUMBER($AN29)),OFFSET(RiskMatrixRef,-$AN29+1,AO29-1),"") | AT29: =IF(AND(ISNUMBER(AP29),ISNUMBER($AN29)),OFFSET(RiskMatrixRef,-$AN29+1,AP29-1),"") | AU29: =IF(AND(ISNUMBER(AQ29),ISNUMBER($AN29)),OFFSET(RiskMatrixRef,-$AN29+1,AQ29-1),"") | AV29: =IF(AND(ISNUMBER(AR29),ISNUMBER($AN29)),OFFSET(RiskMatrixRef,-$AN29+1,AR29-1),"")
B30: 0133-2 0134-2 | C30: PTO Hull - STBD PTO Hull - PORT | D30: Provision of watertight compartment | E30: 2 | F30: Loading in wave environment, with large motions | G30: Hole in single comparment | H30: 1) water ingress through hole (bilge removes water from compartment) | I30: Leak in FRP - fatigue crack due to uncertainties in loading | J30: Normal | K30: 1) Single empty compartment filling does not sink WEC 2) bilge pumps in every watertight compartment | M30: 1) bilge detection | N30: Dry dock for FRP repair and replacement of damaged components | O30: 7 | P30: 1 | Q30: 1 | R30: 1 | S30: 7 | T30: =IF(AND(ISNUMBER(P30),ISNUMBER($O30)),OFFSET(RiskMatrixRef,-$O30+1,P30-1),"") -> Low | U30: =IF(AND(ISNUMBER(Q30),ISNUMBER($O30)),OFFSET(RiskMatrixRef,-$O30+1,Q30-1),"") -> Low | V30: =IF(AND(ISNUMBER(R30),ISNUMBER($O30)),OFFSET(RiskMatrixRef,-$O30+1,R30-1),"") -> Low | W30: =IF(AND(ISNUMBER(S30),ISNUMBER($O30)),OFFSET(RiskMatrixRef,-$O30+1,S30-1),"") -> Med | X30: 1) Load derivation methodology to take into account the uncertainties in the loading due to site characterisation measurements and hydrodynamic modelling. 2) Uncertainty of loading estimates to be reduced by comparison of hydrodynamic behavior in simulation versus tank testing. 3) Design load cases to be defined considering all phases (e.g. operating w/ fault, installation, etc.), and to include investigation of localized loading from e.g. slamming. 4) Derivation of localized loading to be developed, and validated via instrumentation of prototype at-sea deployment. 5) Design fatigue factors (DFF) shall be applied to reduce probability of fatigue failure. 6) Establish inspection plan | Y30: See also comment on "improper design" (0111-1) Action the same as "Leak in FRP - fatigue crack due to improper design" for Nacelle Tube For loading uncertainty and simulation accuracy, see action on "Extreme wave event loading" in HULL | AG30: =IF(AND(ISNUMBER(AC30),ISNUMBER($AB30)),OFFSET(RiskMatrixRef,-$AB30+1,AC30-1),"") | AH30: =IF(AND(ISNUMBER(AD30),ISNUMBER($AB30)),OFFSET(RiskMatrixRef,-$AB30+1,AD30-1),"") | AI30: =IF(AND(ISNUMBER(AE30),ISNUMBER($AB30)),OFFSET(RiskMatrixRef,-$AB30+1,AE30-1),"") | AJ30: =IF(AND(ISNUMBER(AF30),ISNUMBER($AB30)),OFFSET(RiskMatrixRef,-$AB30+1,AF30-1),"") | AS30: =IF(AND(ISNUMBER(AO30),ISNUMBER($AN30)),OFFSET(RiskMatrixRef,-$AN30+1,AO30-1),"") | AT30: =IF(AND(ISNUMBER(AP30),ISNUMBER($AN30)),OFFSET(RiskMatrixRef,-$AN30+1,AP30-1),"") | AU30: =IF(AND(ISNUMBER(AQ30),ISNUMBER($AN30)),OFFSET(RiskMatrixRef,-$AN30+1,AQ30-1),"") | AV30: =IF(AND(ISNUMBER(AR30),ISNUMBER($AN30)),OFFSET(RiskMatrixRef,-$AN30+1,AR30-1),"")
