Workbook
Name RiskMatrixRef: '[1]set up'!$C$14
Name RiskMatrixRef: 'set up'!$C$14

Sheet Data Rights Notice

Sheet 0200 PTO System
O2: Risk Ranking | AC2: Updated Risk Ranking | AO2: 2nd Updated Risk Ranking
B4: 0200 PTO System FMECA Table | P4: Severity Class | T4: Risk Class | AD4: Severity Class | AH4: Risk Class | AP4: Severity Class | AT4: Risk Class
B5: Risk ID | C5: Item Description | D5: Function | E5: Tech. Class | F5: Novel Aspects | G5: Failure Mode | H5: Failure Effects (Local, WEC, System) | I5: Failure Cause(s) | J5: Initial Mode of Operation | K5: Risk Reduction Design | L5: Preventative Detection | M5: Post Failure Detection | N5: Post Failure Repair Strategy (automated, manual) | O5: Occurrence | P5: Human Safety | Q5: Environment | R5: Operation | S5: Assets | T5: Human Safety | U5: Environment | V5: Operation | W5: Assets | X5: Recommended Actions | Y5: DVN GL comments | Z5: CPWR Response Notes | AA5: Responsible Party | AB5: Actions Taken | AC5: Occurrence | AD5: Human Safety | AE5: Environment | AF5: Operation | AG5: Assets | AH5: Human Safety | AI5: Environment | AJ5: Operation | AK5: Assets | AL5: 2nd Recommended Actions | AM5: Responsible Party (2nd) | AN5: Actions Taken (2nd) | AO5: Occurrence | AP5: Human Safety | AQ5: Environment | AR5: Operation | AS5: Assets | AT5: Human Safety | AU5: Environment | AV5: Operation | AW5: Assets | AX5: Status (open or closed) | AY5: Notes
B6: 200-1 | C6: PTO | D6: PTO functions are electromechanical energy conversion, torque transmission, constrain generator to 1DOF rotation and maintain rotor/stator airgap, with minimal friction. The PTO is composed of electrical and mechanical components. | E6: 2 | F6: Marine application | G6: Structural failure Loss of PTO | H6: Mechanical Severe structural failure WEC is no longer functioning | I6: Loading in fore-in-aft configuration greater than predicted (note that CPwr numerical modeling is not able to accurately represent the very low freeboard fore float in fore-in-aft configuration) | J6: Normal | K6: 1) Conservative partial safety factor 2) Numerical modeling with additional freeboard | L6: monitoring strain gauges (likely not on the fore float or arms, but rather on the shaft and/or nacelle tube) | M6: 1) Surveillance 2) SCADA 3) etc | N6: Dry dock repair if possible, if not loss of projects | O6: 3 | P6: 4 | Q6: 7 | R6: 9 | S6: 9 | T6: Low | U6: Low | V6: Med | W6: Med | AY6: Determine where strain monitoring can be used effectively
B7: 210-1 | C7: Stator Segment | D7: Electromechanical energy conversion | E7: 2 | F7: Marine application | G7: Fire/smoke due to electrical short Loss of stator segment Loss of PTO | H7: Electrical 1) Stator segment is is electrical isolated 2) PTO is shutdown and electrically isolated. 3) Heat production in shorted segment 4) Freshwater cooling flow is increased 5) smoke/fire 6) Fire spreads | I7: Electrical short (non-moisture or corrosion) - Short in coils - Short in connector - Short in PTC or KTY circuit Creating an overheating condition which leads to fire/smoke | J7: Normal | K7: 1) Segmented design 2) PTC elements iniating automatic disconnect on overtemperature 3) Circuit breaker isolates each stator segment on over current and/or ground fault 3) Quality marine design and manufacturing 4) V&V (insulation check, pulse test, high voltage test) | L7: 1) Automated stator disconnect, overcurrent protection. 2) PTC element initiates overtemperature shutdown. 3) KTY 84 sensor - temperature monitoring circuit for data trend analysis 2) Stator group performance analysis, data trend. | M7: 1) PTC Stator fault Alarm - overtemperature stator segment 2) PTO shutdown fault Alarm 3) PTO fire Alarm 4) PTO compartment air quality monitoring & alarm 5) Surveillance system - PTO visible & IR camera | N7: Dry dock repair/overall depending on extent of the fire damage | O7: 4 | P7: 1 | Q7: 3 | R7: 7 | S7: 7 | T7: =IF(AND(ISNUMBER(P7),ISNUMBER($O7)),OFFSET(RiskMatrixRef,-$O7+1,P7-1),"") -> Low | U7: =IF(AND(ISNUMBER(Q7),ISNUMBER($O7)),OFFSET(RiskMatrixRef,-$O7+1,Q7-1),"") -> Low | V7: =IF(AND(ISNUMBER(R7),ISNUMBER($O7)),OFFSET(RiskMatrixRef,-$O7+1,R7-1),"") -> Low | W7: =IF(AND(ISNUMBER(S7),ISNUMBER($O7)),OFFSET(RiskMatrixRef,-$O7+1,S7-1),"") -> Low | X7: Demonstrate fire can be contained within a compartment. Definition of the acceptable damage due to fire to be provided, and it has to be demonstrated that extent of fireproofing is compatible with the allowable damage. Manufacturing documentation to demonstrate the frequency of short circuit of coils are compatible with the occurrence class defined. | Y7: CP to clarify if temperature monitoring of the stator segments/coil is present? Suggest text for recommended action: Demonstrate fire can be contained within a compartment. Definition of the acceptable damage due to fire to be provided, and it has to be demonstrated that extent of fireproofing is compatible with the allowable damage. Manufacturing documentation to demonstrate the frequency of short circuit of coils are compatible with the occurrence class defined. | Z7: Each stator has KTY 84 sensor - temperature monitoring circuit and a PTC element for overtemperature shutdown. Stators short circuit torque is less then rated torque, no mechanical issue. Average thermal dissipation (heat) is much lower then rated. Further investigation during LandRAY testing will refine cooling requirements and cooling system controls. Cooling system will meet or exceed flow requirements of stator continuous load rating. Stators will be rating either IEC 600034-1 S3, S9, or other based on LandRAY testing. LandRAY stator is rated S3, and will be analyzed for S9 non-periodic load and speed variations, and for real seas stochastic load variations. | AA7: JP | AH7: =IF(AND(ISNUMBER(AD7),ISNUMBER($AC7)),OFFSET(RiskMatrixRef,-$AC7+1,AD7-1),"") | AI7: =IF(AND(ISNUMBER(AE7),ISNUMBER($AC7)),OFFSET(RiskMatrixRef,-$AC7+1,AE7-1),"") | AJ7: =IF(AND(ISNUMBER(AF7),ISNUMBER($AC7)),OFFSET(RiskMatrixRef,-$AC7+1,AF7-1),"") | AK7: =IF(AND(ISNUMBER(AG7),ISNUMBER($AC7)),OFFSET(RiskMatrixRef,-$AC7+1,AG7-1),"") | AT7: =IF(AND(ISNUMBER(AP7),ISNUMBER($AO7)),OFFSET(RiskMatrixRef,-$AO7+1,AP7-1),"") | AU7: =IF(AND(ISNUMBER(AQ7),ISNUMBER($AO7)),OFFSET(RiskMatrixRef,-$AO7+1,AQ7-1),"") | AV7: =IF(AND(ISNUMBER(AR7),ISNUMBER($AO7)),OFFSET(RiskMatrixRef,-$AO7+1,AR7-1),"") | AW7: =IF(AND(ISNUMBER(AS7),ISNUMBER($AO7)),OFFSET(RiskMatrixRef,-$AO7+1,AS7-1),"")
B8: 210-1 | C8: Stator Segment | D8: Electromechanical energy conversion | E8: 2 | F8: Marine application | G8: Loss of stator segment due to high heat, Loss of PTO | H8: Electrical 1) Stator is isolated, PTC overtemperature initiates segment isolation breaker to open 2) PTO inisates a controlled shutdown 3) Heat production in shorted segment 4) Cooling system flow is increased to reduce temperature | I8: Overheating - single stator segment cause by: 1) Short circuit in stator segment 2) Faulty PTC temperature 3) Short in back iron leading to high eddy current losses. 4) Stator segment internal cooling tube blockage or leak. | J8: Normal | K8: 1) Segmented design 2) PTC elements iniating automatic disconnect on overtemperature 3) Circuit breaker isolates each stator segment on over current and/or ground fault 3) Quality marine design and manufacturing 4) V&V (insulation check, pulse test, high voltage test) | L8: 1) KTY 84 sensor - temperature monitoring circuit for data trend analysis of each segment 2) Stator group performance analysis, data trend. | M8: 1) Stator fault Alarm - overtemperature stator segment 2) PTO shutdown fault Alarm 3) KTY temperature monitor data | N8: 1) Dry dock repair to replace stator segment, 2) Determine segment is not an issue, and operate PTO with one less segment. PTO is design to operate with any number of stator segments to reduce dry dock repair frequency in the case of a stator segment fault. | O8: 5 | P8: 1 | Q8: 3 | R8: 4 | S8: 4 | T8: =IF(AND(ISNUMBER(P8),ISNUMBER($O8)),OFFSET(RiskMatrixRef,-$O8+1,P8-1),"") -> Low | U8: =IF(AND(ISNUMBER(Q8),ISNUMBER($O8)),OFFSET(RiskMatrixRef,-$O8+1,Q8-1),"") -> Low | V8: =IF(AND(ISNUMBER(R8),ISNUMBER($O8)),OFFSET(RiskMatrixRef,-$O8+1,R8-1),"") -> Low | W8: =IF(AND(ISNUMBER(S8),ISNUMBER($O8)),OFFSET(RiskMatrixRef,-$O8+1,S8-1),"") -> Low | X8: LandRAY - Testing reports of the stator segment to demonstrate that temperature of the stator segment is below the limit for overheating. The environment for testing shall replicate the actual operating conditions in WEC. | Y8: Suggest text for recommended action: Testing reports of the stator segment to demonstrate that temperature of the stator segment is below the limit for overheating. The environment for testing shall replicate the actual operating conditions in WEC. | Z8: Overheating in single stator segment would note normally not lead to fire. Segment is immediately electrically isolated from the rest of the generator/electric plant. PTO controlled shut-down is initiated. Service request is submitted. **(Cooling demand is less then stator segment rated. Cooling system is design to be meet maximum rated cooling flow of segments. To increase efficiency, cooling flow is reduced to meet demand.) | AA8: JP | AH8: =IF(AND(ISNUMBER(AD8),ISNUMBER($AC8)),OFFSET(RiskMatrixRef,-$AC8+1,AD8-1),"") | AI8: =IF(AND(ISNUMBER(AE8),ISNUMBER($AC8)),OFFSET(RiskMatrixRef,-$AC8+1,AE8-1),"") | AJ8: =IF(AND(ISNUMBER(AF8),ISNUMBER($AC8)),OFFSET(RiskMatrixRef,-$AC8+1,AF8-1),"") | AK8: =IF(AND(ISNUMBER(AG8),ISNUMBER($AC8)),OFFSET(RiskMatrixRef,-$AC8+1,AG8-1),"") | AT8: =IF(AND(ISNUMBER(AP8),ISNUMBER($AO8)),OFFSET(RiskMatrixRef,-$AO8+1,AP8-1),"") | AU8: =IF(AND(ISNUMBER(AQ8),ISNUMBER($AO8)),OFFSET(RiskMatrixRef,-$AO8+1,AQ8-1),"") | AV8: =IF(AND(ISNUMBER(AR8),ISNUMBER($AO8)),OFFSET(RiskMatrixRef,-$AO8+1,AR8-1),"") | AW8: =IF(AND(ISNUMBER(AS8),ISNUMBER($AO8)),OFFSET(RiskMatrixRef,-$AO8+1,AS8-1),"")
B9: 210-2 | C9: Stator Segment | D9: Electromechanical energy conversion | E9: 2 | F9: Marine application | G9: Single Multiple stator segment failure | H9: Mechanical 1) Heat in segment due to eddy currents at back iron corrosion location. 2) Corrosion leads to electrical short in coils, high heat and current. 3) Stator segment is electrically isolated, PTO is shut down. 5) Deformation/expansion from overheating rusting back iron and reduction of air gap. 6) Impact with rotor, debris from damage travel to air gap causing damage to other segments and ultimately failure of the generator | I9: Corrosion induced failure | J9: Normal | K9: 1) Resin encased stators 2) Sealing epoxy coating on stator segments to seal any mirco cracks in resin 2) Automatic disconnect due to overtemperaure 3) Automatic disconnect on overcurrent 4) Stainless and aluminum stator housing materials | L9: 1) Visual inspection 2) Surveillence system cameras 3) KTC stator tempature profile monitoring. Alarm if out of operating range before overtemperature. | M9: 1) PTC Stator fault Alarm - overtemperature stator segment 2) PTO shutdown fault Alarm 3) Surveillance system - PTO visible & IR camera 4)Vibration monitoring: Vibration sensor threshold high alarm. | N9: Dry dock repair | O9: 4 | P9: 1 | Q9: 1 | R9: 7 | S9: 7 | T9: =IF(AND(ISNUMBER(P9),ISNUMBER($O9)),OFFSET(RiskMatrixRef,-$O9+1,P9-1),"") -> Low | U9: =IF(AND(ISNUMBER(Q9),ISNUMBER($O9)),OFFSET(RiskMatrixRef,-$O9+1,Q9-1),"") -> Low | V9: =IF(AND(ISNUMBER(R9),ISNUMBER($O9)),OFFSET(RiskMatrixRef,-$O9+1,R9-1),"") -> Low | W9: =IF(AND(ISNUMBER(S9),ISNUMBER($O9)),OFFSET(RiskMatrixRef,-$O9+1,S9-1),"") -> Low | Y9: Multiple stator segment failure in the failure mode is because of the possible resultant damage due to the debris in the air gap (from mechanical failure of a stator segment). | Z9: Multiple stator failures considered. Risk is similar because occurrence goes down and severity goes up. Specific to mechanical failure - complete structure degradation of stator segment. Very unliked. | AH9: =IF(AND(ISNUMBER(AD9),ISNUMBER($AC9)),OFFSET(RiskMatrixRef,-$AC9+1,AD9-1),"") | AI9: =IF(AND(ISNUMBER(AE9),ISNUMBER($AC9)),OFFSET(RiskMatrixRef,-$AC9+1,AE9-1),"") | AJ9: =IF(AND(ISNUMBER(AF9),ISNUMBER($AC9)),OFFSET(RiskMatrixRef,-$AC9+1,AF9-1),"") | AK9: =IF(AND(ISNUMBER(AG9),ISNUMBER($AC9)),OFFSET(RiskMatrixRef,-$AC9+1,AG9-1),"") | AT9: =IF(AND(ISNUMBER(AP9),ISNUMBER($AO9)),OFFSET(RiskMatrixRef,-$AO9+1,AP9-1),"") | AU9: =IF(AND(ISNUMBER(AQ9),ISNUMBER($AO9)),OFFSET(RiskMatrixRef,-$AO9+1,AQ9-1),"") | AV9: =IF(AND(ISNUMBER(AR9),ISNUMBER($AO9)),OFFSET(RiskMatrixRef,-$AO9+1,AR9-1),"") | AW9: =IF(AND(ISNUMBER(AS9),ISNUMBER($AO9)),OFFSET(RiskMatrixRef,-$AO9+1,AS9-1),"")
B10: 210-3 | C10: Stator Segment | D10: Electromechanical energy conversion | E10: 2 | F10: Marine application | G10: Single Multiple stator segment failure | H10: Mechanical 1) Heat in segment due to eddy currents at back iron corrosion location. 2) Corrosion leads to electrical short in coils, high heat and current. 3) Stator segment is electrically isolated, PTO is shut down. 5) Deformation/expansion from overheating rusting back iron and reduction of air gap. 6) Impact with rotor, debris from damage travel to air gap causing damage to other segments and ultimately failure of the generator | I10: Manufacturing defect results in failure | J10: Normal | K10: 1) Commercial product 2) V&V (QC) | L10: 1) Visual inspection 2) Surveillence system cameras 3) KTC stator tempature profile monitoring. Alarm if out of operating range before overtemperature. | M10: 1) PTC Stator fault Alarm - overtemperature stator segment 2) PTO shutdown fault Alarm 3) Surveillance system - PTO visible & IR camera 4)Vibration monitoring: Vibration sensor threshold high alarm. | N10: Dry dock repair | O10: 3 | P10: 1 | Q10: 1 | R10: 7 | S10: 7 | T10: =IF(AND(ISNUMBER(P10),ISNUMBER($O10)),OFFSET(RiskMatrixRef,-$O10+1,P10-1),"") -> Low | U10: =IF(AND(ISNUMBER(Q10),ISNUMBER($O10)),OFFSET(RiskMatrixRef,-$O10+1,Q10-1),"") -> Low | V10: =IF(AND(ISNUMBER(R10),ISNUMBER($O10)),OFFSET(RiskMatrixRef,-$O10+1,R10-1),"") -> Low | W10: =IF(AND(ISNUMBER(S10),ISNUMBER($O10)),OFFSET(RiskMatrixRef,-$O10+1,S10-1),"") -> Low | Y10: General comment for components with "Manufacturing defect results in failure" as the failure cause: Occurrence is low based on the assumption that the manufacturer is able to provide evidence for reliability compatible to the occurrence class. Please confirm. | Z10: Commercial manufacturing techniques used for linear motors. Reliable compatible since manufacturing method is established and proven successful. | AH10: =IF(AND(ISNUMBER(AD10),ISNUMBER($AC10)),OFFSET(RiskMatrixRef,-$AC10+1,AD10-1),"") | AI10: =IF(AND(ISNUMBER(AE10),ISNUMBER($AC10)),OFFSET(RiskMatrixRef,-$AC10+1,AE10-1),"") | AJ10: =IF(AND(ISNUMBER(AF10),ISNUMBER($AC10)),OFFSET(RiskMatrixRef,-$AC10+1,AF10-1),"") | AK10: =IF(AND(ISNUMBER(AG10),ISNUMBER($AC10)),OFFSET(RiskMatrixRef,-$AC10+1,AG10-1),"") | AT10: =IF(AND(ISNUMBER(AP10),ISNUMBER($AO10)),OFFSET(RiskMatrixRef,-$AO10+1,AP10-1),"") | AU10: =IF(AND(ISNUMBER(AQ10),ISNUMBER($AO10)),OFFSET(RiskMatrixRef,-$AO10+1,AQ10-1),"") | AV10: =IF(AND(ISNUMBER(AR10),ISNUMBER($AO10)),OFFSET(RiskMatrixRef,-$AO10+1,AR10-1),"") | AW10: =IF(AND(ISNUMBER(AS10),ISNUMBER($AO10)),OFFSET(RiskMatrixRef,-$AO10+1,AS10-1),"")
B11: 210-4 | C11: Stator Segment | D11: Electromechanical energy conversion | E11: 2 | F11: Marine application | G11: Single stator segment failure | H11: Electrical 1) Stator is isolated, PTC overtemperature or over current shutdown. 2) PTO inisates a controlled shutdown 3) Heat production in shorted segment 4) Cooling system flow is increased to reduce temperature | I11: Moisture induced failure, moisture leads to stator internal electrical short. | J11: Normal | K11: 1) Resin encased stators 2) Sealing epoxy coating on stator segments to seal any mirco cracks in resin 2) Automatic disconnect due to overtemperaure 3) Automatic disconnect on overcurrent 4) Stainless and aluminum stator housing materials 5) Each segment has isolation breaker. | L11: 1) Compartment environmental moniotring - moisture and humidity kept within compartmetnal specifications by climate control system 2) Bilge level sensor 3) Surveillence system cameras 4) Visual inspection 5) KTC stator tempature profile monitoring | M11: 1) PTC Stator fault Alarm - overtemperature and overcurrent stator segment 2) PTO shutdown fault Alarm 3) Compartment environmental monitoring and bilge sensors 4) Surveillance system - PTO visible & IR camera 5) Visual inspection | N11: Dry dock repair | O11: 4 | P11: 1 | Q11: 1 | R11: 7 | S11: 7 | T11: =IF(AND(ISNUMBER(P11),ISNUMBER($O11)),OFFSET(RiskMatrixRef,-$O11+1,P11-1),"") -> Low | U11: =IF(AND(ISNUMBER(Q11),ISNUMBER($O11)),OFFSET(RiskMatrixRef,-$O11+1,Q11-1),"") -> Low | V11: =IF(AND(ISNUMBER(R11),ISNUMBER($O11)),OFFSET(RiskMatrixRef,-$O11+1,R11-1),"") -> Low | W11: =IF(AND(ISNUMBER(S11),ISNUMBER($O11)),OFFSET(RiskMatrixRef,-$O11+1,S11-1),"") -> Low | Z11: Moisture/ater induced electrical fault that does not lead to fire is more likely then fire. Need to reduce occurance of fire/smoke. | AH11: =IF(AND(ISNUMBER(AD11),ISNUMBER($AC11)),OFFSET(RiskMatrixRef,-$AC11+1,AD11-1),"") | AI11: =IF(AND(ISNUMBER(AE11),ISNUMBER($AC11)),OFFSET(RiskMatrixRef,-$AC11+1,AE11-1),"") | AJ11: =IF(AND(ISNUMBER(AF11),ISNUMBER($AC11)),OFFSET(RiskMatrixRef,-$AC11+1,AF11-1),"") | AK11: =IF(AND(ISNUMBER(AG11),ISNUMBER($AC11)),OFFSET(RiskMatrixRef,-$AC11+1,AG11-1),"") | AT11: =IF(AND(ISNUMBER(AP11),ISNUMBER($AO11)),OFFSET(RiskMatrixRef,-$AO11+1,AP11-1),"") | AU11: =IF(AND(ISNUMBER(AQ11),ISNUMBER($AO11)),OFFSET(RiskMatrixRef,-$AO11+1,AQ11-1),"") | AV11: =IF(AND(ISNUMBER(AR11),ISNUMBER($AO11)),OFFSET(RiskMatrixRef,-$AO11+1,AR11-1),"") | AW11: =IF(AND(ISNUMBER(AS11),ISNUMBER($AO11)),OFFSET(RiskMatrixRef,-$AO11+1,AS11-1),"")
B12: 210-5 | C12: Stator Segment | D12: Electromechanical energy conversion | E12: 2 | F12: Marine application | G12: Multiple stator segment failure | H12: Mechanical 1) Loss of stator segment 2) Loss of PTO - control shutdown after segment is lost. 3) Heat in segment 4) Damage to components and debris travel to air gap causing more damage | I12: Vibration induced failure | J12: Normal | K12: 1) Vibration monitoring 2) Stator Cart design engages segment locally to rotor 3) Reduced cogging forces 4) Structural rigidity high for extreme loads. Vibration load causes very minimal deflection/movement. 5) Structural design | L12: 1) Vibration monitoring 2) Torque rod load cells on smart cart. | M12: 1) PTC Stator fault Alarm - overtemperature and overcurrent stator segment 2) PTO shutdown fault Alarm 3) Surveillance system - PTO visible & IR camera 4) Visual inspection | N12: Dry dock repair | O12: 5 | P12: 1 | Q12: 1 | R12: 7 | S12: 7 | T12: =IF(AND(ISNUMBER(P12),ISNUMBER($O12)),OFFSET(RiskMatrixRef,-$O12+1,P12-1),"") -> Low | U12: =IF(AND(ISNUMBER(Q12),ISNUMBER($O12)),OFFSET(RiskMatrixRef,-$O12+1,Q12-1),"") -> Low | V12: =IF(AND(ISNUMBER(R12),ISNUMBER($O12)),OFFSET(RiskMatrixRef,-$O12+1,R12-1),"") -> Med | W12: =IF(AND(ISNUMBER(S12),ISNUMBER($O12)),OFFSET(RiskMatrixRef,-$O12+1,S12-1),"") -> Med | Y12: Probability class lower than that for FLS design because of multiple failure of stator segment Suggested text for recommended action : Manufacturing documentation to demonstrate the limits of vibration level on the component is higher than the maximum level of vibration of the WEC. | Z12: Vibration load should have minimal/negligible effects on the stator cart. Initial analysis of design shows extreme loads much higher; therefore, due to rigidity of the design, deflection of component (stator cart and relative position on rotor) during vibration is fiducial, below reasonability detectable. What is required for this proof? | AH12: =IF(AND(ISNUMBER(AD12),ISNUMBER($AC12)),OFFSET(RiskMatrixRef,-$AC12+1,AD12-1),"") | AI12: =IF(AND(ISNUMBER(AE12),ISNUMBER($AC12)),OFFSET(RiskMatrixRef,-$AC12+1,AE12-1),"") | AJ12: =IF(AND(ISNUMBER(AF12),ISNUMBER($AC12)),OFFSET(RiskMatrixRef,-$AC12+1,AF12-1),"") | AK12: =IF(AND(ISNUMBER(AG12),ISNUMBER($AC12)),OFFSET(RiskMatrixRef,-$AC12+1,AG12-1),"") | AT12: =IF(AND(ISNUMBER(AP12),ISNUMBER($AO12)),OFFSET(RiskMatrixRef,-$AO12+1,AP12-1),"") | AU12: =IF(AND(ISNUMBER(AQ12),ISNUMBER($AO12)),OFFSET(RiskMatrixRef,-$AO12+1,AQ12-1),"") | AV12: =IF(AND(ISNUMBER(AR12),ISNUMBER($AO12)),OFFSET(RiskMatrixRef,-$AO12+1,AR12-1),"") | AW12: =IF(AND(ISNUMBER(AS12),ISNUMBER($AO12)),OFFSET(RiskMatrixRef,-$AO12+1,AS12-1),"")
B13: 210-6 | C13: Stator Segment | D13: Electromechanical energy conversion | E13: 2 | F13: Marine application | G13: Multiple stator segment failure | H13: 1) Loss of stator segment 2) Loss of PTO 3) Damage to components and debris travel to air gap causing more damage | I13: Accidental impact from rotor or Operational impact between stator segment and rotor. | J13: Normal | K13: 1) Stator cart design - localize tolerances to a single segment - localize and isolate loads - Position of stator localized to rotor position below stator. | L13: 1) Airgap sensors on smart cart 2) Noise monitoring 3) Surveillance systems - camera visually inspections | M13: 1) SCADA diagnostics - PTO shutdown 2) Audio noise threshold alarm 3) Vibration sensors 4) Suveillance system - camera | N13: Dry dock repair | O13: 3 | P13: 1 | Q13: 1 | R13: 7 | S13: 7 | T13: =IF(AND(ISNUMBER(P13),ISNUMBER($O13)),OFFSET(RiskMatrixRef,-$O13+1,P13-1),"") -> Low | U13: =IF(AND(ISNUMBER(Q13),ISNUMBER($O13)),OFFSET(RiskMatrixRef,-$O13+1,Q13-1),"") -> Low | V13: =IF(AND(ISNUMBER(R13),ISNUMBER($O13)),OFFSET(RiskMatrixRef,-$O13+1,R13-1),"") -> Low | W13: =IF(AND(ISNUMBER(S13),ISNUMBER($O13)),OFFSET(RiskMatrixRef,-$O13+1,S13-1),"") -> Low | Y13: Suggest text for recommended action: Demonstrate, via analysis, that contact between stator and rotor segments can be avoided in the worse load case. If impact is possible, then the structural analysis shall demonstrate structural integrity of the component is within the acceptance criteria when subject to the impact | Z13: Design of stator care and rail bearingssystem, and FEA analysis of design for extreme loading, designed and proven no contact. Worst load case does not effect airgap, only acceleration in the X-Y axis, which in extreme increases airgap, not decreases.
B14: 220-1 | C14: Rotor Segment mounting | D14: Hold rotor in place | E14: 2 | F14: Marine application | G14: mechanical failure | H14: 1) Rotor segment impacts stator segments - Magnet comes loose - Corrosion bubbles up the magent material greater than airgap - Material scraping and damage to surfaces | I14: Corrosion induced failure | J14: Normal | K14: 1) Proper hardware material selection 2) Rotor special moisture resistance epoxy coating 3) Magnet coating design for marine applications | L14: 1) Compartment environmental moniotring - moisture and humidity kept within compartmetnal specifications by climate control system 2) Bilge level sensor 3) Surveillence system cameras 4) Visual inspection 5) KTC stator tempature profile monitoring | M14: 1) Surveillance system - PTO visible & IR camera 2)Vibration monitoring: Vibration sensor threshold high alarm. | N14: Dry dock repair | O14: 5 | P14: 1 | Q14: 1 | R14: 7 | S14: 7 | T14: =IF(AND(ISNUMBER(P14),ISNUMBER($O14)),OFFSET(RiskMatrixRef,-$O14+1,P14-1),"") -> Low | U14: =IF(AND(ISNUMBER(Q14),ISNUMBER($O14)),OFFSET(RiskMatrixRef,-$O14+1,Q14-1),"") -> Low | V14: =IF(AND(ISNUMBER(R14),ISNUMBER($O14)),OFFSET(RiskMatrixRef,-$O14+1,R14-1),"") -> Med | W14: =IF(AND(ISNUMBER(S14),ISNUMBER($O14)),OFFSET(RiskMatrixRef,-$O14+1,S14-1),"") -> Med | Y14: Assume it has the same occurrence class as operation impact. Recommended action same as that for stator segment. Please clarify what is the corrosion protection system on the rotor segment mounting. | Z14: Corrosion coating rated to meet or exceed the compartmental rating of the generator. Each Rotor segment is vacuum impregnated with epoxy resin and them coating with marine grade epoxy coating. | AH14: =IF(AND(ISNUMBER(AD14),ISNUMBER($AC14)),OFFSET(RiskMatrixRef,-$AC14+1,AD14-1),"") | AI14: =IF(AND(ISNUMBER(AE14),ISNUMBER($AC14)),OFFSET(RiskMatrixRef,-$AC14+1,AE14-1),"") | AJ14: =IF(AND(ISNUMBER(AF14),ISNUMBER($AC14)),OFFSET(RiskMatrixRef,-$AC14+1,AF14-1),"") | AK14: =IF(AND(ISNUMBER(AG14),ISNUMBER($AC14)),OFFSET(RiskMatrixRef,-$AC14+1,AG14-1),"") | AT14: =IF(AND(ISNUMBER(AP14),ISNUMBER($AO14)),OFFSET(RiskMatrixRef,-$AO14+1,AP14-1),"") | AU14: =IF(AND(ISNUMBER(AQ14),ISNUMBER($AO14)),OFFSET(RiskMatrixRef,-$AO14+1,AQ14-1),"") | AV14: =IF(AND(ISNUMBER(AR14),ISNUMBER($AO14)),OFFSET(RiskMatrixRef,-$AO14+1,AR14-1),"") | AW14: =IF(AND(ISNUMBER(AS14),ISNUMBER($AO14)),OFFSET(RiskMatrixRef,-$AO14+1,AS14-1),"")
B15: 220-2 | C15: Rotor Segment mounting | D15: Hold rotor in place | E15: 2 | F15: Marine application | G15: mechanical failure | H15: T-bar hardware failure - Bolts that hold T bar in place | I15: Manufacturing defect results in failure | J15: Normal | K15: 1) V&V - Quality of bolt - Torque spec inspection 2) Adjacent rotor hold rotor in place with magnetic force coupling of permanent magnets | L15: 1) Surveillence system cameras 2) Visual inspection 3) Airgap measurement on smart stator cart | M15: 1) Surveillance system - PTO visible & IR camera 2)Vibration monitoring: Vibration sensor threshold high alarm. | N15: Dry dock repair | O15: 3 | P15: 1 | Q15: 1 | R15: 7 | S15: 7 | T15: =IF(AND(ISNUMBER(P15),ISNUMBER($O15)),OFFSET(RiskMatrixRef,-$O15+1,P15-1),"") -> Low | U15: =IF(AND(ISNUMBER(Q15),ISNUMBER($O15)),OFFSET(RiskMatrixRef,-$O15+1,Q15-1),"") -> Low | V15: =IF(AND(ISNUMBER(R15),ISNUMBER($O15)),OFFSET(RiskMatrixRef,-$O15+1,R15-1),"") -> Low | W15: =IF(AND(ISNUMBER(S15),ISNUMBER($O15)),OFFSET(RiskMatrixRef,-$O15+1,S15-1),"") -> Low | Y15: See risk ID 210-3 for comment | Z15: Material selection and sourcing. Quality bolts. | AH15: =IF(AND(ISNUMBER(AD15),ISNUMBER($AC15)),OFFSET(RiskMatrixRef,-$AC15+1,AD15-1),"") | AI15: =IF(AND(ISNUMBER(AE15),ISNUMBER($AC15)),OFFSET(RiskMatrixRef,-$AC15+1,AE15-1),"") | AJ15: =IF(AND(ISNUMBER(AF15),ISNUMBER($AC15)),OFFSET(RiskMatrixRef,-$AC15+1,AF15-1),"") | AK15: =IF(AND(ISNUMBER(AG15),ISNUMBER($AC15)),OFFSET(RiskMatrixRef,-$AC15+1,AG15-1),"") | AT15: =IF(AND(ISNUMBER(AP15),ISNUMBER($AO15)),OFFSET(RiskMatrixRef,-$AO15+1,AP15-1),"") | AU15: =IF(AND(ISNUMBER(AQ15),ISNUMBER($AO15)),OFFSET(RiskMatrixRef,-$AO15+1,AQ15-1),"") | AV15: =IF(AND(ISNUMBER(AR15),ISNUMBER($AO15)),OFFSET(RiskMatrixRef,-$AO15+1,AR15-1),"") | AW15: =IF(AND(ISNUMBER(AS15),ISNUMBER($AO15)),OFFSET(RiskMatrixRef,-$AO15+1,AS15-1),"")
B16: 220-3 | C16: Rotor Segment mounting | D16: Hold rotor in place | E16: 2 | F16: Marine application | G16: mechanical failure | H16: 1) Rotor segment impacts stator segments | I16: Vibration induced failure | J16: Normal | K16: 1) Use of COTS mounting technique 2) Proper torque spec on hardware for mounting to FRP backing | L16: 1) Surveillence system cameras 2) Visual inspection 3) Airgap measurement on smart stator cart | M16: Surveillance camera | N16: Dry dock repair | O16: 7 | P16: 1 | Q16: 1 | R16: 7 | S16: 7 | T16: =IF(AND(ISNUMBER(P16),ISNUMBER($O16)),OFFSET(RiskMatrixRef,-$O16+1,P16-1),"") -> Low | U16: =IF(AND(ISNUMBER(Q16),ISNUMBER($O16)),OFFSET(RiskMatrixRef,-$O16+1,Q16-1),"") -> Low | V16: =IF(AND(ISNUMBER(R16),ISNUMBER($O16)),OFFSET(RiskMatrixRef,-$O16+1,R16-1),"") -> Med | W16: =IF(AND(ISNUMBER(S16),ISNUMBER($O16)),OFFSET(RiskMatrixRef,-$O16+1,S16-1),"") -> Med | X16: The recommended action is to investigate the dynamic movement of the rotor and assess the effect of the vibration loads on the structure integrity (fatigue) of the component. The acceptance criteria for the maximum vibration level shall be defined, based on FE analysis. The FE analysis, considering these failure mechanisms, need to demonstrate the structural strength is within the acceptance criteria in the standard and the impact on functionality of the device is within the acceptance criteria. The monitoring of the vibration shall be done to identify the level of vibrations during in-service life. If any excessive vibration is detected, intervention is required to reduce the vibration level below the maximum level, as defined in the acceptance criteria (conditioning monitoring). | Y16: Probability class same as FLS design Suggested text for recommended action: The recommended action is to investigate the dynamic movement of the rotor and assess the effect of the vibration loads on the structure integrity (fatigue) of the component. The acceptance criteria for the maximum vibration level shall be defined, based on FE analysis. The FE analysis, considering these failure mechanisms, need to demonstrate the structural strength is within the acceptance criteria in the standard and the impact on functionality of the device is within the acceptance criteria. The monitoring of the vibration shall be done to identify the level of vibrations during in-service life. If any excessive vibration is detected, intervention is required to reduce the vibration level below the maximum level, as defined in the acceptance criteria (conditioning monitoring). | Z16: Extreme is much higher than vibration, for most cases, virbation fatique failure not a concern due to the extreme load design cases much higher then vibration. Will be investigatd further during LandRAY. As recommended, the acceptance criteria for the maximum vibration level shall be defined, based on FE analysis. Why is occurrence high? (7). T-bar rotor attachment is a commerical standard used by Siemens. The only varaition is using FRP for the rotor tire. Torque specificaion takes into consideration the FRP properties. Analysis will be made and risk should be low. | AH16: =IF(AND(ISNUMBER(AD16),ISNUMBER($AC16)),OFFSET(RiskMatrixRef,-$AC16+1,AD16-1),"") | AI16: =IF(AND(ISNUMBER(AE16),ISNUMBER($AC16)),OFFSET(RiskMatrixRef,-$AC16+1,AE16-1),"") | AJ16: =IF(AND(ISNUMBER(AF16),ISNUMBER($AC16)),OFFSET(RiskMatrixRef,-$AC16+1,AF16-1),"") | AK16: =IF(AND(ISNUMBER(AG16),ISNUMBER($AC16)),OFFSET(RiskMatrixRef,-$AC16+1,AG16-1),"") | AT16: =IF(AND(ISNUMBER(AP16),ISNUMBER($AO16)),OFFSET(RiskMatrixRef,-$AO16+1,AP16-1),"") | AU16: =IF(AND(ISNUMBER(AQ16),ISNUMBER($AO16)),OFFSET(RiskMatrixRef,-$AO16+1,AQ16-1),"") | AV16: =IF(AND(ISNUMBER(AR16),ISNUMBER($AO16)),OFFSET(RiskMatrixRef,-$AO16+1,AR16-1),"") | AW16: =IF(AND(ISNUMBER(AS16),ISNUMBER($AO16)),OFFSET(RiskMatrixRef,-$AO16+1,AS16-1),"")
B17: 220-4 | C17: Rotor Segment | D17: Create magnetic field | E17: 2 | F17: Marine application | G17: Failure of single rotor magnet | H17: 1) Loss of field strength 2) Reduction in voltage 3) Reduction in power | I17: Corrosion induced failure | J17: Normal | K17: 1) Resin encased 2) Special marine grade epoxy coating on surface mountied magnets | L17: Visual inspection | M17: Visual inspection | N17: Dry dock repair | O17: 5 | P17: 1 | Q17: 1 | R17: 6 | S17: 7 | T17: =IF(AND(ISNUMBER(P17),ISNUMBER($O17)),OFFSET(RiskMatrixRef,-$O17+1,P17-1),"") -> Low | U17: =IF(AND(ISNUMBER(Q17),ISNUMBER($O17)),OFFSET(RiskMatrixRef,-$O17+1,Q17-1),"") -> Low | V17: =IF(AND(ISNUMBER(R17),ISNUMBER($O17)),OFFSET(RiskMatrixRef,-$O17+1,R17-1),"") -> Low | W17: =IF(AND(ISNUMBER(S17),ISNUMBER($O17)),OFFSET(RiskMatrixRef,-$O17+1,S17-1),"") -> Med | X17: Demonstrate, via manufacturing documentation or testing reports, that the long term integrity of the coating is within the design criteria for the corrosion protection system on the rotor. | Y17: Please state the material of the bolts and its corrosion protection system. Suggest text for recommended action: Demonstrate, via manufacturing documentation or testing reports, that the long term integrity of the coating is within the design criteria for the corrosion protection system on the rotor. | Z17: Components are/will designed to exceed the compartment environmental rating. Documentation of magnetic rotor segments and associated mounting hardware will be included | AH17: =IF(AND(ISNUMBER(AD17),ISNUMBER($AC17)),OFFSET(RiskMatrixRef,-$AC17+1,AD17-1),"") | AI17: =IF(AND(ISNUMBER(AE17),ISNUMBER($AC17)),OFFSET(RiskMatrixRef,-$AC17+1,AE17-1),"") | AJ17: =IF(AND(ISNUMBER(AF17),ISNUMBER($AC17)),OFFSET(RiskMatrixRef,-$AC17+1,AF17-1),"") | AK17: =IF(AND(ISNUMBER(AG17),ISNUMBER($AC17)),OFFSET(RiskMatrixRef,-$AC17+1,AG17-1),"") | AT17: =IF(AND(ISNUMBER(AP17),ISNUMBER($AO17)),OFFSET(RiskMatrixRef,-$AO17+1,AP17-1),"") | AU17: =IF(AND(ISNUMBER(AQ17),ISNUMBER($AO17)),OFFSET(RiskMatrixRef,-$AO17+1,AQ17-1),"") | AV17: =IF(AND(ISNUMBER(AR17),ISNUMBER($AO17)),OFFSET(RiskMatrixRef,-$AO17+1,AR17-1),"") | AW17: =IF(AND(ISNUMBER(AS17),ISNUMBER($AO17)),OFFSET(RiskMatrixRef,-$AO17+1,AS17-1),"")
B18: 220-5 | C18: Rotor Segment | D18: Create magnetic field | E18: 2 | F18: Marine application | G18: Failure of single rotor magnet | H18: 1) Loss of field strength 2) Reduction in voltage 3) Reduction in power | I18: Manufacturing defect results in failure | J18: Normal | K18: V&V | L18: Visual inspection | M18: Visual inspection | N18: Dry dock repair | O18: 4 | P18: 1 | Q18: 1 | R18: 6 | S18: 7 | T18: =IF(AND(ISNUMBER(P18),ISNUMBER($O18)),OFFSET(RiskMatrixRef,-$O18+1,P18-1),"") -> Low | U18: =IF(AND(ISNUMBER(Q18),ISNUMBER($O18)),OFFSET(RiskMatrixRef,-$O18+1,Q18-1),"") -> Low | V18: =IF(AND(ISNUMBER(R18),ISNUMBER($O18)),OFFSET(RiskMatrixRef,-$O18+1,R18-1),"") -> Low | W18: =IF(AND(ISNUMBER(S18),ISNUMBER($O18)),OFFSET(RiskMatrixRef,-$O18+1,S18-1),"") -> Low | Y18: Occurrence is low based on the assumption that Siemens is able to provide evidence for reliability compatible to the occurrence class. Please confirm | Z18: Yes, Siemens is using commercial manufacturing techniques and quality control which will result in s low probability of manufacturing defects. | AH18: =IF(AND(ISNUMBER(AD18),ISNUMBER($AC18)),OFFSET(RiskMatrixRef,-$AC18+1,AD18-1),"") | AI18: =IF(AND(ISNUMBER(AE18),ISNUMBER($AC18)),OFFSET(RiskMatrixRef,-$AC18+1,AE18-1),"") | AJ18: =IF(AND(ISNUMBER(AF18),ISNUMBER($AC18)),OFFSET(RiskMatrixRef,-$AC18+1,AF18-1),"") | AK18: =IF(AND(ISNUMBER(AG18),ISNUMBER($AC18)),OFFSET(RiskMatrixRef,-$AC18+1,AG18-1),"") | AT18: =IF(AND(ISNUMBER(AP18),ISNUMBER($AO18)),OFFSET(RiskMatrixRef,-$AO18+1,AP18-1),"") | AU18: =IF(AND(ISNUMBER(AQ18),ISNUMBER($AO18)),OFFSET(RiskMatrixRef,-$AO18+1,AQ18-1),"") | AV18: =IF(AND(ISNUMBER(AR18),ISNUMBER($AO18)),OFFSET(RiskMatrixRef,-$AO18+1,AR18-1),"") | AW18: =IF(AND(ISNUMBER(AS18),ISNUMBER($AO18)),OFFSET(RiskMatrixRef,-$AO18+1,AS18-1),"")
B19: 220-6 | C19: Rotor Segment | D19: Create magnetic field | E19: 2 | F19: Marine application | G19: Failure of single rotor magnet | H19: 1) Loss of field strength 2) Reduction in voltage 3) Reduction in power | I19: Vibration induced failure | J19: Normal | K19: 1) Resin encased 2) Modal analysis | L19: Visual inspection | M19: Visual inspection | N19: Dry dock repair | O19: 7 | P19: 1 | Q19: 1 | R19: 6 | S19: 7 | T19: =IF(AND(ISNUMBER(P19),ISNUMBER($O19)),OFFSET(RiskMatrixRef,-$O19+1,P19-1),"") -> Low | U19: =IF(AND(ISNUMBER(Q19),ISNUMBER($O19)),OFFSET(RiskMatrixRef,-$O19+1,Q19-1),"") -> Low | V19: =IF(AND(ISNUMBER(R19),ISNUMBER($O19)),OFFSET(RiskMatrixRef,-$O19+1,R19-1),"") -> Med | W19: =IF(AND(ISNUMBER(S19),ISNUMBER($O19)),OFFSET(RiskMatrixRef,-$O19+1,S19-1),"") -> Med | Y19: Probability class same as FLS design | Z19: Why is occurrence high? (7). T-bar rotor attachment is a commerical standard used by Siemens. The only varaition is using FRP for the rotor tire. Torque specificaion takes into consideration the FRP properties. Analysis will be made and risk should be low. Also StingRAY has a shorter deployment life. | AH19: =IF(AND(ISNUMBER(AD19),ISNUMBER($AC19)),OFFSET(RiskMatrixRef,-$AC19+1,AD19-1),"") | AI19: =IF(AND(ISNUMBER(AE19),ISNUMBER($AC19)),OFFSET(RiskMatrixRef,-$AC19+1,AE19-1),"") | AJ19: =IF(AND(ISNUMBER(AF19),ISNUMBER($AC19)),OFFSET(RiskMatrixRef,-$AC19+1,AF19-1),"") | AK19: =IF(AND(ISNUMBER(AG19),ISNUMBER($AC19)),OFFSET(RiskMatrixRef,-$AC19+1,AG19-1),"") | AT19: =IF(AND(ISNUMBER(AP19),ISNUMBER($AO19)),OFFSET(RiskMatrixRef,-$AO19+1,AP19-1),"") | AU19: =IF(AND(ISNUMBER(AQ19),ISNUMBER($AO19)),OFFSET(RiskMatrixRef,-$AO19+1,AQ19-1),"") | AV19: =IF(AND(ISNUMBER(AR19),ISNUMBER($AO19)),OFFSET(RiskMatrixRef,-$AO19+1,AR19-1),"") | AW19: =IF(AND(ISNUMBER(AS19),ISNUMBER($AO19)),OFFSET(RiskMatrixRef,-$AO19+1,AS19-1),"")
B20: 220-7 | C20: Rotor Segment | D20: Create magnetic field | E20: 2 | F20: Marine application | G20: 1) Short circuit in stator - high current and heat leading to 2) de-magnetization of magnets over range of operation of faulted stator segment. | H20: Reduced magnetic field (EMF) for part of the rotor over the theta angle range of operation. | I20: Fault in stator segment - High current - High heat Coupled with vibration | J20: Normal | K20: 1) Rare earth NdFeB magnetics reduce risk of de-mag 2) Airgap designed for mutual inductance high enough to protect against short circuit current. Includes knowledge of phase shift of current with regards to the electrical pole position, out of pole alignment, reduced ability to demagnetize | L20: Design | M20: None | N20: Dry dock repair | O20: 3 | P20: 1 | Q20: 1 | R20: 6 | S20: 6 | T20: =IF(AND(ISNUMBER(P20),ISNUMBER($O20)),OFFSET(RiskMatrixRef,-$O20+1,P20-1),"") -> Low | U20: =IF(AND(ISNUMBER(Q20),ISNUMBER($O20)),OFFSET(RiskMatrixRef,-$O20+1,Q20-1),"") -> Low | V20: =IF(AND(ISNUMBER(R20),ISNUMBER($O20)),OFFSET(RiskMatrixRef,-$O20+1,R20-1),"") -> Low | W20: =IF(AND(ISNUMBER(S20),ISNUMBER($O20)),OFFSET(RiskMatrixRef,-$O20+1,S20-1),"") -> Low | Y20: De-magnetization of magnets (BH-curves of magnet material at elevated temperatures) due to short-circuit in e.g. connection line should be addressed as a risk somewhere, where the failure cause can range from material defects over thermal issues to damages by service personnel. Please update the FMECA. | Z20: OK, this is a second level contingency design, first there must be a short circuit in stator segment - Siemens noted as low risk due the NdFeB magnets, short circuit with relutance of magnetic circuit and phase shift of current would not normally cause de-mag. It should be documented and explained in more detail.
B21: 230-1 | C21: Stator Cables | D21: Connection between stator segments in PTO compartment to MoMos in dry control room | E21: 1 | F21: none | G21: Stator cable open | H21: 1) Loss of stator segment 2) Other stator segments with same MoMo gets extra current for one wave cycle 3) failure detected 4) Command higher damping on other 35 stators 5) Reduced efficiency | I21: Corrosion induced failure | J21: Normal | K21: 1) Marine rated cable and corrector 2) Climate control | M21: SCADA diagnostics | N21: Accept failure or dry dock repair | O21: 7 | P21: 1 | Q21: 1 | R21: 4 | S21: 4 | T21: =IF(AND(ISNUMBER(P21),ISNUMBER($O21)),OFFSET(RiskMatrixRef,-$O21+1,P21-1),"") -> Low | U21: =IF(AND(ISNUMBER(Q21),ISNUMBER($O21)),OFFSET(RiskMatrixRef,-$O21+1,Q21-1),"") -> Low | V21: =IF(AND(ISNUMBER(R21),ISNUMBER($O21)),OFFSET(RiskMatrixRef,-$O21+1,R21-1),"") -> Low | W21: =IF(AND(ISNUMBER(S21),ISNUMBER($O21)),OFFSET(RiskMatrixRef,-$O21+1,S21-1),"") -> Low | Y21: Low severity assuming single failure Corrosion occurrence in line with corrosion failures (FLS) | AH21: =IF(AND(ISNUMBER(AD21),ISNUMBER($AC21)),OFFSET(RiskMatrixRef,-$AC21+1,AD21-1),"") | AI21: =IF(AND(ISNUMBER(AE21),ISNUMBER($AC21)),OFFSET(RiskMatrixRef,-$AC21+1,AE21-1),"") | AJ21: =IF(AND(ISNUMBER(AF21),ISNUMBER($AC21)),OFFSET(RiskMatrixRef,-$AC21+1,AF21-1),"") | AK21: =IF(AND(ISNUMBER(AG21),ISNUMBER($AC21)),OFFSET(RiskMatrixRef,-$AC21+1,AG21-1),"") | AT21: =IF(AND(ISNUMBER(AP21),ISNUMBER($AO21)),OFFSET(RiskMatrixRef,-$AO21+1,AP21-1),"") | AU21: =IF(AND(ISNUMBER(AQ21),ISNUMBER($AO21)),OFFSET(RiskMatrixRef,-$AO21+1,AQ21-1),"") | AV21: =IF(AND(ISNUMBER(AR21),ISNUMBER($AO21)),OFFSET(RiskMatrixRef,-$AO21+1,AR21-1),"") | AW21: =IF(AND(ISNUMBER(AS21),ISNUMBER($AO21)),OFFSET(RiskMatrixRef,-$AO21+1,AS21-1),"")
B22: 230-2 | C22: Stator Cables | D22: Connection between stator segments in PTO compartment to MoMos in dry control room | E22: 1 | F22: none | G22: Stator cable open | H22: 1) Loss of stator segment 2) Other stator segments with same MoMo gets extra current for one wave cycle 3) failure detected 4) Command higher damping on other 35 stators 5) Reduced efficiency | I22: Manufacturing defect results in failure | J22: Normal | K22: 1) Commercial product 2) V&V (QC) | M22: SCADA diagnostics | N22: Accept failure or dry dock repair | O22: 3 | P22: 1 | Q22: 1 | R22: 4 | S22: 4 | T22: =IF(AND(ISNUMBER(P22),ISNUMBER($O22)),OFFSET(RiskMatrixRef,-$O22+1,P22-1),"") -> Low | U22: =IF(AND(ISNUMBER(Q22),ISNUMBER($O22)),OFFSET(RiskMatrixRef,-$O22+1,Q22-1),"") -> Low | V22: =IF(AND(ISNUMBER(R22),ISNUMBER($O22)),OFFSET(RiskMatrixRef,-$O22+1,R22-1),"") -> Low | W22: =IF(AND(ISNUMBER(S22),ISNUMBER($O22)),OFFSET(RiskMatrixRef,-$O22+1,S22-1),"") -> Low | Y22: Low severity assuming single failure | AH22: =IF(AND(ISNUMBER(AD22),ISNUMBER($AC22)),OFFSET(RiskMatrixRef,-$AC22+1,AD22-1),"") | AI22: =IF(AND(ISNUMBER(AE22),ISNUMBER($AC22)),OFFSET(RiskMatrixRef,-$AC22+1,AE22-1),"") | AJ22: =IF(AND(ISNUMBER(AF22),ISNUMBER($AC22)),OFFSET(RiskMatrixRef,-$AC22+1,AF22-1),"") | AK22: =IF(AND(ISNUMBER(AG22),ISNUMBER($AC22)),OFFSET(RiskMatrixRef,-$AC22+1,AG22-1),"") | AT22: =IF(AND(ISNUMBER(AP22),ISNUMBER($AO22)),OFFSET(RiskMatrixRef,-$AO22+1,AP22-1),"") | AU22: =IF(AND(ISNUMBER(AQ22),ISNUMBER($AO22)),OFFSET(RiskMatrixRef,-$AO22+1,AQ22-1),"") | AV22: =IF(AND(ISNUMBER(AR22),ISNUMBER($AO22)),OFFSET(RiskMatrixRef,-$AO22+1,AR22-1),"") | AW22: =IF(AND(ISNUMBER(AS22),ISNUMBER($AO22)),OFFSET(RiskMatrixRef,-$AO22+1,AS22-1),"")
B23: 230-3 | C23: Stator Cables | D23: Connection between stator segments in PTO compartment to MoMos in dry control room | E23: 1 | F23: none | G23: Stator cable short | H23: 1) Loss of stator segment 2) Heat in segment 3) Command higher damping on other 35 stators 4) Reduced efficiency | I23: Moisture induced failure | J23: Normal | K23: 1) Marine rated cable and corrector 2) Climate control | M23: SCADA diagnostics | N23: 1) Automatic breaker trip 2) accept failure or dry dock repair | O23: 4 | P23: 1 | Q23: 1 | R23: 4 | S23: 4 | T23: =IF(AND(ISNUMBER(P23),ISNUMBER($O23)),OFFSET(RiskMatrixRef,-$O23+1,P23-1),"") -> Low | U23: =IF(AND(ISNUMBER(Q23),ISNUMBER($O23)),OFFSET(RiskMatrixRef,-$O23+1,Q23-1),"") -> Low | V23: =IF(AND(ISNUMBER(R23),ISNUMBER($O23)),OFFSET(RiskMatrixRef,-$O23+1,R23-1),"") -> Low | W23: =IF(AND(ISNUMBER(S23),ISNUMBER($O23)),OFFSET(RiskMatrixRef,-$O23+1,S23-1),"") -> Low | Y23: Low severity assuming single failure | AH23: =IF(AND(ISNUMBER(AD23),ISNUMBER($AC23)),OFFSET(RiskMatrixRef,-$AC23+1,AD23-1),"") | AI23: =IF(AND(ISNUMBER(AE23),ISNUMBER($AC23)),OFFSET(RiskMatrixRef,-$AC23+1,AE23-1),"") | AJ23: =IF(AND(ISNUMBER(AF23),ISNUMBER($AC23)),OFFSET(RiskMatrixRef,-$AC23+1,AF23-1),"") | AK23: =IF(AND(ISNUMBER(AG23),ISNUMBER($AC23)),OFFSET(RiskMatrixRef,-$AC23+1,AG23-1),"") | AT23: =IF(AND(ISNUMBER(AP23),ISNUMBER($AO23)),OFFSET(RiskMatrixRef,-$AO23+1,AP23-1),"") | AU23: =IF(AND(ISNUMBER(AQ23),ISNUMBER($AO23)),OFFSET(RiskMatrixRef,-$AO23+1,AQ23-1),"") | AV23: =IF(AND(ISNUMBER(AR23),ISNUMBER($AO23)),OFFSET(RiskMatrixRef,-$AO23+1,AR23-1),"") | AW23: =IF(AND(ISNUMBER(AS23),ISNUMBER($AO23)),OFFSET(RiskMatrixRef,-$AO23+1,AS23-1),"")
B24: 230-4 | C24: Stator Cables | D24: Connection between stator segments in PTO compartment to MoMos in dry control room | E24: 1 | F24: none | G24: Stator cable open | H24: 1) Loss of stator segment 2) Other stator segments with same MoMo gets extra current for one wave cycle 3) failure detected 4) Command higher damping on other 35 stators 5) Reduced efficiency | I24: Vibration induced failure | J24: Normal | K24: 1) Marine rated cable and corrector | M24: SCADA diagnostics | N24: Accept failure or dry dock repair | O24: 7 | P24: 1 | Q24: 1 | R24: 4 | S24: 4 | T24: =IF(AND(ISNUMBER(P24),ISNUMBER($O24)),OFFSET(RiskMatrixRef,-$O24+1,P24-1),"") -> Low | U24: =IF(AND(ISNUMBER(Q24),ISNUMBER($O24)),OFFSET(RiskMatrixRef,-$O24+1,Q24-1),"") -> Low | V24: =IF(AND(ISNUMBER(R24),ISNUMBER($O24)),OFFSET(RiskMatrixRef,-$O24+1,R24-1),"") -> Low | W24: =IF(AND(ISNUMBER(S24),ISNUMBER($O24)),OFFSET(RiskMatrixRef,-$O24+1,S24-1),"") -> Low | Y24: Low severity assuming single failure | AH24: =IF(AND(ISNUMBER(AD24),ISNUMBER($AC24)),OFFSET(RiskMatrixRef,-$AC24+1,AD24-1),"") | AI24: =IF(AND(ISNUMBER(AE24),ISNUMBER($AC24)),OFFSET(RiskMatrixRef,-$AC24+1,AE24-1),"") | AJ24: =IF(AND(ISNUMBER(AF24),ISNUMBER($AC24)),OFFSET(RiskMatrixRef,-$AC24+1,AF24-1),"") | AK24: =IF(AND(ISNUMBER(AG24),ISNUMBER($AC24)),OFFSET(RiskMatrixRef,-$AC24+1,AG24-1),"") | AT24: =IF(AND(ISNUMBER(AP24),ISNUMBER($AO24)),OFFSET(RiskMatrixRef,-$AO24+1,AP24-1),"") | AU24: =IF(AND(ISNUMBER(AQ24),ISNUMBER($AO24)),OFFSET(RiskMatrixRef,-$AO24+1,AQ24-1),"") | AV24: =IF(AND(ISNUMBER(AR24),ISNUMBER($AO24)),OFFSET(RiskMatrixRef,-$AO24+1,AR24-1),"") | AW24: =IF(AND(ISNUMBER(AS24),ISNUMBER($AO24)),OFFSET(RiskMatrixRef,-$AO24+1,AS24-1),"")
B25: 240-1 | C25: PTO to hull interface | D25: Transfer PTO and rotor loads to sub-structure | E25: 2 | F25: Loading | G25: FRP fracture | H25: 1) Loss of torque transmitted by PTO 2) Flooded PTO compartment 3) Debris broken off | I25: Wear/fatigue | J25: Normal | K25: None | L25: None | M25: 1) Vibration sensors and bearing temperature 2) Abnormal speed with respect to the wave climate and damping | N25: Dry dock repair | O25: 4 | P25: 1 | Q25: 4 | R25: 9 | S25: 8 | T25: =IF(AND(ISNUMBER(P25),ISNUMBER($O25)),OFFSET(RiskMatrixRef,-$O25+1,P25-1),"") -> Low | U25: =IF(AND(ISNUMBER(Q25),ISNUMBER($O25)),OFFSET(RiskMatrixRef,-$O25+1,Q25-1),"") -> Low | V25: =IF(AND(ISNUMBER(R25),ISNUMBER($O25)),OFFSET(RiskMatrixRef,-$O25+1,R25-1),"") -> Med | W25: =IF(AND(ISNUMBER(S25),ISNUMBER($O25)),OFFSET(RiskMatrixRef,-$O25+1,S25-1),"") -> Med | X25: 1) Load derivation methodology to take into account the uncertainties in the loading due to site characterization measurements and hydrodynamic modelling. 2) CPower to demonstrate the derivation of loading is conservative for the site, including providing evidence from site assessment and validation of the overall loading upon deployment. | Y25: Please include the FMECA of item 240 | AH25: =IF(AND(ISNUMBER(AD25),ISNUMBER($AC25)),OFFSET(RiskMatrixRef,-$AC25+1,AD25-1),"") | AI25: =IF(AND(ISNUMBER(AE25),ISNUMBER($AC25)),OFFSET(RiskMatrixRef,-$AC25+1,AE25-1),"") | AJ25: =IF(AND(ISNUMBER(AF25),ISNUMBER($AC25)),OFFSET(RiskMatrixRef,-$AC25+1,AF25-1),"") | AK25: =IF(AND(ISNUMBER(AG25),ISNUMBER($AC25)),OFFSET(RiskMatrixRef,-$AC25+1,AG25-1),"") | AT25: =IF(AND(ISNUMBER(AP25),ISNUMBER($AO25)),OFFSET(RiskMatrixRef,-$AO25+1,AP25-1),"") | AU25: =IF(AND(ISNUMBER(AQ25),ISNUMBER($AO25)),OFFSET(RiskMatrixRef,-$AO25+1,AQ25-1),"") | AV25: =IF(AND(ISNUMBER(AR25),ISNUMBER($AO25)),OFFSET(RiskMatrixRef,-$AO25+1,AR25-1),"") | AW25: =IF(AND(ISNUMBER(AS25),ISNUMBER($AO25)),OFFSET(RiskMatrixRef,-$AO25+1,AS25-1),"")
B26: 240-2 | C26: PTO to hull interface | D26: Transfer PTO and rotor loads to sub-structure | E26: 2 | F26: Loading | G26: FRP fracture | H26: 1) Loss of torque transmitted by PTO 2) Flooded PTO compartment 3) Debris broken off | I26: Manufacturing defect | J26: Normal | K26: None | L26: None | M26: 1) Vibration sensors and bearing temperature 2) Abnormal speed with respect to the wave climate and damping | N26: Dry dock repair | O26: 3 | P26: 1 | Q26: 4 | R26: 9 | S26: 8 | T26: =IF(AND(ISNUMBER(P26),ISNUMBER($O26)),OFFSET(RiskMatrixRef,-$O26+1,P26-1),"") -> Low | U26: =IF(AND(ISNUMBER(Q26),ISNUMBER($O26)),OFFSET(RiskMatrixRef,-$O26+1,Q26-1),"") -> Low | V26: =IF(AND(ISNUMBER(R26),ISNUMBER($O26)),OFFSET(RiskMatrixRef,-$O26+1,R26-1),"") -> Med | W26: =IF(AND(ISNUMBER(S26),ISNUMBER($O26)),OFFSET(RiskMatrixRef,-$O26+1,S26-1),"") -> Low | X26: 1) Cpower to provide evidence that maintenance not needed in 20 years by manufacturer for all loading cases and with use of lubrication system 2) Occurrence is low based on the assumption that the manufacturer is able to provide evidence for reliability compatible to the occurrence class. | Y26: Please include the FMECA of item 240 | AH26: =IF(AND(ISNUMBER(AD26),ISNUMBER($AC26)),OFFSET(RiskMatrixRef,-$AC26+1,AD26-1),"") | AI26: =IF(AND(ISNUMBER(AE26),ISNUMBER($AC26)),OFFSET(RiskMatrixRef,-$AC26+1,AE26-1),"") | AJ26: =IF(AND(ISNUMBER(AF26),ISNUMBER($AC26)),OFFSET(RiskMatrixRef,-$AC26+1,AF26-1),"") | AK26: =IF(AND(ISNUMBER(AG26),ISNUMBER($AC26)),OFFSET(RiskMatrixRef,-$AC26+1,AG26-1),"") | AT26: =IF(AND(ISNUMBER(AP26),ISNUMBER($AO26)),OFFSET(RiskMatrixRef,-$AO26+1,AP26-1),"") | AU26: =IF(AND(ISNUMBER(AQ26),ISNUMBER($AO26)),OFFSET(RiskMatrixRef,-$AO26+1,AQ26-1),"") | AV26: =IF(AND(ISNUMBER(AR26),ISNUMBER($AO26)),OFFSET(RiskMatrixRef,-$AO26+1,AR26-1),"") | AW26: =IF(AND(ISNUMBER(AS26),ISNUMBER($AO26)),OFFSET(RiskMatrixRef,-$AO26+1,AS26-1),"")
B27: 240-3 | C27: PTO to hull interface | D27: Transfer PTO and rotor loads to sub-structure | E27: 2 | F27: Loading | G27: FRP fracture | H27: 1) Loss of torque transmitted by PTO 2) Flooded PTO compartment 3) Debris broken off | I27: Contamination, corrosion | J27: Normal | K27: FRP material selection | L27: None | M27: 1) Vibration sensors and bearing temperature 2) Abnormal speed with respect to the wave climate and damping | N27: Dry dock repair | O27: 3 | P27: 1 | Q27: 4 | R27: 9 | S27: 8 | T27: =IF(AND(ISNUMBER(P27),ISNUMBER($O27)),OFFSET(RiskMatrixRef,-$O27+1,P27-1),"") -> Low | U27: =IF(AND(ISNUMBER(Q27),ISNUMBER($O27)),OFFSET(RiskMatrixRef,-$O27+1,Q27-1),"") -> Low | V27: =IF(AND(ISNUMBER(R27),ISNUMBER($O27)),OFFSET(RiskMatrixRef,-$O27+1,R27-1),"") -> Med | W27: =IF(AND(ISNUMBER(S27),ISNUMBER($O27)),OFFSET(RiskMatrixRef,-$O27+1,S27-1),"") -> Low | Y27: Please include the FMECA of item 240 | AH27: =IF(AND(ISNUMBER(AD27),ISNUMBER($AC27)),OFFSET(RiskMatrixRef,-$AC27+1,AD27-1),"") | AI27: =IF(AND(ISNUMBER(AE27),ISNUMBER($AC27)),OFFSET(RiskMatrixRef,-$AC27+1,AE27-1),"") | AJ27: =IF(AND(ISNUMBER(AF27),ISNUMBER($AC27)),OFFSET(RiskMatrixRef,-$AC27+1,AF27-1),"") | AK27: =IF(AND(ISNUMBER(AG27),ISNUMBER($AC27)),OFFSET(RiskMatrixRef,-$AC27+1,AG27-1),"") | AT27: =IF(AND(ISNUMBER(AP27),ISNUMBER($AO27)),OFFSET(RiskMatrixRef,-$AO27+1,AP27-1),"") | AU27: =IF(AND(ISNUMBER(AQ27),ISNUMBER($AO27)),OFFSET(RiskMatrixRef,-$AO27+1,AQ27-1),"") | AV27: =IF(AND(ISNUMBER(AR27),ISNUMBER($AO27)),OFFSET(RiskMatrixRef,-$AO27+1,AR27-1),"") | AW27: =IF(AND(ISNUMBER(AS27),ISNUMBER($AO27)),OFFSET(RiskMatrixRef,-$AO27+1,AS27-1),"")
B28: 240-4 | C28: PTO to hull interface | D28: Transfer PTO and rotor loads to sub-structure | E28: 2 | F28: Loading | G28: FRP fracture | H28: 1) Loss of torque transmitted by PTO 2) Flooded PTO compartment 3) Debris broken off | I28: Extreme loading | J28: Normal | K28: None | L28: None | M28: 1) Vibration sensors and bearing temperature 2) Abnormal speed with respect to the wave climate and damping | N28: Dry dock repair | O28: 4 | P28: 1 | Q28: 4 | R28: 9 | S28: 8 | T28: =IF(AND(ISNUMBER(P28),ISNUMBER($O28)),OFFSET(RiskMatrixRef,-$O28+1,P28-1),"") -> Low | U28: =IF(AND(ISNUMBER(Q28),ISNUMBER($O28)),OFFSET(RiskMatrixRef,-$O28+1,Q28-1),"") -> Low | V28: =IF(AND(ISNUMBER(R28),ISNUMBER($O28)),OFFSET(RiskMatrixRef,-$O28+1,R28-1),"") -> Med | W28: =IF(AND(ISNUMBER(S28),ISNUMBER($O28)),OFFSET(RiskMatrixRef,-$O28+1,S28-1),"") -> Med | X28: 1) Load derivation methodology to take into account the uncertainties in the loading due to site characterization measurements and hydrodynamic modelling. 2) Research how to measure loads during StingRAY to increase certainty of extreme load modelling | Y28: Please include the FMECA of item 240 | AH28: =IF(AND(ISNUMBER(AD28),ISNUMBER($AC28)),OFFSET(RiskMatrixRef,-$AC28+1,AD28-1),"") | AI28: =IF(AND(ISNUMBER(AE28),ISNUMBER($AC28)),OFFSET(RiskMatrixRef,-$AC28+1,AE28-1),"") | AJ28: =IF(AND(ISNUMBER(AF28),ISNUMBER($AC28)),OFFSET(RiskMatrixRef,-$AC28+1,AF28-1),"") | AK28: =IF(AND(ISNUMBER(AG28),ISNUMBER($AC28)),OFFSET(RiskMatrixRef,-$AC28+1,AG28-1),"") | AT28: =IF(AND(ISNUMBER(AP28),ISNUMBER($AO28)),OFFSET(RiskMatrixRef,-$AO28+1,AP28-1),"") | AU28: =IF(AND(ISNUMBER(AQ28),ISNUMBER($AO28)),OFFSET(RiskMatrixRef,-$AO28+1,AQ28-1),"") | AV28: =IF(AND(ISNUMBER(AR28),ISNUMBER($AO28)),OFFSET(RiskMatrixRef,-$AO28+1,AR28-1),"") | AW28: =IF(AND(ISNUMBER(AS28),ISNUMBER($AO28)),OFFSET(RiskMatrixRef,-$AO28+1,AS28-1),"")
B29: 250-1 | C29: PTO shaft | D29: Transmit torque from float drive arm to the rotor | E29: 2 | F29: Loading | G29: Steel fracture | H29: 1) Shaft broken off 2) Loss of torque transmitted to PTO 3) Damage to nacelle tube from broken off shaft and float arm | I29: Wear/fatigue | J29: Normal | K29: None | L29: None | M29: 1) Vibration sensors and bearing temperature 2) Abnormal speed with respect to the wave climate and damping | N29: Dry dock repair | O29: 4 | P29: 1 | Q29: 1 | R29: 9 | S29: 8 | T29: =IF(AND(ISNUMBER(P29),ISNUMBER($O29)),OFFSET(RiskMatrixRef,-$O29+1,P29-1),"") -> Low | U29: =IF(AND(ISNUMBER(Q29),ISNUMBER($O29)),OFFSET(RiskMatrixRef,-$O29+1,Q29-1),"") -> Low | V29: =IF(AND(ISNUMBER(R29),ISNUMBER($O29)),OFFSET(RiskMatrixRef,-$O29+1,R29-1),"") -> Med | W29: =IF(AND(ISNUMBER(S29),ISNUMBER($O29)),OFFSET(RiskMatrixRef,-$O29+1,S29-1),"") -> Med | X29: 1) Load derivation methodology to take into account the uncertainties in the loading due to site characterization measurements and hydrodynamic modelling. 2) CPower to demonstrate the derivation of loading is conservative for the site, including providing evidence from site assessment and validation of the overall loading upon deployment. | Y29: Please include the FMECA of item 250 | AH29: =IF(AND(ISNUMBER(AD29),ISNUMBER($AC29)),OFFSET(RiskMatrixRef,-$AC29+1,AD29-1),"") | AI29: =IF(AND(ISNUMBER(AE29),ISNUMBER($AC29)),OFFSET(RiskMatrixRef,-$AC29+1,AE29-1),"") | AJ29: =IF(AND(ISNUMBER(AF29),ISNUMBER($AC29)),OFFSET(RiskMatrixRef,-$AC29+1,AF29-1),"") | AK29: =IF(AND(ISNUMBER(AG29),ISNUMBER($AC29)),OFFSET(RiskMatrixRef,-$AC29+1,AG29-1),"") | AT29: =IF(AND(ISNUMBER(AP29),ISNUMBER($AO29)),OFFSET(RiskMatrixRef,-$AO29+1,AP29-1),"") | AU29: =IF(AND(ISNUMBER(AQ29),ISNUMBER($AO29)),OFFSET(RiskMatrixRef,-$AO29+1,AQ29-1),"") | AV29: =IF(AND(ISNUMBER(AR29),ISNUMBER($AO29)),OFFSET(RiskMatrixRef,-$AO29+1,AR29-1),"") | AW29: =IF(AND(ISNUMBER(AS29),ISNUMBER($AO29)),OFFSET(RiskMatrixRef,-$AO29+1,AS29-1),"")
B30: 250-2 | C30: PTO shaft | D30: Transmit torque from float drive arm to the rotor | E30: 2 | F30: Loading | G30: Steel fracture | H30: 1) Shaft broken off 2) Loss of torque transmitted to PTO 3) Damage to nacelle tube from broken off shaft and float arm | I30: Manufacturing defect | J30: Normal | K30: None | L30: None | M30: 1) Vibration sensors and bearing temperature 2) Abnormal speed with respect to the wave climate and damping | N30: Dry dock repair | O30: 3 | P30: 1 | Q30: 1 | R30: 9 | S30: 8 | T30: =IF(AND(ISNUMBER(P30),ISNUMBER($O30)),OFFSET(RiskMatrixRef,-$O30+1,P30-1),"") -> Low | U30: =IF(AND(ISNUMBER(Q30),ISNUMBER($O30)),OFFSET(RiskMatrixRef,-$O30+1,Q30-1),"") -> Low | V30: =IF(AND(ISNUMBER(R30),ISNUMBER($O30)),OFFSET(RiskMatrixRef,-$O30+1,R30-1),"") -> Med | W30: =IF(AND(ISNUMBER(S30),ISNUMBER($O30)),OFFSET(RiskMatrixRef,-$O30+1,S30-1),"") -> Low | X30: 1) Cpower to provide evidence that maintenance not needed in 20 years by manufacturer for all loading cases and with use of lubrication system 2) Occurrence is low based on the assumption that the manufacturer is able to provide evidence for reliability compatible to the occurrence class. | Y30: Please include the FMECA of item 250 | AH30: =IF(AND(ISNUMBER(AD30),ISNUMBER($AC30)),OFFSET(RiskMatrixRef,-$AC30+1,AD30-1),"") | AI30: =IF(AND(ISNUMBER(AE30),ISNUMBER($AC30)),OFFSET(RiskMatrixRef,-$AC30+1,AE30-1),"") | AJ30: =IF(AND(ISNUMBER(AF30),ISNUMBER($AC30)),OFFSET(RiskMatrixRef,-$AC30+1,AF30-1),"") | AK30: =IF(AND(ISNUMBER(AG30),ISNUMBER($AC30)),OFFSET(RiskMatrixRef,-$AC30+1,AG30-1),"") | AT30: =IF(AND(ISNUMBER(AP30),ISNUMBER($AO30)),OFFSET(RiskMatrixRef,-$AO30+1,AP30-1),"") | AU30: =IF(AND(ISNUMBER(AQ30),ISNUMBER($AO30)),OFFSET(RiskMatrixRef,-$AO30+1,AQ30-1),"") | AV30: =IF(AND(ISNUMBER(AR30),ISNUMBER($AO30)),OFFSET(RiskMatrixRef,-$AO30+1,AR30-1),"") | AW30: =IF(AND(ISNUMBER(AS30),ISNUMBER($AO30)),OFFSET(RiskMatrixRef,-$AO30+1,AS30-1),"")
B31: 250-3 | C31: PTO shaft | D31: Transmit torque from float drive arm to the rotor | E31: 2 | F31: Loading | G31: Steel fracture | H31: 1) Shaft broken off 2) Loss of torque transmitted to PTO 3) Damage to nacelle tube from broken off shaft and float arm | I31: Contamination, corrosion | J31: Normal | K31: None | L31: None | M31: 1) Vibration sensors and bearing temperature 2) Abnormal speed with respect to the wave climate and damping | N31: Dry dock repair | O31: 4 | P31: 1 | Q31: 1 | R31: 9 | S31: 8 | T31: =IF(AND(ISNUMBER(P31),ISNUMBER($O31)),OFFSET(RiskMatrixRef,-$O31+1,P31-1),"") -> Low | U31: =IF(AND(ISNUMBER(Q31),ISNUMBER($O31)),OFFSET(RiskMatrixRef,-$O31+1,Q31-1),"") -> Low | V31: =IF(AND(ISNUMBER(R31),ISNUMBER($O31)),OFFSET(RiskMatrixRef,-$O31+1,R31-1),"") -> Med | W31: =IF(AND(ISNUMBER(S31),ISNUMBER($O31)),OFFSET(RiskMatrixRef,-$O31+1,S31-1),"") -> Med | Y31: Please include the FMECA of item 250 | AH31: =IF(AND(ISNUMBER(AD31),ISNUMBER($AC31)),OFFSET(RiskMatrixRef,-$AC31+1,AD31-1),"") | AI31: =IF(AND(ISNUMBER(AE31),ISNUMBER($AC31)),OFFSET(RiskMatrixRef,-$AC31+1,AE31-1),"") | AJ31: =IF(AND(ISNUMBER(AF31),ISNUMBER($AC31)),OFFSET(RiskMatrixRef,-$AC31+1,AF31-1),"") | AK31: =IF(AND(ISNUMBER(AG31),ISNUMBER($AC31)),OFFSET(RiskMatrixRef,-$AC31+1,AG31-1),"") | AT31: =IF(AND(ISNUMBER(AP31),ISNUMBER($AO31)),OFFSET(RiskMatrixRef,-$AO31+1,AP31-1),"") | AU31: =IF(AND(ISNUMBER(AQ31),ISNUMBER($AO31)),OFFSET(RiskMatrixRef,-$AO31+1,AQ31-1),"") | AV31: =IF(AND(ISNUMBER(AR31),ISNUMBER($AO31)),OFFSET(RiskMatrixRef,-$AO31+1,AR31-1),"") | AW31: =IF(AND(ISNUMBER(AS31),ISNUMBER($AO31)),OFFSET(RiskMatrixRef,-$AO31+1,AS31-1),"")
B32: 250-4 | C32: PTO shaft | D32: Transmit torque from float drive arm to the rotor | E32: 2 | F32: Loading | G32: Steel fracture | H32: 1) Shaft broken off 2) Loss of torque transmitted to PTO 3) Damage to nacelle tube from broken off shaft and float arm | I32: Extreme loading | J32: Normal | K32: None | L32: None | M32: 1) Vibration sensors and bearing temperature 2) Abnormal speed with respect to the wave climate and damping | N32: Dry dock repair | O32: 4 | P32: 1 | Q32: 1 | R32: 9 | S32: 8 | T32: =IF(AND(ISNUMBER(P32),ISNUMBER($O32)),OFFSET(RiskMatrixRef,-$O32+1,P32-1),"") -> Low | U32: =IF(AND(ISNUMBER(Q32),ISNUMBER($O32)),OFFSET(RiskMatrixRef,-$O32+1,Q32-1),"") -> Low | V32: =IF(AND(ISNUMBER(R32),ISNUMBER($O32)),OFFSET(RiskMatrixRef,-$O32+1,R32-1),"") -> Med | W32: =IF(AND(ISNUMBER(S32),ISNUMBER($O32)),OFFSET(RiskMatrixRef,-$O32+1,S32-1),"") -> Med | X32: 1) Load derivation methodology to take into account the uncertainties in the loading due to site characterization measurements and hydrodynamic modelling. 2) Research how to measure loads during StingRAY to increase certainty of extreme load modelling | Y32: Please include the FMECA of item 250 | AH32: =IF(AND(ISNUMBER(AD32),ISNUMBER($AC32)),OFFSET(RiskMatrixRef,-$AC32+1,AD32-1),"") | AI32: =IF(AND(ISNUMBER(AE32),ISNUMBER($AC32)),OFFSET(RiskMatrixRef,-$AC32+1,AE32-1),"") | AJ32: =IF(AND(ISNUMBER(AF32),ISNUMBER($AC32)),OFFSET(RiskMatrixRef,-$AC32+1,AF32-1),"") | AK32: =IF(AND(ISNUMBER(AG32),ISNUMBER($AC32)),OFFSET(RiskMatrixRef,-$AC32+1,AG32-1),"") | AT32: =IF(AND(ISNUMBER(AP32),ISNUMBER($AO32)),OFFSET(RiskMatrixRef,-$AO32+1,AP32-1),"") | AU32: =IF(AND(ISNUMBER(AQ32),ISNUMBER($AO32)),OFFSET(RiskMatrixRef,-$AO32+1,AQ32-1),"") | AV32: =IF(AND(ISNUMBER(AR32),ISNUMBER($AO32)),OFFSET(RiskMatrixRef,-$AO32+1,AR32-1),"") | AW32: =IF(AND(ISNUMBER(AS32),ISNUMBER($AO32)),OFFSET(RiskMatrixRef,-$AO32+1,AS32-1),"")
