Workbook
Name RiskMatrixRef: '[2]set up'!$C$14
Name RiskMatrixRef: 'set up'!$C$14

Sheet Data Rights Notice

Sheet 0300 Electric Plant System
O2: Risk Ranking | AA2: Updated Risk Ranking | AM2: 2nd Updated Risk Ranking
B4: 0300 Electric Plant (Motion-to-Grid, Siemens) FMECA Table | P4: Severity Class | T4: Risk Class | AB4: Severity Class | AF4: Risk Class | AN4: Severity Class | AR4: Risk Class
B5: Risk ID | C5: Item Description | D5: Function | E5: Tech. Class | F5: Novel Aspects | G5: Failure Mode | H5: Failure Effects (Local, WEC, System) | I5: Failure Cause(s) | J5: Initial Mode of Operation | K5: Risk Reduction Design | L5: Preventative Detection | M5: Post Failure Detection | N5: Post Failure Repair Strategy (automated, manual) | O5: Occurrence | P5: Human Safety | Q5: Environment | R5: Operation | S5: Assets | T5: Human Safety | U5: Environment | V5: Operation | W5: Assets | X5: Recommended Actions | Y5: Responsible Party | Z5: Actions Taken | AA5: Occurrence | AB5: Human Safety | AC5: Environment | AD5: Operation | AE5: Assets | AF5: Human Safety | AG5: Environment | AH5: Operation | AI5: Assets | AJ5: 2nd Recommended Actions | AK5: Responsible Party (2nd) | AL5: Actions Taken (2nd) | AM5: Occurrence | AN5: Human Safety | AO5: Environment | AP5: Operation | AQ5: Assets | AR5: Human Safety | AS5: Environment | AT5: Operation | AU5: Assets | AV5: Status (open or closed) | AW5: Notes | AX5: DNV GL comments | AY5: CPwr Comment
B6: 0310-1 | C6: Motor Modules (MoMo) | D6: Control and synchronize a group of stator segments | E6: 2 | F6: Maintenance intervals; Good control of ambient and temperature; Vibrations | G6: Failed multiple (x) MoMos | H6: 1) PTO controlled shutdown 2) Operator can re-start once diagnostics determines fault is isloated and there is no further risk. Re-start PTO with: a. Partial loss of Generator, x/9 b. Reduced max torque by x/9 c. Reduced max damping d. Reduction in power due to torque limit reduction by x/9 | I6: Corrosion induced failure short circuit | J6: Normal | K6: 1) Marine rated corrosion resistance design 2) Redundant design Segmented generator, controlled by 6 groups of MoMos. | L6: 1) Visual inspection | M6: SCADA Diagnostics | N6: Manual in-situ inspection and repair | O6: 7 | P6: 1 | Q6: 1 | R6: 5 | S6: 5 | T6: =IF(AND(ISNUMBER(P6),ISNUMBER($O6)),OFFSET(RiskMatrixRef,-$O6+1,P6-1),"") -> Low | U6: =IF(AND(ISNUMBER(Q6),ISNUMBER($O6)),OFFSET(RiskMatrixRef,-$O6+1,Q6-1),"") -> Low | V6: =IF(AND(ISNUMBER(R6),ISNUMBER($O6)),OFFSET(RiskMatrixRef,-$O6+1,R6-1),"") -> Med | W6: =IF(AND(ISNUMBER(S6),ISNUMBER($O6)),OFFSET(RiskMatrixRef,-$O6+1,S6-1),"") -> Med | X6: All electrical components can be repaired in-situ. This is assuming that the repair is possible considering the limitations below: 1. Limitation due to access and size of the hatches and size of the modules to be repaired. 2. Movement of WEC 3. Commissioning/partial commissioning or testing offshore after repair or replacement of parts. Clarify between failure that requires replacement of the whole module (dry dock) and partial replacement (in-situ) Also see risk ID 0330-1 for comment on occurrence class | AF6: =IF(AND(ISNUMBER(AB6),ISNUMBER($AA6)),OFFSET(RiskMatrixRef,-$AA6+1,AB6-1),"") | AG6: =IF(AND(ISNUMBER(AC6),ISNUMBER($AA6)),OFFSET(RiskMatrixRef,-$AA6+1,AC6-1),"") | AH6: =IF(AND(ISNUMBER(AD6),ISNUMBER($AA6)),OFFSET(RiskMatrixRef,-$AA6+1,AD6-1),"") | AI6: =IF(AND(ISNUMBER(AE6),ISNUMBER($AA6)),OFFSET(RiskMatrixRef,-$AA6+1,AE6-1),"") | AR6: =IF(AND(ISNUMBER(AN6),ISNUMBER($AM6)),OFFSET(RiskMatrixRef,-$AM6+1,AN6-1),"") | AS6: =IF(AND(ISNUMBER(AO6),ISNUMBER($AM6)),OFFSET(RiskMatrixRef,-$AM6+1,AO6-1),"") | AT6: =IF(AND(ISNUMBER(AP6),ISNUMBER($AM6)),OFFSET(RiskMatrixRef,-$AM6+1,AP6-1),"") | AU6: =IF(AND(ISNUMBER(AQ6),ISNUMBER($AM6)),OFFSET(RiskMatrixRef,-$AM6+1,AQ6-1),"") | AX6: 0310: Failure mode: overspeed in motor operation possible/ to be considered? Furthermore, asynchronous or motor operation of single MoMos possible? Please clarify if overspeed during motor operation, asynchronous of motor operation of single MoMos is possible. Failure mode needs to be considered. General comment: All electrical components can be repaired in-situ. This is assuming that the repair is possible considering the limitations below: 1. Limitation due to access and size of the hatches and size of the modules to be repaired. 2. Movement of WEC 3. Commissioning/partial commissioning or testing offshore after repair or replacement of parts. Please clarify. For the failure that requires replacement of the whole module, would a dry dock repair required due to the limitations mentioned above? Also see risk ID 0330-1 for comment on occurrence class | AY6: The speed rating for the machine is 150% higher than extreme seas freewheeling worst case real seas simulation. In the case of speed being higher than set point of 100% speed (~15rpm) M2G MoMo controller can disconnect and allow freewheeling. While freewheeling, all power electronics are isolated from higher voltage potentials. The MoMos are 4-quadrant controllers, which motor or generate in either direction. An error in controller could cause issue with direction, but M2G control diagnostics would quickly alarm and fault out. Mechanically designed to either motor or generate at any given time.
B7: 0310-2 | C7: Motor Modules (MoMo) | D7: Control and synchronize a group of stator segments | E7: 2 | F7: Maintenance intervals; Good control of ambient and temperature; Vibrations | G7: Failed multiple (x) MoMos | H7: 1) PTO controlled shutdown 2) Operator can re-start once diagnostics determines fault is isloated and there is no further risk. Re-start PTO with: a. Partial loss of Generator, x/9 b. Reduced max torque by x/9 c. Reduced max damping d. Reduction in power due to torque limit reduction by x/9 | I7: Improper installation or manufacturing defect results in failure | J7: Normal | K7: 1) V&V (QC) | L7: none | M7: SCADA Diagnostics | N7: Manual in-situ inspection and repair | O7: 5 | P7: 1 | Q7: 1 | R7: 5 | S7: 5 | T7: =IF(AND(ISNUMBER(P7),ISNUMBER($O7)),OFFSET(RiskMatrixRef,-$O7+1,P7-1),"") -> Low | U7: =IF(AND(ISNUMBER(Q7),ISNUMBER($O7)),OFFSET(RiskMatrixRef,-$O7+1,Q7-1),"") -> Low | V7: =IF(AND(ISNUMBER(R7),ISNUMBER($O7)),OFFSET(RiskMatrixRef,-$O7+1,R7-1),"") -> Low | W7: =IF(AND(ISNUMBER(S7),ISNUMBER($O7)),OFFSET(RiskMatrixRef,-$O7+1,S7-1),"") -> Low | X7: It is assumed that failure due to improper installation or manufacturing faults are usually mitigated via manufacturer's in house quality control and testing of the components. Anything outisde of what is normal should be documented. | AF7: =IF(AND(ISNUMBER(AB7),ISNUMBER($AA7)),OFFSET(RiskMatrixRef,-$AA7+1,AB7-1),"") | AG7: =IF(AND(ISNUMBER(AC7),ISNUMBER($AA7)),OFFSET(RiskMatrixRef,-$AA7+1,AC7-1),"") | AH7: =IF(AND(ISNUMBER(AD7),ISNUMBER($AA7)),OFFSET(RiskMatrixRef,-$AA7+1,AD7-1),"") | AI7: =IF(AND(ISNUMBER(AE7),ISNUMBER($AA7)),OFFSET(RiskMatrixRef,-$AA7+1,AE7-1),"") | AR7: =IF(AND(ISNUMBER(AN7),ISNUMBER($AM7)),OFFSET(RiskMatrixRef,-$AM7+1,AN7-1),"") | AS7: =IF(AND(ISNUMBER(AO7),ISNUMBER($AM7)),OFFSET(RiskMatrixRef,-$AM7+1,AO7-1),"") | AT7: =IF(AND(ISNUMBER(AP7),ISNUMBER($AM7)),OFFSET(RiskMatrixRef,-$AM7+1,AP7-1),"") | AU7: =IF(AND(ISNUMBER(AQ7),ISNUMBER($AM7)),OFFSET(RiskMatrixRef,-$AM7+1,AQ7-1),"") | AX7: It is assumed that failure due to improper installation or manufacturing faults are usually mitigated via manufacturer's in house quality control and testing of the components. The failure mode should focus on quality control or testing specific to the WEC applications. Hence, the description of failure cause to be more specific to capture the failure causes unique to StingRAY device, or remove if none has been identified. | AY7: Aggreed. Most are coverd by manufacture with regards to the equipment. Installation into the WEC is performed by a 3rd party and requires additional V&V of the final complete system assembled inside of the nacelle/WEC.
B8: 0310-3 | C8: Motor Modules (MoMo) | D8: Control and synchronize a group of stator segments | E8: 2 | F8: Maintenance intervals; Good control of ambient and temperature; Vibrations | G8: Failed multiple (x) MoMos | H8: 1) PTO controlled shutdown 2) Operator can re-start once diagnostics determines fault is isloated and there is no further risk. Re-start PTO with: a. Partial loss of Generator, x/9 b. Reduced max torque by x/9 c. Reduced max damping d. Reduction in power due to torque limit reduction by x/9 | I8: Vibration and/or motion induced failure | J8: Normal | K8: 1) Vibration analysis 2) Equipment and installation designed for dynamic environment 2) Redundant design, 6 MoMo per generator | L8: none | M8: SCADA Diagnostics | N8: Manual in-situ inspection and repair | O8: 6 | P8: 1 | Q8: 1 | R8: 5 | S8: 5 | T8: =IF(AND(ISNUMBER(P8),ISNUMBER($O8)),OFFSET(RiskMatrixRef,-$O8+1,P8-1),"") -> Low | U8: =IF(AND(ISNUMBER(Q8),ISNUMBER($O8)),OFFSET(RiskMatrixRef,-$O8+1,Q8-1),"") -> Low | V8: =IF(AND(ISNUMBER(R8),ISNUMBER($O8)),OFFSET(RiskMatrixRef,-$O8+1,R8-1),"") -> Low | W8: =IF(AND(ISNUMBER(S8),ISNUMBER($O8)),OFFSET(RiskMatrixRef,-$O8+1,S8-1),"") -> Low | AF8: =IF(AND(ISNUMBER(AB8),ISNUMBER($AA8)),OFFSET(RiskMatrixRef,-$AA8+1,AB8-1),"") | AG8: =IF(AND(ISNUMBER(AC8),ISNUMBER($AA8)),OFFSET(RiskMatrixRef,-$AA8+1,AC8-1),"") | AH8: =IF(AND(ISNUMBER(AD8),ISNUMBER($AA8)),OFFSET(RiskMatrixRef,-$AA8+1,AD8-1),"") | AI8: =IF(AND(ISNUMBER(AE8),ISNUMBER($AA8)),OFFSET(RiskMatrixRef,-$AA8+1,AE8-1),"") | AR8: =IF(AND(ISNUMBER(AN8),ISNUMBER($AM8)),OFFSET(RiskMatrixRef,-$AM8+1,AN8-1),"") | AS8: =IF(AND(ISNUMBER(AO8),ISNUMBER($AM8)),OFFSET(RiskMatrixRef,-$AM8+1,AO8-1),"") | AT8: =IF(AND(ISNUMBER(AP8),ISNUMBER($AM8)),OFFSET(RiskMatrixRef,-$AM8+1,AP8-1),"") | AU8: =IF(AND(ISNUMBER(AQ8),ISNUMBER($AM8)),OFFSET(RiskMatrixRef,-$AM8+1,AQ8-1),"")
B9: 0310-4 | C9: Motor Modules (MoMo) | D9: Control and synchronize a group of stator segments | E9: 2 | F9: Maintenance intervals; Good control of ambient and temperature; Vibrations | G9: Failed multiple (x) MoMos | H9: 1) PTO controlled shutdown 2) Operator can re-start once diagnostics determines fault is isloated and there is no further risk. Re-start PTO with: a. Partial loss of Generator, x/9 b. Reduced max torque by x/9 c. Reduced max damping d. Reduction in power due to torque limit reduction by x/9 | I9: Water induced failure (non-corrosion) | J9: Normal | K9: 1) Marine rated waterproof enclosure 2) Limit number of MoMo per enclosure 3) Redundant design, 6 MoMo per generator | L9: 1) SCADA diagnostics 2) Visual inspection | M9: SCADA Diagnostics | N9: Manual in-situ inspection and repair | O9: 6 | P9: 1 | Q9: 1 | R9: 5 | S9: 5 | T9: =IF(AND(ISNUMBER(P9),ISNUMBER($O9)),OFFSET(RiskMatrixRef,-$O9+1,P9-1),"") -> Low | U9: =IF(AND(ISNUMBER(Q9),ISNUMBER($O9)),OFFSET(RiskMatrixRef,-$O9+1,Q9-1),"") -> Low | V9: =IF(AND(ISNUMBER(R9),ISNUMBER($O9)),OFFSET(RiskMatrixRef,-$O9+1,R9-1),"") -> Low | W9: =IF(AND(ISNUMBER(S9),ISNUMBER($O9)),OFFSET(RiskMatrixRef,-$O9+1,S9-1),"") -> Low | AF9: =IF(AND(ISNUMBER(AB9),ISNUMBER($AA9)),OFFSET(RiskMatrixRef,-$AA9+1,AB9-1),"") | AG9: =IF(AND(ISNUMBER(AC9),ISNUMBER($AA9)),OFFSET(RiskMatrixRef,-$AA9+1,AC9-1),"") | AH9: =IF(AND(ISNUMBER(AD9),ISNUMBER($AA9)),OFFSET(RiskMatrixRef,-$AA9+1,AD9-1),"") | AI9: =IF(AND(ISNUMBER(AE9),ISNUMBER($AA9)),OFFSET(RiskMatrixRef,-$AA9+1,AE9-1),"") | AR9: =IF(AND(ISNUMBER(AN9),ISNUMBER($AM9)),OFFSET(RiskMatrixRef,-$AM9+1,AN9-1),"") | AS9: =IF(AND(ISNUMBER(AO9),ISNUMBER($AM9)),OFFSET(RiskMatrixRef,-$AM9+1,AO9-1),"") | AT9: =IF(AND(ISNUMBER(AP9),ISNUMBER($AM9)),OFFSET(RiskMatrixRef,-$AM9+1,AP9-1),"") | AU9: =IF(AND(ISNUMBER(AQ9),ISNUMBER($AM9)),OFFSET(RiskMatrixRef,-$AM9+1,AQ9-1),"")
B10: 0310-5 | C10: Motor Modules (MoMo) | D10: Control and synchronize a group of stator segments | E10: 2 | F10: Maintenance intervals; Good control of ambient and temperature; Vibrations | G10: Failed multiple (x) MoMos in enclosure due to enclosure short | H10: 1) PTO controlled shutdown 2) Operator can re-start once diagnostics determines fault is isloated and there is no further risk. Re-start PTO with: a. Partial loss of Generator, x/9 b. Reduced max torque by x/9 c. Reduced max damping d. Reduction in power due to torque limit reduction by x/9 | I10: Electrical short (no water or corrosion) | J10: Normal | K10: 1) Marine rated waterproof enclosure 2) Limit number of MoMo per enclosure 3) Redundant design, 6 MoMo per generator | L10: 1) SCADA diagnostics 2) Visual inspection | M10: SCADA Diagnostics | N10: Manual in-situ inspection and repair | O10: 5 | P10: 1 | Q10: 1 | R10: 5 | S10: 5 | T10: =IF(AND(ISNUMBER(P10),ISNUMBER($O10)),OFFSET(RiskMatrixRef,-$O10+1,P10-1),"") -> Low | U10: =IF(AND(ISNUMBER(Q10),ISNUMBER($O10)),OFFSET(RiskMatrixRef,-$O10+1,Q10-1),"") -> Low | V10: =IF(AND(ISNUMBER(R10),ISNUMBER($O10)),OFFSET(RiskMatrixRef,-$O10+1,R10-1),"") -> Low | W10: =IF(AND(ISNUMBER(S10),ISNUMBER($O10)),OFFSET(RiskMatrixRef,-$O10+1,S10-1),"") -> Low | AF10: =IF(AND(ISNUMBER(AB10),ISNUMBER($AA10)),OFFSET(RiskMatrixRef,-$AA10+1,AB10-1),"") | AG10: =IF(AND(ISNUMBER(AC10),ISNUMBER($AA10)),OFFSET(RiskMatrixRef,-$AA10+1,AC10-1),"") | AH10: =IF(AND(ISNUMBER(AD10),ISNUMBER($AA10)),OFFSET(RiskMatrixRef,-$AA10+1,AD10-1),"") | AI10: =IF(AND(ISNUMBER(AE10),ISNUMBER($AA10)),OFFSET(RiskMatrixRef,-$AA10+1,AE10-1),"") | AR10: =IF(AND(ISNUMBER(AN10),ISNUMBER($AM10)),OFFSET(RiskMatrixRef,-$AM10+1,AN10-1),"") | AS10: =IF(AND(ISNUMBER(AO10),ISNUMBER($AM10)),OFFSET(RiskMatrixRef,-$AM10+1,AO10-1),"") | AT10: =IF(AND(ISNUMBER(AP10),ISNUMBER($AM10)),OFFSET(RiskMatrixRef,-$AM10+1,AP10-1),"") | AU10: =IF(AND(ISNUMBER(AQ10),ISNUMBER($AM10)),OFFSET(RiskMatrixRef,-$AM10+1,AQ10-1),"")
B11: 0310-6 | C11: Motor Modules (MoMo) | D11: Control and synchronize a group of stator segments | E11: 2 | F11: Maintenance intervals; Good control of ambient and temperature; Vibrations | G11: Failed single MoMo | H11: 1) PTO controlled shutdown 2) Operator can re-start once diagnostics determines fault is isloated and there is no further risk. Re-start PTO with: a. Partial loss of Generator, 1/9 b. Reduced max torque by x19 c. Reduced max damping d. Reduction in power due to torque limit reduction by 1/9 | I11: Corrosion induced failure short circuit | J11: Normal | K11: 1)Marine rated corrosion resistance design 2) Segmented generator, controlled by 9 independent MoMos. | L11: 1) SCADA diagnostics 2) Visual inspection | M11: SCADA Diagnostics | N11: Manual in-situ inspection and repair | O11: 7 | P11: 1 | Q11: 1 | R11: 4 | S11: 4 | T11: =IF(AND(ISNUMBER(P11),ISNUMBER($O11)),OFFSET(RiskMatrixRef,-$O11+1,P11-1),"") -> Low | U11: =IF(AND(ISNUMBER(Q11),ISNUMBER($O11)),OFFSET(RiskMatrixRef,-$O11+1,Q11-1),"") -> Low | V11: =IF(AND(ISNUMBER(R11),ISNUMBER($O11)),OFFSET(RiskMatrixRef,-$O11+1,R11-1),"") -> Low | W11: =IF(AND(ISNUMBER(S11),ISNUMBER($O11)),OFFSET(RiskMatrixRef,-$O11+1,S11-1),"") -> Low | AF11: =IF(AND(ISNUMBER(AB11),ISNUMBER($AA11)),OFFSET(RiskMatrixRef,-$AA11+1,AB11-1),"") | AG11: =IF(AND(ISNUMBER(AC11),ISNUMBER($AA11)),OFFSET(RiskMatrixRef,-$AA11+1,AC11-1),"") | AH11: =IF(AND(ISNUMBER(AD11),ISNUMBER($AA11)),OFFSET(RiskMatrixRef,-$AA11+1,AD11-1),"") | AI11: =IF(AND(ISNUMBER(AE11),ISNUMBER($AA11)),OFFSET(RiskMatrixRef,-$AA11+1,AE11-1),"") | AR11: =IF(AND(ISNUMBER(AN11),ISNUMBER($AM11)),OFFSET(RiskMatrixRef,-$AM11+1,AN11-1),"") | AS11: =IF(AND(ISNUMBER(AO11),ISNUMBER($AM11)),OFFSET(RiskMatrixRef,-$AM11+1,AO11-1),"") | AT11: =IF(AND(ISNUMBER(AP11),ISNUMBER($AM11)),OFFSET(RiskMatrixRef,-$AM11+1,AP11-1),"") | AU11: =IF(AND(ISNUMBER(AQ11),ISNUMBER($AM11)),OFFSET(RiskMatrixRef,-$AM11+1,AQ11-1),"") | AW11: Is there enough current capacity in the MoMos to make up for the reduced torque limit? Depend on final design | AX11: See comment in Risk ID 0330-1 | AY11: OK
B12: 0310-7 | C12: Motor Modules (MoMo) | D12: Control and synchronize a group of stator segments | E12: 2 | F12: Maintenance intervals; Good control of ambient and temperature; Vibrations | G12: Failed single MoMo | H12: 1) PTO controlled shutdown 2) Operator can re-start once diagnostics determines fault is isloated and there is no further risk. Re-start PTO with: a. Partial loss of Generator, 1/9 b. Reduced max torque by x19 c. Reduced max damping d. Reduction in power due to torque limit reduction by 1/9 | I12: Improper installation or manufacturing defect results in failure | J12: Normal | K12: 1) V&V (QC) 2) Segmented generator, controlled by 9 independent MoMos. | L12: none | M12: SCADA Diagnostics | N12: Manual in-situ inspection and repair | O12: 6 | P12: 1 | Q12: 1 | R12: 4 | S12: 4 | T12: =IF(AND(ISNUMBER(P12),ISNUMBER($O12)),OFFSET(RiskMatrixRef,-$O12+1,P12-1),"") -> Low | U12: =IF(AND(ISNUMBER(Q12),ISNUMBER($O12)),OFFSET(RiskMatrixRef,-$O12+1,Q12-1),"") -> Low | V12: =IF(AND(ISNUMBER(R12),ISNUMBER($O12)),OFFSET(RiskMatrixRef,-$O12+1,R12-1),"") -> Low | W12: =IF(AND(ISNUMBER(S12),ISNUMBER($O12)),OFFSET(RiskMatrixRef,-$O12+1,S12-1),"") -> Low | AF12: =IF(AND(ISNUMBER(AB12),ISNUMBER($AA12)),OFFSET(RiskMatrixRef,-$AA12+1,AB12-1),"") | AG12: =IF(AND(ISNUMBER(AC12),ISNUMBER($AA12)),OFFSET(RiskMatrixRef,-$AA12+1,AC12-1),"") | AH12: =IF(AND(ISNUMBER(AD12),ISNUMBER($AA12)),OFFSET(RiskMatrixRef,-$AA12+1,AD12-1),"") | AI12: =IF(AND(ISNUMBER(AE12),ISNUMBER($AA12)),OFFSET(RiskMatrixRef,-$AA12+1,AE12-1),"") | AR12: =IF(AND(ISNUMBER(AN12),ISNUMBER($AM12)),OFFSET(RiskMatrixRef,-$AM12+1,AN12-1),"") | AS12: =IF(AND(ISNUMBER(AO12),ISNUMBER($AM12)),OFFSET(RiskMatrixRef,-$AM12+1,AO12-1),"") | AT12: =IF(AND(ISNUMBER(AP12),ISNUMBER($AM12)),OFFSET(RiskMatrixRef,-$AM12+1,AP12-1),"") | AU12: =IF(AND(ISNUMBER(AQ12),ISNUMBER($AM12)),OFFSET(RiskMatrixRef,-$AM12+1,AQ12-1),"") | AX12: See comment in Risk ID 0310-2 | AY12: OK
B13: 0310-8 | C13: Motor Modules (MoMo) | D13: Control and synchronize a group of stator segments | E13: 1 2 | F13: none Maintenance intervals; Good control of ambient and temperature; Vibrations | G13: Failed single MoMo | H13: 1) PTO controlled shutdown 2) Operator can re-start once diagnostics determines fault is isloated and there is no further risk. Re-start PTO with: a. Partial loss of Generator, 1/9 b. Reduced max torque by x19 c. Reduced max damping d. Reduction in power due to torque limit reduction by 1/9 | I13: Vibration and/or motion induced failure | J13: Normal | K13: 1) Vibration analysis 2) Equipment and installation designed for dynamic environment 2) Segmented generator, controlled by 9 independent MoMos. | L13: 1) Visual inspection | M13: SCADA Diagnostics | N13: Manual in-situ inspection and repair | O13: 7 | P13: 1 | Q13: 1 | R13: 4 | S13: 4 | T13: =IF(AND(ISNUMBER(P13),ISNUMBER($O13)),OFFSET(RiskMatrixRef,-$O13+1,P13-1),"") -> Low | U13: =IF(AND(ISNUMBER(Q13),ISNUMBER($O13)),OFFSET(RiskMatrixRef,-$O13+1,Q13-1),"") -> Low | V13: =IF(AND(ISNUMBER(R13),ISNUMBER($O13)),OFFSET(RiskMatrixRef,-$O13+1,R13-1),"") -> Low | W13: =IF(AND(ISNUMBER(S13),ISNUMBER($O13)),OFFSET(RiskMatrixRef,-$O13+1,S13-1),"") -> Low | X13: Check vibration ratings and standards, use LandRAY vibration data | AF13: =IF(AND(ISNUMBER(AB13),ISNUMBER($AA13)),OFFSET(RiskMatrixRef,-$AA13+1,AB13-1),"") | AG13: =IF(AND(ISNUMBER(AC13),ISNUMBER($AA13)),OFFSET(RiskMatrixRef,-$AA13+1,AC13-1),"") | AH13: =IF(AND(ISNUMBER(AD13),ISNUMBER($AA13)),OFFSET(RiskMatrixRef,-$AA13+1,AD13-1),"") | AI13: =IF(AND(ISNUMBER(AE13),ISNUMBER($AA13)),OFFSET(RiskMatrixRef,-$AA13+1,AE13-1),"") | AR13: =IF(AND(ISNUMBER(AN13),ISNUMBER($AM13)),OFFSET(RiskMatrixRef,-$AM13+1,AN13-1),"") | AS13: =IF(AND(ISNUMBER(AO13),ISNUMBER($AM13)),OFFSET(RiskMatrixRef,-$AM13+1,AO13-1),"") | AT13: =IF(AND(ISNUMBER(AP13),ISNUMBER($AM13)),OFFSET(RiskMatrixRef,-$AM13+1,AP13-1),"") | AU13: =IF(AND(ISNUMBER(AQ13),ISNUMBER($AM13)),OFFSET(RiskMatrixRef,-$AM13+1,AQ13-1),"")
B14: 0310-9 | C14: Motor Modules (MoMo) | D14: Control and synchronize a group of stator segments | E14: 2 | F14: Maintenance intervals; Good control of ambient and temperature; Vibrations | G14: Failed single MoMo | H14: 1) PTO controlled shutdown 2) Operator can re-start once diagnostics determines fault is isloated and there is no further risk. Re-start PTO with: a. Partial loss of Generator, 1/9 b. Reduced max torque by x19 c. Reduced max damping d. Reduction in power due to torque limit reduction by 1/9 | I14: Water induced failure (non-corrosion) | J14: Normal | K14: 1) Marine rated waterproof enclosure 2) Limit number of MoMo per enclosure 3) Segmented generator, controlled by 9 independent MoMos. | L14: 1) SCADA diagnostics 2) Visual inspection | M14: SCADA Diagnostics | N14: Manual in-situ inspection and repair | O14: 7 | P14: 1 | Q14: 1 | R14: 4 | S14: 4 | T14: =IF(AND(ISNUMBER(P14),ISNUMBER($O14)),OFFSET(RiskMatrixRef,-$O14+1,P14-1),"") -> Low | U14: =IF(AND(ISNUMBER(Q14),ISNUMBER($O14)),OFFSET(RiskMatrixRef,-$O14+1,Q14-1),"") -> Low | V14: =IF(AND(ISNUMBER(R14),ISNUMBER($O14)),OFFSET(RiskMatrixRef,-$O14+1,R14-1),"") -> Low | W14: =IF(AND(ISNUMBER(S14),ISNUMBER($O14)),OFFSET(RiskMatrixRef,-$O14+1,S14-1),"") -> Low | X14: Dry control room standards during installation and maintenance | AF14: =IF(AND(ISNUMBER(AB14),ISNUMBER($AA14)),OFFSET(RiskMatrixRef,-$AA14+1,AB14-1),"") | AG14: =IF(AND(ISNUMBER(AC14),ISNUMBER($AA14)),OFFSET(RiskMatrixRef,-$AA14+1,AC14-1),"") | AH14: =IF(AND(ISNUMBER(AD14),ISNUMBER($AA14)),OFFSET(RiskMatrixRef,-$AA14+1,AD14-1),"") | AI14: =IF(AND(ISNUMBER(AE14),ISNUMBER($AA14)),OFFSET(RiskMatrixRef,-$AA14+1,AE14-1),"") | AR14: =IF(AND(ISNUMBER(AN14),ISNUMBER($AM14)),OFFSET(RiskMatrixRef,-$AM14+1,AN14-1),"") | AS14: =IF(AND(ISNUMBER(AO14),ISNUMBER($AM14)),OFFSET(RiskMatrixRef,-$AM14+1,AO14-1),"") | AT14: =IF(AND(ISNUMBER(AP14),ISNUMBER($AM14)),OFFSET(RiskMatrixRef,-$AM14+1,AP14-1),"") | AU14: =IF(AND(ISNUMBER(AQ14),ISNUMBER($AM14)),OFFSET(RiskMatrixRef,-$AM14+1,AQ14-1),"")
B15: 0320-1 | C15: DC Bus | D15: Electrical connection between MoMos, ALMs, Energy Storage, and Emergency resistor | E15: 2 | F15: Maintenance intervals; Good control of ambient and temperature; Vibrations | G15: Short DC bus | H15: 1) PTO controlled shutdown 2) Loss of AC power generation 2) Loss of power production from one PTO 3) Open DC cross connect to isolate port from stbd PTO | I15: Corrosion induced failure short circuit | J15: Normal | K15: 1)Marine rated corrosion resistance design 2) Independent buses, one for each PTO | L15: 1) Visual inspection | M15: SCADA Diagnostics | N15: Manual in-situ inspection and repair | O15: 7 | P15: 1 | Q15: 1 | R15: 5 | S15: 5 | T15: =IF(AND(ISNUMBER(P15),ISNUMBER($O15)),OFFSET(RiskMatrixRef,-$O15+1,P15-1),"") -> Low | U15: =IF(AND(ISNUMBER(Q15),ISNUMBER($O15)),OFFSET(RiskMatrixRef,-$O15+1,Q15-1),"") -> Low | V15: =IF(AND(ISNUMBER(R15),ISNUMBER($O15)),OFFSET(RiskMatrixRef,-$O15+1,R15-1),"") -> Med | W15: =IF(AND(ISNUMBER(S15),ISNUMBER($O15)),OFFSET(RiskMatrixRef,-$O15+1,S15-1),"") -> Med | X15: Use watertight cable, connectors and enclosures. Route cable for no rubbing abrasion. | AF15: =IF(AND(ISNUMBER(AB15),ISNUMBER($AA15)),OFFSET(RiskMatrixRef,-$AA15+1,AB15-1),"") | AG15: =IF(AND(ISNUMBER(AC15),ISNUMBER($AA15)),OFFSET(RiskMatrixRef,-$AA15+1,AC15-1),"") | AH15: =IF(AND(ISNUMBER(AD15),ISNUMBER($AA15)),OFFSET(RiskMatrixRef,-$AA15+1,AD15-1),"") | AI15: =IF(AND(ISNUMBER(AE15),ISNUMBER($AA15)),OFFSET(RiskMatrixRef,-$AA15+1,AE15-1),"") | AR15: =IF(AND(ISNUMBER(AN15),ISNUMBER($AM15)),OFFSET(RiskMatrixRef,-$AM15+1,AN15-1),"") | AS15: =IF(AND(ISNUMBER(AO15),ISNUMBER($AM15)),OFFSET(RiskMatrixRef,-$AM15+1,AO15-1),"") | AT15: =IF(AND(ISNUMBER(AP15),ISNUMBER($AM15)),OFFSET(RiskMatrixRef,-$AM15+1,AP15-1),"") | AU15: =IF(AND(ISNUMBER(AQ15),ISNUMBER($AM15)),OFFSET(RiskMatrixRef,-$AM15+1,AQ15-1),"") | AX15: See comment in Risk ID 0330-1 | AY15: OK
B16: 0320-2 | C16: DC Bus | D16: Electrical connection between MoMos, ALMs, Energy Storage, and Emergency resistor | E16: 2 | F16: Maintenance intervals; Good control of ambient and temperature; Vibrations | G16: Short DC bus | H16: 1) PTO controlled shutdown 2) Loss of AC power generation 2) Loss of power production from one PTO 3) Open DC cross connect to isolate port from stbd PTO | I16: Improper installation or manufacturing defect results in failure | J16: Normal | K16: 1) V&V (QC) 2) Independent buses, one for each PTO | L16: none | M16: SCADA Diagnostics | N16: Manual in-situ inspection and repair | O16: 5 | P16: 1 | Q16: 1 | R16: 5 | S16: 5 | T16: =IF(AND(ISNUMBER(P16),ISNUMBER($O16)),OFFSET(RiskMatrixRef,-$O16+1,P16-1),"") -> Low | U16: =IF(AND(ISNUMBER(Q16),ISNUMBER($O16)),OFFSET(RiskMatrixRef,-$O16+1,Q16-1),"") -> Low | V16: =IF(AND(ISNUMBER(R16),ISNUMBER($O16)),OFFSET(RiskMatrixRef,-$O16+1,R16-1),"") -> Low | W16: =IF(AND(ISNUMBER(S16),ISNUMBER($O16)),OFFSET(RiskMatrixRef,-$O16+1,S16-1),"") -> Low | AF16: =IF(AND(ISNUMBER(AB16),ISNUMBER($AA16)),OFFSET(RiskMatrixRef,-$AA16+1,AB16-1),"") | AG16: =IF(AND(ISNUMBER(AC16),ISNUMBER($AA16)),OFFSET(RiskMatrixRef,-$AA16+1,AC16-1),"") | AH16: =IF(AND(ISNUMBER(AD16),ISNUMBER($AA16)),OFFSET(RiskMatrixRef,-$AA16+1,AD16-1),"") | AI16: =IF(AND(ISNUMBER(AE16),ISNUMBER($AA16)),OFFSET(RiskMatrixRef,-$AA16+1,AE16-1),"") | AR16: =IF(AND(ISNUMBER(AN16),ISNUMBER($AM16)),OFFSET(RiskMatrixRef,-$AM16+1,AN16-1),"") | AS16: =IF(AND(ISNUMBER(AO16),ISNUMBER($AM16)),OFFSET(RiskMatrixRef,-$AM16+1,AO16-1),"") | AT16: =IF(AND(ISNUMBER(AP16),ISNUMBER($AM16)),OFFSET(RiskMatrixRef,-$AM16+1,AP16-1),"") | AU16: =IF(AND(ISNUMBER(AQ16),ISNUMBER($AM16)),OFFSET(RiskMatrixRef,-$AM16+1,AQ16-1),"") | AX16: See comment in Risk ID 0310-2 | AY16: OK
B17: 0320-3 | C17: DC Bus | D17: Electrical connection between MoMos, ALMs, Energy Storage, and Emergency resistor | E17: 2 | F17: Maintenance intervals; Good control of ambient and temperature; Vibrations | G17: Short DC bus | H17: 1) PTO controlled shutdown 2) Loss of AC power generation 2) Loss of power production from one PTO 3) Open DC cross connect to isolate port from stbd PTO | I17: Vibration and/or motion induced failure | J17: Normal | K17: 1) Vibration analysis 2) Equipment and installation designed for dynamic environment 3) Independent buses, one for each PTO | L17: none | M17: SCADA Diagnostics | N17: Manual in-situ inspection and repair | O17: 5 | P17: 1 | Q17: 1 | R17: 5 | S17: 5 | T17: =IF(AND(ISNUMBER(P17),ISNUMBER($O17)),OFFSET(RiskMatrixRef,-$O17+1,P17-1),"") -> Low | U17: =IF(AND(ISNUMBER(Q17),ISNUMBER($O17)),OFFSET(RiskMatrixRef,-$O17+1,Q17-1),"") -> Low | V17: =IF(AND(ISNUMBER(R17),ISNUMBER($O17)),OFFSET(RiskMatrixRef,-$O17+1,R17-1),"") -> Low | W17: =IF(AND(ISNUMBER(S17),ISNUMBER($O17)),OFFSET(RiskMatrixRef,-$O17+1,S17-1),"") -> Low | X17: Vibration induced failure is normally expected to have occurrence class 7, same as that for MoMo. Given the novelty, the probability of failure remains uncertain unless manufacturer is able to provide evidence or data to show that the reliability of the component is compatible to the occurrence class assigned. Therefore, it is recommended to use severity class 7 such that a recommended action is given to ensure the risks are controlled. | AF17: =IF(AND(ISNUMBER(AB17),ISNUMBER($AA17)),OFFSET(RiskMatrixRef,-$AA17+1,AB17-1),"") | AG17: =IF(AND(ISNUMBER(AC17),ISNUMBER($AA17)),OFFSET(RiskMatrixRef,-$AA17+1,AC17-1),"") | AH17: =IF(AND(ISNUMBER(AD17),ISNUMBER($AA17)),OFFSET(RiskMatrixRef,-$AA17+1,AD17-1),"") | AI17: =IF(AND(ISNUMBER(AE17),ISNUMBER($AA17)),OFFSET(RiskMatrixRef,-$AA17+1,AE17-1),"") | AR17: =IF(AND(ISNUMBER(AN17),ISNUMBER($AM17)),OFFSET(RiskMatrixRef,-$AM17+1,AN17-1),"") | AS17: =IF(AND(ISNUMBER(AO17),ISNUMBER($AM17)),OFFSET(RiskMatrixRef,-$AM17+1,AO17-1),"") | AT17: =IF(AND(ISNUMBER(AP17),ISNUMBER($AM17)),OFFSET(RiskMatrixRef,-$AM17+1,AP17-1),"") | AU17: =IF(AND(ISNUMBER(AQ17),ISNUMBER($AM17)),OFFSET(RiskMatrixRef,-$AM17+1,AQ17-1),"") | AX17: Please provide the basis of using different occurrence class for failure cause "Vibration and/or motion induced failure" for all the components in the electric plant. Vibration induced failure is normally expected to have occurrence class 7, same as that for MoMo. Given the novelty, the probability of failure remains uncertain unless manufacturer is able to provide evidence or data to show that the reliability of the component is compatible to the occurrence class assigned. Therefore, it is recommended to use severity class 7 such that a recommended action is given to ensure the risks are controlled. | AY17: Agreed. Vibration analysis at mounting location and design to incorporate vibration mitigation to reduce risk of a vibration induced failure or fault shall be included in all 0300 engineering design requirements.
B18: 0320-4 | C18: DC Bus | D18: Electrical connection between MoMos, ALMs, Energy Storage, and Emergency resistor | E18: 2 | F18: Maintenance intervals; Good control of ambient and temperature; Vibrations | G18: Short DC bus | H18: 1) PTO controlled shutdown 2) Loss of AC power generation 2) Loss of power production from one PTO 3) Open DC cross connect to isolate port from stbd PTO | I18: Water induced failure (non-corrosion) | J18: Normal | K18: 1) Dry control room 2) Marine rated design 3) Independent buses, one for each PTO | L18: 1) SCADA diagnostics 2) Visual inspection | M18: SCADA Diagnostics | N18: Manual in-situ inspection and repair | O18: 7 | P18: 1 | Q18: 1 | R18: 5 | S18: 5 | T18: =IF(AND(ISNUMBER(P18),ISNUMBER($O18)),OFFSET(RiskMatrixRef,-$O18+1,P18-1),"") -> Low | U18: =IF(AND(ISNUMBER(Q18),ISNUMBER($O18)),OFFSET(RiskMatrixRef,-$O18+1,Q18-1),"") -> Low | V18: =IF(AND(ISNUMBER(R18),ISNUMBER($O18)),OFFSET(RiskMatrixRef,-$O18+1,R18-1),"") -> Med | W18: =IF(AND(ISNUMBER(S18),ISNUMBER($O18)),OFFSET(RiskMatrixRef,-$O18+1,S18-1),"") -> Med | AF18: =IF(AND(ISNUMBER(AB18),ISNUMBER($AA18)),OFFSET(RiskMatrixRef,-$AA18+1,AB18-1),"") | AG18: =IF(AND(ISNUMBER(AC18),ISNUMBER($AA18)),OFFSET(RiskMatrixRef,-$AA18+1,AC18-1),"") | AH18: =IF(AND(ISNUMBER(AD18),ISNUMBER($AA18)),OFFSET(RiskMatrixRef,-$AA18+1,AD18-1),"") | AI18: =IF(AND(ISNUMBER(AE18),ISNUMBER($AA18)),OFFSET(RiskMatrixRef,-$AA18+1,AE18-1),"") | AR18: =IF(AND(ISNUMBER(AN18),ISNUMBER($AM18)),OFFSET(RiskMatrixRef,-$AM18+1,AN18-1),"") | AS18: =IF(AND(ISNUMBER(AO18),ISNUMBER($AM18)),OFFSET(RiskMatrixRef,-$AM18+1,AO18-1),"") | AT18: =IF(AND(ISNUMBER(AP18),ISNUMBER($AM18)),OFFSET(RiskMatrixRef,-$AM18+1,AP18-1),"") | AU18: =IF(AND(ISNUMBER(AQ18),ISNUMBER($AM18)),OFFSET(RiskMatrixRef,-$AM18+1,AQ18-1),"") | AW18: DC cross-connection is an electrical DC connection linking all MoMo to a signal DC bus. This allows for better power smoothing and increases the reliability of power production. Port/Stbd MoMo power production can therfore be fed to either port/stbd ALM+AIM to grid. | AX18: Please clarify the "Open DC cross connect" failure effect | AY18: OK add notes
B19: 0320-5 | C19: DC Bus | D19: Electrical connection between MoMos, ALMs, Energy Storage, and Emergency resistor | E19: 2 | F19: Maintenance intervals; Good control of ambient and temperature; Vibrations | G19: Open DC bus | H19: 1) PTO controlled shutdown 2) Loss of AC power generation 2) Loss of power production from one PTO 3) Open DC cross connect to isolate port from stbd PTO | I19: Corrosion induced failure short circuit | J19: Normal | K19: 1)Marine rated corrosion resistance design 2) Independent buses, one for each PTO | L19: 1) Visual inspection | M19: SCADA Diagnostics | N19: Manual in-situ inspection and repair | O19: 7 | P19: 1 | Q19: 1 | R19: 5 | S19: 5 | T19: =IF(AND(ISNUMBER(P19),ISNUMBER($O19)),OFFSET(RiskMatrixRef,-$O19+1,P19-1),"") -> Low | U19: =IF(AND(ISNUMBER(Q19),ISNUMBER($O19)),OFFSET(RiskMatrixRef,-$O19+1,Q19-1),"") -> Low | V19: =IF(AND(ISNUMBER(R19),ISNUMBER($O19)),OFFSET(RiskMatrixRef,-$O19+1,R19-1),"") -> Med | W19: =IF(AND(ISNUMBER(S19),ISNUMBER($O19)),OFFSET(RiskMatrixRef,-$O19+1,S19-1),"") -> Med | X19: Use watertight cable, connectors and enclosures. Route cable for no rubbing abrasion. | AF19: =IF(AND(ISNUMBER(AB19),ISNUMBER($AA19)),OFFSET(RiskMatrixRef,-$AA19+1,AB19-1),"") | AG19: =IF(AND(ISNUMBER(AC19),ISNUMBER($AA19)),OFFSET(RiskMatrixRef,-$AA19+1,AC19-1),"") | AH19: =IF(AND(ISNUMBER(AD19),ISNUMBER($AA19)),OFFSET(RiskMatrixRef,-$AA19+1,AD19-1),"") | AI19: =IF(AND(ISNUMBER(AE19),ISNUMBER($AA19)),OFFSET(RiskMatrixRef,-$AA19+1,AE19-1),"") | AR19: =IF(AND(ISNUMBER(AN19),ISNUMBER($AM19)),OFFSET(RiskMatrixRef,-$AM19+1,AN19-1),"") | AS19: =IF(AND(ISNUMBER(AO19),ISNUMBER($AM19)),OFFSET(RiskMatrixRef,-$AM19+1,AO19-1),"") | AT19: =IF(AND(ISNUMBER(AP19),ISNUMBER($AM19)),OFFSET(RiskMatrixRef,-$AM19+1,AP19-1),"") | AU19: =IF(AND(ISNUMBER(AQ19),ISNUMBER($AM19)),OFFSET(RiskMatrixRef,-$AM19+1,AQ19-1),"") | AX19: See comment in Risk ID 0330-1 | AY19: OK, but disagree with increased occurrence the blanketed response using "FLS" for reasoning - Explain how to relate Fatigue Limit State to the hard mounted electrical bus?
B20: 0320-6 | C20: DC Bus | D20: Electrical connection between MoMos, ALMs, Energy Storage, and Emergency resistor | E20: 2 | F20: Maintenance intervals; Good control of ambient and temperature; Vibrations | G20: Open DC bus | H20: 1) PTO controlled shutdown 2) Loss of AC power generation 2) Loss of power production from one PTO 3) Open DC cross connect to isolate port from stbd PTO | I20: Improper installation or manufacturing defect results in failure | J20: Normal | K20: 1) V&V (QC) 2) Independent buses, one for each PTO | L20: none | M20: SCADA Diagnostics | N20: Manual in-situ inspection and repair | O20: 5 | P20: 1 | Q20: 1 | R20: 5 | S20: 5 | T20: =IF(AND(ISNUMBER(P20),ISNUMBER($O20)),OFFSET(RiskMatrixRef,-$O20+1,P20-1),"") -> Low | U20: =IF(AND(ISNUMBER(Q20),ISNUMBER($O20)),OFFSET(RiskMatrixRef,-$O20+1,Q20-1),"") -> Low | V20: =IF(AND(ISNUMBER(R20),ISNUMBER($O20)),OFFSET(RiskMatrixRef,-$O20+1,R20-1),"") -> Low | W20: =IF(AND(ISNUMBER(S20),ISNUMBER($O20)),OFFSET(RiskMatrixRef,-$O20+1,S20-1),"") -> Low | AF20: =IF(AND(ISNUMBER(AB20),ISNUMBER($AA20)),OFFSET(RiskMatrixRef,-$AA20+1,AB20-1),"") | AG20: =IF(AND(ISNUMBER(AC20),ISNUMBER($AA20)),OFFSET(RiskMatrixRef,-$AA20+1,AC20-1),"") | AH20: =IF(AND(ISNUMBER(AD20),ISNUMBER($AA20)),OFFSET(RiskMatrixRef,-$AA20+1,AD20-1),"") | AI20: =IF(AND(ISNUMBER(AE20),ISNUMBER($AA20)),OFFSET(RiskMatrixRef,-$AA20+1,AE20-1),"") | AR20: =IF(AND(ISNUMBER(AN20),ISNUMBER($AM20)),OFFSET(RiskMatrixRef,-$AM20+1,AN20-1),"") | AS20: =IF(AND(ISNUMBER(AO20),ISNUMBER($AM20)),OFFSET(RiskMatrixRef,-$AM20+1,AO20-1),"") | AT20: =IF(AND(ISNUMBER(AP20),ISNUMBER($AM20)),OFFSET(RiskMatrixRef,-$AM20+1,AP20-1),"") | AU20: =IF(AND(ISNUMBER(AQ20),ISNUMBER($AM20)),OFFSET(RiskMatrixRef,-$AM20+1,AQ20-1),"") | AX20: See comment in Risk ID 0310-2 | AY20: OK
B21: 0320-7 | C21: DC Bus | D21: Electrical connection between MoMos, ALMs, Energy Storage, and Emergency resistor | E21: 2 | F21: Maintenance intervals; Good control of ambient and temperature; Vibrations | G21: Open DC bus | H21: 1) PTO controlled shutdown 2) Loss of AC power generation 2) Loss of power production from one PTO 3) Open DC cross connect to isolate port from stbd PTO | I21: Vibration and/or motion induced failure | J21: Normal | K21: 1) Vibration analysis 2) Equipment and installation designed for dynamic environment 3) Independent buses, one for each PTO | L21: none | M21: SCADA Diagnostics | N21: Manual in-situ inspection and repair | O21: 5 | P21: 1 | Q21: 1 | R21: 5 | S21: 5 | T21: =IF(AND(ISNUMBER(P21),ISNUMBER($O21)),OFFSET(RiskMatrixRef,-$O21+1,P21-1),"") -> Low | U21: =IF(AND(ISNUMBER(Q21),ISNUMBER($O21)),OFFSET(RiskMatrixRef,-$O21+1,Q21-1),"") -> Low | V21: =IF(AND(ISNUMBER(R21),ISNUMBER($O21)),OFFSET(RiskMatrixRef,-$O21+1,R21-1),"") -> Low | W21: =IF(AND(ISNUMBER(S21),ISNUMBER($O21)),OFFSET(RiskMatrixRef,-$O21+1,S21-1),"") -> Low | AF21: =IF(AND(ISNUMBER(AB21),ISNUMBER($AA21)),OFFSET(RiskMatrixRef,-$AA21+1,AB21-1),"") | AG21: =IF(AND(ISNUMBER(AC21),ISNUMBER($AA21)),OFFSET(RiskMatrixRef,-$AA21+1,AC21-1),"") | AH21: =IF(AND(ISNUMBER(AD21),ISNUMBER($AA21)),OFFSET(RiskMatrixRef,-$AA21+1,AD21-1),"") | AI21: =IF(AND(ISNUMBER(AE21),ISNUMBER($AA21)),OFFSET(RiskMatrixRef,-$AA21+1,AE21-1),"") | AR21: =IF(AND(ISNUMBER(AN21),ISNUMBER($AM21)),OFFSET(RiskMatrixRef,-$AM21+1,AN21-1),"") | AS21: =IF(AND(ISNUMBER(AO21),ISNUMBER($AM21)),OFFSET(RiskMatrixRef,-$AM21+1,AO21-1),"") | AT21: =IF(AND(ISNUMBER(AP21),ISNUMBER($AM21)),OFFSET(RiskMatrixRef,-$AM21+1,AP21-1),"") | AU21: =IF(AND(ISNUMBER(AQ21),ISNUMBER($AM21)),OFFSET(RiskMatrixRef,-$AM21+1,AQ21-1),"") | AX21: see comment in risk 0320-3 | AY21: OK
B22: 0320-8 | C22: DC Bus | D22: Electrical connection between MoMos, ALMs, Energy Storage, and Emergency resistor | E22: 3 | F22: Maintenance intervals; Good control of ambient and temperature; Vibrations | G22: Short DC bus | H22: 1) PTO controlled shutdown 2) Loss of AC power generation 2) Loss of power production from one PTO 3) Open DC cross connect to isolate port from stbd PTO | I22: Corrosion induced failure short circuit | J22: Normal | K22: 1)Marine rated corrosion resistance design 2) Independent buses, one for each PTO | L22: 1) Visual inspection | M22: SCADA Diagnostics | N22: Manual in-situ inspection and repair | O22: 5.2857143 | P22: 1 | Q22: 1 | R22: 5 | S22: 5 | T22: =IF(AND(ISNUMBER(P22),ISNUMBER($O22)),OFFSET(RiskMatrixRef,-$O22+1,P22-1),"") -> Low | U22: =IF(AND(ISNUMBER(Q22),ISNUMBER($O22)),OFFSET(RiskMatrixRef,-$O22+1,Q22-1),"") -> Low | V22: =IF(AND(ISNUMBER(R22),ISNUMBER($O22)),OFFSET(RiskMatrixRef,-$O22+1,R22-1),"") -> Low | W22: =IF(AND(ISNUMBER(S22),ISNUMBER($O22)),OFFSET(RiskMatrixRef,-$O22+1,S22-1),"") -> Low | X22: Use watertight cable, connectors and enclosures. Route cable for no rubbing abrasion. | AF22: =IF(AND(ISNUMBER(AB22),ISNUMBER($AA22)),OFFSET(RiskMatrixRef,-$AA22+1,AB22-1),"") | AG22: =IF(AND(ISNUMBER(AC22),ISNUMBER($AA22)),OFFSET(RiskMatrixRef,-$AA22+1,AC22-1),"") | AH22: =IF(AND(ISNUMBER(AD22),ISNUMBER($AA22)),OFFSET(RiskMatrixRef,-$AA22+1,AD22-1),"") | AI22: =IF(AND(ISNUMBER(AE22),ISNUMBER($AA22)),OFFSET(RiskMatrixRef,-$AA22+1,AE22-1),"") | AR22: =IF(AND(ISNUMBER(AN22),ISNUMBER($AM22)),OFFSET(RiskMatrixRef,-$AM22+1,AN22-1),"") | AS22: =IF(AND(ISNUMBER(AO22),ISNUMBER($AM22)),OFFSET(RiskMatrixRef,-$AM22+1,AO22-1),"") | AT22: =IF(AND(ISNUMBER(AP22),ISNUMBER($AM22)),OFFSET(RiskMatrixRef,-$AM22+1,AP22-1),"") | AU22: =IF(AND(ISNUMBER(AQ22),ISNUMBER($AM22)),OFFSET(RiskMatrixRef,-$AM22+1,AQ22-1),"") | AX22: See comment in Risk ID 0330-2 | AY22: OK
B23: 0320-9 | C23: DC Bus | D23: Electrical connection between MoMos, ALMs, Energy Storage, and Emergency resistor | E23: 4 | F23: Maintenance intervals; Good control of ambient and temperature; Vibrations | G23: Short DC bus | H23: 1) PTO controlled shutdown 2) Loss of AC power generation 2) Loss of power production from one PTO 3) Open DC cross connect to isolate port from stbd PTO | I23: Improper installation or manufacturing defect results in failure | J23: Normal | K23: 1) V&V (QC) 2) Independent buses, one for each PTO | L23: none | M23: SCADA Diagnostics | N23: Manual in-situ inspection and repair | O23: 5.1428571 | P23: 1 | Q23: 1 | R23: 5 | S23: 5 | T23: =IF(AND(ISNUMBER(P23),ISNUMBER($O23)),OFFSET(RiskMatrixRef,-$O23+1,P23-1),"") -> Low | U23: =IF(AND(ISNUMBER(Q23),ISNUMBER($O23)),OFFSET(RiskMatrixRef,-$O23+1,Q23-1),"") -> Low | V23: =IF(AND(ISNUMBER(R23),ISNUMBER($O23)),OFFSET(RiskMatrixRef,-$O23+1,R23-1),"") -> Low | W23: =IF(AND(ISNUMBER(S23),ISNUMBER($O23)),OFFSET(RiskMatrixRef,-$O23+1,S23-1),"") -> Low | AF23: =IF(AND(ISNUMBER(AB23),ISNUMBER($AA23)),OFFSET(RiskMatrixRef,-$AA23+1,AB23-1),"") | AG23: =IF(AND(ISNUMBER(AC23),ISNUMBER($AA23)),OFFSET(RiskMatrixRef,-$AA23+1,AC23-1),"") | AH23: =IF(AND(ISNUMBER(AD23),ISNUMBER($AA23)),OFFSET(RiskMatrixRef,-$AA23+1,AD23-1),"") | AI23: =IF(AND(ISNUMBER(AE23),ISNUMBER($AA23)),OFFSET(RiskMatrixRef,-$AA23+1,AE23-1),"") | AR23: =IF(AND(ISNUMBER(AN23),ISNUMBER($AM23)),OFFSET(RiskMatrixRef,-$AM23+1,AN23-1),"") | AS23: =IF(AND(ISNUMBER(AO23),ISNUMBER($AM23)),OFFSET(RiskMatrixRef,-$AM23+1,AO23-1),"") | AT23: =IF(AND(ISNUMBER(AP23),ISNUMBER($AM23)),OFFSET(RiskMatrixRef,-$AM23+1,AP23-1),"") | AU23: =IF(AND(ISNUMBER(AQ23),ISNUMBER($AM23)),OFFSET(RiskMatrixRef,-$AM23+1,AQ23-1),"") | AX23: See comment in Risk ID 0310-3 | AY23: OK
B24: 0330-1 | C24: Energy Storage | D24: Power smoothing Stores and provides energy to the ALM | E24: 2 | F24: Maintenance intervals; Good control of ambient and temperature; Vibrations | G24: Faulted Energy Storage | H24: 1) Loss of power smoothing capability 2) Reduction in power production to HECO grid connection limit 500kW. No power smoothing results in reduced average power production 3) Reduced damping due to power limit | I24: Corrosion induced failure short/open circuit | J24: Normal | K24: 1) Marine rated corrosion resistance design 2) Divided system, two energy storage, one port, one stbd. | L24: 1) Visual inspection | M24: SCADA Diagnostics | N24: Manual in-situ inspection and repair | O24: 7 | P24: 1 | Q24: 1 | R24: 6 | S24: 5 | T24: =IF(AND(ISNUMBER(P24),ISNUMBER($O24)),OFFSET(RiskMatrixRef,-$O24+1,P24-1),"") -> Low | U24: =IF(AND(ISNUMBER(Q24),ISNUMBER($O24)),OFFSET(RiskMatrixRef,-$O24+1,Q24-1),"") -> Low | V24: =IF(AND(ISNUMBER(R24),ISNUMBER($O24)),OFFSET(RiskMatrixRef,-$O24+1,R24-1),"") -> Med | W24: =IF(AND(ISNUMBER(S24),ISNUMBER($O24)),OFFSET(RiskMatrixRef,-$O24+1,S24-1),"") -> Med | X24: 1) HECO interface requirements needed | AF24: =IF(AND(ISNUMBER(AB24),ISNUMBER($AA24)),OFFSET(RiskMatrixRef,-$AA24+1,AB24-1),"") | AG24: =IF(AND(ISNUMBER(AC24),ISNUMBER($AA24)),OFFSET(RiskMatrixRef,-$AA24+1,AC24-1),"") | AH24: =IF(AND(ISNUMBER(AD24),ISNUMBER($AA24)),OFFSET(RiskMatrixRef,-$AA24+1,AD24-1),"") | AI24: =IF(AND(ISNUMBER(AE24),ISNUMBER($AA24)),OFFSET(RiskMatrixRef,-$AA24+1,AE24-1),"") | AR24: =IF(AND(ISNUMBER(AN24),ISNUMBER($AM24)),OFFSET(RiskMatrixRef,-$AM24+1,AN24-1),"") | AS24: =IF(AND(ISNUMBER(AO24),ISNUMBER($AM24)),OFFSET(RiskMatrixRef,-$AM24+1,AO24-1),"") | AT24: =IF(AND(ISNUMBER(AP24),ISNUMBER($AM24)),OFFSET(RiskMatrixRef,-$AM24+1,AP24-1),"") | AU24: =IF(AND(ISNUMBER(AQ24),ISNUMBER($AM24)),OFFSET(RiskMatrixRef,-$AM24+1,AQ24-1),"") | AW24: Should include controllable power burn resistor bank for loss of energy storage & loss of grid connection faults | AX24: Corrosion induced failure should have probability of failure corresponding to FLS design criteria. Although the component is marinised, the probability of failure remains uncertain unless the manufacturer is able to provide evidence or data to demonstrate the reliability of the component is compatible to the occurrence class assigned. Therefore, it is recommended to use severity class 7 such that a recommended action is given to ensure the risks are controlled. | AY24: OK - FLS - "vibrations" need to be applied to the mounting of all equipment within the enclosures. The control room climate control system is responsible for maintaining the humidity, and corrosion due to the presence of moisture should be maintained at an acceptable level beyond any risk of FLS.
B25: 0330-2 | C25: Energy Storage | D25: Power smoothing Stores and provides energy to the ALM | E25: 2 | F25: Maintenance intervals; Good control of ambient and temperature; Vibrations | G25: Faulted Energy Storage | H25: 1) Loss of power smoothing capability 2) Reduction in power production to HECO grid connection limit 500kW. No power smoothing results in reduced average power production 3) Reduced damping due to power limit | I25: Improper installation or manufacturing defect results in failure | J25: Normal | K25: 1) V&V (QC) 2) Divided system, two energy storage, one port, one stbd. | L25: none | M25: SCADA Diagnostics | N25: Manual in-situ inspection and repair | O25: 5 | P25: 1 | Q25: 1 | R25: 6 | S25: 5 | T25: =IF(AND(ISNUMBER(P25),ISNUMBER($O25)),OFFSET(RiskMatrixRef,-$O25+1,P25-1),"") -> Low | U25: =IF(AND(ISNUMBER(Q25),ISNUMBER($O25)),OFFSET(RiskMatrixRef,-$O25+1,Q25-1),"") -> Low | V25: =IF(AND(ISNUMBER(R25),ISNUMBER($O25)),OFFSET(RiskMatrixRef,-$O25+1,R25-1),"") -> Low | W25: =IF(AND(ISNUMBER(S25),ISNUMBER($O25)),OFFSET(RiskMatrixRef,-$O25+1,S25-1),"") -> Low | X25: 1) HECO interface requirements needed | AF25: =IF(AND(ISNUMBER(AB25),ISNUMBER($AA25)),OFFSET(RiskMatrixRef,-$AA25+1,AB25-1),"") | AG25: =IF(AND(ISNUMBER(AC25),ISNUMBER($AA25)),OFFSET(RiskMatrixRef,-$AA25+1,AC25-1),"") | AH25: =IF(AND(ISNUMBER(AD25),ISNUMBER($AA25)),OFFSET(RiskMatrixRef,-$AA25+1,AD25-1),"") | AI25: =IF(AND(ISNUMBER(AE25),ISNUMBER($AA25)),OFFSET(RiskMatrixRef,-$AA25+1,AE25-1),"") | AR25: =IF(AND(ISNUMBER(AN25),ISNUMBER($AM25)),OFFSET(RiskMatrixRef,-$AM25+1,AN25-1),"") | AS25: =IF(AND(ISNUMBER(AO25),ISNUMBER($AM25)),OFFSET(RiskMatrixRef,-$AM25+1,AO25-1),"") | AT25: =IF(AND(ISNUMBER(AP25),ISNUMBER($AM25)),OFFSET(RiskMatrixRef,-$AM25+1,AP25-1),"") | AU25: =IF(AND(ISNUMBER(AQ25),ISNUMBER($AM25)),OFFSET(RiskMatrixRef,-$AM25+1,AQ25-1),"") | AW25: Should include controllable power burn resistor bank for loss of energy storage & loss of grid connection faults | AX25: See comment in Risk ID 0310-2 | AY25: OK
B26: 0330-3 | C26: Energy Storage | D26: Power smoothing Stores and provides energy to the ALM | E26: 2 | F26: Maintenance intervals; Good control of ambient and temperature; Vibrations | G26: Faulted Energy Storage | H26: 1) Loss of power smoothing capability 2) Reduction in power production to HECO grid connection limit 500kW. No power smoothing results in reduced average power production 3) Reduced damping due to power limit | I26: Vibration and/or motion induced failure | J26: Normal | K26: 1) Vibration analysis 2) Equipment and installation designed for dynamic environment 3) Divided system, two energy storage, one port, one stbd. | L26: none | M26: SCADA Diagnostics | N26: Manual in-situ inspection and repair | O26: 6 | P26: 1 | Q26: 1 | R26: 6 | S26: 5 | T26: =IF(AND(ISNUMBER(P26),ISNUMBER($O26)),OFFSET(RiskMatrixRef,-$O26+1,P26-1),"") -> Low | U26: =IF(AND(ISNUMBER(Q26),ISNUMBER($O26)),OFFSET(RiskMatrixRef,-$O26+1,Q26-1),"") -> Low | V26: =IF(AND(ISNUMBER(R26),ISNUMBER($O26)),OFFSET(RiskMatrixRef,-$O26+1,R26-1),"") -> Med | W26: =IF(AND(ISNUMBER(S26),ISNUMBER($O26)),OFFSET(RiskMatrixRef,-$O26+1,S26-1),"") -> Low | X26: 1) HECO interface requirements needed | AF26: =IF(AND(ISNUMBER(AB26),ISNUMBER($AA26)),OFFSET(RiskMatrixRef,-$AA26+1,AB26-1),"") | AG26: =IF(AND(ISNUMBER(AC26),ISNUMBER($AA26)),OFFSET(RiskMatrixRef,-$AA26+1,AC26-1),"") | AH26: =IF(AND(ISNUMBER(AD26),ISNUMBER($AA26)),OFFSET(RiskMatrixRef,-$AA26+1,AD26-1),"") | AI26: =IF(AND(ISNUMBER(AE26),ISNUMBER($AA26)),OFFSET(RiskMatrixRef,-$AA26+1,AE26-1),"") | AR26: =IF(AND(ISNUMBER(AN26),ISNUMBER($AM26)),OFFSET(RiskMatrixRef,-$AM26+1,AN26-1),"") | AS26: =IF(AND(ISNUMBER(AO26),ISNUMBER($AM26)),OFFSET(RiskMatrixRef,-$AM26+1,AO26-1),"") | AT26: =IF(AND(ISNUMBER(AP26),ISNUMBER($AM26)),OFFSET(RiskMatrixRef,-$AM26+1,AP26-1),"") | AU26: =IF(AND(ISNUMBER(AQ26),ISNUMBER($AM26)),OFFSET(RiskMatrixRef,-$AM26+1,AQ26-1),"") | AW26: Should include controllable power burn resistor bank for loss of energy storage & loss of grid connection faults | AX26: see comment in risk 0320-3 | AY26: OK
B27: 0330-4 | C27: Energy Storage | D27: Power smoothing Stores and provides energy to the ALM | E27: 2 | F27: Maintenance intervals; Good control of ambient and temperature; Vibrations | G27: Faulted Energy Storage | H27: 1) Loss of power smoothing capability 2) Reduction in power production to HECO grid connection limit 500kW. No power smoothing results in reduced average power production 3) Reduced damping due to power limit | I27: Water induced failure (non-corrosion) | J27: Normal | K27: 1) Marine rated waterproof design 2) Divided system, two energy storage, one port, one stbd. | L27: 1) SCADA diagnostics 2) Visual inspection | M27: SCADA Diagnostics | N27: Manual in-situ inspection and repair | O27: 4 | P27: 1 | Q27: 1 | R27: 6 | S27: 5 | T27: =IF(AND(ISNUMBER(P27),ISNUMBER($O27)),OFFSET(RiskMatrixRef,-$O27+1,P27-1),"") -> Low | U27: =IF(AND(ISNUMBER(Q27),ISNUMBER($O27)),OFFSET(RiskMatrixRef,-$O27+1,Q27-1),"") -> Low | V27: =IF(AND(ISNUMBER(R27),ISNUMBER($O27)),OFFSET(RiskMatrixRef,-$O27+1,R27-1),"") -> Low | W27: =IF(AND(ISNUMBER(S27),ISNUMBER($O27)),OFFSET(RiskMatrixRef,-$O27+1,S27-1),"") -> Low | X27: 1) HECO interface requirements needed 2) Define energy storage water resistance | AF27: =IF(AND(ISNUMBER(AB27),ISNUMBER($AA27)),OFFSET(RiskMatrixRef,-$AA27+1,AB27-1),"") | AG27: =IF(AND(ISNUMBER(AC27),ISNUMBER($AA27)),OFFSET(RiskMatrixRef,-$AA27+1,AC27-1),"") | AH27: =IF(AND(ISNUMBER(AD27),ISNUMBER($AA27)),OFFSET(RiskMatrixRef,-$AA27+1,AD27-1),"") | AI27: =IF(AND(ISNUMBER(AE27),ISNUMBER($AA27)),OFFSET(RiskMatrixRef,-$AA27+1,AE27-1),"") | AR27: =IF(AND(ISNUMBER(AN27),ISNUMBER($AM27)),OFFSET(RiskMatrixRef,-$AM27+1,AN27-1),"") | AS27: =IF(AND(ISNUMBER(AO27),ISNUMBER($AM27)),OFFSET(RiskMatrixRef,-$AM27+1,AO27-1),"") | AT27: =IF(AND(ISNUMBER(AP27),ISNUMBER($AM27)),OFFSET(RiskMatrixRef,-$AM27+1,AP27-1),"") | AU27: =IF(AND(ISNUMBER(AQ27),ISNUMBER($AM27)),OFFSET(RiskMatrixRef,-$AM27+1,AQ27-1),"") | AW27: Should include controllable power burn resistor bank for loss of energy storage & loss of grid connection faults, Caps are IP-65 | AX27: Occurrence class is lower than that in the MoMo for the same failure cause. Please explain. | AY27: There are more MoMo enclosures than energy storage. Put to the same value of occurrence.
B28: 0330-5 | C28: Energy Storage | D28: Power smoothing Stores and provides energy to the ALM | E28: 2 | F28: Maintenance intervals; Good control of ambient and temperature; Vibrations | G28: Fire/smoke | H28: 1) Electrically isolate enclosures with smoke/fire 2) Automatic fire suppression activated in enclosure by presence of fire/heat 3) Loss of power smoothing capability 4) Reduction in power production to HECO grid connection limit 500kW. No power smoothing results in reduced average power production 5) Reduced damping due to power limit | I28: Electrical short fault leads to smoke/fire | J28: Normal | K28: 1) Safety & Emergency system - smoke alarm - SCADA initiated electrical isolation of enclosures with smoke/fire 2) Automatic fire suppression activated in enclosure by presence of fire/heat – CO2 fills enclosure 3) Loss of power smoothing capability 4) Reduction in power production to HECO grid connection limit 500kW. No power smoothing results in reduced average power production 5) Reduced damping due to power limit | L28: 1) Safety & Emergency systems smoke alarm - isolate before fire breaks out 2) SCADA diagnostics 3) Surveillance - visual inspection | M28: SCADA Diagnostics | N28: Manual in-situ inspection and repair - dry dock repair is damage is extensive | O28: 7 | P28: 1 | Q28: 1 | R28: 5 | S28: 5 | T28: =IF(AND(ISNUMBER(P28),ISNUMBER($O28)),OFFSET(RiskMatrixRef,-$O28+1,P28-1),"") -> Low | U28: =IF(AND(ISNUMBER(Q28),ISNUMBER($O28)),OFFSET(RiskMatrixRef,-$O28+1,Q28-1),"") -> Low | V28: =IF(AND(ISNUMBER(R28),ISNUMBER($O28)),OFFSET(RiskMatrixRef,-$O28+1,R28-1),"") -> Med | W28: =IF(AND(ISNUMBER(S28),ISNUMBER($O28)),OFFSET(RiskMatrixRef,-$O28+1,S28-1),"") -> Med | X28: Energy storage will include resistive discharge in case of a fire. Energy storage will electrically isolate from the M2G then discharge the capacitors via local discharge resistor. | AF28: =IF(AND(ISNUMBER(AB28),ISNUMBER($AA28)),OFFSET(RiskMatrixRef,-$AA28+1,AB28-1),"") | AG28: =IF(AND(ISNUMBER(AC28),ISNUMBER($AA28)),OFFSET(RiskMatrixRef,-$AA28+1,AC28-1),"") | AH28: =IF(AND(ISNUMBER(AD28),ISNUMBER($AA28)),OFFSET(RiskMatrixRef,-$AA28+1,AD28-1),"") | AI28: =IF(AND(ISNUMBER(AE28),ISNUMBER($AA28)),OFFSET(RiskMatrixRef,-$AA28+1,AE28-1),"") | AR28: =IF(AND(ISNUMBER(AN28),ISNUMBER($AM28)),OFFSET(RiskMatrixRef,-$AM28+1,AN28-1),"") | AS28: =IF(AND(ISNUMBER(AO28),ISNUMBER($AM28)),OFFSET(RiskMatrixRef,-$AM28+1,AO28-1),"") | AT28: =IF(AND(ISNUMBER(AP28),ISNUMBER($AM28)),OFFSET(RiskMatrixRef,-$AM28+1,AP28-1),"") | AU28: =IF(AND(ISNUMBER(AQ28),ISNUMBER($AM28)),OFFSET(RiskMatrixRef,-$AM28+1,AQ28-1),"") | AW28: Should include controllable power burn resistor bank for loss of energy storage & loss of grid connection faults | AX28: See comment in risk ID 0320-9 | AY28: Engineering design requirements are being modified to increase safety for maintenance and in care of fault.
B29: 0340-1 | C29: ALM+AIM grid interface | D29: Controls level and quality of power delivered to the grid | E29: 2 | F29: Maintenance intervals; Good control of ambient and temperature; Vibrations | G29: Failed ALM+AIM grid interface | H29: 1) Electrically isolate the ALM+AIM from dc bus 2) Power to grid reduced to one ALM, half capacity (e.g. 300kW) 2) Loss of power generation 3)Adverse effect in heavy wave climate | I29: Corrosion induced failure short circuit | J29: Normal | K29: 1)Marine rated corrosion resistance design 2) Redundant design, two ALM+AIM grid interface modules | L29: 1) Visual inspection | M29: SCADA Diagnostics | N29: Manual in-situ inspection and repair | O29: 7 | P29: 1 | Q29: 1 | R29: 4 | S29: 5 | T29: =IF(AND(ISNUMBER(P29),ISNUMBER($O29)),OFFSET(RiskMatrixRef,-$O29+1,P29-1),"") -> Low | U29: =IF(AND(ISNUMBER(Q29),ISNUMBER($O29)),OFFSET(RiskMatrixRef,-$O29+1,Q29-1),"") -> Low | V29: =IF(AND(ISNUMBER(R29),ISNUMBER($O29)),OFFSET(RiskMatrixRef,-$O29+1,R29-1),"") -> Low | W29: =IF(AND(ISNUMBER(S29),ISNUMBER($O29)),OFFSET(RiskMatrixRef,-$O29+1,S29-1),"") -> Med | AF29: =IF(AND(ISNUMBER(AB29),ISNUMBER($AA29)),OFFSET(RiskMatrixRef,-$AA29+1,AB29-1),"") | AG29: =IF(AND(ISNUMBER(AC29),ISNUMBER($AA29)),OFFSET(RiskMatrixRef,-$AA29+1,AC29-1),"") | AH29: =IF(AND(ISNUMBER(AD29),ISNUMBER($AA29)),OFFSET(RiskMatrixRef,-$AA29+1,AD29-1),"") | AI29: =IF(AND(ISNUMBER(AE29),ISNUMBER($AA29)),OFFSET(RiskMatrixRef,-$AA29+1,AE29-1),"") | AR29: =IF(AND(ISNUMBER(AN29),ISNUMBER($AM29)),OFFSET(RiskMatrixRef,-$AM29+1,AN29-1),"") | AS29: =IF(AND(ISNUMBER(AO29),ISNUMBER($AM29)),OFFSET(RiskMatrixRef,-$AM29+1,AO29-1),"") | AT29: =IF(AND(ISNUMBER(AP29),ISNUMBER($AM29)),OFFSET(RiskMatrixRef,-$AM29+1,AP29-1),"") | AU29: =IF(AND(ISNUMBER(AQ29),ISNUMBER($AM29)),OFFSET(RiskMatrixRef,-$AM29+1,AQ29-1),"") | AW29: Depending on the amount of power smoothing required, power reduction or power burn could occur. For example, if power is allowed to vary from 0-500kW and each ALM is 300kW, power now is reduced to band of 0-300kW. | AX29: See comment in Risk ID 0330-1 | AY29: OK
B30: 0340-2 | C30: ALM+AIM grid interface | D30: Controls level and quality of power delivered to the grid | E30: 2 | F30: Maintenance intervals; Good control of ambient and temperature; Vibrations | G30: Failed ALM+AIM grid interface | H30: 1) Electrically isolate the ALM+AIM from dc bus 2) Power to grid reduced to one ALM, half capacity (e.g. 300kW) 2) Loss of power generation 3)Adverse effect in heavy wave climate | I30: Improper installation or manufacturing defect results in failure | J30: Normal | K30: 1) V&V (QC) 2) Redundant design, two ALM+AIM grid interface modules | L30: none | M30: SCADA Diagnostics | N30: Manual in-situ inspection and repair | O30: 5 | P30: 1 | Q30: 1 | R30: 4 | S30: 5 | T30: =IF(AND(ISNUMBER(P30),ISNUMBER($O30)),OFFSET(RiskMatrixRef,-$O30+1,P30-1),"") -> Low | U30: =IF(AND(ISNUMBER(Q30),ISNUMBER($O30)),OFFSET(RiskMatrixRef,-$O30+1,Q30-1),"") -> Low | V30: =IF(AND(ISNUMBER(R30),ISNUMBER($O30)),OFFSET(RiskMatrixRef,-$O30+1,R30-1),"") -> Low | W30: =IF(AND(ISNUMBER(S30),ISNUMBER($O30)),OFFSET(RiskMatrixRef,-$O30+1,S30-1),"") -> Low | AF30: =IF(AND(ISNUMBER(AB30),ISNUMBER($AA30)),OFFSET(RiskMatrixRef,-$AA30+1,AB30-1),"") | AG30: =IF(AND(ISNUMBER(AC30),ISNUMBER($AA30)),OFFSET(RiskMatrixRef,-$AA30+1,AC30-1),"") | AH30: =IF(AND(ISNUMBER(AD30),ISNUMBER($AA30)),OFFSET(RiskMatrixRef,-$AA30+1,AD30-1),"") | AI30: =IF(AND(ISNUMBER(AE30),ISNUMBER($AA30)),OFFSET(RiskMatrixRef,-$AA30+1,AE30-1),"") | AR30: =IF(AND(ISNUMBER(AN30),ISNUMBER($AM30)),OFFSET(RiskMatrixRef,-$AM30+1,AN30-1),"") | AS30: =IF(AND(ISNUMBER(AO30),ISNUMBER($AM30)),OFFSET(RiskMatrixRef,-$AM30+1,AO30-1),"") | AT30: =IF(AND(ISNUMBER(AP30),ISNUMBER($AM30)),OFFSET(RiskMatrixRef,-$AM30+1,AP30-1),"") | AU30: =IF(AND(ISNUMBER(AQ30),ISNUMBER($AM30)),OFFSET(RiskMatrixRef,-$AM30+1,AQ30-1),"") | AW30: Depending on the amount of power smoothing required, power reduction or power burn could occur. For example, if power is allowed to vary from 0-500kW and each ALM is 300kW, power now is reduced to band of 0-300kW. | AX30: See comment in Risk ID 0310-2 | AY30: OK
B31: 0340-3 | C31: ALM+AIM grid interface | D31: Controls level and quality of power delivered to the grid | E31: 2 | F31: Maintenance intervals; Good control of ambient and temperature; Vibrations | G31: Failed ALM+AIM grid interface | H31: 1) Electrically isolate the ALM+AIM from dc bus 2) Power to grid reduced to one ALM, half capacity (e.g. 300kW) 2) Loss of power generation 3)Adverse effect in heavy wave climate | I31: Vibration and/or motion induced failure | J31: Normal | K31: 1) Vibration analysis 2) Equipment and installation designed for dynamic environment 3) Redundant design, 2 ALM+AIM grid interface modules | L31: none | M31: SCADA Diagnostics | N31: Manual in-situ inspection and repair | O31: 6 | P31: 1 | Q31: 1 | R31: 4 | S31: 5 | T31: =IF(AND(ISNUMBER(P31),ISNUMBER($O31)),OFFSET(RiskMatrixRef,-$O31+1,P31-1),"") -> Low | U31: =IF(AND(ISNUMBER(Q31),ISNUMBER($O31)),OFFSET(RiskMatrixRef,-$O31+1,Q31-1),"") -> Low | V31: =IF(AND(ISNUMBER(R31),ISNUMBER($O31)),OFFSET(RiskMatrixRef,-$O31+1,R31-1),"") -> Low | W31: =IF(AND(ISNUMBER(S31),ISNUMBER($O31)),OFFSET(RiskMatrixRef,-$O31+1,S31-1),"") -> Low | AF31: =IF(AND(ISNUMBER(AB31),ISNUMBER($AA31)),OFFSET(RiskMatrixRef,-$AA31+1,AB31-1),"") | AG31: =IF(AND(ISNUMBER(AC31),ISNUMBER($AA31)),OFFSET(RiskMatrixRef,-$AA31+1,AC31-1),"") | AH31: =IF(AND(ISNUMBER(AD31),ISNUMBER($AA31)),OFFSET(RiskMatrixRef,-$AA31+1,AD31-1),"") | AI31: =IF(AND(ISNUMBER(AE31),ISNUMBER($AA31)),OFFSET(RiskMatrixRef,-$AA31+1,AE31-1),"") | AR31: =IF(AND(ISNUMBER(AN31),ISNUMBER($AM31)),OFFSET(RiskMatrixRef,-$AM31+1,AN31-1),"") | AS31: =IF(AND(ISNUMBER(AO31),ISNUMBER($AM31)),OFFSET(RiskMatrixRef,-$AM31+1,AO31-1),"") | AT31: =IF(AND(ISNUMBER(AP31),ISNUMBER($AM31)),OFFSET(RiskMatrixRef,-$AM31+1,AP31-1),"") | AU31: =IF(AND(ISNUMBER(AQ31),ISNUMBER($AM31)),OFFSET(RiskMatrixRef,-$AM31+1,AQ31-1),"") | AW31: Depending on the amount of power smoothing required, power reduction or power burn could occur. For example, if power is allowed to vary from 0-500kW and each ALM is 300kW, power now is reduced to band of 0-300kW. | AX31: see comment in risk 0320-3 | AY31: OK
