Workbook
Name RiskMatrixRef: '[2]set up'!$C$14
Name RiskMatrixRef: 'set up'!$C$14

Sheet Data Rights Notice

Sheet 0400 SCADA
O2: Risk Ranking | AA2: Updated Risk Ranking | AM2: 2nd Updated Risk Ranking
B4: 0400 SCADA FMECA Table | P4: Severity Class | T4: Risk Class | AB4: Severity Class | AF4: Risk Class | AN4: Severity Class | AR4: Risk Class
B5: Risk ID | C5: Item Description | D5: Function | E5: Tech. Class | F5: Novel Aspects | G5: Failure Mode | H5: Failure Effects (Local, WEC, System) | I5: Failure Cause(s) | J5: Initial Mode of Operation | K5: Risk Reduction Design | L5: Preventative Detection | M5: Post Failure Detection | N5: Post Failure Repair Strategy (automated, manual) | O5: Occurrence | P5: Human Safety | Q5: Environment | R5: Operation | S5: Assets | T5: Human Safety | U5: Environment | V5: Operation | W5: Assets | X5: Recommended Actions | Y5: Responsible Party | Z5: Actions Taken | AA5: Occurrence | AB5: Human Safety | AC5: Environment | AD5: Operation | AE5: Assets | AF5: Human Safety | AG5: Environment | AH5: Operation | AI5: Assets | AJ5: 2nd Recommended Actions | AK5: Responsible Party (2nd) | AL5: Actions Taken (2nd) | AM5: Occurrence | AN5: Human Safety | AO5: Environment | AP5: Operation | AQ5: Assets | AR5: Human Safety | AS5: Environment | AT5: Operation | AU5: Assets | AV5: Status (open or closed) | AW5: Notes | AX5: DNV GL comment
B6: 400-1 | C6: SCADA components | D6: Control and data collection | E6: 1 | F6: none | G6: Fire/smoke | H6: 1) Power loss due to short 2) Damage to SCADA system | I6: Electrical short or internal component failure | J6: Normal | K6: 1) All SCADA functions are redundant on alternate side 2) Airtight enclosures 3) Low power 4) In cabinet fire suppression | L6: 1) Fire/smoke alarm | M6: 1) Enclosure fire alarm 2) Enclosure temperature 3) Visible and IR camera | N6: Manual in-situ repair and inspection | O6: 5 | P6: 1 | Q6: 1 | R6: 6 | S6: 5 | T6: =IF(AND(ISNUMBER(P6),ISNUMBER($O6)),OFFSET(RiskMatrixRef,-$O6+1,P6-1),"") -> Low | U6: =IF(AND(ISNUMBER(Q6),ISNUMBER($O6)),OFFSET(RiskMatrixRef,-$O6+1,Q6-1),"") -> Low | V6: =IF(AND(ISNUMBER(R6),ISNUMBER($O6)),OFFSET(RiskMatrixRef,-$O6+1,R6-1),"") -> Low | W6: =IF(AND(ISNUMBER(S6),ISNUMBER($O6)),OFFSET(RiskMatrixRef,-$O6+1,S6-1),"") -> Low | AF6: =IF(AND(ISNUMBER(AB6),ISNUMBER($AA6)),OFFSET(RiskMatrixRef,-$AA6+1,AB6-1),"") | AG6: =IF(AND(ISNUMBER(AC6),ISNUMBER($AA6)),OFFSET(RiskMatrixRef,-$AA6+1,AC6-1),"") | AH6: =IF(AND(ISNUMBER(AD6),ISNUMBER($AA6)),OFFSET(RiskMatrixRef,-$AA6+1,AD6-1),"") | AI6: =IF(AND(ISNUMBER(AE6),ISNUMBER($AA6)),OFFSET(RiskMatrixRef,-$AA6+1,AE6-1),"") | AR6: =IF(AND(ISNUMBER(AN6),ISNUMBER($AM6)),OFFSET(RiskMatrixRef,-$AM6+1,AN6-1),"") | AS6: =IF(AND(ISNUMBER(AO6),ISNUMBER($AM6)),OFFSET(RiskMatrixRef,-$AM6+1,AO6-1),"") | AT6: =IF(AND(ISNUMBER(AP6),ISNUMBER($AM6)),OFFSET(RiskMatrixRef,-$AM6+1,AP6-1),"") | AU6: =IF(AND(ISNUMBER(AQ6),ISNUMBER($AM6)),OFFSET(RiskMatrixRef,-$AM6+1,AQ6-1),"")
B7: 410-1 | C7: Single PTO tape scale encoder | D7: Provide position feedback to drives | E7: 2 | F7: new environment | G7: Signal failure | H7: 1) Single encoder fail 2) Loss of position feedback | I7: Wiring Issue - unknown internal fault - unknown poor solder joint - wire chaffe due to improper routing | J7: Normal | K7: 1) V&V 2) Redundant encoders | L7: 1) None | M7: 1) Encoder data | N7: Manual switch of encoders onboard Programmatically selected encoders from internal system comparison. | O7: 7 | P7: 1 | Q7: 1 | R7: 2 | S7: 4 | T7: =IF(AND(ISNUMBER(P7),ISNUMBER($O7)),OFFSET(RiskMatrixRef,-$O7+1,P7-1),"") -> Low | U7: =IF(AND(ISNUMBER(Q7),ISNUMBER($O7)),OFFSET(RiskMatrixRef,-$O7+1,Q7-1),"") -> Low | V7: =IF(AND(ISNUMBER(R7),ISNUMBER($O7)),OFFSET(RiskMatrixRef,-$O7+1,R7-1),"") -> Low | W7: =IF(AND(ISNUMBER(S7),ISNUMBER($O7)),OFFSET(RiskMatrixRef,-$O7+1,S7-1),"") -> Low | X7: In agreement with DNVGL comment, this Failure Cause is covered by 410-2,3,5,6 and could be removed. | AF7: =IF(AND(ISNUMBER(AB7),ISNUMBER($AA7)),OFFSET(RiskMatrixRef,-$AA7+1,AB7-1),"") | AG7: =IF(AND(ISNUMBER(AC7),ISNUMBER($AA7)),OFFSET(RiskMatrixRef,-$AA7+1,AC7-1),"") | AH7: =IF(AND(ISNUMBER(AD7),ISNUMBER($AA7)),OFFSET(RiskMatrixRef,-$AA7+1,AD7-1),"") | AI7: =IF(AND(ISNUMBER(AE7),ISNUMBER($AA7)),OFFSET(RiskMatrixRef,-$AA7+1,AE7-1),"") | AR7: =IF(AND(ISNUMBER(AN7),ISNUMBER($AM7)),OFFSET(RiskMatrixRef,-$AM7+1,AN7-1),"") | AS7: =IF(AND(ISNUMBER(AO7),ISNUMBER($AM7)),OFFSET(RiskMatrixRef,-$AM7+1,AO7-1),"") | AT7: =IF(AND(ISNUMBER(AP7),ISNUMBER($AM7)),OFFSET(RiskMatrixRef,-$AM7+1,AP7-1),"") | AU7: =IF(AND(ISNUMBER(AQ7),ISNUMBER($AM7)),OFFSET(RiskMatrixRef,-$AM7+1,AQ7-1),"") | AW7: Can signals be multiplexed and switched remotely? - Yes, internal comparison can be performed of all encoders and they can be switched automatically or manually remotely. | AX7: It is assumed that failure due to improper installation or manufacturing faults are usually mitigated via manufacturer's in house quality control and testing of the components. The failure mode should focus on quality control or testing specific to the WEC applications. Hence, the description of failure cause to be more specific to capture the failure causes unique to StingRAY device, or remove if none has been identified.
B8: 410-2 | C8: Single PTO tape scale encoder | D8: Provide position feedback to drives | E8: 2 | F8: new environment | G8: Signal failure | H8: 1) Single encoder fail 2) Loss of position feedback | I8: Corrosion induced failure | J8: Normal | K8: 1) Material selection 2) IP 67 3) Climate Control 4) Redundant encoders | L8: 1) None | M8: 1) Encoder data | N8: Manual switch of encoders onboard Programmatically selected encoders from internal system comparison. | O8: 6 | P8: 1 | Q8: 1 | R8: 2 | S8: 4 | T8: =IF(AND(ISNUMBER(P8),ISNUMBER($O8)),OFFSET(RiskMatrixRef,-$O8+1,P8-1),"") -> Low | U8: =IF(AND(ISNUMBER(Q8),ISNUMBER($O8)),OFFSET(RiskMatrixRef,-$O8+1,Q8-1),"") -> Low | V8: =IF(AND(ISNUMBER(R8),ISNUMBER($O8)),OFFSET(RiskMatrixRef,-$O8+1,R8-1),"") -> Low | W8: =IF(AND(ISNUMBER(S8),ISNUMBER($O8)),OFFSET(RiskMatrixRef,-$O8+1,S8-1),"") -> Low | AF8: =IF(AND(ISNUMBER(AB8),ISNUMBER($AA8)),OFFSET(RiskMatrixRef,-$AA8+1,AB8-1),"") | AG8: =IF(AND(ISNUMBER(AC8),ISNUMBER($AA8)),OFFSET(RiskMatrixRef,-$AA8+1,AC8-1),"") | AH8: =IF(AND(ISNUMBER(AD8),ISNUMBER($AA8)),OFFSET(RiskMatrixRef,-$AA8+1,AD8-1),"") | AI8: =IF(AND(ISNUMBER(AE8),ISNUMBER($AA8)),OFFSET(RiskMatrixRef,-$AA8+1,AE8-1),"") | AR8: =IF(AND(ISNUMBER(AN8),ISNUMBER($AM8)),OFFSET(RiskMatrixRef,-$AM8+1,AN8-1),"") | AS8: =IF(AND(ISNUMBER(AO8),ISNUMBER($AM8)),OFFSET(RiskMatrixRef,-$AM8+1,AO8-1),"") | AT8: =IF(AND(ISNUMBER(AP8),ISNUMBER($AM8)),OFFSET(RiskMatrixRef,-$AM8+1,AP8-1),"") | AU8: =IF(AND(ISNUMBER(AQ8),ISNUMBER($AM8)),OFFSET(RiskMatrixRef,-$AM8+1,AQ8-1),"") | AW8: Reduced Severity Class of Operation due to having redundant encoders in design. | AX8: If redundant encoders then effect on operation of single encoder failure and therefore Severity class would be lower.
B9: 410-2 | C9: Single PTO tape scale encoder | D9: Provide position feedback to drives | E9: 2 | F9: new environment | G9: Signal failure | H9: 1) Single encoder fail 2) Loss of position feedback | I9: Contamination induced failure | J9: Normal | K9: 1) Thorough cleaning at commissioning 2) Redundant encoders | L9: 1) None | M9: 1) Encoder data | N9: Manual switch of encoders onboard Programmatically selected encoders from internal system comparison. | O9: 7 | P9: 1 | Q9: 1 | R9: 2 | S9: 4 | T9: =IF(AND(ISNUMBER(P9),ISNUMBER($O9)),OFFSET(RiskMatrixRef,-$O9+1,P9-1),"") -> Low | U9: =IF(AND(ISNUMBER(Q9),ISNUMBER($O9)),OFFSET(RiskMatrixRef,-$O9+1,Q9-1),"") -> Low | V9: =IF(AND(ISNUMBER(R9),ISNUMBER($O9)),OFFSET(RiskMatrixRef,-$O9+1,R9-1),"") -> Low | W9: =IF(AND(ISNUMBER(S9),ISNUMBER($O9)),OFFSET(RiskMatrixRef,-$O9+1,S9-1),"") -> Low | AF9: =IF(AND(ISNUMBER(AB9),ISNUMBER($AA9)),OFFSET(RiskMatrixRef,-$AA9+1,AB9-1),"") | AG9: =IF(AND(ISNUMBER(AC9),ISNUMBER($AA9)),OFFSET(RiskMatrixRef,-$AA9+1,AC9-1),"") | AH9: =IF(AND(ISNUMBER(AD9),ISNUMBER($AA9)),OFFSET(RiskMatrixRef,-$AA9+1,AD9-1),"") | AI9: =IF(AND(ISNUMBER(AE9),ISNUMBER($AA9)),OFFSET(RiskMatrixRef,-$AA9+1,AE9-1),"") | AR9: =IF(AND(ISNUMBER(AN9),ISNUMBER($AM9)),OFFSET(RiskMatrixRef,-$AM9+1,AN9-1),"") | AS9: =IF(AND(ISNUMBER(AO9),ISNUMBER($AM9)),OFFSET(RiskMatrixRef,-$AM9+1,AO9-1),"") | AT9: =IF(AND(ISNUMBER(AP9),ISNUMBER($AM9)),OFFSET(RiskMatrixRef,-$AM9+1,AP9-1),"") | AU9: =IF(AND(ISNUMBER(AQ9),ISNUMBER($AM9)),OFFSET(RiskMatrixRef,-$AM9+1,AQ9-1),"") | AW9: Reduced Severity Class of Operation due to having redundant encoders in design. | AX9: If redundant encoders then effect on operation of single encoder failure and therefore Severity class would be lower.
B10: 410-3 | C10: Single PTO tape scale encoder | D10: Provide position feedback to drives | E10: 2 | F10: new environment | G10: Signal failure | H10: 1) Single encoder fail 2) Loss of position feedback | I10: Improper installation or manufacturing defect results in failure | J10: Normal | K10: 1) V&V 2) Redundant encoders | L10: 1) None | M10: 1) Encoder data | N10: Manual switch of encoders onboard Programmatically selected encoders from internal system comparison. | O10: 7 | P10: 1 | Q10: 1 | R10: 2 | S10: 4 | T10: =IF(AND(ISNUMBER(P10),ISNUMBER($O10)),OFFSET(RiskMatrixRef,-$O10+1,P10-1),"") -> Low | U10: =IF(AND(ISNUMBER(Q10),ISNUMBER($O10)),OFFSET(RiskMatrixRef,-$O10+1,Q10-1),"") -> Low | V10: =IF(AND(ISNUMBER(R10),ISNUMBER($O10)),OFFSET(RiskMatrixRef,-$O10+1,R10-1),"") -> Low | W10: =IF(AND(ISNUMBER(S10),ISNUMBER($O10)),OFFSET(RiskMatrixRef,-$O10+1,S10-1),"") -> Low | AF10: =IF(AND(ISNUMBER(AB10),ISNUMBER($AA10)),OFFSET(RiskMatrixRef,-$AA10+1,AB10-1),"") | AG10: =IF(AND(ISNUMBER(AC10),ISNUMBER($AA10)),OFFSET(RiskMatrixRef,-$AA10+1,AC10-1),"") | AH10: =IF(AND(ISNUMBER(AD10),ISNUMBER($AA10)),OFFSET(RiskMatrixRef,-$AA10+1,AD10-1),"") | AI10: =IF(AND(ISNUMBER(AE10),ISNUMBER($AA10)),OFFSET(RiskMatrixRef,-$AA10+1,AE10-1),"") | AR10: =IF(AND(ISNUMBER(AN10),ISNUMBER($AM10)),OFFSET(RiskMatrixRef,-$AM10+1,AN10-1),"") | AS10: =IF(AND(ISNUMBER(AO10),ISNUMBER($AM10)),OFFSET(RiskMatrixRef,-$AM10+1,AO10-1),"") | AT10: =IF(AND(ISNUMBER(AP10),ISNUMBER($AM10)),OFFSET(RiskMatrixRef,-$AM10+1,AP10-1),"") | AU10: =IF(AND(ISNUMBER(AQ10),ISNUMBER($AM10)),OFFSET(RiskMatrixRef,-$AM10+1,AQ10-1),"") | AW10: Reduced Severity Class of Operation due to having redundant encoders in design. | AX10: See comment in Risk ID 410-1. Since the occurrence class assigned here is higher, please clarify if this is due to improper installation or manufacturing faults that are specific to the WEC.
B11: 410-4 | C11: Single PTO tape scale encoder | D11: Provide position feedback to drives | E11: 2 | F11: new environment | G11: Signal failure | H11: 1) Single encoder fail 2) Loss of position feedback | I11: Software / programming error during program revision. | J11: Normal | K11: 1) V&V 2) Security | L11: 1) None | M11: 1) Encoder data | N11: Manual switch of encoders onboard Manual correction of software/programming error, onboard or remotely. | O11: 5 | P11: 1 | Q11: 1 | R11: 6 | S11: 4 | T11: =IF(AND(ISNUMBER(P11),ISNUMBER($O11)),OFFSET(RiskMatrixRef,-$O11+1,P11-1),"") -> Low | U11: =IF(AND(ISNUMBER(Q11),ISNUMBER($O11)),OFFSET(RiskMatrixRef,-$O11+1,Q11-1),"") -> Low | V11: =IF(AND(ISNUMBER(R11),ISNUMBER($O11)),OFFSET(RiskMatrixRef,-$O11+1,R11-1),"") -> Low | W11: =IF(AND(ISNUMBER(S11),ISNUMBER($O11)),OFFSET(RiskMatrixRef,-$O11+1,S11-1),"") -> Low | AF11: =IF(AND(ISNUMBER(AB11),ISNUMBER($AA11)),OFFSET(RiskMatrixRef,-$AA11+1,AB11-1),"") | AG11: =IF(AND(ISNUMBER(AC11),ISNUMBER($AA11)),OFFSET(RiskMatrixRef,-$AA11+1,AC11-1),"") | AH11: =IF(AND(ISNUMBER(AD11),ISNUMBER($AA11)),OFFSET(RiskMatrixRef,-$AA11+1,AD11-1),"") | AI11: =IF(AND(ISNUMBER(AE11),ISNUMBER($AA11)),OFFSET(RiskMatrixRef,-$AA11+1,AE11-1),"") | AR11: =IF(AND(ISNUMBER(AN11),ISNUMBER($AM11)),OFFSET(RiskMatrixRef,-$AM11+1,AN11-1),"") | AS11: =IF(AND(ISNUMBER(AO11),ISNUMBER($AM11)),OFFSET(RiskMatrixRef,-$AM11+1,AO11-1),"") | AT11: =IF(AND(ISNUMBER(AP11),ISNUMBER($AM11)),OFFSET(RiskMatrixRef,-$AM11+1,AP11-1),"") | AU11: =IF(AND(ISNUMBER(AQ11),ISNUMBER($AM11)),OFFSET(RiskMatrixRef,-$AM11+1,AQ11-1),"") | AW11: Reduced Occurrence by 1 level as encoder operation is unlikely to be modified post-deployment and will be fully tested during commissioning and testing. | AX11: It is expected that most software and programming error will have been corrected during commissioning and testing, unless CPwr expects the software/programme will be continuously refined and modified after deployment and the existing testing and commissioning of the programme is not able to detect the error. Please provide a more specific description of the failure cause.
B12: 410-5 | C12: Single PTO tape scale encoder | D12: Provide position feedback to drives | E12: 2 | F12: new environment | G12: Signal failure | H12: 1) Single encoder fail 2) Loss of position feedback | I12: Vibration and/or motion induced failure | J12: Normal | K12: 1) Modal analysis 2) Redundant encoders | L12: 1) None | M12: 1) Encoder data | N12: Manual switch of encoders onboard Programmatically selected encoders from internal system comparison. | O12: 7 | P12: 1 | Q12: 1 | R12: 2 | S12: 4 | T12: =IF(AND(ISNUMBER(P12),ISNUMBER($O12)),OFFSET(RiskMatrixRef,-$O12+1,P12-1),"") -> Low | U12: =IF(AND(ISNUMBER(Q12),ISNUMBER($O12)),OFFSET(RiskMatrixRef,-$O12+1,Q12-1),"") -> Low | V12: =IF(AND(ISNUMBER(R12),ISNUMBER($O12)),OFFSET(RiskMatrixRef,-$O12+1,R12-1),"") -> Low | W12: =IF(AND(ISNUMBER(S12),ISNUMBER($O12)),OFFSET(RiskMatrixRef,-$O12+1,S12-1),"") -> Low | AF12: =IF(AND(ISNUMBER(AB12),ISNUMBER($AA12)),OFFSET(RiskMatrixRef,-$AA12+1,AB12-1),"") | AG12: =IF(AND(ISNUMBER(AC12),ISNUMBER($AA12)),OFFSET(RiskMatrixRef,-$AA12+1,AC12-1),"") | AH12: =IF(AND(ISNUMBER(AD12),ISNUMBER($AA12)),OFFSET(RiskMatrixRef,-$AA12+1,AD12-1),"") | AI12: =IF(AND(ISNUMBER(AE12),ISNUMBER($AA12)),OFFSET(RiskMatrixRef,-$AA12+1,AE12-1),"") | AR12: =IF(AND(ISNUMBER(AN12),ISNUMBER($AM12)),OFFSET(RiskMatrixRef,-$AM12+1,AN12-1),"") | AS12: =IF(AND(ISNUMBER(AO12),ISNUMBER($AM12)),OFFSET(RiskMatrixRef,-$AM12+1,AO12-1),"") | AT12: =IF(AND(ISNUMBER(AP12),ISNUMBER($AM12)),OFFSET(RiskMatrixRef,-$AM12+1,AP12-1),"") | AU12: =IF(AND(ISNUMBER(AQ12),ISNUMBER($AM12)),OFFSET(RiskMatrixRef,-$AM12+1,AQ12-1),"") | AW12: Reduced Severity Class of Operation due to having redundant encoders in design. | AX12: If redundant encoders then effect on operation of single encoder failure and therefore Severity class would be lower.
B13: 410-6 | C13: Single PTO tape scale encoder | D13: Provide position feedback to drives | E13: 2 | F13: new environment | G13: Signal failure | H13: 1) Single encoder fail 2) Loss of position feedback | I13: Water induced failure (non-corrosion) | J13: Normal | K13: 1) IP 67 2) Redundant encoders | L13: 1) None | M13: 1) Encoder data | N13: Manual switch of encoders onboard Programmatically selected encoders from internal system comparison. | O13: 7 | P13: 1 | Q13: 1 | R13: 2 | S13: 4 | T13: =IF(AND(ISNUMBER(P13),ISNUMBER($O13)),OFFSET(RiskMatrixRef,-$O13+1,P13-1),"") -> Low | U13: =IF(AND(ISNUMBER(Q13),ISNUMBER($O13)),OFFSET(RiskMatrixRef,-$O13+1,Q13-1),"") -> Low | V13: =IF(AND(ISNUMBER(R13),ISNUMBER($O13)),OFFSET(RiskMatrixRef,-$O13+1,R13-1),"") -> Low | W13: =IF(AND(ISNUMBER(S13),ISNUMBER($O13)),OFFSET(RiskMatrixRef,-$O13+1,S13-1),"") -> Low | AF13: =IF(AND(ISNUMBER(AB13),ISNUMBER($AA13)),OFFSET(RiskMatrixRef,-$AA13+1,AB13-1),"") | AG13: =IF(AND(ISNUMBER(AC13),ISNUMBER($AA13)),OFFSET(RiskMatrixRef,-$AA13+1,AC13-1),"") | AH13: =IF(AND(ISNUMBER(AD13),ISNUMBER($AA13)),OFFSET(RiskMatrixRef,-$AA13+1,AD13-1),"") | AI13: =IF(AND(ISNUMBER(AE13),ISNUMBER($AA13)),OFFSET(RiskMatrixRef,-$AA13+1,AE13-1),"") | AR13: =IF(AND(ISNUMBER(AN13),ISNUMBER($AM13)),OFFSET(RiskMatrixRef,-$AM13+1,AN13-1),"") | AS13: =IF(AND(ISNUMBER(AO13),ISNUMBER($AM13)),OFFSET(RiskMatrixRef,-$AM13+1,AO13-1),"") | AT13: =IF(AND(ISNUMBER(AP13),ISNUMBER($AM13)),OFFSET(RiskMatrixRef,-$AM13+1,AP13-1),"") | AU13: =IF(AND(ISNUMBER(AQ13),ISNUMBER($AM13)),OFFSET(RiskMatrixRef,-$AM13+1,AQ13-1),"") | AW13: Reduced Severity Class of Operation due to having redundant encoders in design. | AX13: If redundant encoders then effect on operation of single encoder failure and therefore Severity class would be lower.
B14: 410-7 | C14: Backups + 1 encoders failure | D14: Provide position feedback to drives | E14: 2 | F14: new environment | G14: Encoder failure | H14: 1) Incorrect signal - uncontrolled damping 2) No signal - freewheeling 3) Loss of position feedback | I14: All encoders failed for one PTO | J14: Normal | K14: 1) having installed backups | L14: 1) None | M14: 1) Encoder data | N14: Dry-dock required for repair. | O14: 4 | P14: 1 | Q14: 1 | R14: 7 | S14: 7 | T14: =IF(AND(ISNUMBER(P14),ISNUMBER($O14)),OFFSET(RiskMatrixRef,-$O14+1,P14-1),"") -> Low | U14: =IF(AND(ISNUMBER(Q14),ISNUMBER($O14)),OFFSET(RiskMatrixRef,-$O14+1,Q14-1),"") -> Low | V14: =IF(AND(ISNUMBER(R14),ISNUMBER($O14)),OFFSET(RiskMatrixRef,-$O14+1,R14-1),"") -> Low | W14: =IF(AND(ISNUMBER(S14),ISNUMBER($O14)),OFFSET(RiskMatrixRef,-$O14+1,S14-1),"") -> Low | X14: Increase redundancy of encoders to 100% to reduce Occurrence. | AW14: Requires 6 encoders for operation of 3 CU320s. 100% redundant encoders which can be swapped programmatically. | AX14: CP to expand the FMEA using the same failure modes in "single failure", but one lower class of occurrence. CP to provide reccommended action for mitigation of medium risk level
B15: 410-8 | C15: Encoder power from M2G | D15: Provide position feedback to drives | E15: 2 | F15: new environment | G15: Signal failure | H15: 1) All encoder fail for one PTO | I15: Power failure to encoder | J15: Normal | K15: 1) Redundant power supplies 2) Powered from M2G | L15: 1) None | M15: 1) Encoder data | N15: manual supply replacement | O15: 3 | P15: 1 | Q15: 1 | R15: 6 | S15: 2 | T15: =IF(AND(ISNUMBER(P15),ISNUMBER($O15)),OFFSET(RiskMatrixRef,-$O15+1,P15-1),"") -> Low | U15: =IF(AND(ISNUMBER(Q15),ISNUMBER($O15)),OFFSET(RiskMatrixRef,-$O15+1,Q15-1),"") -> Low | V15: =IF(AND(ISNUMBER(R15),ISNUMBER($O15)),OFFSET(RiskMatrixRef,-$O15+1,R15-1),"") -> Low | W15: =IF(AND(ISNUMBER(S15),ISNUMBER($O15)),OFFSET(RiskMatrixRef,-$O15+1,S15-1),"") -> Low | AF15: =IF(AND(ISNUMBER(AB15),ISNUMBER($AA15)),OFFSET(RiskMatrixRef,-$AA15+1,AB15-1),"") | AG15: =IF(AND(ISNUMBER(AC15),ISNUMBER($AA15)),OFFSET(RiskMatrixRef,-$AA15+1,AC15-1),"") | AH15: =IF(AND(ISNUMBER(AD15),ISNUMBER($AA15)),OFFSET(RiskMatrixRef,-$AA15+1,AD15-1),"") | AI15: =IF(AND(ISNUMBER(AE15),ISNUMBER($AA15)),OFFSET(RiskMatrixRef,-$AA15+1,AE15-1),"") | AR15: =IF(AND(ISNUMBER(AN15),ISNUMBER($AM15)),OFFSET(RiskMatrixRef,-$AM15+1,AN15-1),"") | AS15: =IF(AND(ISNUMBER(AO15),ISNUMBER($AM15)),OFFSET(RiskMatrixRef,-$AM15+1,AO15-1),"") | AT15: =IF(AND(ISNUMBER(AP15),ISNUMBER($AM15)),OFFSET(RiskMatrixRef,-$AM15+1,AP15-1),"") | AU15: =IF(AND(ISNUMBER(AQ15),ISNUMBER($AM15)),OFFSET(RiskMatrixRef,-$AM15+1,AQ15-1),"") | AW15: Power from M2G
B16: 410-10 | C16: Generator gap sensor | D16: Provides stator position w.r.t. the outer housing and rotor | E16: 2 | F16: new environment | G16: Signal failure | H16: 1) No gap data from failed sensor | I16: Hardware or wiring failure - corrosion induced - water induced - contamination - vibration | J16: Normal | K16: 1) Redundant sensors on separate stators. | L16: 1) None | M16: 1) Gap sensor data lost | N16: Dry-dock required for repair. Single failure tolerable. | O16: 9 | P16: 1 | Q16: 1 | R16: 2 | S16: 2 | T16: =IF(AND(ISNUMBER(P16),ISNUMBER($O16)),OFFSET(RiskMatrixRef,-$O16+1,P16-1),"") -> Low | U16: =IF(AND(ISNUMBER(Q16),ISNUMBER($O16)),OFFSET(RiskMatrixRef,-$O16+1,Q16-1),"") -> Low | V16: =IF(AND(ISNUMBER(R16),ISNUMBER($O16)),OFFSET(RiskMatrixRef,-$O16+1,R16-1),"") -> Low | W16: =IF(AND(ISNUMBER(S16),ISNUMBER($O16)),OFFSET(RiskMatrixRef,-$O16+1,S16-1),"") -> Low | AF16: =IF(AND(ISNUMBER(AB16),ISNUMBER($AA16)),OFFSET(RiskMatrixRef,-$AA16+1,AB16-1),"") | AG16: =IF(AND(ISNUMBER(AC16),ISNUMBER($AA16)),OFFSET(RiskMatrixRef,-$AA16+1,AC16-1),"") | AH16: =IF(AND(ISNUMBER(AD16),ISNUMBER($AA16)),OFFSET(RiskMatrixRef,-$AA16+1,AD16-1),"") | AI16: =IF(AND(ISNUMBER(AE16),ISNUMBER($AA16)),OFFSET(RiskMatrixRef,-$AA16+1,AE16-1),"") | AR16: =IF(AND(ISNUMBER(AN16),ISNUMBER($AM16)),OFFSET(RiskMatrixRef,-$AM16+1,AN16-1),"") | AS16: =IF(AND(ISNUMBER(AO16),ISNUMBER($AM16)),OFFSET(RiskMatrixRef,-$AM16+1,AO16-1),"") | AT16: =IF(AND(ISNUMBER(AP16),ISNUMBER($AM16)),OFFSET(RiskMatrixRef,-$AM16+1,AP16-1),"") | AU16: =IF(AND(ISNUMBER(AQ16),ISNUMBER($AM16)),OFFSET(RiskMatrixRef,-$AM16+1,AQ16-1),"") | AW16: Operation Risk reduced further as loss of sensor data does not affect generator performance. Arranged all failures back to one row as all failures carried the same risk rankings. | AX16: Suggest to include a more detailed FMEA that includes different failure modes, see detail breakdown below. For the rest of the sensor: 1. Assess if the failure causes apply. 2. Assess if the risk ranking are the same Answers to 1 and 2 are "yes", then just make reference to the risk ID of this component to avoid repetition.
B17: 410-11 | C17: Torque rod load cell | D17: provides measured stator torque for one stator section | E17: 1 | F17: none | G17: Signal failure | H17: 1) No torque data from failed sensor | I17: Hardware or wiring failure | J17: Normal | K17: 1) Mechanically safe because available torque is limited the load cell's rating, which is well below the mechanical design limit. 2) Redundant sensors on separate stators. | L17: 1) None | M17: 1) Link bar data lost | N17: Dry-dock required for repair. Single failure tolerable. | O17: 8 | P17: 1 | Q17: 1 | R17: 3 | S17: 3 | T17: =IF(AND(ISNUMBER(P17),ISNUMBER($O17)),OFFSET(RiskMatrixRef,-$O17+1,P17-1),"") -> Low | U17: =IF(AND(ISNUMBER(Q17),ISNUMBER($O17)),OFFSET(RiskMatrixRef,-$O17+1,Q17-1),"") -> Low | V17: =IF(AND(ISNUMBER(R17),ISNUMBER($O17)),OFFSET(RiskMatrixRef,-$O17+1,R17-1),"") -> Low | W17: =IF(AND(ISNUMBER(S17),ISNUMBER($O17)),OFFSET(RiskMatrixRef,-$O17+1,S17-1),"") -> Low | AF17: =IF(AND(ISNUMBER(AB17),ISNUMBER($AA17)),OFFSET(RiskMatrixRef,-$AA17+1,AB17-1),"") | AG17: =IF(AND(ISNUMBER(AC17),ISNUMBER($AA17)),OFFSET(RiskMatrixRef,-$AA17+1,AC17-1),"") | AH17: =IF(AND(ISNUMBER(AD17),ISNUMBER($AA17)),OFFSET(RiskMatrixRef,-$AA17+1,AD17-1),"") | AI17: =IF(AND(ISNUMBER(AE17),ISNUMBER($AA17)),OFFSET(RiskMatrixRef,-$AA17+1,AE17-1),"") | AR17: =IF(AND(ISNUMBER(AN17),ISNUMBER($AM17)),OFFSET(RiskMatrixRef,-$AM17+1,AN17-1),"") | AS17: =IF(AND(ISNUMBER(AO17),ISNUMBER($AM17)),OFFSET(RiskMatrixRef,-$AM17+1,AO17-1),"") | AT17: =IF(AND(ISNUMBER(AP17),ISNUMBER($AM17)),OFFSET(RiskMatrixRef,-$AM17+1,AP17-1),"") | AU17: =IF(AND(ISNUMBER(AQ17),ISNUMBER($AM17)),OFFSET(RiskMatrixRef,-$AM17+1,AQ17-1),"") | AW17: Mechanically safe because available torque is limited the load cell's rating, which is well below the mechanical design limit. | AX17: See comment in risk ID 410-10
B18: 410-12 | C18: Rail wheel load pin | D18: provides normal force on rail wheels for one stator section | E18: 1 | F18: none | G18: Signal failure | H18: 1) No load data from failed sensor | I18: Hardware or wiring failure | J18: Normal | K18: 1) Redundant sensors | L18: 1) None | M18: 1) Rail wheel load data lost | N18: Dry-dock required for repair. Single failure tolerable | O18: 8 | P18: 1 | Q18: 1 | R18: 3 | S18: 3 | T18: =IF(AND(ISNUMBER(P18),ISNUMBER($O18)),OFFSET(RiskMatrixRef,-$O18+1,P18-1),"") -> Low | U18: =IF(AND(ISNUMBER(Q18),ISNUMBER($O18)),OFFSET(RiskMatrixRef,-$O18+1,Q18-1),"") -> Low | V18: =IF(AND(ISNUMBER(R18),ISNUMBER($O18)),OFFSET(RiskMatrixRef,-$O18+1,R18-1),"") -> Low | W18: =IF(AND(ISNUMBER(S18),ISNUMBER($O18)),OFFSET(RiskMatrixRef,-$O18+1,S18-1),"") -> Low | AF18: =IF(AND(ISNUMBER(AB18),ISNUMBER($AA18)),OFFSET(RiskMatrixRef,-$AA18+1,AB18-1),"") | AG18: =IF(AND(ISNUMBER(AC18),ISNUMBER($AA18)),OFFSET(RiskMatrixRef,-$AA18+1,AC18-1),"") | AH18: =IF(AND(ISNUMBER(AD18),ISNUMBER($AA18)),OFFSET(RiskMatrixRef,-$AA18+1,AD18-1),"") | AI18: =IF(AND(ISNUMBER(AE18),ISNUMBER($AA18)),OFFSET(RiskMatrixRef,-$AA18+1,AE18-1),"") | AR18: =IF(AND(ISNUMBER(AN18),ISNUMBER($AM18)),OFFSET(RiskMatrixRef,-$AM18+1,AN18-1),"") | AS18: =IF(AND(ISNUMBER(AO18),ISNUMBER($AM18)),OFFSET(RiskMatrixRef,-$AM18+1,AO18-1),"") | AT18: =IF(AND(ISNUMBER(AP18),ISNUMBER($AM18)),OFFSET(RiskMatrixRef,-$AM18+1,AP18-1),"") | AU18: =IF(AND(ISNUMBER(AQ18),ISNUMBER($AM18)),OFFSET(RiskMatrixRef,-$AM18+1,AQ18-1),"") | AX18: See comment in risk ID 410-10
B19: 410-13 | C19: Seal gap sensor | D19: Provides seal gap position | E19: 2 | F19: new environment | G19: Signal failure | H19: 1) No seal gap data from failed sensor | I19: Hardware or wiring failure | J19: Normal | L19: 1) None | M19: 1) Seal gap data lost | N19: Dry-dock required for repair. Single failure tolerable | O19: 9 | P19: 1 | Q19: 1 | R19: 2 | S19: 2 | T19: =IF(AND(ISNUMBER(P19),ISNUMBER($O19)),OFFSET(RiskMatrixRef,-$O19+1,P19-1),"") -> Low | U19: =IF(AND(ISNUMBER(Q19),ISNUMBER($O19)),OFFSET(RiskMatrixRef,-$O19+1,Q19-1),"") -> Low | V19: =IF(AND(ISNUMBER(R19),ISNUMBER($O19)),OFFSET(RiskMatrixRef,-$O19+1,R19-1),"") -> Low | W19: =IF(AND(ISNUMBER(S19),ISNUMBER($O19)),OFFSET(RiskMatrixRef,-$O19+1,S19-1),"") -> Low | AF19: =IF(AND(ISNUMBER(AB19),ISNUMBER($AA19)),OFFSET(RiskMatrixRef,-$AA19+1,AB19-1),"") | AG19: =IF(AND(ISNUMBER(AC19),ISNUMBER($AA19)),OFFSET(RiskMatrixRef,-$AA19+1,AC19-1),"") | AH19: =IF(AND(ISNUMBER(AD19),ISNUMBER($AA19)),OFFSET(RiskMatrixRef,-$AA19+1,AD19-1),"") | AI19: =IF(AND(ISNUMBER(AE19),ISNUMBER($AA19)),OFFSET(RiskMatrixRef,-$AA19+1,AE19-1),"") | AR19: =IF(AND(ISNUMBER(AN19),ISNUMBER($AM19)),OFFSET(RiskMatrixRef,-$AM19+1,AN19-1),"") | AS19: =IF(AND(ISNUMBER(AO19),ISNUMBER($AM19)),OFFSET(RiskMatrixRef,-$AM19+1,AO19-1),"") | AT19: =IF(AND(ISNUMBER(AP19),ISNUMBER($AM19)),OFFSET(RiskMatrixRef,-$AM19+1,AP19-1),"") | AU19: =IF(AND(ISNUMBER(AQ19),ISNUMBER($AM19)),OFFSET(RiskMatrixRef,-$AM19+1,AQ19-1),"") | AW19: Operation Risk reduced further as loss of sensor data does not affect generator performance. | AX19: See comment in risk ID 410-10
B20: 410-14 | C20: Main/secondary bearing temperature | D20: Provides bearing temperatures | E20: 2 | F20: Marine application Vibration levels | G20: Signal failure | H20: 1) No bearing temp data | I20: Hardware or wiring failure | J20: Normal | K20: 1) Redundancy 4x per bearing | L20: 1) None | M20: 1) Bearing temp data lost | N20: Dry-dock required for repair. Single failure tolerable | O20: 8 | P20: 1 | Q20: 1 | R20: 2 | S20: 1 | T20: =IF(AND(ISNUMBER(P20),ISNUMBER($O20)),OFFSET(RiskMatrixRef,-$O20+1,P20-1),"") -> Low | U20: =IF(AND(ISNUMBER(Q20),ISNUMBER($O20)),OFFSET(RiskMatrixRef,-$O20+1,Q20-1),"") -> Low | V20: =IF(AND(ISNUMBER(R20),ISNUMBER($O20)),OFFSET(RiskMatrixRef,-$O20+1,R20-1),"") -> Low | W20: =IF(AND(ISNUMBER(S20),ISNUMBER($O20)),OFFSET(RiskMatrixRef,-$O20+1,S20-1),"") -> Low | AF20: =IF(AND(ISNUMBER(AB20),ISNUMBER($AA20)),OFFSET(RiskMatrixRef,-$AA20+1,AB20-1),"") | AG20: =IF(AND(ISNUMBER(AC20),ISNUMBER($AA20)),OFFSET(RiskMatrixRef,-$AA20+1,AC20-1),"") | AH20: =IF(AND(ISNUMBER(AD20),ISNUMBER($AA20)),OFFSET(RiskMatrixRef,-$AA20+1,AD20-1),"") | AI20: =IF(AND(ISNUMBER(AE20),ISNUMBER($AA20)),OFFSET(RiskMatrixRef,-$AA20+1,AE20-1),"") | AR20: =IF(AND(ISNUMBER(AN20),ISNUMBER($AM20)),OFFSET(RiskMatrixRef,-$AM20+1,AN20-1),"") | AS20: =IF(AND(ISNUMBER(AO20),ISNUMBER($AM20)),OFFSET(RiskMatrixRef,-$AM20+1,AO20-1),"") | AT20: =IF(AND(ISNUMBER(AP20),ISNUMBER($AM20)),OFFSET(RiskMatrixRef,-$AM20+1,AP20-1),"") | AU20: =IF(AND(ISNUMBER(AQ20),ISNUMBER($AM20)),OFFSET(RiskMatrixRef,-$AM20+1,AQ20-1),"") | AW20: Sensor will be rated for the environment. | AX20: See comment in risk ID 410-10
B21: 410-15 | C21: SCADA enclosure temperature | D21: Provides SCADA enclosure temperatures | E21: 2 | F21: Marine application Vibration levels | G21: Signal failure | H21: 1) No enclosure temperature | I21: Hardware or wiring failure | J21: Normal | L21: 1) None | M21: 1) SCADA enclosure data lost | N21: Manual in-situ repair and inspection | O21: 8 | P21: 1 | Q21: 1 | R21: 2 | S21: 1 | T21: =IF(AND(ISNUMBER(P21),ISNUMBER($O21)),OFFSET(RiskMatrixRef,-$O21+1,P21-1),"") -> Low | U21: =IF(AND(ISNUMBER(Q21),ISNUMBER($O21)),OFFSET(RiskMatrixRef,-$O21+1,Q21-1),"") -> Low | V21: =IF(AND(ISNUMBER(R21),ISNUMBER($O21)),OFFSET(RiskMatrixRef,-$O21+1,R21-1),"") -> Low | W21: =IF(AND(ISNUMBER(S21),ISNUMBER($O21)),OFFSET(RiskMatrixRef,-$O21+1,S21-1),"") -> Low | AF21: =IF(AND(ISNUMBER(AB21),ISNUMBER($AA21)),OFFSET(RiskMatrixRef,-$AA21+1,AB21-1),"") | AG21: =IF(AND(ISNUMBER(AC21),ISNUMBER($AA21)),OFFSET(RiskMatrixRef,-$AA21+1,AC21-1),"") | AH21: =IF(AND(ISNUMBER(AD21),ISNUMBER($AA21)),OFFSET(RiskMatrixRef,-$AA21+1,AD21-1),"") | AI21: =IF(AND(ISNUMBER(AE21),ISNUMBER($AA21)),OFFSET(RiskMatrixRef,-$AA21+1,AE21-1),"") | AR21: =IF(AND(ISNUMBER(AN21),ISNUMBER($AM21)),OFFSET(RiskMatrixRef,-$AM21+1,AN21-1),"") | AS21: =IF(AND(ISNUMBER(AO21),ISNUMBER($AM21)),OFFSET(RiskMatrixRef,-$AM21+1,AO21-1),"") | AT21: =IF(AND(ISNUMBER(AP21),ISNUMBER($AM21)),OFFSET(RiskMatrixRef,-$AM21+1,AP21-1),"") | AU21: =IF(AND(ISNUMBER(AQ21),ISNUMBER($AM21)),OFFSET(RiskMatrixRef,-$AM21+1,AQ21-1),"") | AW21: Sensor will be rated for the environment. | AX21: See comment in risk ID 410-10
B22: 410-16 | C22: PTO module temperature | D22: Provides PTO structure temperatures | E22: 2 | F22: Marine application Vibration levels | G22: Signal failure | H22: 1) No PTO structure temperature | I22: Hardware or wiring failure | J22: Normal | L22: 1) None | M22: 1) PTO structure temp data lost | N22: Manual in-situ repair and inspection | O22: 8 | P22: 1 | Q22: 1 | R22: 2 | S22: 1 | T22: =IF(AND(ISNUMBER(P22),ISNUMBER($O22)),OFFSET(RiskMatrixRef,-$O22+1,P22-1),"") -> Low | U22: =IF(AND(ISNUMBER(Q22),ISNUMBER($O22)),OFFSET(RiskMatrixRef,-$O22+1,Q22-1),"") -> Low | V22: =IF(AND(ISNUMBER(R22),ISNUMBER($O22)),OFFSET(RiskMatrixRef,-$O22+1,R22-1),"") -> Low | W22: =IF(AND(ISNUMBER(S22),ISNUMBER($O22)),OFFSET(RiskMatrixRef,-$O22+1,S22-1),"") -> Low | AF22: =IF(AND(ISNUMBER(AB22),ISNUMBER($AA22)),OFFSET(RiskMatrixRef,-$AA22+1,AB22-1),"") | AG22: =IF(AND(ISNUMBER(AC22),ISNUMBER($AA22)),OFFSET(RiskMatrixRef,-$AA22+1,AC22-1),"") | AH22: =IF(AND(ISNUMBER(AD22),ISNUMBER($AA22)),OFFSET(RiskMatrixRef,-$AA22+1,AD22-1),"") | AI22: =IF(AND(ISNUMBER(AE22),ISNUMBER($AA22)),OFFSET(RiskMatrixRef,-$AA22+1,AE22-1),"") | AR22: =IF(AND(ISNUMBER(AN22),ISNUMBER($AM22)),OFFSET(RiskMatrixRef,-$AM22+1,AN22-1),"") | AS22: =IF(AND(ISNUMBER(AO22),ISNUMBER($AM22)),OFFSET(RiskMatrixRef,-$AM22+1,AO22-1),"") | AT22: =IF(AND(ISNUMBER(AP22),ISNUMBER($AM22)),OFFSET(RiskMatrixRef,-$AM22+1,AP22-1),"") | AU22: =IF(AND(ISNUMBER(AQ22),ISNUMBER($AM22)),OFFSET(RiskMatrixRef,-$AM22+1,AQ22-1),"") | AW22: Sensor will be rated for the environment. | AX22: See comment in risk ID 410-10
B23: 410-17 | C23: PTO module humidity | D23: Provides PTO structure humidity | E23: 2 | F23: Marine application Vibration levels | G23: Signal failure | H23: 1) No PTO structure humidity | I23: Hardware or wiring failure | J23: Normal | L23: 1) None | M23: 1) PTO structure humidity data lost | N23: Manual in-situ repair and inspection | O23: 8 | P23: 1 | Q23: 1 | R23: 2 | S23: 1 | T23: =IF(AND(ISNUMBER(P23),ISNUMBER($O23)),OFFSET(RiskMatrixRef,-$O23+1,P23-1),"") -> Low | U23: =IF(AND(ISNUMBER(Q23),ISNUMBER($O23)),OFFSET(RiskMatrixRef,-$O23+1,Q23-1),"") -> Low | V23: =IF(AND(ISNUMBER(R23),ISNUMBER($O23)),OFFSET(RiskMatrixRef,-$O23+1,R23-1),"") -> Low | W23: =IF(AND(ISNUMBER(S23),ISNUMBER($O23)),OFFSET(RiskMatrixRef,-$O23+1,S23-1),"") -> Low | AF23: =IF(AND(ISNUMBER(AB23),ISNUMBER($AA23)),OFFSET(RiskMatrixRef,-$AA23+1,AB23-1),"") | AG23: =IF(AND(ISNUMBER(AC23),ISNUMBER($AA23)),OFFSET(RiskMatrixRef,-$AA23+1,AC23-1),"") | AH23: =IF(AND(ISNUMBER(AD23),ISNUMBER($AA23)),OFFSET(RiskMatrixRef,-$AA23+1,AD23-1),"") | AI23: =IF(AND(ISNUMBER(AE23),ISNUMBER($AA23)),OFFSET(RiskMatrixRef,-$AA23+1,AE23-1),"") | AR23: =IF(AND(ISNUMBER(AN23),ISNUMBER($AM23)),OFFSET(RiskMatrixRef,-$AM23+1,AN23-1),"") | AS23: =IF(AND(ISNUMBER(AO23),ISNUMBER($AM23)),OFFSET(RiskMatrixRef,-$AM23+1,AO23-1),"") | AT23: =IF(AND(ISNUMBER(AP23),ISNUMBER($AM23)),OFFSET(RiskMatrixRef,-$AM23+1,AP23-1),"") | AU23: =IF(AND(ISNUMBER(AQ23),ISNUMBER($AM23)),OFFSET(RiskMatrixRef,-$AM23+1,AQ23-1),"") | AW23: Sensor will be rated for the environment. | AX23: See comment in risk ID 410-10
B24: 410-18 | C24: Control room temperature | D24: Provides control room temperatures | E24: 2 | F24: Marine application Vibration levels | G24: Signal failure | H24: 1) No control room temperature | I24: Hardware or wiring failure | J24: Normal | L24: 1) None | M24: 1) Control room temp data lost | N24: Manual in-situ repair and inspection | O24: 8 | P24: 1 | Q24: 1 | R24: 2 | S24: 1 | T24: =IF(AND(ISNUMBER(P24),ISNUMBER($O24)),OFFSET(RiskMatrixRef,-$O24+1,P24-1),"") -> Low | U24: =IF(AND(ISNUMBER(Q24),ISNUMBER($O24)),OFFSET(RiskMatrixRef,-$O24+1,Q24-1),"") -> Low | V24: =IF(AND(ISNUMBER(R24),ISNUMBER($O24)),OFFSET(RiskMatrixRef,-$O24+1,R24-1),"") -> Low | W24: =IF(AND(ISNUMBER(S24),ISNUMBER($O24)),OFFSET(RiskMatrixRef,-$O24+1,S24-1),"") -> Low | AF24: =IF(AND(ISNUMBER(AB24),ISNUMBER($AA24)),OFFSET(RiskMatrixRef,-$AA24+1,AB24-1),"") | AG24: =IF(AND(ISNUMBER(AC24),ISNUMBER($AA24)),OFFSET(RiskMatrixRef,-$AA24+1,AC24-1),"") | AH24: =IF(AND(ISNUMBER(AD24),ISNUMBER($AA24)),OFFSET(RiskMatrixRef,-$AA24+1,AD24-1),"") | AI24: =IF(AND(ISNUMBER(AE24),ISNUMBER($AA24)),OFFSET(RiskMatrixRef,-$AA24+1,AE24-1),"") | AR24: =IF(AND(ISNUMBER(AN24),ISNUMBER($AM24)),OFFSET(RiskMatrixRef,-$AM24+1,AN24-1),"") | AS24: =IF(AND(ISNUMBER(AO24),ISNUMBER($AM24)),OFFSET(RiskMatrixRef,-$AM24+1,AO24-1),"") | AT24: =IF(AND(ISNUMBER(AP24),ISNUMBER($AM24)),OFFSET(RiskMatrixRef,-$AM24+1,AP24-1),"") | AU24: =IF(AND(ISNUMBER(AQ24),ISNUMBER($AM24)),OFFSET(RiskMatrixRef,-$AM24+1,AQ24-1),"") | AW24: Sensor will be rated for the environment. | AX24: See comment in risk ID 410-10
B25: 410-19 | C25: Control room humidity | D25: Provides control room structure humidity | E25: 2 | F25: Marine application Vibration levels | G25: Signal failure | H25: 1) No control room humidity | I25: Hardware or wiring failure | J25: Normal | L25: 1) None | M25: 1) Control room humidity data lost | N25: Manual in-situ repair and inspection | O25: 8 | P25: 1 | Q25: 1 | R25: 2 | S25: 1 | T25: =IF(AND(ISNUMBER(P25),ISNUMBER($O25)),OFFSET(RiskMatrixRef,-$O25+1,P25-1),"") -> Low | U25: =IF(AND(ISNUMBER(Q25),ISNUMBER($O25)),OFFSET(RiskMatrixRef,-$O25+1,Q25-1),"") -> Low | V25: =IF(AND(ISNUMBER(R25),ISNUMBER($O25)),OFFSET(RiskMatrixRef,-$O25+1,R25-1),"") -> Low | W25: =IF(AND(ISNUMBER(S25),ISNUMBER($O25)),OFFSET(RiskMatrixRef,-$O25+1,S25-1),"") -> Low | AF25: =IF(AND(ISNUMBER(AB25),ISNUMBER($AA25)),OFFSET(RiskMatrixRef,-$AA25+1,AB25-1),"") | AG25: =IF(AND(ISNUMBER(AC25),ISNUMBER($AA25)),OFFSET(RiskMatrixRef,-$AA25+1,AC25-1),"") | AH25: =IF(AND(ISNUMBER(AD25),ISNUMBER($AA25)),OFFSET(RiskMatrixRef,-$AA25+1,AD25-1),"") | AI25: =IF(AND(ISNUMBER(AE25),ISNUMBER($AA25)),OFFSET(RiskMatrixRef,-$AA25+1,AE25-1),"") | AR25: =IF(AND(ISNUMBER(AN25),ISNUMBER($AM25)),OFFSET(RiskMatrixRef,-$AM25+1,AN25-1),"") | AS25: =IF(AND(ISNUMBER(AO25),ISNUMBER($AM25)),OFFSET(RiskMatrixRef,-$AM25+1,AO25-1),"") | AT25: =IF(AND(ISNUMBER(AP25),ISNUMBER($AM25)),OFFSET(RiskMatrixRef,-$AM25+1,AP25-1),"") | AU25: =IF(AND(ISNUMBER(AQ25),ISNUMBER($AM25)),OFFSET(RiskMatrixRef,-$AM25+1,AQ25-1),"") | AW25: Sensor will be rated for the environment. | AX25: See comment in risk ID 410-10
B26: 410-20 | C26: Stator sensor temperatures | D26: Provides sensor temperatures | E26: 2 | F26: Marine application Vibration levels | G26: Signal failure | H26: 1) No sensor temp data from failed sensor | I26: Hardware or wiring failure | J26: Normal | L26: 1) None | M26: 1) Sensor temp data lost | N26: Dry-dock required for repair. Single failure tolerable | O26: 8 | P26: 1 | Q26: 1 | R26: 2 | S26: 1 | T26: =IF(AND(ISNUMBER(P26),ISNUMBER($O26)),OFFSET(RiskMatrixRef,-$O26+1,P26-1),"") -> Low | U26: =IF(AND(ISNUMBER(Q26),ISNUMBER($O26)),OFFSET(RiskMatrixRef,-$O26+1,Q26-1),"") -> Low | V26: =IF(AND(ISNUMBER(R26),ISNUMBER($O26)),OFFSET(RiskMatrixRef,-$O26+1,R26-1),"") -> Low | W26: =IF(AND(ISNUMBER(S26),ISNUMBER($O26)),OFFSET(RiskMatrixRef,-$O26+1,S26-1),"") -> Low | AF26: =IF(AND(ISNUMBER(AB26),ISNUMBER($AA26)),OFFSET(RiskMatrixRef,-$AA26+1,AB26-1),"") | AG26: =IF(AND(ISNUMBER(AC26),ISNUMBER($AA26)),OFFSET(RiskMatrixRef,-$AA26+1,AC26-1),"") | AH26: =IF(AND(ISNUMBER(AD26),ISNUMBER($AA26)),OFFSET(RiskMatrixRef,-$AA26+1,AD26-1),"") | AI26: =IF(AND(ISNUMBER(AE26),ISNUMBER($AA26)),OFFSET(RiskMatrixRef,-$AA26+1,AE26-1),"") | AR26: =IF(AND(ISNUMBER(AN26),ISNUMBER($AM26)),OFFSET(RiskMatrixRef,-$AM26+1,AN26-1),"") | AS26: =IF(AND(ISNUMBER(AO26),ISNUMBER($AM26)),OFFSET(RiskMatrixRef,-$AM26+1,AO26-1),"") | AT26: =IF(AND(ISNUMBER(AP26),ISNUMBER($AM26)),OFFSET(RiskMatrixRef,-$AM26+1,AP26-1),"") | AU26: =IF(AND(ISNUMBER(AQ26),ISNUMBER($AM26)),OFFSET(RiskMatrixRef,-$AM26+1,AQ26-1),"") | AW26: Sensor will be rated for the environment. | AX26: See comment in risk ID 410-10
B27: 410-21 | C27: Station power draw | D27: Provides station power draw | E27: 2 | F27: Marine application Vibration levels | G27: Signal failure | H27: 1) No station power draw data | I27: Hardware or wiring failure | J27: Normal | L27: 1) None | M27: 1) Station power data lost | N27: Manual in-situ repair and inspection | O27: 8 | P27: 1 | Q27: 1 | R27: 2 | S27: 2 | T27: =IF(AND(ISNUMBER(P27),ISNUMBER($O27)),OFFSET(RiskMatrixRef,-$O27+1,P27-1),"") -> Low | U27: =IF(AND(ISNUMBER(Q27),ISNUMBER($O27)),OFFSET(RiskMatrixRef,-$O27+1,Q27-1),"") -> Low | V27: =IF(AND(ISNUMBER(R27),ISNUMBER($O27)),OFFSET(RiskMatrixRef,-$O27+1,R27-1),"") -> Low | W27: =IF(AND(ISNUMBER(S27),ISNUMBER($O27)),OFFSET(RiskMatrixRef,-$O27+1,S27-1),"") -> Low | AF27: =IF(AND(ISNUMBER(AB27),ISNUMBER($AA27)),OFFSET(RiskMatrixRef,-$AA27+1,AB27-1),"") | AG27: =IF(AND(ISNUMBER(AC27),ISNUMBER($AA27)),OFFSET(RiskMatrixRef,-$AA27+1,AC27-1),"") | AH27: =IF(AND(ISNUMBER(AD27),ISNUMBER($AA27)),OFFSET(RiskMatrixRef,-$AA27+1,AD27-1),"") | AI27: =IF(AND(ISNUMBER(AE27),ISNUMBER($AA27)),OFFSET(RiskMatrixRef,-$AA27+1,AE27-1),"") | AR27: =IF(AND(ISNUMBER(AN27),ISNUMBER($AM27)),OFFSET(RiskMatrixRef,-$AM27+1,AN27-1),"") | AS27: =IF(AND(ISNUMBER(AO27),ISNUMBER($AM27)),OFFSET(RiskMatrixRef,-$AM27+1,AO27-1),"") | AT27: =IF(AND(ISNUMBER(AP27),ISNUMBER($AM27)),OFFSET(RiskMatrixRef,-$AM27+1,AP27-1),"") | AU27: =IF(AND(ISNUMBER(AQ27),ISNUMBER($AM27)),OFFSET(RiskMatrixRef,-$AM27+1,AQ27-1),"") | AW27: Sensor will be rated for the environment. | AX27: See comment in risk ID 410-10
B28: 410-22 | C28: Bilge water level | D28: Provide bilge water level | E28: 1 | F28: none | G28: Signal failure | H28: 1) No bilge water level data from failed sensor | I28: Hardware or wiring failure | J28: Normal | K28: 1) Redundancy | L28: 1) None | M28: 1) Bilge level data lost | N28: Manual in-situ repair and inspection | O28: 8 | P28: 1 | Q28: 1 | R28: 3 | S28: 1 | T28: =IF(AND(ISNUMBER(P28),ISNUMBER($O28)),OFFSET(RiskMatrixRef,-$O28+1,P28-1),"") -> Low | U28: =IF(AND(ISNUMBER(Q28),ISNUMBER($O28)),OFFSET(RiskMatrixRef,-$O28+1,Q28-1),"") -> Low | V28: =IF(AND(ISNUMBER(R28),ISNUMBER($O28)),OFFSET(RiskMatrixRef,-$O28+1,R28-1),"") -> Low | W28: =IF(AND(ISNUMBER(S28),ISNUMBER($O28)),OFFSET(RiskMatrixRef,-$O28+1,S28-1),"") -> Low | AF28: =IF(AND(ISNUMBER(AB28),ISNUMBER($AA28)),OFFSET(RiskMatrixRef,-$AA28+1,AB28-1),"") | AG28: =IF(AND(ISNUMBER(AC28),ISNUMBER($AA28)),OFFSET(RiskMatrixRef,-$AA28+1,AC28-1),"") | AH28: =IF(AND(ISNUMBER(AD28),ISNUMBER($AA28)),OFFSET(RiskMatrixRef,-$AA28+1,AD28-1),"") | AI28: =IF(AND(ISNUMBER(AE28),ISNUMBER($AA28)),OFFSET(RiskMatrixRef,-$AA28+1,AE28-1),"") | AR28: =IF(AND(ISNUMBER(AN28),ISNUMBER($AM28)),OFFSET(RiskMatrixRef,-$AM28+1,AN28-1),"") | AS28: =IF(AND(ISNUMBER(AO28),ISNUMBER($AM28)),OFFSET(RiskMatrixRef,-$AM28+1,AO28-1),"") | AT28: =IF(AND(ISNUMBER(AP28),ISNUMBER($AM28)),OFFSET(RiskMatrixRef,-$AM28+1,AP28-1),"") | AU28: =IF(AND(ISNUMBER(AQ28),ISNUMBER($AM28)),OFFSET(RiskMatrixRef,-$AM28+1,AQ28-1),"") | AW28: Safe (accessible) side of PTO module and redundant sensors rated for the environment. | AX28: Is this required signal for start of bilge pump? Severity class to be higher if failure of sensor could lead to water ingress into electrical equipment.
B29: 410-23 | C29: Bilge pump status | D29: Provides bilge pump status data | E29: 1 | F29: none | G29: Signal failure | H29: 1) No bilge pump status | I29: Hardware or wiring failure | J29: Normal | K29: 1) Redundant systems | L29: 1) None | M29: 1) Comparison to float switch data | N29: Manual in-situ repair and inspection | O29: 8 | P29: 1 | Q29: 1 | R29: 2 | S29: 1 | T29: =IF(AND(ISNUMBER(P29),ISNUMBER($O29)),OFFSET(RiskMatrixRef,-$O29+1,P29-1),"") -> Low | U29: =IF(AND(ISNUMBER(Q29),ISNUMBER($O29)),OFFSET(RiskMatrixRef,-$O29+1,Q29-1),"") -> Low | V29: =IF(AND(ISNUMBER(R29),ISNUMBER($O29)),OFFSET(RiskMatrixRef,-$O29+1,R29-1),"") -> Low | W29: =IF(AND(ISNUMBER(S29),ISNUMBER($O29)),OFFSET(RiskMatrixRef,-$O29+1,S29-1),"") -> Low | AW29: Sensor will be rated for the environment and redundant sensors. | AX29: Is this required signal for start of bilge pump? Severity class to be higher if failure of sensor could lead to water ingress into electrical equipment.
B30: 410-24 | C30: Cooling temp, pressure, flow sensor | D30: Provides cooling data | E30: 1 | F30: none | G30: Signal failure | H30: 1) No cooling data from failed sensor | I30: Hardware or wiring failure | J30: Normal | L30: 1) None | M30: 1) Cooling parameter data lost | N30: Manual in-situ repair and inspection | O30: 8 | P30: 1 | Q30: 1 | R30: 3 | S30: 2 | T30: =IF(AND(ISNUMBER(P30),ISNUMBER($O30)),OFFSET(RiskMatrixRef,-$O30+1,P30-1),"") -> Low | U30: =IF(AND(ISNUMBER(Q30),ISNUMBER($O30)),OFFSET(RiskMatrixRef,-$O30+1,Q30-1),"") -> Low | V30: =IF(AND(ISNUMBER(R30),ISNUMBER($O30)),OFFSET(RiskMatrixRef,-$O30+1,R30-1),"") -> Low | W30: =IF(AND(ISNUMBER(S30),ISNUMBER($O30)),OFFSET(RiskMatrixRef,-$O30+1,S30-1),"") -> Low | AF30: =IF(AND(ISNUMBER(AB30),ISNUMBER($AA30)),OFFSET(RiskMatrixRef,-$AA30+1,AB30-1),"") | AG30: =IF(AND(ISNUMBER(AC30),ISNUMBER($AA30)),OFFSET(RiskMatrixRef,-$AA30+1,AC30-1),"") | AH30: =IF(AND(ISNUMBER(AD30),ISNUMBER($AA30)),OFFSET(RiskMatrixRef,-$AA30+1,AD30-1),"") | AI30: =IF(AND(ISNUMBER(AE30),ISNUMBER($AA30)),OFFSET(RiskMatrixRef,-$AA30+1,AE30-1),"") | AR30: =IF(AND(ISNUMBER(AN30),ISNUMBER($AM30)),OFFSET(RiskMatrixRef,-$AM30+1,AN30-1),"") | AS30: =IF(AND(ISNUMBER(AO30),ISNUMBER($AM30)),OFFSET(RiskMatrixRef,-$AM30+1,AO30-1),"") | AT30: =IF(AND(ISNUMBER(AP30),ISNUMBER($AM30)),OFFSET(RiskMatrixRef,-$AM30+1,AP30-1),"") | AU30: =IF(AND(ISNUMBER(AQ30),ISNUMBER($AM30)),OFFSET(RiskMatrixRef,-$AM30+1,AQ30-1),"") | AW30: Sensor will be rated for the environment and redundant sensors. | AX30: Is failure of sensor only for collection of data, i.e. the cooling system runs continuously during operation therefore not relying on start/stop signals resulting from the data collected by these sensors. Failure of cooling system would have higher severity class
B31: 410-25 | C31: Fibber optic strain measurement | D31: Provides strain data | E31: 1 | F31: none | G31: Signal failure | H31: 1) No strain data from failed sensor | I31: Hardware or wiring failure | J31: Normal | K31: 1) Redundancy | L31: 1) None | M31: 1) Strain data lost | N31: 1) Interrogator repairable in-situ 2) Single failure tolerable for strain gauge array requires dry dock repair | O31: 8 | P31: 1 | Q31: 1 | R31: 3 | S31: 3 | T31: =IF(AND(ISNUMBER(P31),ISNUMBER($O31)),OFFSET(RiskMatrixRef,-$O31+1,P31-1),"") -> Low | U31: =IF(AND(ISNUMBER(Q31),ISNUMBER($O31)),OFFSET(RiskMatrixRef,-$O31+1,Q31-1),"") -> Low | V31: =IF(AND(ISNUMBER(R31),ISNUMBER($O31)),OFFSET(RiskMatrixRef,-$O31+1,R31-1),"") -> Low | W31: =IF(AND(ISNUMBER(S31),ISNUMBER($O31)),OFFSET(RiskMatrixRef,-$O31+1,S31-1),"") -> Low | AF31: =IF(AND(ISNUMBER(AB31),ISNUMBER($AA31)),OFFSET(RiskMatrixRef,-$AA31+1,AB31-1),"") | AG31: =IF(AND(ISNUMBER(AC31),ISNUMBER($AA31)),OFFSET(RiskMatrixRef,-$AA31+1,AC31-1),"") | AH31: =IF(AND(ISNUMBER(AD31),ISNUMBER($AA31)),OFFSET(RiskMatrixRef,-$AA31+1,AD31-1),"") | AI31: =IF(AND(ISNUMBER(AE31),ISNUMBER($AA31)),OFFSET(RiskMatrixRef,-$AA31+1,AE31-1),"") | AR31: =IF(AND(ISNUMBER(AN31),ISNUMBER($AM31)),OFFSET(RiskMatrixRef,-$AM31+1,AN31-1),"") | AS31: =IF(AND(ISNUMBER(AO31),ISNUMBER($AM31)),OFFSET(RiskMatrixRef,-$AM31+1,AO31-1),"") | AT31: =IF(AND(ISNUMBER(AP31),ISNUMBER($AM31)),OFFSET(RiskMatrixRef,-$AM31+1,AP31-1),"") | AU31: =IF(AND(ISNUMBER(AQ31),ISNUMBER($AM31)),OFFSET(RiskMatrixRef,-$AM31+1,AQ31-1),"") | AW31: Sensor will be rated for the environment. | AX31: See comment in risk ID 410-10
B32: 410-26 | C32: Inertial measurement unit (IMU) | D32: Provides nacelle body motion data | E32: 1 | F32: none | G32: Signal failure | H32: 1) No motion data from failed sensor | I32: Hardware or wiring failure | J32: Normal | K32: 1) Redundancy | L32: 1) None | M32: 1) IMU data lost | N32: Manual in-situ repair and inspection | O32: 8 | P32: 1 | Q32: 1 | R32: 3 | S32: 3 | T32: =IF(AND(ISNUMBER(P32),ISNUMBER($O32)),OFFSET(RiskMatrixRef,-$O32+1,P32-1),"") -> Low | U32: =IF(AND(ISNUMBER(Q32),ISNUMBER($O32)),OFFSET(RiskMatrixRef,-$O32+1,Q32-1),"") -> Low | V32: =IF(AND(ISNUMBER(R32),ISNUMBER($O32)),OFFSET(RiskMatrixRef,-$O32+1,R32-1),"") -> Low | W32: =IF(AND(ISNUMBER(S32),ISNUMBER($O32)),OFFSET(RiskMatrixRef,-$O32+1,S32-1),"") -> Low | AW32: Sensor will be rated for the environment. | AX32: See comment in risk ID 410-10
B33: 410-27 | C33: Communication with M2G | D33: Communicates all M2G data and PTO control commands | E33: 1 | F33: none | G33: Signal failure | H33: 1) No M2G data 2) PTO goes to default control mode in absence of SCADA communication | I33: Hardware or wiring failure | J33: Normal | K33: 1) V&V | L33: 1) None | M33: 1) M2G data lost 2) PTO control not responding | N33: Manual in-situ repair and inspection | O33: 7 | P33: 1 | Q33: 1 | R33: 3 | S33: 3 | T33: =IF(AND(ISNUMBER(P33),ISNUMBER($O33)),OFFSET(RiskMatrixRef,-$O33+1,P33-1),"") -> Low | U33: =IF(AND(ISNUMBER(Q33),ISNUMBER($O33)),OFFSET(RiskMatrixRef,-$O33+1,Q33-1),"") -> Low | V33: =IF(AND(ISNUMBER(R33),ISNUMBER($O33)),OFFSET(RiskMatrixRef,-$O33+1,R33-1),"") -> Low | W33: =IF(AND(ISNUMBER(S33),ISNUMBER($O33)),OFFSET(RiskMatrixRef,-$O33+1,S33-1),"") -> Low | AF33: =IF(AND(ISNUMBER(AB33),ISNUMBER($AA33)),OFFSET(RiskMatrixRef,-$AA33+1,AB33-1),"") | AG33: =IF(AND(ISNUMBER(AC33),ISNUMBER($AA33)),OFFSET(RiskMatrixRef,-$AA33+1,AC33-1),"") | AH33: =IF(AND(ISNUMBER(AD33),ISNUMBER($AA33)),OFFSET(RiskMatrixRef,-$AA33+1,AD33-1),"") | AI33: =IF(AND(ISNUMBER(AE33),ISNUMBER($AA33)),OFFSET(RiskMatrixRef,-$AA33+1,AE33-1),"") | AR33: =IF(AND(ISNUMBER(AN33),ISNUMBER($AM33)),OFFSET(RiskMatrixRef,-$AM33+1,AN33-1),"") | AS33: =IF(AND(ISNUMBER(AO33),ISNUMBER($AM33)),OFFSET(RiskMatrixRef,-$AM33+1,AO33-1),"") | AT33: =IF(AND(ISNUMBER(AP33),ISNUMBER($AM33)),OFFSET(RiskMatrixRef,-$AM33+1,AP33-1),"") | AU33: =IF(AND(ISNUMBER(AQ33),ISNUMBER($AM33)),OFFSET(RiskMatrixRef,-$AM33+1,AQ33-1),"") | AW33: PTO goes to default control mode in absence of SCADA communication | AX33: If loss of PTO control higher consequence? CP to suggest mitigation actions for loss of control?
B34: 410-28 | C34: Real-time AWAC/ADV connection | D34: Provide real-time AWAC data | E34: 1 | F34: none | G34: Signal failure | H34: 1) No AWAC data available | I34: Hardware or wiring failure | J34: Normal | K34: 1) Data can be downloaded later | L34: 1) None | M34: 1) No AWAC data available in real-time | N34: Manual in-situ repair and inspection | O34: 8 | P34: 1 | Q34: 1 | R34: 2 | S34: 3 | T34: =IF(AND(ISNUMBER(P34),ISNUMBER($O34)),OFFSET(RiskMatrixRef,-$O34+1,P34-1),"") -> Low | U34: =IF(AND(ISNUMBER(Q34),ISNUMBER($O34)),OFFSET(RiskMatrixRef,-$O34+1,Q34-1),"") -> Low | V34: =IF(AND(ISNUMBER(R34),ISNUMBER($O34)),OFFSET(RiskMatrixRef,-$O34+1,R34-1),"") -> Low | W34: =IF(AND(ISNUMBER(S34),ISNUMBER($O34)),OFFSET(RiskMatrixRef,-$O34+1,S34-1),"") -> Low | AW34: Real time data not used in control. | AX34: See comment in risk ID 410-10
B35: 410-29 | C35: Anemometer | D35: Provide wind speed and direction | E35: 1 | F35: none | G35: Signal failure | H35: 1) No WEC wind data | I35: Hardware or wiring failure | J35: Normal | K35: none | L35: 1) None | M35: 1) Wind data lost | N35: Manual in-situ repair and inspection | O35: 9 | P35: 1 | Q35: 1 | R35: 2 | S35: 2 | T35: =IF(AND(ISNUMBER(P35),ISNUMBER($O35)),OFFSET(RiskMatrixRef,-$O35+1,P35-1),"") -> Low | U35: =IF(AND(ISNUMBER(Q35),ISNUMBER($O35)),OFFSET(RiskMatrixRef,-$O35+1,Q35-1),"") -> Low | V35: =IF(AND(ISNUMBER(R35),ISNUMBER($O35)),OFFSET(RiskMatrixRef,-$O35+1,R35-1),"") -> Low | W35: =IF(AND(ISNUMBER(S35),ISNUMBER($O35)),OFFSET(RiskMatrixRef,-$O35+1,S35-1),"") -> Low | AW35: Sensor will be rated for the environment. | AX35: See comment in risk ID 410-10
B36: 410-30 | C36: GPS & heading sensor | D36: Provide GPS position and heading | E36: 1 | F36: none | G36: Signal failure | H36: 1) No GPS position or heading data from failed sensor | I36: Hardware or wiring failure | J36: Normal | K36: 1) Redundancy | L36: 1) None | M36: 1) GPS & heading data lost | N36: Manual in-situ repair and inspection | O36: 8 | P36: 1 | Q36: 1 | R36: 2 | S36: 2 | T36: =IF(AND(ISNUMBER(P36),ISNUMBER($O36)),OFFSET(RiskMatrixRef,-$O36+1,P36-1),"") -> Low | U36: =IF(AND(ISNUMBER(Q36),ISNUMBER($O36)),OFFSET(RiskMatrixRef,-$O36+1,Q36-1),"") -> Low | V36: =IF(AND(ISNUMBER(R36),ISNUMBER($O36)),OFFSET(RiskMatrixRef,-$O36+1,R36-1),"") -> Low | W36: =IF(AND(ISNUMBER(S36),ISNUMBER($O36)),OFFSET(RiskMatrixRef,-$O36+1,S36-1),"") -> Low | AW36: Sensor will be rated for the environment. | AX36: See comment in risk ID 410-10
B37: 410-31 | C37: Mooring load cell | D37: Provide mooring load data | E37: 1 | F37: none | G37: Signal failure | H37: 1) No mooring tension from failed sensor | I37: Hardware or wiring failure | J37: Normal | K37: 1) Redundancy 2) Mechanical safety bypass of load cell | L37: 1) Inspection | M37: 1) Mooring data lost | N37: Manual in-situ repair and inspection | O37: 9 | P37: 1 | Q37: 1 | R37: 2 | S37: 4 | T37: =IF(AND(ISNUMBER(P37),ISNUMBER($O37)),OFFSET(RiskMatrixRef,-$O37+1,P37-1),"") -> Low | U37: =IF(AND(ISNUMBER(Q37),ISNUMBER($O37)),OFFSET(RiskMatrixRef,-$O37+1,Q37-1),"") -> Low | V37: =IF(AND(ISNUMBER(R37),ISNUMBER($O37)),OFFSET(RiskMatrixRef,-$O37+1,R37-1),"") -> Low | W37: =IF(AND(ISNUMBER(S37),ISNUMBER($O37)),OFFSET(RiskMatrixRef,-$O37+1,S37-1),"") -> Med | AW37: Load cells and cabling will be rated for the environment. | AX37: See comment in risk ID 410-10
B38: 410-9 | C38: Power supply | D38: Provide power to SCADA | E38: 1 | F38: none | G38: SCADA offline | H38: 1) No SCADA data 2) PTO goes to defaul control mode 3) Cooling controlers go to default control mode | I38: Power supply failure - corrosion induced - vibration or motion induced - water induced | J38: Normal | K38: 1) Power supply Redundancy 2) Functional redundancy of SCADA components 3) Individual controllers have default modes of operation in absense of SCADA comm. | L38: 1) Status of individual PS | M38: 1) No SCADA | N38: Manual in-situ repair and inspection | O38: 7 | P38: 1 | Q38: 1 | R38: 5 | S38: 3 | T38: =IF(AND(ISNUMBER(P38),ISNUMBER($O38)),OFFSET(RiskMatrixRef,-$O38+1,P38-1),"") -> Low | U38: =IF(AND(ISNUMBER(Q38),ISNUMBER($O38)),OFFSET(RiskMatrixRef,-$O38+1,Q38-1),"") -> Low | V38: =IF(AND(ISNUMBER(R38),ISNUMBER($O38)),OFFSET(RiskMatrixRef,-$O38+1,R38-1),"") -> Med | W38: =IF(AND(ISNUMBER(S38),ISNUMBER($O38)),OFFSET(RiskMatrixRef,-$O38+1,S38-1),"") -> Low | AW38: Power supply will be rated for the environment. All failure causes fall into the same risk rankings and so kept in one Risk ID. | AX38: More specific failure mode analysis required, see the suggested breakdown directly below.
B39: 410-32 | C39: Vibration accelerometer | D39: Provide vibration data | E39: 1 | F39: none | G39: Signal failure | H39: 1) No vibration data from failed sensor | I39: Hardware or wiring failure | J39: Normal | K39: 1) Redundancy | L39: 1) None | M39: 1) Data lost | N39: Manual in-situ repair and inspection on most locations | O39: 8 | P39: 1 | Q39: 1 | R39: 3 | S39: 3 | T39: =IF(AND(ISNUMBER(P39),ISNUMBER($O39)),OFFSET(RiskMatrixRef,-$O39+1,P39-1),"") -> Low | U39: =IF(AND(ISNUMBER(Q39),ISNUMBER($O39)),OFFSET(RiskMatrixRef,-$O39+1,Q39-1),"") -> Low | V39: =IF(AND(ISNUMBER(R39),ISNUMBER($O39)),OFFSET(RiskMatrixRef,-$O39+1,R39-1),"") -> Low | W39: =IF(AND(ISNUMBER(S39),ISNUMBER($O39)),OFFSET(RiskMatrixRef,-$O39+1,S39-1),"") -> Low | AW39: Sensor will be rated for the environment. | AX39: See comment in risk ID 410-10
B40: 430-1 | C40: PLC | D40: Issue cooling commands | E40: 1 2 | F40: none Marine application Vibration levels | G40: PLC Failure | H40: 1) PTO command failure 2) Cooling system command failure 3) Alarming failure | I40: Corrosion induced failure short circuit | J40: Normal | K40: 1) Marine rated corrosion resistant design 2) Sealed enclosure 3) PTO goes to default control mode in absence of SCADA communication | L40: 1) Visual inspection 2) Fault detection of primary PLC | M40: 1) Primary PLC torque command 2) Primary PLC cooling command | N40: Manual in-situ repair and inspection | O40: 5 | P40: 1 | Q40: 1 | R40: 6 | S40: 4 | T40: =IF(AND(ISNUMBER(P40),ISNUMBER($O40)),OFFSET(RiskMatrixRef,-$O40+1,P40-1),"") -> Low | U40: =IF(AND(ISNUMBER(Q40),ISNUMBER($O40)),OFFSET(RiskMatrixRef,-$O40+1,Q40-1),"") -> Low | V40: =IF(AND(ISNUMBER(R40),ISNUMBER($O40)),OFFSET(RiskMatrixRef,-$O40+1,R40-1),"") -> Low | W40: =IF(AND(ISNUMBER(S40),ISNUMBER($O40)),OFFSET(RiskMatrixRef,-$O40+1,S40-1),"") -> Low | AF40: =IF(AND(ISNUMBER(AB40),ISNUMBER($AA40)),OFFSET(RiskMatrixRef,-$AA40+1,AB40-1),"") | AG40: =IF(AND(ISNUMBER(AC40),ISNUMBER($AA40)),OFFSET(RiskMatrixRef,-$AA40+1,AC40-1),"") | AH40: =IF(AND(ISNUMBER(AD40),ISNUMBER($AA40)),OFFSET(RiskMatrixRef,-$AA40+1,AD40-1),"") | AI40: =IF(AND(ISNUMBER(AE40),ISNUMBER($AA40)),OFFSET(RiskMatrixRef,-$AA40+1,AE40-1),"") | AR40: =IF(AND(ISNUMBER(AN40),ISNUMBER($AM40)),OFFSET(RiskMatrixRef,-$AM40+1,AN40-1),"") | AS40: =IF(AND(ISNUMBER(AO40),ISNUMBER($AM40)),OFFSET(RiskMatrixRef,-$AM40+1,AO40-1),"") | AT40: =IF(AND(ISNUMBER(AP40),ISNUMBER($AM40)),OFFSET(RiskMatrixRef,-$AM40+1,AP40-1),"") | AU40: =IF(AND(ISNUMBER(AQ40),ISNUMBER($AM40)),OFFSET(RiskMatrixRef,-$AM40+1,AQ40-1),"") | AW40: Individual controllers have default modes of operation in absense of SCADA comm. | AX40: Occurrence class quite low for corrosion. Manufacturers data to be provided to demonstrate failure rate. Loss of PTO control and safety functions should be higher severity class?
B41: 430-2 | C41: PLC | D41: Issue cooling commands | E41: 1 2 | F41: none Marine application Vibration levels | G41: PLC Failure | H41: 1) PTO command failure 2) Cooling system command failure 3) Alarming failure | I41: Improper installation or manufacturing defect results in failure | J41: Normal | K41: 1) V&V (QC) 2) Redundant SCADA controllers 3) PTO goes to default control mode in absence of SCADA communication | L41: 1) Fault detection of primary PLC | M41: 1) Primary PLC torque command 2) Primary PLC cooling command | N41: Manual in-situ repair and inspection | O41: 5 | P41: 1 | Q41: 1 | R41: 6 | S41: 4 | T41: =IF(AND(ISNUMBER(P41),ISNUMBER($O41)),OFFSET(RiskMatrixRef,-$O41+1,P41-1),"") -> Low | U41: =IF(AND(ISNUMBER(Q41),ISNUMBER($O41)),OFFSET(RiskMatrixRef,-$O41+1,Q41-1),"") -> Low | V41: =IF(AND(ISNUMBER(R41),ISNUMBER($O41)),OFFSET(RiskMatrixRef,-$O41+1,R41-1),"") -> Low | W41: =IF(AND(ISNUMBER(S41),ISNUMBER($O41)),OFFSET(RiskMatrixRef,-$O41+1,S41-1),"") -> Low | AF41: =IF(AND(ISNUMBER(AB41),ISNUMBER($AA41)),OFFSET(RiskMatrixRef,-$AA41+1,AB41-1),"") | AG41: =IF(AND(ISNUMBER(AC41),ISNUMBER($AA41)),OFFSET(RiskMatrixRef,-$AA41+1,AC41-1),"") | AH41: =IF(AND(ISNUMBER(AD41),ISNUMBER($AA41)),OFFSET(RiskMatrixRef,-$AA41+1,AD41-1),"") | AI41: =IF(AND(ISNUMBER(AE41),ISNUMBER($AA41)),OFFSET(RiskMatrixRef,-$AA41+1,AE41-1),"") | AR41: =IF(AND(ISNUMBER(AN41),ISNUMBER($AM41)),OFFSET(RiskMatrixRef,-$AM41+1,AN41-1),"") | AS41: =IF(AND(ISNUMBER(AO41),ISNUMBER($AM41)),OFFSET(RiskMatrixRef,-$AM41+1,AO41-1),"") | AT41: =IF(AND(ISNUMBER(AP41),ISNUMBER($AM41)),OFFSET(RiskMatrixRef,-$AM41+1,AP41-1),"") | AU41: =IF(AND(ISNUMBER(AQ41),ISNUMBER($AM41)),OFFSET(RiskMatrixRef,-$AM41+1,AQ41-1),"") | AW41: Individual controllers have default modes of operation in absense of SCADA comm. | AX41: See comment in Risk ID 410-1.
B42: 430-3 | C42: PLC | D42: Issue PTO commands | E42: 1 2 | F42: none Marine application Vibration levels | G42: PLC Failure | H42: 1) PTO command failure 2) Cooling system command failure 3) Alarming failure | I42: Vibration and/or motion induced failure | J42: Normal | K42: 1) Modal analysis 2) Redundant SCADA controllers 3) PTO goes to default control mode in absence of SCADA communication | L42: 1) Fault detection of primary PLC | M42: 1) Primary PLC torque command 2) Primary PLC cooling command | N42: Manual in-situ repair and inspection | O42: 7 | P42: 1 | Q42: 1 | R42: 6 | S42: 4 | T42: =IF(AND(ISNUMBER(P42),ISNUMBER($O42)),OFFSET(RiskMatrixRef,-$O42+1,P42-1),"") -> Low | U42: =IF(AND(ISNUMBER(Q42),ISNUMBER($O42)),OFFSET(RiskMatrixRef,-$O42+1,Q42-1),"") -> Low | V42: =IF(AND(ISNUMBER(R42),ISNUMBER($O42)),OFFSET(RiskMatrixRef,-$O42+1,R42-1),"") -> Med | W42: =IF(AND(ISNUMBER(S42),ISNUMBER($O42)),OFFSET(RiskMatrixRef,-$O42+1,S42-1),"") -> Low | AF42: =IF(AND(ISNUMBER(AB42),ISNUMBER($AA42)),OFFSET(RiskMatrixRef,-$AA42+1,AB42-1),"") | AG42: =IF(AND(ISNUMBER(AC42),ISNUMBER($AA42)),OFFSET(RiskMatrixRef,-$AA42+1,AC42-1),"") | AH42: =IF(AND(ISNUMBER(AD42),ISNUMBER($AA42)),OFFSET(RiskMatrixRef,-$AA42+1,AD42-1),"") | AI42: =IF(AND(ISNUMBER(AE42),ISNUMBER($AA42)),OFFSET(RiskMatrixRef,-$AA42+1,AE42-1),"") | AR42: =IF(AND(ISNUMBER(AN42),ISNUMBER($AM42)),OFFSET(RiskMatrixRef,-$AM42+1,AN42-1),"") | AS42: =IF(AND(ISNUMBER(AO42),ISNUMBER($AM42)),OFFSET(RiskMatrixRef,-$AM42+1,AO42-1),"") | AT42: =IF(AND(ISNUMBER(AP42),ISNUMBER($AM42)),OFFSET(RiskMatrixRef,-$AM42+1,AP42-1),"") | AU42: =IF(AND(ISNUMBER(AQ42),ISNUMBER($AM42)),OFFSET(RiskMatrixRef,-$AM42+1,AQ42-1),"") | AW42: Individual controllers have default modes of operation in absense of SCADA comm.
...

Sheet version history
A1: Title | B1: StingRAY Control and SCADA FMECA
A2: Doc No | B2: SR-0400-RR
A3: Version | B3: 3.0
A4: Authored | B4: A Schacher
A5: CPwr Review | B5: P Lenee-Bluhm, J Prudell, E Hammagren, Z Zhang, M Ondusko
A6: Expert Review
A7: Eng man Appr
A8: Corp Appr
A11: Version | B11: Date | C11: Summary
A12: 1.0 | B12: 41673 | C12: Released to GH for review
A13: 1.1 | B13: 41716 | C13: Edits following GH review
A14: 2.0 | B14: 41969 | C14: New format and risk ranking, additional input
A15: 3.0 | B15: 42576 | C15: Updated risk matrix, updated for WEC v3.3 technology
A23: The following contains PROTECTED DATA of Columbia Power Technologies, Inc. not for distribution.

Sheet set up
C2: =linkedPage!C2 -> Risk = Occ + Sev | O2: =linkedPage!T2 -> Note:
C3: =linkedPage!C3 -> Severity | O3: =linkedPage!T3 -> - 'set up' and 'linkedPage' are both linked to workbook 'FMECA Master v3.xlsx'
B4: =IF(linkedPage!B4=0,"",linkedPage!B4) -> Occ | C4: =IF(linkedPage!C4=0,"",linkedPage!C4) -> 1 | D4: =IF(linkedPage!D4=0,"",linkedPage!D4) -> 2 | E4: =IF(linkedPage!E4=0,"",linkedPage!E4) -> 3 | F4: =IF(linkedPage!F4=0,"",linkedPage!F4) -> 4 | G4: =IF(linkedPage!G4=0,"",linkedPage!G4) -> 5 | H4: =IF(linkedPage!H4=0,"",linkedPage!H4) -> 6 | I4: =IF(linkedPage!I4=0,"",linkedPage!I4) -> 7 | ... N4: =IF(linkedPage!N4=0,"",linkedPage!N4) | O4: =linkedPage!T4 -> - changes to the tables, risk scores, etc must be made in 'FMECA Master v3.xlsx'
